{
  "version": 8,
  "blockIdVersion": 11,
  "anchorX": 0,
  "anchorY": 0,
  "anchorZ": 0,
  "blocks": [
    {
      "x": -1,
      "y": 1,
      "z": -3,
      "name": "Rock_Magma_Cooled"
    },
    {
      "x": -1,
      "y": 0,
      "z": -2,
      "name": "Ore_Adamantite_Magma_Cracked"
    },
    {
      "x": -1,
      "y": 1,
      "z": -2,
      "name": "Rock_Magma_Cooled"
    },
    {
      "x": -1,
      "y": 2,
      "z": -2,
      "name": "Rock_Magma_Cooled"
    },
    {
      "x": -1,
      "y": 0,
      "z": -1,
      "name": "Rock_Magma_Cooled"
    },
    {
      "x": -1,
      "y": 1,
      "z": -1,
      "name": "Ore_Adamantite_Magma_Cracked"
    },
    {
      "x": -1,
      "y": 2,
      "z": -1,
      "name": "Ore_Adamantite_Magma_Cracked"
    },
    {
      "x": -1,
      "y": 0,
      "z": 0,
      "name": "Rock_Magma_Cooled"
    },
    {
      "x": -1,
      "y": 1,
      "z": 0,
      "name": "Rock_Magma_Cooled_Cobble"
    },
    {
      "x": -1,
      "y": 2,
      "z": 0,
      "name": "Rock_Magma_Cooled_Cobble"
    },
    {
      "x": -1,
      "y": 0,
      "z": 1,
      "name": "Ore_Adamantite_Magma_Cracked"
    },
    {
      "x": -1,
      "y": 1,
      "z": 1,
      "name": "Rock_Magma_Cooled"
    },
    {
      "x": -1,
      "y": 2,
      "z": 1,
      "name": "Ore_Adamantite_Magma_Cracked"
    },
    {
      "x": -1,
      "y": 0,
      "z": 2,
      "name": "Rock_Magma_Cooled"
    },
    {
      "x": -1,
      "y": 1,
      "z": 2,
      "name": "Rock_Magma_Cooled_Cobble"
    },
    {
      "x": -1,
      "y": 2,
      "z": 2,
      "name": "Rock_Magma_Cooled"
    },
    {
      "x": -1,
      "y": 1,
      "z": 3,
      "name": "Rock_Magma_Cooled"
    },
    {
      "x": -1,
      "y": 2,
      "z": 3,
      "name": "Rock_Magma_Cooled"
    },
    {
      "x": 0,
      "y": 1,
      "z": -4,
      "name": "Ore_Adamantite_Magma_Cracked"
    },
    {
      "x": 0,
      "y": 0,
      "z": -3,
      "name": "Ore_Adamantite_Magma_Cracked"
    },
    {
      "x": 0,
      "y": 1,
      "z": -3,
      "name": "Rock_Magma_Cooled_Cobble"
    },
    {
      "x": 0,
      "y": 2,
      "z": -3,
      "name": "Rock_Magma_Cooled"
    },
    {
      "x": 0,
      "y": 0,
      "z": -2,
      "name": "Ore_Adamantite_Magma_Cracked"
    },
    {
      "x": 0,
      "y": 1,
      "z": -2,
      "name": "Rock_Magma_Cooled"
    },
    {
      "x": 0,
      "y": 2,
      "z": -2,
      "name": "Ore_Adamantite_Magma_Cracked"
    },
    {
      "x": 0,
      "y": 0,
      "z": -1,
      "name": "Rock_Magma_Cooled_Cobble"
    },
    {
      "x": 0,
      "y": 1,
      "z": -1,
      "name": "Rock_Magma_Cooled_Cobble"
    },
    {
      "x": 0,
      "y": 2,
      "z": -1,
      "name": "Rock_Magma_Cooled_Cobble"
    },
    {
      "x": 0,
      "y": 3,
      "z": -1,
      "name": "Ore_Adamantite_Magma_Cracked"
    },
    {
      "x": 0,
      "y": 0,
      "z": 0,
      "name": "Rock_Magma_Cooled_Cobble"
    },
    {
      "x": 0,
      "y": 1,
      "z": 0,
      "name": "Ore_Adamantite_Magma_Cracked"
    },
    {
      "x": 0,
      "y": 2,
      "z": 0,
      "name": "Rock_Magma_Cooled_Cobble"
    },
    {
      "x": 0,
      "y": 3,
      "z": 0,
      "name": "Rock_Magma_Cooled"
    },
    {
      "x": 0,
      "y": 0,
      "z": 1,
      "name": "Rock_Magma_Cooled"
    },
    {
      "x": 0,
      "y": 1,
      "z": 1,
      "name": "Ore_Adamantite_Magma_Cracked"
    },
    {
      "x": 0,
      "y": 2,
      "z": 1,
      "name": "Rock_Magma_Cooled"
    },
    {
      "x": 0,
      "y": 3,
      "z": 1,
      "name": "Ore_Adamantite_Magma_Cracked"
    },
    {
      "x": 0,
      "y": 0,
      "z": 2,
      "name": "Ore_Adamantite_Magma_Cracked"
    },
    {
      "x": 0,
      "y": 1,
      "z": 2,
      "name": "Ore_Adamantite_Magma_Cracked"
    },
    {
      "x": 0,
      "y": 2,
      "z": 2,
      "name": "Rock_Magma_Cooled_Cobble"
    },
    {
      "x": 0,
      "y": 0,
      "z": 3,
      "name": "Rock_Magma_Cooled_Cobble"
    },
    {
      "x": 0,
      "y": 1,
      "z": 3,
      "name": "Ore_Adamantite_Magma_Cracked"
    },
    {
      "x": 0,
      "y": 2,
      "z": 3,
      "name": "Ore_Adamantite_Magma_Cracked"
    },
    {
      "x": 0,
      "y": 1,
      "z": 4,
      "name": "Rock_Magma_Cooled"
    },
    {
      "x": 0,
      "y": 2,
      "z": 4,
      "name": "Ore_Adamantite_Magma_Cracked"
    },
    {
      "x": 1,
      "y": 1,
      "z": -4,
      "name": "Rock_Magma_Cooled"
    },
    {
      "x": 1,
      "y": 0,
      "z": -3,
      "name": "Ore_Adamantite_Magma_Cracked"
    },
    {
      "x": 1,
      "y": 1,
      "z": -3,
      "name": "Rock_Magma_Cooled"
    },
    {
      "x": 1,
      "y": 2,
      "z": -3,
      "name": "Ore_Adamantite_Magma_Cracked"
    },
    {
      "x": 1,
      "y": 0,
      "z": -2,
      "name": "Rock_Magma_Cooled"
    },
    {
      "x": 1,
      "y": 1,
      "z": -2,
      "name": "Rock_Magma_Cooled"
    },
    {
      "x": 1,
      "y": 2,
      "z": -2,
      "name": "Ore_Adamantite_Magma_Cracked"
    },
    {
      "x": 1,
      "y": 0,
      "z": -1,
      "name": "Ore_Adamantite_Magma_Cracked"
    },
    {
      "x": 1,
      "y": 1,
      "z": -1,
      "name": "Rock_Magma_Cooled"
    },
    {
      "x": 1,
      "y": 2,
      "z": -1,
      "name": "Ore_Adamantite_Magma_Cracked"
    },
    {
      "x": 1,
      "y": 3,
      "z": -1,
      "name": "Rock_Magma_Cooled"
    },
    {
      "x": 1,
      "y": 0,
      "z": 0,
      "name": "Ore_Adamantite_Magma_Cracked"
    },
    {
      "x": 1,
      "y": 1,
      "z": 0,
      "name": "Rock_Magma_Cooled_Cobble"
    },
    {
      "x": 1,
      "y": 2,
      "z": 0,
      "name": "Rock_Magma_Cooled_Cobble"
    },
    {
      "x": 1,
      "y": 3,
      "z": 0,
      "name": "Rock_Magma_Cooled_Cobble"
    },
    {
      "x": 1,
      "y": 0,
      "z": 1,
      "name": "Ore_Adamantite_Magma_Cracked"
    },
    {
      "x": 1,
      "y": 1,
      "z": 1,
      "name": "Rock_Magma_Cooled_Cobble"
    },
    {
      "x": 1,
      "y": 2,
      "z": 1,
      "name": "Rock_Magma_Cooled"
    },
    {
      "x": 1,
      "y": 3,
      "z": 1,
      "name": "Rock_Magma_Cooled"
    },
    {
      "x": 1,
      "y": 0,
      "z": 2,
      "name": "Rock_Magma_Cooled"
    },
    {
      "x": 1,
      "y": 1,
      "z": 2,
      "name": "Rock_Magma_Cooled_Cobble"
    },
    {
      "x": 1,
      "y": 2,
      "z": 2,
      "name": "Rock_Magma_Cooled"
    },
    {
      "x": 1,
      "y": 3,
      "z": 2,
      "name": "Rock_Magma_Cooled"
    },
    {
      "x": 1,
      "y": 0,
      "z": 3,
      "name": "Rock_Magma_Cooled"
    },
    {
      "x": 1,
      "y": 1,
      "z": 3,
      "name": "Rock_Magma_Cooled"
    },
    {
      "x": 1,
      "y": 2,
      "z": 3,
      "name": "Ore_Adamantite_Magma_Cracked"
    },
    {
      "x": 1,
      "y": 1,
      "z": 4,
      "name": "Rock_Magma_Cooled"
    },
    {
      "x": 1,
      "y": 2,
      "z": 4,
      "name": "Rock_Magma_Cooled_Cobble"
    },
    {
      "x": 2,
      "y": 1,
      "z": -3,
      "name": "Ore_Adamantite_Magma_Cracked"
    },
    {
      "x": 2,
      "y": 0,
      "z": -2,
      "name": "Ore_Adamantite_Magma_Cracked"
    },
    {
      "x": 2,
      "y": 1,
      "z": -2,
      "name": "Ore_Adamantite_Magma_Cracked"
    },
    {
      "x": 2,
      "y": 2,
      "z": -2,
      "name": "Rock_Magma_Cooled_Cobble"
    },
    {
      "x": 2,
      "y": 0,
      "z": -1,
      "name": "Rock_Magma_Cooled_Cobble"
    },
    {
      "x": 2,
      "y": 1,
      "z": -1,
      "name": "Ore_Adamantite_Magma_Cracked"
    },
    {
      "x": 2,
      "y": 2,
      "z": -1,
      "name": "Ore_Adamantite_Magma_Cracked"
    },
    {
      "x": 2,
      "y": 0,
      "z": 0,
      "name": "Rock_Magma_Cooled"
    },
    {
      "x": 2,
      "y": 1,
      "z": 0,
      "name": "Ore_Adamantite_Magma_Cracked"
    },
    {
      "x": 2,
      "y": 2,
      "z": 0,
      "name": "Rock_Magma_Cooled"
    },
    {
      "x": 2,
      "y": 0,
      "z": 1,
      "name": "Rock_Magma_Cooled"
    },
    {
      "x": 2,
      "y": 1,
      "z": 1,
      "name": "Rock_Magma_Cooled_Cobble"
    },
    {
      "x": 2,
      "y": 2,
      "z": 1,
      "name": "Rock_Magma_Cooled_Cobble"
    },
    {
      "x": 2,
      "y": 0,
      "z": 2,
      "name": "Rock_Magma_Cooled_Cobble"
    },
    {
      "x": 2,
      "y": 1,
      "z": 2,
      "name": "Rock_Magma_Cooled"
    },
    {
      "x": 2,
      "y": 2,
      "z": 2,
      "name": "Ore_Adamantite_Magma_Cracked"
    },
    {
      "x": 2,
      "y": 1,
      "z": 3,
      "name": "Rock_Magma_Cooled_Cobble"
    },
    {
      "x": 2,
      "y": 2,
      "z": 3,
      "name": "Ore_Adamantite_Magma_Cracked"
    }
  ],
  "fluids": [
    {
      "x": -1,
      "y": 1,
      "z": -3,
      "name": "Empty",
      "level": 0
    },
    {
      "x": -1,
      "y": 0,
      "z": -2,
      "name": "Empty",
      "level": 0
    },
    {
      "x": -1,
      "y": 1,
      "z": -2,
      "name": "Empty",
      "level": 0
    },
    {
      "x": -1,
      "y": 2,
      "z": -2,
      "name": "Empty",
      "level": 0
    },
    {
      "x": -1,
      "y": 0,
      "z": -1,
      "name": "Empty",
      "level": 0
    },
    {
      "x": -1,
      "y": 1,
      "z": -1,
      "name": "Empty",
      "level": 0
    },
    {
      "x": -1,
      "y": 2,
      "z": -1,
      "name": "Empty",
      "level": 0
    },
    {
      "x": -1,
      "y": 0,
      "z": 0,
      "name": "Empty",
      "level": 0
    },
    {
      "x": -1,
      "y": 1,
      "z": 0,
      "name": "Empty",
      "level": 0
    },
    {
      "x": -1,
      "y": 2,
      "z": 0,
      "name": "Empty",
      "level": 0
    },
    {
      "x": -1,
      "y": 0,
      "z": 1,
      "name": "Empty",
      "level": 0
    },
    {
      "x": -1,
      "y": 1,
      "z": 1,
      "name": "Empty",
      "level": 0
    },
    {
      "x": -1,
      "y": 2,
      "z": 1,
      "name": "Empty",
      "level": 0
    },
    {
      "x": -1,
      "y": 0,
      "z": 2,
      "name": "Empty",
      "level": 0
    },
    {
      "x": -1,
      "y": 1,
      "z": 2,
      "name": "Empty",
      "level": 0
    },
    {
      "x": -1,
      "y": 2,
      "z": 2,
      "name": "Empty",
      "level": 0
    },
    {
      "x": -1,
      "y": 1,
      "z": 3,
      "name": "Empty",
      "level": 0
    },
    {
      "x": -1,
      "y": 2,
      "z": 3,
      "name": "Empty",
      "level": 0
    },
    {
      "x": 0,
      "y": 1,
      "z": -4,
      "name": "Empty",
      "level": 0
    },
    {
      "x": 0,
      "y": 0,
      "z": -3,
      "name": "Empty",
      "level": 0
    },
    {
      "x": 0,
      "y": 1,
      "z": -3,
      "name": "Empty",
      "level": 0
    },
    {
      "x": 0,
      "y": 2,
      "z": -3,
      "name": "Empty",
      "level": 0
    },
    {
      "x": 0,
      "y": 0,
      "z": -2,
      "name": "Empty",
      "level": 0
    },
    {
      "x": 0,
      "y": 1,
      "z": -2,
      "name": "Empty",
      "level": 0
    },
    {
      "x": 0,
      "y": 2,
      "z": -2,
      "name": "Empty",
      "level": 0
    },
    {
      "x": 0,
      "y": 0,
      "z": -1,
      "name": "Empty",
      "level": 0
    },
    {
      "x": 0,
      "y": 1,
      "z": -1,
      "name": "Empty",
      "level": 0
    },
    {
      "x": 0,
      "y": 2,
      "z": -1,
      "name": "Empty",
      "level": 0
    },
    {
      "x": 0,
      "y": 3,
      "z": -1,
      "name": "Empty",
      "level": 0
    },
    {
      "x": 0,
      "y": 0,
      "z": 0,
      "name": "Empty",
      "level": 0
    },
    {
      "x": 0,
      "y": 1,
      "z": 0,
      "name": "Empty",
      "level": 0
    },
    {
      "x": 0,
      "y": 2,
      "z": 0,
      "name": "Empty",
      "level": 0
    },
    {
      "x": 0,
      "y": 3,
      "z": 0,
      "name": "Empty",
      "level": 0
    },
    {
      "x": 0,
      "y": 0,
      "z": 1,
      "name": "Empty",
      "level": 0
    },
    {
      "x": 0,
      "y": 1,
      "z": 1,
      "name": "Empty",
      "level": 0
    },
    {
      "x": 0,
      "y": 2,
      "z": 1,
      "name": "Empty",
      "level": 0
    },
    {
      "x": 0,
      "y": 3,
      "z": 1,
      "name": "Empty",
      "level": 0
    },
    {
      "x": 0,
      "y": 0,
      "z": 2,
      "name": "Empty",
      "level": 0
    },
    {
      "x": 0,
      "y": 1,
      "z": 2,
      "name": "Empty",
      "level": 0
    },
    {
      "x": 0,
      "y": 2,
      "z": 2,
      "name": "Empty",
      "level": 0
    },
    {
      "x": 0,
      "y": 0,
      "z": 3,
      "name": "Empty",
      "level": 0
    },
    {
      "x": 0,
      "y": 1,
      "z": 3,
      "name": "Empty",
      "level": 0
    },
    {
      "x": 0,
      "y": 2,
      "z": 3,
      "name": "Empty",
      "level": 0
    },
    {
      "x": 0,
      "y": 1,
      "z": 4,
      "name": "Empty",
      "level": 0
    },
    {
      "x": 0,
      "y": 2,
      "z": 4,
      "name": "Empty",
      "level": 0
    },
    {
      "x": 1,
      "y": 1,
      "z": -4,
      "name": "Empty",
      "level": 0
    },
    {
      "x": 1,
      "y": 0,
      "z": -3,
      "name": "Empty",
      "level": 0
    },
    {
      "x": 1,
      "y": 1,
      "z": -3,
      "name": "Empty",
      "level": 0
    },
    {
      "x": 1,
      "y": 2,
      "z": -3,
      "name": "Empty",
      "level": 0
    },
    {
      "x": 1,
      "y": 0,
      "z": -2,
      "name": "Empty",
      "level": 0
    },
    {
      "x": 1,
      "y": 1,
      "z": -2,
      "name": "Empty",
      "level": 0
    },
    {
      "x": 1,
      "y": 2,
      "z": -2,
      "name": "Empty",
      "level": 0
    },
    {
      "x": 1,
      "y": 0,
      "z": -1,
      "name": "Empty",
      "level": 0
    },
    {
      "x": 1,
      "y": 1,
      "z": -1,
      "name": "Empty",
      "level": 0
    },
    {
      "x": 1,
      "y": 2,
      "z": -1,
      "name": "Empty",
      "level": 0
    },
    {
      "x": 1,
      "y": 3,
      "z": -1,
      "name": "Empty",
      "level": 0
    },
    {
      "x": 1,
      "y": 0,
      "z": 0,
      "name": "Empty",
      "level": 0
    },
    {
      "x": 1,
      "y": 1,
      "z": 0,
      "name": "Empty",
      "level": 0
    },
    {
      "x": 1,
      "y": 2,
      "z": 0,
      "name": "Empty",
      "level": 0
    },
    {
      "x": 1,
      "y": 3,
      "z": 0,
      "name": "Empty",
      "level": 0
    },
    {
      "x": 1,
      "y": 0,
      "z": 1,
      "name": "Empty",
      "level": 0
    },
    {
      "x": 1,
      "y": 1,
      "z": 1,
      "name": "Empty",
      "level": 0
    },
    {
      "x": 1,
      "y": 2,
      "z": 1,
      "name": "Empty",
      "level": 0
    },
    {
      "x": 1,
      "y": 3,
      "z": 1,
      "name": "Empty",
      "level": 0
    },
    {
      "x": 1,
      "y": 0,
      "z": 2,
      "name": "Empty",
      "level": 0
    },
    {
      "x": 1,
      "y": 1,
      "z": 2,
      "name": "Empty",
      "level": 0
    },
    {
      "x": 1,
      "y": 2,
      "z": 2,
      "name": "Empty",
      "level": 0
    },
    {
      "x": 1,
      "y": 3,
      "z": 2,
      "name": "Empty",
      "level": 0
    },
    {
      "x": 1,
      "y": 0,
      "z": 3,
      "name": "Empty",
      "level": 0
    },
    {
      "x": 1,
      "y": 1,
      "z": 3,
      "name": "Empty",
      "level": 0
    },
    {
      "x": 1,
      "y": 2,
      "z": 3,
      "name": "Empty",
      "level": 0
    },
    {
      "x": 1,
      "y": 1,
      "z": 4,
      "name": "Empty",
      "level": 0
    },
    {
      "x": 1,
      "y": 2,
      "z": 4,
      "name": "Empty",
      "level": 0
    },
    {
      "x": 2,
      "y": 1,
      "z": -3,
      "name": "Empty",
      "level": 0
    },
    {
      "x": 2,
      "y": 0,
      "z": -2,
      "name": "Empty",
      "level": 0
    },
    {
      "x": 2,
      "y": 1,
      "z": -2,
      "name": "Empty",
      "level": 0
    },
    {
      "x": 2,
      "y": 2,
      "z": -2,
      "name": "Empty",
      "level": 0
    },
    {
      "x": 2,
      "y": 0,
      "z": -1,
      "name": "Empty",
      "level": 0
    },
    {
      "x": 2,
      "y": 1,
      "z": -1,
      "name": "Empty",
      "level": 0
    },
    {
      "x": 2,
      "y": 2,
      "z": -1,
      "name": "Empty",
      "level": 0
    },
    {
      "x": 2,
      "y": 0,
      "z": 0,
      "name": "Empty",
      "level": 0
    },
    {
      "x": 2,
      "y": 1,
      "z": 0,
      "name": "Empty",
      "level": 0
    },
    {
      "x": 2,
      "y": 2,
      "z": 0,
      "name": "Empty",
      "level": 0
    },
    {
      "x": 2,
      "y": 0,
      "z": 1,
      "name": "Empty",
      "level": 0
    },
    {
      "x": 2,
      "y": 1,
      "z": 1,
      "name": "Empty",
      "level": 0
    },
    {
      "x": 2,
      "y": 2,
      "z": 1,
      "name": "Empty",
      "level": 0
    },
    {
      "x": 2,
      "y": 0,
      "z": 2,
      "name": "Empty",
      "level": 0
    },
    {
      "x": 2,
      "y": 1,
      "z": 2,
      "name": "Empty",
      "level": 0
    },
    {
      "x": 2,
      "y": 2,
      "z": 2,
      "name": "Empty",
      "level": 0
    },
    {
      "x": 2,
      "y": 1,
      "z": 3,
      "name": "Empty",
      "level": 0
    },
    {
      "x": 2,
      "y": 2,
      "z": 3,
      "name": "Empty",
      "level": 0
    }
  ]
}