{
  "version": 8,
  "blockIdVersion": 11,
  "anchorX": 0,
  "anchorY": 0,
  "anchorZ": 0,
  "blocks": [
    {
      "x": -4,
      "y": 3,
      "z": -1,
      "name": "Soil_Clay_Grey"
    },
    {
      "x": -4,
      "y": 4,
      "z": -1,
      "name": "Soil_Clay_Smooth_Grey"
    },
    {
      "x": -3,
      "y": 4,
      "z": -1,
      "name": "Soil_Clay_Smooth_Grey"
    },
    {
      "x": -3,
      "y": 5,
      "z": -1,
      "name": "Soil_Clay_GreyLight"
    },
    {
      "x": -3,
      "y": 2,
      "z": 0,
      "name": "Soil_Clay_Grey"
    },
    {
      "x": -3,
      "y": 6,
      "z": 1,
      "name": "Soil_Clay_Grey"
    },
    {
      "x": -2,
      "y": 5,
      "z": -1,
      "name": "Soil_Clay_GreyLight"
    },
    {
      "x": -2,
      "y": 1,
      "z": 0,
      "name": "Soil_Clay_Grey"
    },
    {
      "x": -2,
      "y": 2,
      "z": 0,
      "name": "Soil_Clay_Smooth_Grey"
    },
    {
      "x": -2,
      "y": 3,
      "z": 0,
      "name": "Soil_Clay_GreyLight"
    },
    {
      "x": -2,
      "y": 5,
      "z": 1,
      "name": "Soil_Clay_Smooth_Grey"
    },
    {
      "x": -2,
      "y": 6,
      "z": 1,
      "name": "Soil_Clay_Smooth_Grey"
    },
    {
      "x": -1,
      "y": 4,
      "z": -1,
      "name": "Soil_Clay_Smooth_Grey2"
    },
    {
      "x": -1,
      "y": 5,
      "z": -1,
      "name": "Soil_Clay_GreyLight"
    },
    {
      "x": -1,
      "y": 2,
      "z": 0,
      "name": "Soil_Clay_Smooth_Grey2"
    },
    {
      "x": -1,
      "y": 3,
      "z": 0,
      "name": "Soil_Clay_Smooth_Grey2"
    },
    {
      "x": -1,
      "y": 4,
      "z": 0,
      "name": "Soil_Clay_GreyLight"
    },
    {
      "x": -1,
      "y": 5,
      "z": 1,
      "name": "Soil_Clay_Smooth_Grey2"
    },
    {
      "x": -1,
      "y": 6,
      "z": 1,
      "name": "Soil_Clay_GreyLight"
    },
    {
      "x": 0,
      "y": 4,
      "z": -1,
      "name": "Soil_Clay_Smooth_Grey2",
      "support": 15
    },
    {
      "x": 0,
      "y": 5,
      "z": -1,
      "name": "Soil_Clay_GreyLight"
    },
    {
      "x": 0,
      "y": 3,
      "z": 0,
      "name": "Soil_Clay_Smooth_Grey2"
    },
    {
      "x": 0,
      "y": 4,
      "z": 0,
      "name": "Soil_Clay_Smooth_Grey2"
    },
    {
      "x": 0,
      "y": 4,
      "z": 1,
      "name": "Soil_Clay_Smooth_Grey2"
    },
    {
      "x": 0,
      "y": 5,
      "z": 1,
      "name": "Soil_Clay_GreyLight"
    },
    {
      "x": 1,
      "y": 3,
      "z": -1,
      "name": "Soil_Clay_Smooth_Grey2"
    },
    {
      "x": 1,
      "y": 4,
      "z": -1,
      "name": "Soil_Clay_Smooth_Grey2",
      "support": 15
    },
    {
      "x": 1,
      "y": 5,
      "z": -1,
      "name": "Soil_Clay_GreyLight",
      "support": 15
    },
    {
      "x": 1,
      "y": 2,
      "z": 0,
      "name": "Soil_Clay_Smooth_Grey2",
      "support": 15
    },
    {
      "x": 1,
      "y": 3,
      "z": 0,
      "name": "Soil_Clay_Smooth_Grey2"
    },
    {
      "x": 1,
      "y": 4,
      "z": 0,
      "name": "Soil_Clay_Smooth_Grey2"
    },
    {
      "x": 1,
      "y": 3,
      "z": 1,
      "name": "Soil_Clay_Smooth_Grey2"
    },
    {
      "x": 1,
      "y": 4,
      "z": 1,
      "name": "Soil_Clay_Smooth_Grey2"
    },
    {
      "x": 1,
      "y": 5,
      "z": 1,
      "name": "Soil_Clay_GreyLight"
    },
    {
      "x": 2,
      "y": 2,
      "z": -1,
      "name": "Soil_Clay_Smooth_Grey2"
    },
    {
      "x": 2,
      "y": 3,
      "z": -1,
      "name": "Soil_Clay_Smooth_Grey2"
    },
    {
      "x": 2,
      "y": 4,
      "z": -1,
      "name": "Soil_Clay_GreyLight"
    },
    {
      "x": 2,
      "y": 1,
      "z": 0,
      "name": "Soil_Clay_Smooth_Grey2",
      "support": 15
    },
    {
      "x": 2,
      "y": 2,
      "z": 0,
      "name": "Soil_Clay_Smooth_Grey2",
      "support": 15
    },
    {
      "x": 2,
      "y": 3,
      "z": 0,
      "name": "Soil_Clay_Smooth_Grey2",
      "support": 15
    },
    {
      "x": 2,
      "y": 2,
      "z": 1,
      "name": "Soil_Clay_Smooth_Grey2"
    },
    {
      "x": 2,
      "y": 3,
      "z": 1,
      "name": "Soil_Clay_Smooth_Grey2"
    },
    {
      "x": 2,
      "y": 4,
      "z": 1,
      "name": "Soil_Clay_GreyLight"
    },
    {
      "x": 3,
      "y": 1,
      "z": -1,
      "name": "Soil_Clay_Smooth_Grey2"
    },
    {
      "x": 3,
      "y": 2,
      "z": -1,
      "name": "Soil_Clay_Smooth_Grey2"
    },
    {
      "x": 3,
      "y": 3,
      "z": -1,
      "name": "Soil_Clay_GreyLight"
    },
    {
      "x": 3,
      "y": 0,
      "z": 0,
      "name": "Soil_Clay_Smooth_Grey2"
    },
    {
      "x": 3,
      "y": 1,
      "z": 0,
      "name": "Soil_Clay_Smooth_Grey2"
    },
    {
      "x": 3,
      "y": 2,
      "z": 0,
      "name": "Soil_Clay_GreyLight"
    },
    {
      "x": 3,
      "y": 1,
      "z": 1,
      "name": "Soil_Clay_GreyLight"
    },
    {
      "x": 3,
      "y": 2,
      "z": 1,
      "name": "Soil_Clay_GreyLight"
    },
    {
      "x": 3,
      "y": 3,
      "z": 1,
      "name": "Soil_Clay_GreyLight"
    },
    {
      "x": 4,
      "y": 2,
      "z": -1,
      "name": "Soil_Clay_GreyLight"
    },
    {
      "x": 4,
      "y": 0,
      "z": 0,
      "name": "Soil_Clay_GreyLight"
    },
    {
      "x": 4,
      "y": 1,
      "z": 0,
      "name": "Soil_Clay_Smooth_Grey2"
    },
    {
      "x": 4,
      "y": 2,
      "z": 0,
      "name": "Soil_Clay_GreyLight"
    },
    {
      "x": 4,
      "y": 1,
      "z": 1,
      "name": "Soil_Clay_GreyLight"
    },
    {
      "x": 4,
      "y": 2,
      "z": 1,
      "name": "Soil_Clay_GreyLight"
    },
    {
      "x": 5,
      "y": 1,
      "z": -1,
      "name": "Soil_Clay_GreyLight"
    },
    {
      "x": 5,
      "y": 1,
      "z": 0,
      "name": "Soil_Clay_Smooth_Grey2"
    },
    {
      "x": 5,
      "y": 2,
      "z": 0,
      "name": "Soil_Clay_GreyLight",
      "support": 15
    },
    {
      "x": 5,
      "y": 1,
      "z": 1,
      "name": "Soil_Clay_GreyLight"
    }
  ],
  "fluids": [
    {
      "x": -4,
      "y": 3,
      "z": -1,
      "name": "Empty",
      "level": 0
    },
    {
      "x": -4,
      "y": 4,
      "z": -1,
      "name": "Empty",
      "level": 0
    },
    {
      "x": -3,
      "y": 4,
      "z": -1,
      "name": "Empty",
      "level": 0
    },
    {
      "x": -3,
      "y": 5,
      "z": -1,
      "name": "Empty",
      "level": 0
    },
    {
      "x": -3,
      "y": 2,
      "z": 0,
      "name": "Empty",
      "level": 0
    },
    {
      "x": -3,
      "y": 6,
      "z": 1,
      "name": "Empty",
      "level": 0
    },
    {
      "x": -2,
      "y": 5,
      "z": -1,
      "name": "Empty",
      "level": 0
    },
    {
      "x": -2,
      "y": 1,
      "z": 0,
      "name": "Empty",
      "level": 0
    },
    {
      "x": -2,
      "y": 2,
      "z": 0,
      "name": "Empty",
      "level": 0
    },
    {
      "x": -2,
      "y": 3,
      "z": 0,
      "name": "Empty",
      "level": 0
    },
    {
      "x": -2,
      "y": 5,
      "z": 1,
      "name": "Empty",
      "level": 0
    },
    {
      "x": -2,
      "y": 6,
      "z": 1,
      "name": "Empty",
      "level": 0
    },
    {
      "x": -1,
      "y": 4,
      "z": -1,
      "name": "Empty",
      "level": 0
    },
    {
      "x": -1,
      "y": 5,
      "z": -1,
      "name": "Empty",
      "level": 0
    },
    {
      "x": -1,
      "y": 2,
      "z": 0,
      "name": "Empty",
      "level": 0
    },
    {
      "x": -1,
      "y": 3,
      "z": 0,
      "name": "Empty",
      "level": 0
    },
    {
      "x": -1,
      "y": 4,
      "z": 0,
      "name": "Empty",
      "level": 0
    },
    {
      "x": -1,
      "y": 5,
      "z": 1,
      "name": "Empty",
      "level": 0
    },
    {
      "x": -1,
      "y": 6,
      "z": 1,
      "name": "Empty",
      "level": 0
    },
    {
      "x": 0,
      "y": 4,
      "z": -1,
      "name": "Empty",
      "level": 0
    },
    {
      "x": 0,
      "y": 5,
      "z": -1,
      "name": "Empty",
      "level": 0
    },
    {
      "x": 0,
      "y": 3,
      "z": 0,
      "name": "Empty",
      "level": 0
    },
    {
      "x": 0,
      "y": 4,
      "z": 0,
      "name": "Empty",
      "level": 0
    },
    {
      "x": 0,
      "y": 4,
      "z": 1,
      "name": "Empty",
      "level": 0
    },
    {
      "x": 0,
      "y": 5,
      "z": 1,
      "name": "Empty",
      "level": 0
    },
    {
      "x": 1,
      "y": 3,
      "z": -1,
      "name": "Empty",
      "level": 0
    },
    {
      "x": 1,
      "y": 4,
      "z": -1,
      "name": "Empty",
      "level": 0
    },
    {
      "x": 1,
      "y": 5,
      "z": -1,
      "name": "Empty",
      "level": 0
    },
    {
      "x": 1,
      "y": 2,
      "z": 0,
      "name": "Empty",
      "level": 0
    },
    {
      "x": 1,
      "y": 3,
      "z": 0,
      "name": "Empty",
      "level": 0
    },
    {
      "x": 1,
      "y": 4,
      "z": 0,
      "name": "Empty",
      "level": 0
    },
    {
      "x": 1,
      "y": 3,
      "z": 1,
      "name": "Empty",
      "level": 0
    },
    {
      "x": 1,
      "y": 4,
      "z": 1,
      "name": "Empty",
      "level": 0
    },
    {
      "x": 1,
      "y": 5,
      "z": 1,
      "name": "Empty",
      "level": 0
    },
    {
      "x": 2,
      "y": 2,
      "z": -1,
      "name": "Empty",
      "level": 0
    },
    {
      "x": 2,
      "y": 3,
      "z": -1,
      "name": "Empty",
      "level": 0
    },
    {
      "x": 2,
      "y": 4,
      "z": -1,
      "name": "Empty",
      "level": 0
    },
    {
      "x": 2,
      "y": 1,
      "z": 0,
      "name": "Empty",
      "level": 0
    },
    {
      "x": 2,
      "y": 2,
      "z": 0,
      "name": "Empty",
      "level": 0
    },
    {
      "x": 2,
      "y": 3,
      "z": 0,
      "name": "Empty",
      "level": 0
    },
    {
      "x": 2,
      "y": 2,
      "z": 1,
      "name": "Empty",
      "level": 0
    },
    {
      "x": 2,
      "y": 3,
      "z": 1,
      "name": "Empty",
      "level": 0
    },
    {
      "x": 2,
      "y": 4,
      "z": 1,
      "name": "Empty",
      "level": 0
    },
    {
      "x": 3,
      "y": 1,
      "z": -1,
      "name": "Empty",
      "level": 0
    },
    {
      "x": 3,
      "y": 2,
      "z": -1,
      "name": "Empty",
      "level": 0
    },
    {
      "x": 3,
      "y": 3,
      "z": -1,
      "name": "Empty",
      "level": 0
    },
    {
      "x": 3,
      "y": 0,
      "z": 0,
      "name": "Empty",
      "level": 0
    },
    {
      "x": 3,
      "y": 1,
      "z": 0,
      "name": "Empty",
      "level": 0
    },
    {
      "x": 3,
      "y": 2,
      "z": 0,
      "name": "Empty",
      "level": 0
    },
    {
      "x": 3,
      "y": 1,
      "z": 1,
      "name": "Empty",
      "level": 0
    },
    {
      "x": 3,
      "y": 2,
      "z": 1,
      "name": "Empty",
      "level": 0
    },
    {
      "x": 3,
      "y": 3,
      "z": 1,
      "name": "Empty",
      "level": 0
    },
    {
      "x": 4,
      "y": 2,
      "z": -1,
      "name": "Empty",
      "level": 0
    },
    {
      "x": 4,
      "y": 0,
      "z": 0,
      "name": "Empty",
      "level": 0
    },
    {
      "x": 4,
      "y": 1,
      "z": 0,
      "name": "Empty",
      "level": 0
    },
    {
      "x": 4,
      "y": 2,
      "z": 0,
      "name": "Empty",
      "level": 0
    },
    {
      "x": 4,
      "y": 1,
      "z": 1,
      "name": "Empty",
      "level": 0
    },
    {
      "x": 4,
      "y": 2,
      "z": 1,
      "name": "Empty",
      "level": 0
    },
    {
      "x": 5,
      "y": 1,
      "z": -1,
      "name": "Empty",
      "level": 0
    },
    {
      "x": 5,
      "y": 1,
      "z": 0,
      "name": "Empty",
      "level": 0
    },
    {
      "x": 5,
      "y": 2,
      "z": 0,
      "name": "Empty",
      "level": 0
    },
    {
      "x": 5,
      "y": 1,
      "z": 1,
      "name": "Empty",
      "level": 0
    }
  ]
}
