{
  "version": 8,
  "blockIdVersion": 11,
  "anchorX": 0,
  "anchorY": 0,
  "anchorZ": 0,
  "blocks": [
    {
      "x": -6,
      "y": 3,
      "z": -2,
      "name": "Soil_Needles"
    },
    {
      "x": -6,
      "y": 4,
      "z": -2,
      "name": "Soil_Needles"
    },
    {
      "x": -6,
      "y": 3,
      "z": -1,
      "name": "Soil_Needles"
    },
    {
      "x": -6,
      "y": 4,
      "z": -1,
      "name": "Soil_Hive"
    },
    {
      "x": -6,
      "y": 2,
      "z": 0,
      "name": "Plant_Roots_Cave_Small",
      "rotation": 8
    },
    {
      "x": -6,
      "y": 3,
      "z": 0,
      "name": "Soil_Needles"
    },
    {
      "x": -6,
      "y": 3,
      "z": 1,
      "name": "Soil_Needles"
    },
    {
      "x": -6,
      "y": 4,
      "z": 1,
      "name": "Soil_Needles"
    },
    {
      "x": -6,
      "y": 3,
      "z": 2,
      "name": "Soil_Hive"
    },
    {
      "x": -6,
      "y": 4,
      "z": 2,
      "name": "Soil_Needles"
    },
    {
      "x": -5,
      "y": 3,
      "z": -4,
      "name": "Soil_Hive"
    },
    {
      "x": -5,
      "y": 4,
      "z": -4,
      "name": "Soil_Hive"
    },
    {
      "x": -5,
      "y": 3,
      "z": -3,
      "name": "Soil_Needles"
    },
    {
      "x": -5,
      "y": 4,
      "z": -3,
      "name": "Soil_Needles"
    },
    {
      "x": -5,
      "y": 2,
      "z": -2,
      "name": "Soil_Needles"
    },
    {
      "x": -5,
      "y": 4,
      "z": -2,
      "name": "Soil_Grass_Deep"
    },
    {
      "x": -5,
      "y": 2,
      "z": -1,
      "name": "Soil_Needles"
    },
    {
      "x": -5,
      "y": 1,
      "z": 0,
      "name": "Plant_Roots_Cave_Small",
      "rotation": 8
    },
    {
      "x": -5,
      "y": 2,
      "z": 0,
      "name": "Soil_Hive"
    },
    {
      "x": -5,
      "y": 3,
      "z": 0,
      "name": "Soil_Dirt_Lush"
    },
    {
      "x": -5,
      "y": 2,
      "z": 1,
      "name": "Soil_Hive"
    },
    {
      "x": -5,
      "y": 2,
      "z": 2,
      "name": "Soil_Needles"
    },
    {
      "x": -5,
      "y": 4,
      "z": 2,
      "name": "Soil_Grass_Deep"
    },
    {
      "x": -5,
      "y": 5,
      "z": 2,
      "name": "Plant_Bush_Hanging",
      "support": 15
    },
    {
      "x": -5,
      "y": 3,
      "z": 3,
      "name": "Soil_Needles"
    },
    {
      "x": -5,
      "y": 4,
      "z": 3,
      "name": "Soil_Hive"
    },
    {
      "x": -5,
      "y": 3,
      "z": 4,
      "name": "Soil_Needles"
    },
    {
      "x": -5,
      "y": 4,
      "z": 4,
      "name": "Soil_Hive"
    },
    {
      "x": -4,
      "y": 3,
      "z": -5,
      "name": "Soil_Hive"
    },
    {
      "x": -4,
      "y": 4,
      "z": -5,
      "name": "Soil_Hive"
    },
    {
      "x": -4,
      "y": 9,
      "z": -5,
      "name": "Wood_Deadwood_Roof_Hollow",
      "rotation": 2
    },
    {
      "x": -4,
      "y": 2,
      "z": -4,
      "name": "Plant_Roots_Cave_Small",
      "rotation": 8
    },
    {
      "x": -4,
      "y": 3,
      "z": -4,
      "name": "Soil_Needles"
    },
    {
      "x": -4,
      "y": 4,
      "z": -4,
      "name": "Soil_Grass_Deep"
    },
    {
      "x": -4,
      "y": 8,
      "z": -4,
      "name": "Plant_Vine_Wall_Dead",
      "support": 15,
      "rotation": 3
    },
    {
      "x": -4,
      "y": 9,
      "z": -4,
      "name": "Wood_Ash_Branch_Corner",
      "support": 15,
      "rotation": 3
    },
    {
      "x": -4,
      "y": 10,
      "z": -4,
      "name": "Wood_Deadwood_Roof_Steep",
      "rotation": 2
    },
    {
      "x": -4,
      "y": 11,
      "z": -4,
      "name": "Wood_Deadwood_Roof_Steep",
      "filler": 1024,
      "rotation": 2
    },
    {
      "x": -4,
      "y": 1,
      "z": -3,
      "name": "Plant_Roots_Cave_Small",
      "rotation": 8
    },
    {
      "x": -4,
      "y": 2,
      "z": -3,
      "name": "Soil_Needles"
    },
    {
      "x": -4,
      "y": 4,
      "z": -3,
      "name": "Soil_Grass_Deep"
    },
    {
      "x": -4,
      "y": 11,
      "z": -3,
      "name": "Wood_Deadwood_Stairs",
      "rotation": 10
    },
    {
      "x": -4,
      "y": 12,
      "z": -3,
      "name": "Wood_Deadwood_Roof_Steep",
      "rotation": 2
    },
    {
      "x": -4,
      "y": 13,
      "z": -3,
      "name": "Wood_Deadwood_Roof_Steep",
      "filler": 1024,
      "rotation": 2
    },
    {
      "x": -4,
      "y": 2,
      "z": -2,
      "name": "Soil_Hive"
    },
    {
      "x": -4,
      "y": 4,
      "z": -2,
      "name": "Soil_Grass_Deep"
    },
    {
      "x": -4,
      "y": 5,
      "z": -2,
      "name": "Plant_Bush_Hanging",
      "support": 15
    },
    {
      "x": -4,
      "y": 7,
      "z": -2,
      "name": "Plant_Vine_Wall_Dead",
      "support": 15,
      "rotation": 3
    },
    {
      "x": -4,
      "y": 8,
      "z": -2,
      "name": "Plant_Vine_Wall_Dead",
      "support": 15,
      "rotation": 3
    },
    {
      "x": -4,
      "y": 13,
      "z": -2,
      "name": "Wood_Deadwood_Stairs",
      "rotation": 10
    },
    {
      "x": -4,
      "y": 14,
      "z": -2,
      "name": "Wood_Deadwood_Roof",
      "rotation": 2
    },
    {
      "x": -4,
      "y": 0,
      "z": -1,
      "name": "Plant_Roots_Cave_Small",
      "rotation": 8
    },
    {
      "x": -4,
      "y": 1,
      "z": -1,
      "name": "Soil_Needles"
    },
    {
      "x": -4,
      "y": 4,
      "z": -1,
      "name": "Soil_Grass_Deep"
    },
    {
      "x": -4,
      "y": 14,
      "z": -1,
      "name": "Wood_Deadwood_Stairs",
      "rotation": 10
    },
    {
      "x": -4,
      "y": 15,
      "z": -1,
      "name": "Wood_Deadwood_Roof",
      "rotation": 2
    },
    {
      "x": -4,
      "y": 1,
      "z": 0,
      "name": "Soil_Needles"
    },
    {
      "x": -4,
      "y": 12,
      "z": 0,
      "name": "Plant_Vine_Wall_Dead",
      "support": 15,
      "rotation": 3
    },
    {
      "x": -4,
      "y": 15,
      "z": 0,
      "name": "Wood_Deadwood_Planks"
    },
    {
      "x": -4,
      "y": 16,
      "z": 0,
      "name": "Wood_Deadwood_Roof_Flat"
    },
    {
      "x": -4,
      "y": 0,
      "z": 1,
      "name": "Plant_Roots_Cave_Small",
      "rotation": 8
    },
    {
      "x": -4,
      "y": 1,
      "z": 1,
      "name": "Soil_Needles"
    },
    {
      "x": -4,
      "y": 4,
      "z": 1,
      "name": "Soil_Grass_Deep"
    },
    {
      "x": -4,
      "y": 14,
      "z": 1,
      "name": "Wood_Deadwood_Stairs",
      "rotation": 8
    },
    {
      "x": -4,
      "y": 15,
      "z": 1,
      "name": "Wood_Deadwood_Roof"
    },
    {
      "x": -4,
      "y": 1,
      "z": 2,
      "name": "Plant_Roots_Cave_Small",
      "rotation": 8
    },
    {
      "x": -4,
      "y": 2,
      "z": 2,
      "name": "Soil_Needles"
    },
    {
      "x": -4,
      "y": 4,
      "z": 2,
      "name": "Soil_Grass_Deep"
    },
    {
      "x": -4,
      "y": 8,
      "z": 2,
      "name": "Plant_Vine_Wall_Dead",
      "support": 15,
      "rotation": 3
    },
    {
      "x": -4,
      "y": 13,
      "z": 2,
      "name": "Wood_Deadwood_Stairs",
      "rotation": 8
    },
    {
      "x": -4,
      "y": 14,
      "z": 2,
      "name": "Wood_Deadwood_Roof"
    },
    {
      "x": -4,
      "y": 2,
      "z": 3,
      "name": "Soil_Needles"
    },
    {
      "x": -4,
      "y": 4,
      "z": 3,
      "name": "Soil_Grass_Deep"
    },
    {
      "x": -4,
      "y": 11,
      "z": 3,
      "name": "Wood_Deadwood_Stairs",
      "rotation": 8
    },
    {
      "x": -4,
      "y": 12,
      "z": 3,
      "name": "Wood_Deadwood_Roof_Steep"
    },
    {
      "x": -4,
      "y": 13,
      "z": 3,
      "name": "Wood_Deadwood_Roof_Steep",
      "filler": 1024
    },
    {
      "x": -4,
      "y": 2,
      "z": 4,
      "name": "Plant_Roots_Cave_Small",
      "rotation": 8
    },
    {
      "x": -4,
      "y": 3,
      "z": 4,
      "name": "Soil_Needles"
    },
    {
      "x": -4,
      "y": 4,
      "z": 4,
      "name": "Soil_Grass_Deep"
    },
    {
      "x": -4,
      "y": 9,
      "z": 4,
      "name": "Wood_Ash_Branch_Corner",
      "support": 15,
      "rotation": 3
    },
    {
      "x": -4,
      "y": 10,
      "z": 4,
      "name": "Wood_Deadwood_Roof_Steep"
    },
    {
      "x": -4,
      "y": 11,
      "z": 4,
      "name": "Wood_Deadwood_Roof_Steep",
      "filler": 1024
    },
    {
      "x": -4,
      "y": 3,
      "z": 5,
      "name": "Soil_Hive"
    },
    {
      "x": -4,
      "y": 4,
      "z": 5,
      "name": "Soil_Hive"
    },
    {
      "x": -4,
      "y": 9,
      "z": 5,
      "name": "Wood_Deadwood_Roof_Hollow"
    },
    {
      "x": -3,
      "y": 3,
      "z": -5,
      "name": "Soil_Hive"
    },
    {
      "x": -3,
      "y": 4,
      "z": -5,
      "name": "Soil_Hive"
    },
    {
      "x": -3,
      "y": 6,
      "z": -5,
      "name": "Plant_Vine_Wall_Dead",
      "support": 15,
      "rotation": 2
    },
    {
      "x": -3,
      "y": 8,
      "z": -5,
      "name": "Wood_Ash_Branch_Corner",
      "support": 15,
      "rotation": 2
    },
    {
      "x": -3,
      "y": 9,
      "z": -5,
      "name": "Wood_Deadwood_Roof",
      "rotation": 2
    },
    {
      "x": -3,
      "y": 2,
      "z": -4,
      "name": "Soil_Hive"
    },
    {
      "x": -3,
      "y": 4,
      "z": -4,
      "name": "Soil_Dirt_Lush"
    },
    {
      "x": -3,
      "y": 5,
      "z": -4,
      "name": "Wood_Ash_Trunk_Full",
      "support": 15
    },
    {
      "x": -3,
      "y": 6,
      "z": -4,
      "name": "Wood_Ash_Trunk_Full",
      "support": 15
    },
    {
      "x": -3,
      "y": 7,
      "z": -4,
      "name": "Wood_Ash_Trunk_Full",
      "support": 15
    },
    {
      "x": -3,
      "y": 8,
      "z": -4,
      "name": "Wood_Ash_Trunk_Full",
      "support": 15
    },
    {
      "x": -3,
      "y": 9,
      "z": -4,
      "name": "Wood_Ash_Trunk_Full",
      "support": 15
    },
    {
      "x": -3,
      "y": 10,
      "z": -4,
      "name": "Wood_Deadwood_Roof_Steep",
      "rotation": 2
    },
    {
      "x": -3,
      "y": 11,
      "z": -4,
      "name": "Wood_Deadwood_Roof_Steep",
      "filler": 1024,
      "rotation": 2
    },
    {
      "x": -3,
      "y": 2,
      "z": -3,
      "name": "Soil_Needles"
    },
    {
      "x": -3,
      "y": 4,
      "z": -3,
      "name": "Soil_Dirt_Lush"
    },
    {
      "x": -3,
      "y": 5,
      "z": -3,
      "name": "Rock_Basalt_Brick"
    },
    {
      "x": -3,
      "y": 6,
      "z": -3,
      "name": "*Wood_Village_Wall_GreyDark_Full_State_Definitions_Bottom"
    },
    {
      "x": -3,
      "y": 7,
      "z": -3,
      "name": "*Wood_Village_Wall_GreyDark_Full_State_Definitions_Middle"
    },
    {
      "x": -3,
      "y": 8,
      "z": -3,
      "name": "*Wood_Village_Wall_GreyDark_Full_State_Definitions_Middle"
    },
    {
      "x": -3,
      "y": 9,
      "z": -3,
      "name": "*Wood_Village_Wall_GreyDark_Full_State_Definitions_Top"
    },
    {
      "x": -3,
      "y": 10,
      "z": -3,
      "name": "Wood_Ash_Trunk_Full",
      "support": 15
    },
    {
      "x": -3,
      "y": 11,
      "z": -3,
      "name": "Wood_Ash_Trunk_Full",
      "support": 15
    },
    {
      "x": -3,
      "y": 12,
      "z": -3,
      "name": "Wood_Deadwood_Roof_Steep",
      "rotation": 2
    },
    {
      "x": -3,
      "y": 13,
      "z": -3,
      "name": "Wood_Deadwood_Roof_Steep",
      "filler": 1024,
      "rotation": 2
    },
    {
      "x": -3,
      "y": 1,
      "z": -2,
      "name": "Soil_Hive"
    },
    {
      "x": -3,
      "y": 4,
      "z": -2,
      "name": "Soil_Dirt_Lush"
    },
    {
      "x": -3,
      "y": 5,
      "z": -2,
      "name": "Rock_Basalt_Brick"
    },
    {
      "x": -3,
      "y": 6,
      "z": -2,
      "name": "*Wood_Village_Wall_GreyDark_Full_State_Definitions_Bottom"
    },
    {
      "x": -3,
      "y": 7,
      "z": -2,
      "name": "*Wood_Village_Wall_GreyDark_Full_State_Definitions_Middle"
    },
    {
      "x": -3,
      "y": 8,
      "z": -2,
      "name": "*Wood_Village_Wall_GreyDark_Full_State_Definitions_Middle"
    },
    {
      "x": -3,
      "y": 9,
      "z": -2,
      "name": "*Wood_Village_Wall_GreyDark_Full_State_Definitions_Middle"
    },
    {
      "x": -3,
      "y": 10,
      "z": -2,
      "name": "*Wood_Village_Wall_GreyDark_Full_State_Definitions_Middle"
    },
    {
      "x": -3,
      "y": 11,
      "z": -2,
      "name": "*Wood_Village_Wall_GreyDark_Full_State_Definitions_Top"
    },
    {
      "x": -3,
      "y": 12,
      "z": -2,
      "name": "Wood_Ash_Trunk_Full",
      "support": 15
    },
    {
      "x": -3,
      "y": 13,
      "z": -2,
      "name": "Wood_Ash_Trunk_Full",
      "support": 15
    },
    {
      "x": -3,
      "y": 14,
      "z": -2,
      "name": "Wood_Deadwood_Roof",
      "rotation": 2
    },
    {
      "x": -3,
      "y": 1,
      "z": -1,
      "name": "Soil_Needles"
    },
    {
      "x": -3,
      "y": 4,
      "z": -1,
      "name": "Soil_Dirt_Lush"
    },
    {
      "x": -3,
      "y": 5,
      "z": -1,
      "name": "Rock_Basalt_Brick"
    },
    {
      "x": -3,
      "y": 6,
      "z": -1,
      "name": "Wood_Village_Wall_GreyDark_Full"
    },
    {
      "x": -3,
      "y": 7,
      "z": -1,
      "name": "Furniture_Human_Ruins_Window",
      "rotation": 1
    },
    {
      "x": -3,
      "y": 8,
      "z": -1,
      "name": "Furniture_Human_Ruins_Window",
      "rotation": 1
    },
    {
      "x": -3,
      "y": 9,
      "z": -1,
      "name": "Furniture_Human_Ruins_Window",
      "rotation": 1
    },
    {
      "x": -3,
      "y": 10,
      "z": -1,
      "name": "*Wood_Village_Wall_GreyDark_Full_State_Definitions_Bottom"
    },
    {
      "x": -3,
      "y": 11,
      "z": -1,
      "name": "*Wood_Village_Wall_GreyDark_Full_State_Definitions_Middle"
    },
    {
      "x": -3,
      "y": 12,
      "z": -1,
      "name": "*Wood_Village_Wall_GreyDark_Full_State_Definitions_Middle"
    },
    {
      "x": -3,
      "y": 13,
      "z": -1,
      "name": "*Wood_Village_Wall_GreyDark_Full_State_Definitions_Top"
    },
    {
      "x": -3,
      "y": 14,
      "z": -1,
      "name": "Wood_Ash_Trunk_Full",
      "support": 15
    },
    {
      "x": -3,
      "y": 15,
      "z": -1,
      "name": "Wood_Deadwood_Roof",
      "rotation": 2
    },
    {
      "x": -3,
      "y": 1,
      "z": 0,
      "name": "Soil_Hive"
    },
    {
      "x": -3,
      "y": 4,
      "z": 0,
      "name": "Soil_Dirt_Lush"
    },
    {
      "x": -3,
      "y": 5,
      "z": 0,
      "name": "Rock_Basalt_Brick"
    },
    {
      "x": -3,
      "y": 6,
      "z": 0,
      "name": "Wood_Village_Wall_GreyDark_Full"
    },
    {
      "x": -3,
      "y": 7,
      "z": 0,
      "name": "Furniture_Human_Ruins_Window",
      "rotation": 1
    },
    {
      "x": -3,
      "y": 8,
      "z": 0,
      "name": "Furniture_Human_Ruins_Window",
      "rotation": 1
    },
    {
      "x": -3,
      "y": 9,
      "z": 0,
      "name": "Furniture_Human_Ruins_Window",
      "rotation": 1
    },
    {
      "x": -3,
      "y": 10,
      "z": 0,
      "name": "Furniture_Human_Ruins_Window",
      "rotation": 1
    },
    {
      "x": -3,
      "y": 11,
      "z": 0,
      "name": "*Wood_Village_Wall_GreyDark_Full_State_Definitions_Bottom"
    },
    {
      "x": -3,
      "y": 12,
      "z": 0,
      "name": "*Wood_Village_Wall_GreyDark_Full_State_Definitions_Middle"
    },
    {
      "x": -3,
      "y": 13,
      "z": 0,
      "name": "*Wood_Village_Wall_GreyDark_Full_State_Definitions_Middle"
    },
    {
      "x": -3,
      "y": 14,
      "z": 0,
      "name": "*Wood_Village_Wall_GreyDark_Full_State_Definitions_Top"
    },
    {
      "x": -3,
      "y": 15,
      "z": 0,
      "name": "Wood_Ash_Trunk_Full",
      "support": 15
    },
    {
      "x": -3,
      "y": 16,
      "z": 0,
      "name": "Wood_Deadwood_Roof_Flat"
    },
    {
      "x": -3,
      "y": 1,
      "z": 1,
      "name": "Soil_Needles"
    },
    {
      "x": -3,
      "y": 4,
      "z": 1,
      "name": "Soil_Dirt_Lush"
    },
    {
      "x": -3,
      "y": 5,
      "z": 1,
      "name": "Rock_Basalt_Brick"
    },
    {
      "x": -3,
      "y": 6,
      "z": 1,
      "name": "Wood_Village_Wall_GreyDark_Full"
    },
    {
      "x": -3,
      "y": 7,
      "z": 1,
      "name": "Furniture_Human_Ruins_Window",
      "rotation": 1
    },
    {
      "x": -3,
      "y": 8,
      "z": 1,
      "name": "Furniture_Human_Ruins_Window",
      "rotation": 1
    },
    {
      "x": -3,
      "y": 9,
      "z": 1,
      "name": "Furniture_Human_Ruins_Window",
      "rotation": 1
    },
    {
      "x": -3,
      "y": 10,
      "z": 1,
      "name": "*Wood_Village_Wall_GreyDark_Full_State_Definitions_Bottom"
    },
    {
      "x": -3,
      "y": 11,
      "z": 1,
      "name": "*Wood_Village_Wall_GreyDark_Full_State_Definitions_Middle"
    },
    {
      "x": -3,
      "y": 12,
      "z": 1,
      "name": "*Wood_Village_Wall_GreyDark_Full_State_Definitions_Middle"
    },
    {
      "x": -3,
      "y": 13,
      "z": 1,
      "name": "*Wood_Village_Wall_GreyDark_Full_State_Definitions_Top"
    },
    {
      "x": -3,
      "y": 14,
      "z": 1,
      "name": "Wood_Ash_Trunk_Full",
      "support": 15
    },
    {
      "x": -3,
      "y": 15,
      "z": 1,
      "name": "Wood_Deadwood_Roof"
    },
    {
      "x": -3,
      "y": 1,
      "z": 2,
      "name": "Soil_Needles"
    },
    {
      "x": -3,
      "y": 4,
      "z": 2,
      "name": "Soil_Dirt_Lush"
    },
    {
      "x": -3,
      "y": 5,
      "z": 2,
      "name": "Rock_Basalt_Brick"
    },
    {
      "x": -3,
      "y": 6,
      "z": 2,
      "name": "*Wood_Village_Wall_GreyDark_Full_State_Definitions_Bottom"
    },
    {
      "x": -3,
      "y": 7,
      "z": 2,
      "name": "*Wood_Village_Wall_GreyDark_Full_State_Definitions_Middle"
    },
    {
      "x": -3,
      "y": 8,
      "z": 2,
      "name": "*Wood_Village_Wall_GreyDark_Full_State_Definitions_Middle"
    },
    {
      "x": -3,
      "y": 9,
      "z": 2,
      "name": "*Wood_Village_Wall_GreyDark_Full_State_Definitions_Middle"
    },
    {
      "x": -3,
      "y": 10,
      "z": 2,
      "name": "*Wood_Village_Wall_GreyDark_Full_State_Definitions_Middle"
    },
    {
      "x": -3,
      "y": 11,
      "z": 2,
      "name": "*Wood_Village_Wall_GreyDark_Full_State_Definitions_Top"
    },
    {
      "x": -3,
      "y": 12,
      "z": 2,
      "name": "Wood_Ash_Trunk_Full",
      "support": 15
    },
    {
      "x": -3,
      "y": 13,
      "z": 2,
      "name": "Wood_Ash_Trunk_Full",
      "support": 15
    },
    {
      "x": -3,
      "y": 14,
      "z": 2,
      "name": "Wood_Deadwood_Roof"
    },
    {
      "x": -3,
      "y": 2,
      "z": 3,
      "name": "Soil_Needles"
    },
    {
      "x": -3,
      "y": 4,
      "z": 3,
      "name": "Soil_Dirt_Lush"
    },
    {
      "x": -3,
      "y": 5,
      "z": 3,
      "name": "Rock_Basalt_Brick"
    },
    {
      "x": -3,
      "y": 6,
      "z": 3,
      "name": "*Wood_Village_Wall_GreyDark_Full_State_Definitions_Bottom"
    },
    {
      "x": -3,
      "y": 7,
      "z": 3,
      "name": "*Wood_Village_Wall_GreyDark_Full_State_Definitions_Middle"
    },
    {
      "x": -3,
      "y": 8,
      "z": 3,
      "name": "*Wood_Village_Wall_GreyDark_Full_State_Definitions_Middle"
    },
    {
      "x": -3,
      "y": 9,
      "z": 3,
      "name": "*Wood_Village_Wall_GreyDark_Full_State_Definitions_Top"
    },
    {
      "x": -3,
      "y": 10,
      "z": 3,
      "name": "Wood_Ash_Trunk_Full",
      "support": 15
    },
    {
      "x": -3,
      "y": 11,
      "z": 3,
      "name": "Wood_Ash_Trunk_Full",
      "support": 15
    },
    {
      "x": -3,
      "y": 12,
      "z": 3,
      "name": "Wood_Deadwood_Roof_Steep"
    },
    {
      "x": -3,
      "y": 13,
      "z": 3,
      "name": "Wood_Deadwood_Roof_Steep",
      "filler": 1024
    },
    {
      "x": -3,
      "y": 2,
      "z": 4,
      "name": "Soil_Needles"
    },
    {
      "x": -3,
      "y": 4,
      "z": 4,
      "name": "Soil_Dirt_Lush"
    },
    {
      "x": -3,
      "y": 5,
      "z": 4,
      "name": "Wood_Ash_Trunk_Full",
      "support": 15
    },
    {
      "x": -3,
      "y": 6,
      "z": 4,
      "name": "Wood_Ash_Trunk_Full",
      "support": 15
    },
    {
      "x": -3,
      "y": 7,
      "z": 4,
      "name": "Wood_Ash_Trunk_Full",
      "support": 15
    },
    {
      "x": -3,
      "y": 8,
      "z": 4,
      "name": "Wood_Ash_Trunk_Full",
      "support": 15
    },
    {
      "x": -3,
      "y": 9,
      "z": 4,
      "name": "Wood_Ash_Trunk_Full",
      "support": 15
    },
    {
      "x": -3,
      "y": 10,
      "z": 4,
      "name": "Wood_Deadwood_Roof_Steep"
    },
    {
      "x": -3,
      "y": 11,
      "z": 4,
      "name": "Wood_Deadwood_Roof_Steep",
      "filler": 1024
    },
    {
      "x": -3,
      "y": 3,
      "z": 5,
      "name": "Soil_Hive"
    },
    {
      "x": -3,
      "y": 4,
      "z": 5,
      "name": "Soil_Needles"
    },
    {
      "x": -3,
      "y": 7,
      "z": 5,
      "name": "Plant_Vine_Wall_Dead",
      "support": 15
    },
    {
      "x": -3,
      "y": 8,
      "z": 5,
      "name": "Wood_Ash_Branch_Corner",
      "support": 15
    },
    {
      "x": -3,
      "y": 9,
      "z": 5,
      "name": "Wood_Deadwood_Roof"
    },
    {
      "x": -2,
      "y": 3,
      "z": -6,
      "name": "Soil_Needles"
    },
    {
      "x": -2,
      "y": 4,
      "z": -6,
      "name": "Soil_Hive"
    },
    {
      "x": -2,
      "y": 2,
      "z": -5,
      "name": "Soil_Needles"
    },
    {
      "x": -2,
      "y": 4,
      "z": -5,
      "name": "Soil_Grass_Deep"
    },
    {
      "x": -2,
      "y": 9,
      "z": -5,
      "name": "Wood_Deadwood_Roof_Hollow",
      "rotation": 2
    },
    {
      "x": -2,
      "y": 4,
      "z": -4,
      "name": "Soil_Dirt_Lush"
    },
    {
      "x": -2,
      "y": 5,
      "z": -4,
      "name": "Rock_Basalt_Brick"
    },
    {
      "x": -2,
      "y": 6,
      "z": -4,
      "name": "*Wood_Village_Wall_GreyDark_Full_State_Definitions_Bottom"
    },
    {
      "x": -2,
      "y": 7,
      "z": -4,
      "name": "*Wood_Village_Wall_GreyDark_Full_State_Definitions_Middle"
    },
    {
      "x": -2,
      "y": 8,
      "z": -4,
      "name": "*Wood_Village_Wall_GreyDark_Full_State_Definitions_Top"
    },
    {
      "x": -2,
      "y": 9,
      "z": -4,
      "name": "Wood_Ash_Trunk_Full",
      "support": 15,
      "rotation": 5
    },
    {
      "x": -2,
      "y": 10,
      "z": -4,
      "name": "Wood_Deadwood_Roof_Steep",
      "rotation": 2
    },
    {
      "x": -2,
      "y": 11,
      "z": -4,
      "name": "Wood_Deadwood_Roof_Steep",
      "filler": 1024,
      "rotation": 2
    },
    {
      "x": -2,
      "y": 1,
      "z": -3,
      "name": "Soil_Hive"
    },
    {
      "x": -2,
      "y": 4,
      "z": -3,
      "name": "Wood_Deadwood_Planks",
      "support": 15
    },
    {
      "x": -2,
      "y": 5,
      "z": -3,
      "name": "Furniture_Human_Ruins_Chest_Large",
      "filler": 31
    },
    {
      "x": -2,
      "y": 11,
      "z": -3,
      "name": "Wood_Deadwood_Stairs",
      "rotation": 10
    },
    {
      "x": -2,
      "y": 12,
      "z": -3,
      "name": "Wood_Deadwood_Roof_Steep",
      "rotation": 2
    },
    {
      "x": -2,
      "y": 13,
      "z": -3,
      "name": "Wood_Deadwood_Roof_Steep",
      "filler": 1024,
      "rotation": 2
    },
    {
      "x": -2,
      "y": 1,
      "z": -2,
      "name": "Soil_Needles"
    },
    {
      "x": -2,
      "y": 4,
      "z": -2,
      "name": "Wood_Deadwood_Planks",
      "support": 15
    },
    {
      "x": -2,
      "y": 13,
      "z": -2,
      "name": "Wood_Deadwood_Stairs",
      "rotation": 10
    },
    {
      "x": -2,
      "y": 14,
      "z": -2,
      "name": "Wood_Deadwood_Roof",
      "rotation": 2
    },
    {
      "x": -2,
      "y": 1,
      "z": -1,
      "name": "Soil_Needles"
    },
    {
      "x": -2,
      "y": 4,
      "z": -1,
      "name": "Wood_Deadwood_Planks",
      "support": 15
    },
    {
      "x": -2,
      "y": 5,
      "z": -1,
      "name": "Bench_Furnace",
      "components": {
        "Components": {
          "BenchBlock": {
            "TierLevel": 1,
            "UpgradeItems": []
          },
          "ProcessingBenchBlock": {
            "InputContainer": {
              "Id": "Simple",
              "Capacity": 2,
              "Items": {}
            },
            "FuelContainer": {
              "Id": "Simple",
              "Capacity": 1,
              "Items": {}
            },
            "OutputContainer": {
              "Id": "Simple",
              "Capacity": 4,
              "Items": {}
            },
            "Progress": 0.0,
            "FuelTime": 0.0,
            "Active": false,
            "NextExtra": 2,
            "LastTickGameTime": "0001-01-23T12:00:00Z"
          },
          "PlacedByInteraction": {
            "WhoPlacedUuid": {
              "$binary": "v7RyWIT/TYKnXA2XcxdQtw==",
              "$type": "04"
            }
          }
        }
      },
      "rotation": 1
    },
    {
      "x": -2,
      "y": 6,
      "z": -1,
      "name": "Bench_Furnace",
      "filler": 1024,
      "rotation": 1
    },
    {
      "x": -2,
      "y": 14,
      "z": -1,
      "name": "Wood_Deadwood_Stairs",
      "rotation": 10
    },
    {
      "x": -2,
      "y": 15,
      "z": -1,
      "name": "Wood_Deadwood_Roof",
      "rotation": 2
    },
    {
      "x": -2,
      "y": 1,
      "z": 0,
      "name": "Soil_Hive"
    },
    {
      "x": -2,
      "y": 4,
      "z": 0,
      "name": "Wood_Deadwood_Planks",
      "support": 15
    },
    {
      "x": -2,
      "y": 5,
      "z": 0,
      "name": "Bench_Furnace",
      "filler": 32,
      "rotation": 1
    },
    {
      "x": -2,
      "y": 6,
      "z": 0,
      "name": "Bench_Furnace",
      "filler": 1056,
      "rotation": 1
    },
    {
      "x": -2,
      "y": 15,
      "z": 0,
      "name": "Wood_Ash_Trunk_Full",
      "support": 15,
      "rotation": 5
    },
    {
      "x": -2,
      "y": 16,
      "z": 0,
      "name": "Wood_Deadwood_Roof_Flat"
    },
    {
      "x": -2,
      "y": 1,
      "z": 1,
      "name": "Soil_Needles"
    },
    {
      "x": -2,
      "y": 4,
      "z": 1,
      "name": "Wood_Deadwood_Planks",
      "support": 15
    },
    {
      "x": -2,
      "y": 14,
      "z": 1,
      "name": "Wood_Deadwood_Stairs",
      "rotation": 8
    },
    {
      "x": -2,
      "y": 15,
      "z": 1,
      "name": "Wood_Deadwood_Roof"
    },
    {
      "x": -2,
      "y": 1,
      "z": 2,
      "name": "Soil_Needles"
    },
    {
      "x": -2,
      "y": 4,
      "z": 2,
      "name": "Wood_Deadwood_Planks",
      "support": 15
    },
    {
      "x": -2,
      "y": 5,
      "z": 2,
      "name": "Furniture_Human_Ruins_Bed",
      "filler": 992,
      "rotation": 1
    },
    {
      "x": -2,
      "y": 6,
      "z": 2,
      "name": "Furniture_Human_Ruins_Bed",
      "filler": 2016,
      "rotation": 1
    },
    {
      "x": -2,
      "y": 13,
      "z": 2,
      "name": "Wood_Deadwood_Stairs",
      "rotation": 8
    },
    {
      "x": -2,
      "y": 14,
      "z": 2,
      "name": "Wood_Deadwood_Roof"
    },
    {
      "x": -2,
      "y": 1,
      "z": 3,
      "name": "Soil_Needles"
    },
    {
      "x": -2,
      "y": 4,
      "z": 3,
      "name": "Wood_Deadwood_Planks",
      "support": 15
    },
    {
      "x": -2,
      "y": 5,
      "z": 3,
      "name": "Furniture_Human_Ruins_Bed",
      "components": {
        "Components": {
          "PlacedByInteraction": {
            "WhoPlacedUuid": {
              "$binary": "v7RyWIT/TYKnXA2XcxdQtw==",
              "$type": "04"
            }
          },
          "RespawnBlock": {}
        }
      },
      "rotation": 1
    },
    {
      "x": -2,
      "y": 6,
      "z": 3,
      "name": "Furniture_Human_Ruins_Bed",
      "filler": 1024,
      "rotation": 1
    },
    {
      "x": -2,
      "y": 11,
      "z": 3,
      "name": "Wood_Deadwood_Stairs",
      "rotation": 8
    },
    {
      "x": -2,
      "y": 12,
      "z": 3,
      "name": "Wood_Deadwood_Roof_Steep"
    },
    {
      "x": -2,
      "y": 13,
      "z": 3,
      "name": "Wood_Deadwood_Roof_Steep",
      "filler": 1024
    },
    {
      "x": -2,
      "y": 4,
      "z": 4,
      "name": "Soil_Dirt_Lush"
    },
    {
      "x": -2,
      "y": 5,
      "z": 4,
      "name": "Rock_Basalt_Brick"
    },
    {
      "x": -2,
      "y": 6,
      "z": 4,
      "name": "*Wood_Village_Wall_GreyDark_Full_State_Definitions_Bottom"
    },
    {
      "x": -2,
      "y": 7,
      "z": 4,
      "name": "*Wood_Village_Wall_GreyDark_Full_State_Definitions_Middle"
    },
    {
      "x": -2,
      "y": 8,
      "z": 4,
      "name": "*Wood_Village_Wall_GreyDark_Full_State_Definitions_Top"
    },
    {
      "x": -2,
      "y": 9,
      "z": 4,
      "name": "Wood_Ash_Trunk_Full",
      "support": 15,
      "rotation": 5
    },
    {
      "x": -2,
      "y": 10,
      "z": 4,
      "name": "Wood_Deadwood_Roof_Steep"
    },
    {
      "x": -2,
      "y": 11,
      "z": 4,
      "name": "Wood_Deadwood_Roof_Steep",
      "filler": 1024
    },
    {
      "x": -2,
      "y": 2,
      "z": 5,
      "name": "Soil_Needles"
    },
    {
      "x": -2,
      "y": 4,
      "z": 5,
      "name": "Soil_Grass_Deep"
    },
    {
      "x": -2,
      "y": 9,
      "z": 5,
      "name": "Wood_Deadwood_Roof_Hollow"
    },
    {
      "x": -2,
      "y": 3,
      "z": 6,
      "name": "Soil_Needles"
    },
    {
      "x": -2,
      "y": 4,
      "z": 6,
      "name": "Soil_Hive"
    },
    {
      "x": -2,
      "y": 5,
      "z": 6,
      "name": "Plant_Bush_Hanging",
      "support": 15
    },
    {
      "x": -1,
      "y": 3,
      "z": -6,
      "name": "Soil_Hive"
    },
    {
      "x": -1,
      "y": 4,
      "z": -6,
      "name": "Soil_Needles"
    },
    {
      "x": -1,
      "y": 2,
      "z": -5,
      "name": "Soil_Hive"
    },
    {
      "x": -1,
      "y": 4,
      "z": -5,
      "name": "Soil_Grass_Deep"
    },
    {
      "x": -1,
      "y": 5,
      "z": -5,
      "name": "Plant_Bush_Hanging",
      "support": 15
    },
    {
      "x": -1,
      "y": 9,
      "z": -5,
      "name": "Wood_Deadwood_Roof_Hollow",
      "rotation": 2
    },
    {
      "x": -1,
      "y": 1,
      "z": -4,
      "name": "Soil_Needles"
    },
    {
      "x": -1,
      "y": 4,
      "z": -4,
      "name": "Soil_Dirt_Lush"
    },
    {
      "x": -1,
      "y": 5,
      "z": -4,
      "name": "Rock_Basalt_Brick"
    },
    {
      "x": -1,
      "y": 6,
      "z": -4,
      "name": "Furniture_Human_Ruins_Window"
    },
    {
      "x": -1,
      "y": 7,
      "z": -4,
      "name": "Furniture_Human_Ruins_Window"
    },
    {
      "x": -1,
      "y": 8,
      "z": -4,
      "name": "Wood_Village_Wall_GreyDark_Full"
    },
    {
      "x": -1,
      "y": 9,
      "z": -4,
      "name": "Wood_Ash_Trunk_Full",
      "support": 15,
      "rotation": 5
    },
    {
      "x": -1,
      "y": 10,
      "z": -4,
      "name": "Wood_Deadwood_Roof_Steep",
      "rotation": 2
    },
    {
      "x": -1,
      "y": 11,
      "z": -4,
      "name": "Wood_Deadwood_Roof_Steep",
      "filler": 1024,
      "rotation": 2
    },
    {
      "x": -1,
      "y": 1,
      "z": -3,
      "name": "Soil_Needles"
    },
    {
      "x": -1,
      "y": 4,
      "z": -3,
      "name": "Wood_Deadwood_Planks",
      "support": 15
    },
    {
      "x": -1,
      "y": 5,
      "z": -3,
      "name": "Furniture_Human_Ruins_Chest_Large",
      "components": {
        "Components": {
          "ItemContainerBlock": {
            "ItemContainer": {
              "Capacity": 63,
              "Items": {}
            },
            "Capacity": 63
          }
        }
      }
    },
    {
      "x": -1,
      "y": 11,
      "z": -3,
      "name": "Wood_Deadwood_Stairs",
      "rotation": 10
    },
    {
      "x": -1,
      "y": 12,
      "z": -3,
      "name": "Wood_Deadwood_Roof_Steep",
      "rotation": 2
    },
    {
      "x": -1,
      "y": 13,
      "z": -3,
      "name": "Wood_Deadwood_Roof_Steep",
      "filler": 1024,
      "rotation": 2
    },
    {
      "x": -1,
      "y": 1,
      "z": -2,
      "name": "Soil_Hive"
    },
    {
      "x": -1,
      "y": 4,
      "z": -2,
      "name": "Wood_Deadwood_Planks",
      "support": 15
    },
    {
      "x": -1,
      "y": 13,
      "z": -2,
      "name": "Wood_Deadwood_Stairs",
      "rotation": 10
    },
    {
      "x": -1,
      "y": 14,
      "z": -2,
      "name": "Wood_Deadwood_Roof",
      "rotation": 2
    },
    {
      "x": -1,
      "y": 1,
      "z": -1,
      "name": "Soil_Needles"
    },
    {
      "x": -1,
      "y": 4,
      "z": -1,
      "name": "Wood_Deadwood_Planks",
      "support": 15
    },
    {
      "x": -1,
      "y": 14,
      "z": -1,
      "name": "Wood_Deadwood_Stairs",
      "rotation": 10
    },
    {
      "x": -1,
      "y": 15,
      "z": -1,
      "name": "Wood_Deadwood_Roof",
      "rotation": 2
    },
    {
      "x": -1,
      "y": 0,
      "z": 0,
      "name": "Plant_Roots_Cave_Small",
      "rotation": 8
    },
    {
      "x": -1,
      "y": 1,
      "z": 0,
      "name": "Soil_Needles"
    },
    {
      "x": -1,
      "y": 4,
      "z": 0,
      "name": "Wood_Deadwood_Planks",
      "support": 15
    },
    {
      "x": -1,
      "y": 15,
      "z": 0,
      "name": "Wood_Ash_Trunk_Full",
      "support": 15,
      "rotation": 5
    },
    {
      "x": -1,
      "y": 16,
      "z": 0,
      "name": "Wood_Deadwood_Roof_Flat"
    },
    {
      "x": -1,
      "y": 0,
      "z": 1,
      "name": "Plant_Roots_Cave_Small",
      "rotation": 8
    },
    {
      "x": -1,
      "y": 1,
      "z": 1,
      "name": "Soil_Needles"
    },
    {
      "x": -1,
      "y": 4,
      "z": 1,
      "name": "Wood_Deadwood_Planks",
      "support": 15
    },
    {
      "x": -1,
      "y": 14,
      "z": 1,
      "name": "Wood_Deadwood_Stairs",
      "rotation": 8
    },
    {
      "x": -1,
      "y": 15,
      "z": 1,
      "name": "Wood_Deadwood_Roof"
    },
    {
      "x": -1,
      "y": 1,
      "z": 2,
      "name": "Soil_Needles"
    },
    {
      "x": -1,
      "y": 4,
      "z": 2,
      "name": "Wood_Deadwood_Planks",
      "support": 15
    },
    {
      "x": -1,
      "y": 5,
      "z": 2,
      "name": "Furniture_Human_Ruins_Bed",
      "filler": 993,
      "rotation": 1
    },
    {
      "x": -1,
      "y": 6,
      "z": 2,
      "name": "Furniture_Human_Ruins_Bed",
      "filler": 2017,
      "rotation": 1
    },
    {
      "x": -1,
      "y": 13,
      "z": 2,
      "name": "Wood_Deadwood_Stairs",
      "rotation": 8
    },
    {
      "x": -1,
      "y": 14,
      "z": 2,
      "name": "Wood_Deadwood_Roof"
    },
    {
      "x": -1,
      "y": 1,
      "z": 3,
      "name": "Soil_Needles"
    },
    {
      "x": -1,
      "y": 4,
      "z": 3,
      "name": "Wood_Deadwood_Planks",
      "support": 15
    },
    {
      "x": -1,
      "y": 5,
      "z": 3,
      "name": "Furniture_Human_Ruins_Bed",
      "filler": 1,
      "rotation": 1
    },
    {
      "x": -1,
      "y": 6,
      "z": 3,
      "name": "Furniture_Human_Ruins_Bed",
      "filler": 1025,
      "rotation": 1
    },
    {
      "x": -1,
      "y": 11,
      "z": 3,
      "name": "Wood_Deadwood_Stairs",
      "rotation": 8
    },
    {
      "x": -1,
      "y": 12,
      "z": 3,
      "name": "Wood_Deadwood_Roof_Steep"
    },
    {
      "x": -1,
      "y": 13,
      "z": 3,
      "name": "Wood_Deadwood_Roof_Steep",
      "filler": 1024
    },
    {
      "x": -1,
      "y": 1,
      "z": 4,
      "name": "Soil_Hive"
    },
    {
      "x": -1,
      "y": 4,
      "z": 4,
      "name": "Soil_Dirt_Lush"
    },
    {
      "x": -1,
      "y": 5,
      "z": 4,
      "name": "Rock_Basalt_Brick"
    },
    {
      "x": -1,
      "y": 6,
      "z": 4,
      "name": "Furniture_Human_Ruins_Window"
    },
    {
      "x": -1,
      "y": 7,
      "z": 4,
      "name": "Furniture_Human_Ruins_Window"
    },
    {
      "x": -1,
      "y": 8,
      "z": 4,
      "name": "Wood_Village_Wall_GreyDark_Full"
    },
    {
      "x": -1,
      "y": 9,
      "z": 4,
      "name": "Wood_Ash_Trunk_Full",
      "support": 15,
      "rotation": 5
    },
    {
      "x": -1,
      "y": 10,
      "z": 4,
      "name": "Wood_Deadwood_Roof_Steep"
    },
    {
      "x": -1,
      "y": 11,
      "z": 4,
      "name": "Wood_Deadwood_Roof_Steep",
      "filler": 1024
    },
    {
      "x": -1,
      "y": 2,
      "z": 5,
      "name": "Soil_Hive"
    },
    {
      "x": -1,
      "y": 4,
      "z": 5,
      "name": "Soil_Grass_Deep"
    },
    {
      "x": -1,
      "y": 9,
      "z": 5,
      "name": "Wood_Deadwood_Roof_Hollow"
    },
    {
      "x": -1,
      "y": 2,
      "z": 6,
      "name": "Plant_Roots_Cave_Small",
      "rotation": 8
    },
    {
      "x": -1,
      "y": 3,
      "z": 6,
      "name": "Soil_Needles"
    },
    {
      "x": -1,
      "y": 4,
      "z": 6,
      "name": "Soil_Hive"
    },
    {
      "x": 0,
      "y": 2,
      "z": -6,
      "name": "Plant_Roots_Cave_Small",
      "rotation": 8
    },
    {
      "x": 0,
      "y": 3,
      "z": -6,
      "name": "Soil_Needles"
    },
    {
      "x": 0,
      "y": 4,
      "z": -6,
      "name": "Soil_Needles"
    },
    {
      "x": 0,
      "y": 2,
      "z": -5,
      "name": "Soil_Hive"
    },
    {
      "x": 0,
      "y": 4,
      "z": -5,
      "name": "Soil_Grass_Deep"
    },
    {
      "x": 0,
      "y": 8,
      "z": -5,
      "name": "Plant_Vine_Wall_Dead",
      "support": 15,
      "rotation": 2
    },
    {
      "x": 0,
      "y": 9,
      "z": -5,
      "name": "Wood_Deadwood_Roof_Hollow",
      "rotation": 2
    },
    {
      "x": 0,
      "y": 1,
      "z": -4,
      "name": "Soil_Needles"
    },
    {
      "x": 0,
      "y": 4,
      "z": -4,
      "name": "Soil_Dirt_Lush"
    },
    {
      "x": 0,
      "y": 5,
      "z": -4,
      "name": "Rock_Basalt_Brick"
    },
    {
      "x": 0,
      "y": 6,
      "z": -4,
      "name": "*Wood_Village_Wall_GreyDark_Full_State_Definitions_Bottom"
    },
    {
      "x": 0,
      "y": 7,
      "z": -4,
      "name": "*Wood_Village_Wall_GreyDark_Full_State_Definitions_Middle"
    },
    {
      "x": 0,
      "y": 8,
      "z": -4,
      "name": "*Wood_Village_Wall_GreyDark_Full_State_Definitions_Top"
    },
    {
      "x": 0,
      "y": 9,
      "z": -4,
      "name": "Wood_Ash_Trunk_Full",
      "support": 15,
      "rotation": 5
    },
    {
      "x": 0,
      "y": 10,
      "z": -4,
      "name": "Wood_Deadwood_Roof_Steep",
      "rotation": 2
    },
    {
      "x": 0,
      "y": 11,
      "z": -4,
      "name": "Wood_Deadwood_Roof_Steep",
      "filler": 1024,
      "rotation": 2
    },
    {
      "x": 0,
      "y": 1,
      "z": -3,
      "name": "Soil_Needles"
    },
    {
      "x": 0,
      "y": 4,
      "z": -3,
      "name": "Wood_Deadwood_Planks",
      "support": 15
    },
    {
      "x": 0,
      "y": 11,
      "z": -3,
      "name": "Wood_Deadwood_Stairs",
      "rotation": 10
    },
    {
      "x": 0,
      "y": 12,
      "z": -3,
      "name": "Wood_Deadwood_Roof_Steep",
      "rotation": 2
    },
    {
      "x": 0,
      "y": 13,
      "z": -3,
      "name": "Wood_Deadwood_Roof_Steep",
      "filler": 1024,
      "rotation": 2
    },
    {
      "x": 0,
      "y": 0,
      "z": -2,
      "name": "Plant_Roots_Cave_Small",
      "rotation": 8
    },
    {
      "x": 0,
      "y": 1,
      "z": -2,
      "name": "Soil_Needles"
    },
    {
      "x": 0,
      "y": 4,
      "z": -2,
      "name": "Wood_Deadwood_Planks",
      "support": 15
    },
    {
      "x": 0,
      "y": 13,
      "z": -2,
      "name": "Wood_Deadwood_Stairs",
      "rotation": 10
    },
    {
      "x": 0,
      "y": 14,
      "z": -2,
      "name": "Wood_Deadwood_Roof",
      "rotation": 2
    },
    {
      "x": 0,
      "y": 1,
      "z": -1,
      "name": "Soil_Needles"
    },
    {
      "x": 0,
      "y": 4,
      "z": -1,
      "name": "Wood_Deadwood_Planks",
      "support": 15
    },
    {
      "x": 0,
      "y": 14,
      "z": -1,
      "name": "Wood_Deadwood_Stairs",
      "rotation": 10
    },
    {
      "x": 0,
      "y": 15,
      "z": -1,
      "name": "Wood_Deadwood_Roof",
      "rotation": 2
    },
    {
      "x": 0,
      "y": 1,
      "z": 0,
      "name": "Soil_Hive"
    },
    {
      "x": 0,
      "y": 4,
      "z": 0,
      "name": "Wood_Deadwood_Planks",
      "support": 15
    },
    {
      "x": 0,
      "y": 15,
      "z": 0,
      "name": "Wood_Ash_Trunk_Full",
      "support": 15,
      "rotation": 5
    },
    {
      "x": 0,
      "y": 16,
      "z": 0,
      "name": "Wood_Deadwood_Roof_Flat"
    },
    {
      "x": 0,
      "y": 1,
      "z": 1,
      "name": "Soil_Hive"
    },
    {
      "x": 0,
      "y": 4,
      "z": 1,
      "name": "Wood_Deadwood_Planks",
      "support": 15
    },
    {
      "x": 0,
      "y": 14,
      "z": 1,
      "name": "Wood_Deadwood_Stairs",
      "rotation": 8
    },
    {
      "x": 0,
      "y": 15,
      "z": 1,
      "name": "Wood_Deadwood_Roof"
    },
    {
      "x": 0,
      "y": 1,
      "z": 2,
      "name": "Soil_Needles"
    },
    {
      "x": 0,
      "y": 4,
      "z": 2,
      "name": "Wood_Deadwood_Planks",
      "support": 15
    },
    {
      "x": 0,
      "y": 5,
      "z": 2,
      "name": "Furniture_Human_Ruins_Bed",
      "filler": 994,
      "rotation": 1
    },
    {
      "x": 0,
      "y": 6,
      "z": 2,
      "name": "Furniture_Human_Ruins_Bed",
      "filler": 2018,
      "rotation": 1
    },
    {
      "x": 0,
      "y": 13,
      "z": 2,
      "name": "Wood_Deadwood_Stairs",
      "rotation": 8
    },
    {
      "x": 0,
      "y": 14,
      "z": 2,
      "name": "Wood_Deadwood_Roof"
    },
    {
      "x": 0,
      "y": 1,
      "z": 3,
      "name": "Soil_Needles"
    },
    {
      "x": 0,
      "y": 4,
      "z": 3,
      "name": "Wood_Deadwood_Planks",
      "support": 15
    },
    {
      "x": 0,
      "y": 5,
      "z": 3,
      "name": "Furniture_Human_Ruins_Bed",
      "filler": 2,
      "rotation": 1
    },
    {
      "x": 0,
      "y": 6,
      "z": 3,
      "name": "Furniture_Human_Ruins_Bed",
      "filler": 1026,
      "rotation": 1
    },
    {
      "x": 0,
      "y": 11,
      "z": 3,
      "name": "Wood_Deadwood_Stairs",
      "rotation": 8
    },
    {
      "x": 0,
      "y": 12,
      "z": 3,
      "name": "Rock_Basalt_Brick"
    },
    {
      "x": 0,
      "y": 13,
      "z": 3,
      "name": "Rock_Basalt_Brick"
    },
    {
      "x": 0,
      "y": 14,
      "z": 3,
      "name": "Rock_Basalt_Brick"
    },
    {
      "x": 0,
      "y": 15,
      "z": 3,
      "name": "Rock_Basalt_Brick_Pillar_Base",
      "rotation": 8
    },
    {
      "x": 0,
      "y": 1,
      "z": 4,
      "name": "Soil_Needles"
    },
    {
      "x": 0,
      "y": 4,
      "z": 4,
      "name": "Soil_Dirt_Lush"
    },
    {
      "x": 0,
      "y": 5,
      "z": 4,
      "name": "Rock_Basalt_Brick"
    },
    {
      "x": 0,
      "y": 6,
      "z": 4,
      "name": "*Wood_Village_Wall_GreyDark_Full_State_Definitions_Bottom"
    },
    {
      "x": 0,
      "y": 7,
      "z": 4,
      "name": "*Wood_Village_Wall_GreyDark_Full_State_Definitions_Middle"
    },
    {
      "x": 0,
      "y": 8,
      "z": 4,
      "name": "*Wood_Village_Wall_GreyDark_Full_State_Definitions_Top"
    },
    {
      "x": 0,
      "y": 9,
      "z": 4,
      "name": "Wood_Ash_Trunk_Full",
      "support": 15,
      "rotation": 5
    },
    {
      "x": 0,
      "y": 10,
      "z": 4,
      "name": "Wood_Deadwood_Roof_Steep"
    },
    {
      "x": 0,
      "y": 11,
      "z": 4,
      "name": "Wood_Deadwood_Roof_Steep",
      "filler": 1024
    },
    {
      "x": 0,
      "y": 2,
      "z": 5,
      "name": "Soil_Needles"
    },
    {
      "x": 0,
      "y": 4,
      "z": 5,
      "name": "Soil_Grass_Deep"
    },
    {
      "x": 0,
      "y": 7,
      "z": 5,
      "name": "Plant_Vine_Wall_Dead",
      "support": 15
    },
    {
      "x": 0,
      "y": 8,
      "z": 5,
      "name": "Plant_Vine_Wall_Dead",
      "support": 15
    },
    {
      "x": 0,
      "y": 9,
      "z": 5,
      "name": "Wood_Deadwood_Roof_Hollow"
    },
    {
      "x": 0,
      "y": 3,
      "z": 6,
      "name": "Soil_Needles"
    },
    {
      "x": 0,
      "y": 4,
      "z": 6,
      "name": "Soil_Needles"
    },
    {
      "x": 1,
      "y": 3,
      "z": -6,
      "name": "Soil_Needles"
    },
    {
      "x": 1,
      "y": 4,
      "z": -6,
      "name": "Soil_Hive"
    },
    {
      "x": 1,
      "y": 2,
      "z": -5,
      "name": "Soil_Needles"
    },
    {
      "x": 1,
      "y": 4,
      "z": -5,
      "name": "Soil_Grass_Deep"
    },
    {
      "x": 1,
      "y": 9,
      "z": -5,
      "name": "Wood_Deadwood_Roof_Hollow",
      "rotation": 2
    },
    {
      "x": 1,
      "y": 4,
      "z": -4,
      "name": "Soil_Dirt_Lush"
    },
    {
      "x": 1,
      "y": 5,
      "z": -4,
      "name": "Rock_Basalt_Brick"
    },
    {
      "x": 1,
      "y": 6,
      "z": -4,
      "name": "Furniture_Human_Ruins_Window"
    },
    {
      "x": 1,
      "y": 7,
      "z": -4,
      "name": "Furniture_Human_Ruins_Window"
    },
    {
      "x": 1,
      "y": 8,
      "z": -4,
      "name": "Wood_Village_Wall_GreyDark_Full"
    },
    {
      "x": 1,
      "y": 9,
      "z": -4,
      "name": "Wood_Ash_Trunk_Full",
      "support": 15,
      "rotation": 5
    },
    {
      "x": 1,
      "y": 10,
      "z": -4,
      "name": "Wood_Deadwood_Roof_Steep",
      "rotation": 2
    },
    {
      "x": 1,
      "y": 11,
      "z": -4,
      "name": "Wood_Deadwood_Roof_Steep",
      "filler": 1024,
      "rotation": 2
    },
    {
      "x": 1,
      "y": 1,
      "z": -3,
      "name": "Soil_Hive"
    },
    {
      "x": 1,
      "y": 4,
      "z": -3,
      "name": "Wood_Deadwood_Planks",
      "support": 15
    },
    {
      "x": 1,
      "y": 5,
      "z": -3,
      "name": "Furniture_Human_Ruins_Chest_Large",
      "filler": 31
    },
    {
      "x": 1,
      "y": 11,
      "z": -3,
      "name": "Wood_Deadwood_Stairs",
      "rotation": 10
    },
    {
      "x": 1,
      "y": 12,
      "z": -3,
      "name": "Wood_Deadwood_Roof_Steep",
      "rotation": 2
    },
    {
      "x": 1,
      "y": 13,
      "z": -3,
      "name": "Wood_Deadwood_Roof_Steep",
      "filler": 1024,
      "rotation": 2
    },
    {
      "x": 1,
      "y": 1,
      "z": -2,
      "name": "Soil_Needles"
    },
    {
      "x": 1,
      "y": 4,
      "z": -2,
      "name": "Wood_Deadwood_Planks",
      "support": 15
    },
    {
      "x": 1,
      "y": 13,
      "z": -2,
      "name": "Wood_Deadwood_Stairs",
      "rotation": 10
    },
    {
      "x": 1,
      "y": 14,
      "z": -2,
      "name": "Wood_Deadwood_Roof",
      "rotation": 2
    },
    {
      "x": 1,
      "y": 1,
      "z": -1,
      "name": "Soil_Needles"
    },
    {
      "x": 1,
      "y": 4,
      "z": -1,
      "name": "Wood_Deadwood_Planks",
      "support": 15
    },
    {
      "x": 1,
      "y": 14,
      "z": -1,
      "name": "Wood_Deadwood_Stairs",
      "rotation": 10
    },
    {
      "x": 1,
      "y": 15,
      "z": -1,
      "name": "Wood_Deadwood_Roof",
      "rotation": 2
    },
    {
      "x": 1,
      "y": 1,
      "z": 0,
      "name": "Soil_Needles"
    },
    {
      "x": 1,
      "y": 4,
      "z": 0,
      "name": "Wood_Deadwood_Planks",
      "support": 15
    },
    {
      "x": 1,
      "y": 15,
      "z": 0,
      "name": "Wood_Ash_Trunk_Full",
      "support": 15,
      "rotation": 5
    },
    {
      "x": 1,
      "y": 16,
      "z": 0,
      "name": "Wood_Deadwood_Roof_Flat"
    },
    {
      "x": 1,
      "y": 1,
      "z": 1,
      "name": "Soil_Needles"
    },
    {
      "x": 1,
      "y": 4,
      "z": 1,
      "name": "Wood_Deadwood_Planks",
      "support": 15
    },
    {
      "x": 1,
      "y": 14,
      "z": 1,
      "name": "Wood_Deadwood_Stairs",
      "rotation": 8
    },
    {
      "x": 1,
      "y": 15,
      "z": 1,
      "name": "Wood_Deadwood_Roof"
    },
    {
      "x": 1,
      "y": 1,
      "z": 2,
      "name": "Soil_Hive"
    },
    {
      "x": 1,
      "y": 4,
      "z": 2,
      "name": "Wood_Deadwood_Planks",
      "support": 15
    },
    {
      "x": 1,
      "y": 13,
      "z": 2,
      "name": "Wood_Deadwood_Stairs",
      "rotation": 8
    },
    {
      "x": 1,
      "y": 14,
      "z": 2,
      "name": "Wood_Deadwood_Roof"
    },
    {
      "x": 1,
      "y": 1,
      "z": 3,
      "name": "Soil_Needles"
    },
    {
      "x": 1,
      "y": 4,
      "z": 3,
      "name": "Wood_Deadwood_Planks",
      "support": 15
    },
    {
      "x": 1,
      "y": 5,
      "z": 3,
      "name": "Bench_WorkBench",
      "components": {
        "Components": {
          "BenchBlock": {
            "TierLevel": 1,
            "UpgradeItems": []
          },
          "PlacedByInteraction": {
            "WhoPlacedUuid": {
              "$binary": "v7RyWIT/TYKnXA2XcxdQtw==",
              "$type": "04"
            }
          }
        }
      },
      "rotation": 2
    },
    {
      "x": 1,
      "y": 11,
      "z": 3,
      "name": "Wood_Deadwood_Stairs",
      "rotation": 8
    },
    {
      "x": 1,
      "y": 12,
      "z": 3,
      "name": "Wood_Deadwood_Roof_Steep"
    },
    {
      "x": 1,
      "y": 13,
      "z": 3,
      "name": "Wood_Deadwood_Roof_Steep",
      "filler": 1024
    },
    {
      "x": 1,
      "y": 4,
      "z": 4,
      "name": "Soil_Dirt_Lush"
    },
    {
      "x": 1,
      "y": 5,
      "z": 4,
      "name": "Rock_Basalt_Brick"
    },
    {
      "x": 1,
      "y": 6,
      "z": 4,
      "name": "Furniture_Human_Ruins_Window"
    },
    {
      "x": 1,
      "y": 7,
      "z": 4,
      "name": "Furniture_Human_Ruins_Window"
    },
    {
      "x": 1,
      "y": 8,
      "z": 4,
      "name": "Wood_Village_Wall_GreyDark_Full"
    },
    {
      "x": 1,
      "y": 9,
      "z": 4,
      "name": "Wood_Ash_Trunk_Full",
      "support": 15,
      "rotation": 5
    },
    {
      "x": 1,
      "y": 10,
      "z": 4,
      "name": "Wood_Deadwood_Roof_Steep"
    },
    {
      "x": 1,
      "y": 11,
      "z": 4,
      "name": "Wood_Deadwood_Roof_Steep",
      "filler": 1024
    },
    {
      "x": 1,
      "y": 2,
      "z": 5,
      "name": "Soil_Needles"
    },
    {
      "x": 1,
      "y": 4,
      "z": 5,
      "name": "Soil_Grass_Deep"
    },
    {
      "x": 1,
      "y": 5,
      "z": 5,
      "name": "Plant_Bush_Hanging",
      "support": 15
    },
    {
      "x": 1,
      "y": 9,
      "z": 5,
      "name": "Wood_Deadwood_Roof_Hollow"
    },
    {
      "x": 1,
      "y": 3,
      "z": 6,
      "name": "Soil_Hive"
    },
    {
      "x": 1,
      "y": 4,
      "z": 6,
      "name": "Soil_Needles"
    },
    {
      "x": 2,
      "y": 3,
      "z": -6,
      "name": "Soil_Hive"
    },
    {
      "x": 2,
      "y": 4,
      "z": -6,
      "name": "Soil_Hive"
    },
    {
      "x": 2,
      "y": 5,
      "z": -6,
      "name": "Plant_Bush_Hanging",
      "support": 15
    },
    {
      "x": 2,
      "y": 1,
      "z": -5,
      "name": "Plant_Roots_Cave_Small",
      "rotation": 8
    },
    {
      "x": 2,
      "y": 2,
      "z": -5,
      "name": "Soil_Needles"
    },
    {
      "x": 2,
      "y": 4,
      "z": -5,
      "name": "Soil_Grass_Deep"
    },
    {
      "x": 2,
      "y": 6,
      "z": -5,
      "name": "Plant_Vine_Wall_Dead",
      "support": 15,
      "rotation": 2
    },
    {
      "x": 2,
      "y": 9,
      "z": -5,
      "name": "Wood_Deadwood_Roof_Hollow",
      "rotation": 2
    },
    {
      "x": 2,
      "y": 2,
      "z": -4,
      "name": "Soil_Hive"
    },
    {
      "x": 2,
      "y": 4,
      "z": -4,
      "name": "Soil_Dirt_Lush"
    },
    {
      "x": 2,
      "y": 5,
      "z": -4,
      "name": "Rock_Basalt_Brick"
    },
    {
      "x": 2,
      "y": 6,
      "z": -4,
      "name": "*Wood_Village_Wall_GreyDark_Full_State_Definitions_Bottom"
    },
    {
      "x": 2,
      "y": 7,
      "z": -4,
      "name": "*Wood_Village_Wall_GreyDark_Full_State_Definitions_Middle"
    },
    {
      "x": 2,
      "y": 8,
      "z": -4,
      "name": "*Wood_Village_Wall_GreyDark_Full_State_Definitions_Top"
    },
    {
      "x": 2,
      "y": 9,
      "z": -4,
      "name": "Wood_Ash_Trunk_Full",
      "support": 15,
      "rotation": 5
    },
    {
      "x": 2,
      "y": 10,
      "z": -4,
      "name": "Wood_Deadwood_Roof_Steep",
      "rotation": 2
    },
    {
      "x": 2,
      "y": 11,
      "z": -4,
      "name": "Wood_Deadwood_Roof_Steep",
      "filler": 1024,
      "rotation": 2
    },
    {
      "x": 2,
      "y": 1,
      "z": -3,
      "name": "Soil_Hive"
    },
    {
      "x": 2,
      "y": 4,
      "z": -3,
      "name": "Wood_Deadwood_Planks",
      "support": 15
    },
    {
      "x": 2,
      "y": 5,
      "z": -3,
      "name": "Furniture_Human_Ruins_Chest_Large",
      "components": {
        "Components": {
          "ItemContainerBlock": {
            "ItemContainer": {
              "Capacity": 63,
              "Items": {}
            },
            "Capacity": 63
          }
        }
      }
    },
    {
      "x": 2,
      "y": 11,
      "z": -3,
      "name": "Wood_Deadwood_Stairs",
      "rotation": 10
    },
    {
      "x": 2,
      "y": 12,
      "z": -3,
      "name": "Wood_Deadwood_Roof_Steep",
      "rotation": 2
    },
    {
      "x": 2,
      "y": 13,
      "z": -3,
      "name": "Wood_Deadwood_Roof_Steep",
      "filler": 1024,
      "rotation": 2
    },
    {
      "x": 2,
      "y": 1,
      "z": -2,
      "name": "Soil_Needles"
    },
    {
      "x": 2,
      "y": 4,
      "z": -2,
      "name": "Wood_Deadwood_Planks",
      "support": 15
    },
    {
      "x": 2,
      "y": 13,
      "z": -2,
      "name": "Wood_Deadwood_Stairs",
      "rotation": 10
    },
    {
      "x": 2,
      "y": 14,
      "z": -2,
      "name": "Wood_Deadwood_Roof",
      "rotation": 2
    },
    {
      "x": 2,
      "y": 1,
      "z": -1,
      "name": "Soil_Hive"
    },
    {
      "x": 2,
      "y": 4,
      "z": -1,
      "name": "Wood_Deadwood_Planks",
      "support": 15
    },
    {
      "x": 2,
      "y": 14,
      "z": -1,
      "name": "Wood_Deadwood_Stairs",
      "rotation": 10
    },
    {
      "x": 2,
      "y": 15,
      "z": -1,
      "name": "Wood_Deadwood_Roof",
      "rotation": 2
    },
    {
      "x": 2,
      "y": 0,
      "z": 0,
      "name": "Plant_Roots_Cave_Small",
      "rotation": 8
    },
    {
      "x": 2,
      "y": 1,
      "z": 0,
      "name": "Soil_Needles"
    },
    {
      "x": 2,
      "y": 4,
      "z": 0,
      "name": "Wood_Deadwood_Planks",
      "support": 15
    },
    {
      "x": 2,
      "y": 15,
      "z": 0,
      "name": "Wood_Ash_Trunk_Full",
      "support": 15,
      "rotation": 5
    },
    {
      "x": 2,
      "y": 16,
      "z": 0,
      "name": "Wood_Deadwood_Roof_Flat"
    },
    {
      "x": 2,
      "y": 0,
      "z": 1,
      "name": "Plant_Roots_Cave_Small",
      "rotation": 8
    },
    {
      "x": 2,
      "y": 1,
      "z": 1,
      "name": "Soil_Hive"
    },
    {
      "x": 2,
      "y": 4,
      "z": 1,
      "name": "Wood_Deadwood_Planks",
      "support": 15
    },
    {
      "x": 2,
      "y": 14,
      "z": 1,
      "name": "Wood_Deadwood_Stairs",
      "rotation": 8
    },
    {
      "x": 2,
      "y": 15,
      "z": 1,
      "name": "Wood_Deadwood_Roof"
    },
    {
      "x": 2,
      "y": 0,
      "z": 2,
      "name": "Plant_Roots_Cave_Small",
      "rotation": 8
    },
    {
      "x": 2,
      "y": 1,
      "z": 2,
      "name": "Soil_Hive"
    },
    {
      "x": 2,
      "y": 4,
      "z": 2,
      "name": "Wood_Deadwood_Planks",
      "support": 15
    },
    {
      "x": 2,
      "y": 13,
      "z": 2,
      "name": "Wood_Deadwood_Stairs",
      "rotation": 8
    },
    {
      "x": 2,
      "y": 14,
      "z": 2,
      "name": "Wood_Deadwood_Roof"
    },
    {
      "x": 2,
      "y": 1,
      "z": 3,
      "name": "Soil_Hive"
    },
    {
      "x": 2,
      "y": 4,
      "z": 3,
      "name": "Wood_Deadwood_Planks",
      "support": 15
    },
    {
      "x": 2,
      "y": 5,
      "z": 3,
      "name": "Bench_WorkBench",
      "filler": 1,
      "rotation": 2
    },
    {
      "x": 2,
      "y": 11,
      "z": 3,
      "name": "Wood_Deadwood_Stairs",
      "rotation": 8
    },
    {
      "x": 2,
      "y": 12,
      "z": 3,
      "name": "Wood_Deadwood_Roof_Steep"
    },
    {
      "x": 2,
      "y": 13,
      "z": 3,
      "name": "Wood_Deadwood_Roof_Steep",
      "filler": 1024
    },
    {
      "x": 2,
      "y": 1,
      "z": 4,
      "name": "Plant_Roots_Cave_Small",
      "rotation": 8
    },
    {
      "x": 2,
      "y": 2,
      "z": 4,
      "name": "Soil_Needles"
    },
    {
      "x": 2,
      "y": 4,
      "z": 4,
      "name": "Soil_Dirt_Lush"
    },
    {
      "x": 2,
      "y": 5,
      "z": 4,
      "name": "Rock_Basalt_Brick"
    },
    {
      "x": 2,
      "y": 6,
      "z": 4,
      "name": "*Wood_Village_Wall_GreyDark_Full_State_Definitions_Bottom"
    },
    {
      "x": 2,
      "y": 7,
      "z": 4,
      "name": "*Wood_Village_Wall_GreyDark_Full_State_Definitions_Middle"
    },
    {
      "x": 2,
      "y": 8,
      "z": 4,
      "name": "*Wood_Village_Wall_GreyDark_Full_State_Definitions_Top"
    },
    {
      "x": 2,
      "y": 9,
      "z": 4,
      "name": "Wood_Ash_Trunk_Full",
      "support": 15,
      "rotation": 5
    },
    {
      "x": 2,
      "y": 10,
      "z": 4,
      "name": "Wood_Deadwood_Roof_Steep"
    },
    {
      "x": 2,
      "y": 11,
      "z": 4,
      "name": "Wood_Deadwood_Roof_Steep",
      "filler": 1024
    },
    {
      "x": 2,
      "y": 2,
      "z": 5,
      "name": "Soil_Needles"
    },
    {
      "x": 2,
      "y": 4,
      "z": 5,
      "name": "Soil_Grass_Deep"
    },
    {
      "x": 2,
      "y": 9,
      "z": 5,
      "name": "Wood_Deadwood_Roof_Hollow"
    },
    {
      "x": 2,
      "y": 2,
      "z": 6,
      "name": "Plant_Roots_Cave_Small",
      "rotation": 8
    },
    {
      "x": 2,
      "y": 3,
      "z": 6,
      "name": "Soil_Hive"
    },
    {
      "x": 2,
      "y": 4,
      "z": 6,
      "name": "Soil_Hive"
    },
    {
      "x": 3,
      "y": 3,
      "z": -5,
      "name": "Soil_Hive"
    },
    {
      "x": 3,
      "y": 4,
      "z": -5,
      "name": "Soil_Needles"
    },
    {
      "x": 3,
      "y": 8,
      "z": -5,
      "name": "Wood_Ash_Branch_Corner",
      "support": 15,
      "rotation": 2
    },
    {
      "x": 3,
      "y": 9,
      "z": -5,
      "name": "Wood_Deadwood_Roof",
      "rotation": 2
    },
    {
      "x": 3,
      "y": 2,
      "z": -4,
      "name": "Soil_Needles"
    },
    {
      "x": 3,
      "y": 4,
      "z": -4,
      "name": "Soil_Dirt_Lush"
    },
    {
      "x": 3,
      "y": 5,
      "z": -4,
      "name": "Wood_Ash_Trunk_Full",
      "support": 15
    },
    {
      "x": 3,
      "y": 6,
      "z": -4,
      "name": "Wood_Ash_Trunk_Full",
      "support": 15
    },
    {
      "x": 3,
      "y": 7,
      "z": -4,
      "name": "Wood_Ash_Trunk_Full",
      "support": 15
    },
    {
      "x": 3,
      "y": 8,
      "z": -4,
      "name": "Wood_Ash_Trunk_Full",
      "support": 15
    },
    {
      "x": 3,
      "y": 9,
      "z": -4,
      "name": "Wood_Ash_Trunk_Full",
      "support": 15
    },
    {
      "x": 3,
      "y": 10,
      "z": -4,
      "name": "Wood_Deadwood_Roof_Steep",
      "rotation": 2
    },
    {
      "x": 3,
      "y": 11,
      "z": -4,
      "name": "Wood_Deadwood_Roof_Steep",
      "filler": 1024,
      "rotation": 2
    },
    {
      "x": 3,
      "y": 1,
      "z": -3,
      "name": "Plant_Roots_Cave_Small",
      "rotation": 8
    },
    {
      "x": 3,
      "y": 2,
      "z": -3,
      "name": "Soil_Hive"
    },
    {
      "x": 3,
      "y": 4,
      "z": -3,
      "name": "Soil_Dirt_Lush"
    },
    {
      "x": 3,
      "y": 5,
      "z": -3,
      "name": "Rock_Basalt_Brick"
    },
    {
      "x": 3,
      "y": 6,
      "z": -3,
      "name": "*Wood_Village_Wall_GreyDark_Full_State_Definitions_Bottom"
    },
    {
      "x": 3,
      "y": 7,
      "z": -3,
      "name": "*Wood_Village_Wall_GreyDark_Full_State_Definitions_Middle"
    },
    {
      "x": 3,
      "y": 8,
      "z": -3,
      "name": "*Wood_Village_Wall_GreyDark_Full_State_Definitions_Middle"
    },
    {
      "x": 3,
      "y": 9,
      "z": -3,
      "name": "*Wood_Village_Wall_GreyDark_Full_State_Definitions_Top"
    },
    {
      "x": 3,
      "y": 10,
      "z": -3,
      "name": "Wood_Ash_Trunk_Full",
      "support": 15
    },
    {
      "x": 3,
      "y": 11,
      "z": -3,
      "name": "Wood_Ash_Trunk_Full",
      "support": 15
    },
    {
      "x": 3,
      "y": 12,
      "z": -3,
      "name": "Wood_Deadwood_Roof_Steep",
      "rotation": 2
    },
    {
      "x": 3,
      "y": 13,
      "z": -3,
      "name": "Wood_Deadwood_Roof_Steep",
      "filler": 1024,
      "rotation": 2
    },
    {
      "x": 3,
      "y": 0,
      "z": -2,
      "name": "Plant_Roots_Cave_Small",
      "rotation": 8
    },
    {
      "x": 3,
      "y": 1,
      "z": -2,
      "name": "Soil_Needles"
    },
    {
      "x": 3,
      "y": 4,
      "z": -2,
      "name": "Soil_Dirt_Lush"
    },
    {
      "x": 3,
      "y": 5,
      "z": -2,
      "name": "Rock_Basalt_Brick"
    },
    {
      "x": 3,
      "y": 6,
      "z": -2,
      "name": "*Wood_Village_Wall_GreyDark_Full_State_Definitions_Bottom"
    },
    {
      "x": 3,
      "y": 7,
      "z": -2,
      "name": "*Wood_Village_Wall_GreyDark_Full_State_Definitions_Middle"
    },
    {
      "x": 3,
      "y": 8,
      "z": -2,
      "name": "*Wood_Village_Wall_GreyDark_Full_State_Definitions_Middle"
    },
    {
      "x": 3,
      "y": 9,
      "z": -2,
      "name": "*Wood_Village_Wall_GreyDark_Full_State_Definitions_Middle"
    },
    {
      "x": 3,
      "y": 10,
      "z": -2,
      "name": "*Wood_Village_Wall_GreyDark_Full_State_Definitions_Middle"
    },
    {
      "x": 3,
      "y": 11,
      "z": -2,
      "name": "*Wood_Village_Wall_GreyDark_Full_State_Definitions_Top"
    },
    {
      "x": 3,
      "y": 12,
      "z": -2,
      "name": "Wood_Ash_Trunk_Full",
      "support": 15
    },
    {
      "x": 3,
      "y": 13,
      "z": -2,
      "name": "Wood_Ash_Trunk_Full",
      "support": 15
    },
    {
      "x": 3,
      "y": 14,
      "z": -2,
      "name": "Wood_Deadwood_Roof",
      "rotation": 2
    },
    {
      "x": 3,
      "y": 0,
      "z": -1,
      "name": "Plant_Roots_Cave_Small",
      "rotation": 8
    },
    {
      "x": 3,
      "y": 1,
      "z": -1,
      "name": "Soil_Needles"
    },
    {
      "x": 3,
      "y": 4,
      "z": -1,
      "name": "Wood_Deadwood_Planks",
      "support": 15
    },
    {
      "x": 3,
      "y": 7,
      "z": -1,
      "name": "Rock_Basalt_Brick_Stairs",
      "rotation": 10
    },
    {
      "x": 3,
      "y": 8,
      "z": -1,
      "name": "*Wood_Village_Wall_GreyDark_Full_State_Definitions_Bottom"
    },
    {
      "x": 3,
      "y": 9,
      "z": -1,
      "name": "*Wood_Village_Wall_GreyDark_Full_State_Definitions_Top"
    },
    {
      "x": 3,
      "y": 10,
      "z": -1,
      "name": "Furniture_Human_Ruins_Window",
      "rotation": 1
    },
    {
      "x": 3,
      "y": 11,
      "z": -1,
      "name": "*Wood_Village_Wall_GreyDark_Full_State_Definitions_Bottom"
    },
    {
      "x": 3,
      "y": 12,
      "z": -1,
      "name": "*Wood_Village_Wall_GreyDark_Full_State_Definitions_Middle"
    },
    {
      "x": 3,
      "y": 13,
      "z": -1,
      "name": "*Wood_Village_Wall_GreyDark_Full_State_Definitions_Top"
    },
    {
      "x": 3,
      "y": 14,
      "z": -1,
      "name": "Wood_Ash_Trunk_Full",
      "support": 15
    },
    {
      "x": 3,
      "y": 15,
      "z": -1,
      "name": "Wood_Deadwood_Roof",
      "rotation": 2
    },
    {
      "x": 3,
      "y": 1,
      "z": 0,
      "name": "Soil_Needles"
    },
    {
      "x": 3,
      "y": 4,
      "z": 0,
      "name": "Wood_Deadwood_Planks",
      "support": 15
    },
    {
      "x": 3,
      "y": 8,
      "z": 0,
      "name": "Wood_Village_Wall_GreyDark_Full"
    },
    {
      "x": 3,
      "y": 9,
      "z": 0,
      "name": "Furniture_Human_Ruins_Window",
      "rotation": 1
    },
    {
      "x": 3,
      "y": 10,
      "z": 0,
      "name": "Furniture_Human_Ruins_Window",
      "rotation": 1
    },
    {
      "x": 3,
      "y": 11,
      "z": 0,
      "name": "Furniture_Human_Ruins_Window",
      "rotation": 1
    },
    {
      "x": 3,
      "y": 12,
      "z": 0,
      "name": "*Wood_Village_Wall_GreyDark_Full_State_Definitions_Bottom"
    },
    {
      "x": 3,
      "y": 13,
      "z": 0,
      "name": "*Wood_Village_Wall_GreyDark_Full_State_Definitions_Middle"
    },
    {
      "x": 3,
      "y": 14,
      "z": 0,
      "name": "*Wood_Village_Wall_GreyDark_Full_State_Definitions_Top"
    },
    {
      "x": 3,
      "y": 15,
      "z": 0,
      "name": "Wood_Ash_Trunk_Full",
      "support": 15
    },
    {
      "x": 3,
      "y": 16,
      "z": 0,
      "name": "Wood_Deadwood_Roof_Flat"
    },
    {
      "x": 3,
      "y": 1,
      "z": 1,
      "name": "Soil_Hive"
    },
    {
      "x": 3,
      "y": 4,
      "z": 1,
      "name": "Wood_Deadwood_Planks",
      "support": 15
    },
    {
      "x": 3,
      "y": 7,
      "z": 1,
      "name": "Rock_Basalt_Brick_Stairs",
      "rotation": 8
    },
    {
      "x": 3,
      "y": 8,
      "z": 1,
      "name": "*Wood_Village_Wall_GreyDark_Full_State_Definitions_Bottom"
    },
    {
      "x": 3,
      "y": 9,
      "z": 1,
      "name": "*Wood_Village_Wall_GreyDark_Full_State_Definitions_Top"
    },
    {
      "x": 3,
      "y": 10,
      "z": 1,
      "name": "Furniture_Human_Ruins_Window",
      "rotation": 1
    },
    {
      "x": 3,
      "y": 11,
      "z": 1,
      "name": "*Wood_Village_Wall_GreyDark_Full_State_Definitions_Bottom"
    },
    {
      "x": 3,
      "y": 12,
      "z": 1,
      "name": "*Wood_Village_Wall_GreyDark_Full_State_Definitions_Middle"
    },
    {
      "x": 3,
      "y": 13,
      "z": 1,
      "name": "*Wood_Village_Wall_GreyDark_Full_State_Definitions_Top"
    },
    {
      "x": 3,
      "y": 14,
      "z": 1,
      "name": "Wood_Ash_Trunk_Full",
      "support": 15
    },
    {
      "x": 3,
      "y": 15,
      "z": 1,
      "name": "Wood_Deadwood_Roof"
    },
    {
      "x": 3,
      "y": 1,
      "z": 2,
      "name": "Soil_Needles"
    },
    {
      "x": 3,
      "y": 4,
      "z": 2,
      "name": "Soil_Dirt_Lush"
    },
    {
      "x": 3,
      "y": 5,
      "z": 2,
      "name": "Rock_Basalt_Brick"
    },
    {
      "x": 3,
      "y": 6,
      "z": 2,
      "name": "*Wood_Village_Wall_GreyDark_Full_State_Definitions_Bottom"
    },
    {
      "x": 3,
      "y": 7,
      "z": 2,
      "name": "*Wood_Village_Wall_GreyDark_Full_State_Definitions_Middle"
    },
    {
      "x": 3,
      "y": 8,
      "z": 2,
      "name": "*Wood_Village_Wall_GreyDark_Full_State_Definitions_Middle"
    },
    {
      "x": 3,
      "y": 9,
      "z": 2,
      "name": "*Wood_Village_Wall_GreyDark_Full_State_Definitions_Middle"
    },
    {
      "x": 3,
      "y": 10,
      "z": 2,
      "name": "*Wood_Village_Wall_GreyDark_Full_State_Definitions_Middle"
    },
    {
      "x": 3,
      "y": 11,
      "z": 2,
      "name": "*Wood_Village_Wall_GreyDark_Full_State_Definitions_Top"
    },
    {
      "x": 3,
      "y": 12,
      "z": 2,
      "name": "Wood_Ash_Trunk_Full",
      "support": 15
    },
    {
      "x": 3,
      "y": 13,
      "z": 2,
      "name": "Wood_Ash_Trunk_Full",
      "support": 15
    },
    {
      "x": 3,
      "y": 14,
      "z": 2,
      "name": "Wood_Deadwood_Roof"
    },
    {
      "x": 3,
      "y": 2,
      "z": 3,
      "name": "Soil_Needles"
    },
    {
      "x": 3,
      "y": 4,
      "z": 3,
      "name": "Soil_Dirt_Lush"
    },
    {
      "x": 3,
      "y": 5,
      "z": 3,
      "name": "Rock_Basalt_Brick"
    },
    {
      "x": 3,
      "y": 6,
      "z": 3,
      "name": "*Wood_Village_Wall_GreyDark_Full_State_Definitions_Bottom"
    },
    {
      "x": 3,
      "y": 7,
      "z": 3,
      "name": "*Wood_Village_Wall_GreyDark_Full_State_Definitions_Middle"
    },
    {
      "x": 3,
      "y": 8,
      "z": 3,
      "name": "*Wood_Village_Wall_GreyDark_Full_State_Definitions_Middle"
    },
    {
      "x": 3,
      "y": 9,
      "z": 3,
      "name": "*Wood_Village_Wall_GreyDark_Full_State_Definitions_Top"
    },
    {
      "x": 3,
      "y": 10,
      "z": 3,
      "name": "Wood_Ash_Trunk_Full",
      "support": 15
    },
    {
      "x": 3,
      "y": 11,
      "z": 3,
      "name": "Wood_Ash_Trunk_Full",
      "support": 15
    },
    {
      "x": 3,
      "y": 12,
      "z": 3,
      "name": "Wood_Deadwood_Roof_Steep"
    },
    {
      "x": 3,
      "y": 13,
      "z": 3,
      "name": "Wood_Deadwood_Roof_Steep",
      "filler": 1024
    },
    {
      "x": 3,
      "y": 2,
      "z": 4,
      "name": "Soil_Needles"
    },
    {
      "x": 3,
      "y": 4,
      "z": 4,
      "name": "Soil_Dirt_Lush"
    },
    {
      "x": 3,
      "y": 5,
      "z": 4,
      "name": "Wood_Ash_Trunk_Full",
      "support": 15
    },
    {
      "x": 3,
      "y": 6,
      "z": 4,
      "name": "Wood_Ash_Trunk_Full",
      "support": 15
    },
    {
      "x": 3,
      "y": 7,
      "z": 4,
      "name": "Wood_Ash_Trunk_Full",
      "support": 15
    },
    {
      "x": 3,
      "y": 8,
      "z": 4,
      "name": "Wood_Ash_Trunk_Full",
      "support": 15
    },
    {
      "x": 3,
      "y": 9,
      "z": 4,
      "name": "Wood_Ash_Trunk_Full",
      "support": 15
    },
    {
      "x": 3,
      "y": 10,
      "z": 4,
      "name": "Wood_Deadwood_Roof_Steep"
    },
    {
      "x": 3,
      "y": 11,
      "z": 4,
      "name": "Wood_Deadwood_Roof_Steep",
      "filler": 1024
    },
    {
      "x": 3,
      "y": 3,
      "z": 5,
      "name": "Soil_Hive"
    },
    {
      "x": 3,
      "y": 4,
      "z": 5,
      "name": "Soil_Needles"
    },
    {
      "x": 3,
      "y": 6,
      "z": 5,
      "name": "Plant_Vine_Wall_Dead",
      "support": 15
    },
    {
      "x": 3,
      "y": 8,
      "z": 5,
      "name": "Wood_Ash_Branch_Corner",
      "support": 15
    },
    {
      "x": 3,
      "y": 9,
      "z": 5,
      "name": "Wood_Deadwood_Roof"
    },
    {
      "x": 4,
      "y": 2,
      "z": -5,
      "name": "Plant_Roots_Cave_Small",
      "rotation": 8
    },
    {
      "x": 4,
      "y": 3,
      "z": -5,
      "name": "Soil_Needles"
    },
    {
      "x": 4,
      "y": 4,
      "z": -5,
      "name": "Soil_Needles"
    },
    {
      "x": 4,
      "y": 9,
      "z": -5,
      "name": "Wood_Deadwood_Roof_Hollow",
      "rotation": 2
    },
    {
      "x": 4,
      "y": 3,
      "z": -4,
      "name": "Soil_Needles"
    },
    {
      "x": 4,
      "y": 4,
      "z": -4,
      "name": "Soil_Grass_Deep"
    },
    {
      "x": 4,
      "y": 9,
      "z": -4,
      "name": "Wood_Ash_Branch_Corner",
      "support": 15,
      "rotation": 1
    },
    {
      "x": 4,
      "y": 10,
      "z": -4,
      "name": "Wood_Deadwood_Roof_Steep",
      "rotation": 2
    },
    {
      "x": 4,
      "y": 11,
      "z": -4,
      "name": "Wood_Deadwood_Roof_Steep",
      "filler": 1024,
      "rotation": 2
    },
    {
      "x": 4,
      "y": 2,
      "z": -3,
      "name": "Soil_Hive"
    },
    {
      "x": 4,
      "y": 4,
      "z": -3,
      "name": "Soil_Grass_Deep"
    },
    {
      "x": 4,
      "y": 7,
      "z": -3,
      "name": "Plant_Vine_Wall_Dead",
      "support": 15,
      "rotation": 1
    },
    {
      "x": 4,
      "y": 8,
      "z": -3,
      "name": "Plant_Vine_Wall_Dead",
      "support": 15,
      "rotation": 1
    },
    {
      "x": 4,
      "y": 11,
      "z": -3,
      "name": "Wood_Deadwood_Stairs",
      "rotation": 10
    },
    {
      "x": 4,
      "y": 12,
      "z": -3,
      "name": "Wood_Deadwood_Roof_Steep",
      "rotation": 2
    },
    {
      "x": 4,
      "y": 13,
      "z": -3,
      "name": "Wood_Deadwood_Roof_Steep",
      "filler": 1024,
      "rotation": 2
    },
    {
      "x": 4,
      "y": 2,
      "z": -2,
      "name": "Soil_Needles"
    },
    {
      "x": 4,
      "y": 4,
      "z": -2,
      "name": "Soil_Grass_Deep"
    },
    {
      "x": 4,
      "y": 5,
      "z": -2,
      "name": "Plant_Bush_Hanging",
      "support": 15
    },
    {
      "x": 4,
      "y": 13,
      "z": -2,
      "name": "Wood_Deadwood_Stairs",
      "rotation": 10
    },
    {
      "x": 4,
      "y": 14,
      "z": -2,
      "name": "Wood_Deadwood_Roof",
      "rotation": 2
    },
    {
      "x": 4,
      "y": 1,
      "z": -1,
      "name": "Soil_Hive"
    },
    {
      "x": 4,
      "y": 4,
      "z": -1,
      "name": "Soil_Grass_Deep"
    },
    {
      "x": 4,
      "y": 13,
      "z": -1,
      "name": "Plant_Vine_Wall_Dead",
      "support": 15,
      "rotation": 1
    },
    {
      "x": 4,
      "y": 14,
      "z": -1,
      "name": "Wood_Deadwood_Stairs",
      "rotation": 10
    },
    {
      "x": 4,
      "y": 15,
      "z": -1,
      "name": "Wood_Deadwood_Roof",
      "rotation": 2
    },
    {
      "x": 4,
      "y": 0,
      "z": 0,
      "name": "Plant_Roots_Cave_Small",
      "rotation": 8
    },
    {
      "x": 4,
      "y": 1,
      "z": 0,
      "name": "Soil_Hive"
    },
    {
      "x": 4,
      "y": 4,
      "z": 0,
      "name": "Soil_Grass_Deep"
    },
    {
      "x": 4,
      "y": 15,
      "z": 0,
      "name": "Wood_Deadwood_Planks"
    },
    {
      "x": 4,
      "y": 16,
      "z": 0,
      "name": "Wood_Deadwood_Roof_Flat"
    },
    {
      "x": 4,
      "y": 1,
      "z": 1,
      "name": "Soil_Needles"
    },
    {
      "x": 4,
      "y": 4,
      "z": 1,
      "name": "Soil_Grass_Deep"
    },
    {
      "x": 4,
      "y": 14,
      "z": 1,
      "name": "Wood_Deadwood_Stairs",
      "rotation": 8
    },
    {
      "x": 4,
      "y": 15,
      "z": 1,
      "name": "Wood_Deadwood_Roof"
    },
    {
      "x": 4,
      "y": 1,
      "z": 2,
      "name": "Plant_Roots_Cave_Small",
      "rotation": 8
    },
    {
      "x": 4,
      "y": 2,
      "z": 2,
      "name": "Soil_Needles"
    },
    {
      "x": 4,
      "y": 4,
      "z": 2,
      "name": "Soil_Grass_Deep"
    },
    {
      "x": 4,
      "y": 9,
      "z": 2,
      "name": "Plant_Vine_Wall_Dead",
      "support": 15,
      "rotation": 1
    },
    {
      "x": 4,
      "y": 13,
      "z": 2,
      "name": "Wood_Deadwood_Stairs",
      "rotation": 8
    },
    {
      "x": 4,
      "y": 14,
      "z": 2,
      "name": "Wood_Deadwood_Roof"
    },
    {
      "x": 4,
      "y": 2,
      "z": 3,
      "name": "Soil_Needles"
    },
    {
      "x": 4,
      "y": 4,
      "z": 3,
      "name": "Soil_Grass_Deep"
    },
    {
      "x": 4,
      "y": 5,
      "z": 3,
      "name": "Plant_Bush_Hanging",
      "support": 15
    },
    {
      "x": 4,
      "y": 11,
      "z": 3,
      "name": "Wood_Deadwood_Stairs",
      "rotation": 8
    },
    {
      "x": 4,
      "y": 12,
      "z": 3,
      "name": "Wood_Deadwood_Roof_Steep"
    },
    {
      "x": 4,
      "y": 13,
      "z": 3,
      "name": "Wood_Deadwood_Roof_Steep",
      "filler": 1024
    },
    {
      "x": 4,
      "y": 3,
      "z": 4,
      "name": "Soil_Hive"
    },
    {
      "x": 4,
      "y": 4,
      "z": 4,
      "name": "Soil_Grass_Deep"
    },
    {
      "x": 4,
      "y": 9,
      "z": 4,
      "name": "Wood_Ash_Branch_Corner",
      "support": 15,
      "rotation": 1
    },
    {
      "x": 4,
      "y": 10,
      "z": 4,
      "name": "Wood_Deadwood_Roof_Steep"
    },
    {
      "x": 4,
      "y": 11,
      "z": 4,
      "name": "Wood_Deadwood_Roof_Steep",
      "filler": 1024
    },
    {
      "x": 4,
      "y": 3,
      "z": 5,
      "name": "Soil_Hive"
    },
    {
      "x": 4,
      "y": 4,
      "z": 5,
      "name": "Soil_Needles"
    },
    {
      "x": 4,
      "y": 9,
      "z": 5,
      "name": "Wood_Deadwood_Roof_Hollow"
    },
    {
      "x": 5,
      "y": 3,
      "z": -4,
      "name": "Soil_Hive"
    },
    {
      "x": 5,
      "y": 4,
      "z": -4,
      "name": "Soil_Hive"
    },
    {
      "x": 5,
      "y": 3,
      "z": -3,
      "name": "Soil_Needles"
    },
    {
      "x": 5,
      "y": 4,
      "z": -3,
      "name": "Soil_Hive"
    },
    {
      "x": 5,
      "y": 1,
      "z": -2,
      "name": "Plant_Roots_Cave_Small",
      "rotation": 8
    },
    {
      "x": 5,
      "y": 2,
      "z": -2,
      "name": "Soil_Needles"
    },
    {
      "x": 5,
      "y": 4,
      "z": -2,
      "name": "Soil_Grass_Deep"
    },
    {
      "x": 5,
      "y": 2,
      "z": -1,
      "name": "Soil_Needles"
    },
    {
      "x": 5,
      "y": 4,
      "z": -1,
      "name": "Soil_Grass_Deep"
    },
    {
      "x": 5,
      "y": 2,
      "z": 0,
      "name": "Soil_Needles"
    },
    {
      "x": 5,
      "y": 4,
      "z": 0,
      "name": "Soil_Grass_Deep"
    },
    {
      "x": 5,
      "y": 2,
      "z": 1,
      "name": "Soil_Hive"
    },
    {
      "x": 5,
      "y": 4,
      "z": 1,
      "name": "Soil_Grass_Deep"
    },
    {
      "x": 5,
      "y": 2,
      "z": 2,
      "name": "Soil_Needles"
    },
    {
      "x": 5,
      "y": 4,
      "z": 2,
      "name": "Soil_Grass_Deep"
    },
    {
      "x": 5,
      "y": 2,
      "z": 3,
      "name": "Plant_Roots_Cave_Small",
      "rotation": 8
    },
    {
      "x": 5,
      "y": 3,
      "z": 3,
      "name": "Soil_Needles"
    },
    {
      "x": 5,
      "y": 4,
      "z": 3,
      "name": "Soil_Needles"
    },
    {
      "x": 5,
      "y": 3,
      "z": 4,
      "name": "Soil_Needles"
    },
    {
      "x": 5,
      "y": 4,
      "z": 4,
      "name": "Soil_Needles"
    },
    {
      "x": 6,
      "y": 3,
      "z": -2,
      "name": "Soil_Hive"
    },
    {
      "x": 6,
      "y": 4,
      "z": -2,
      "name": "Soil_Needles"
    },
    {
      "x": 6,
      "y": 2,
      "z": -1,
      "name": "Plant_Roots_Cave_Small",
      "rotation": 8
    },
    {
      "x": 6,
      "y": 3,
      "z": -1,
      "name": "Soil_Hive"
    },
    {
      "x": 6,
      "y": 4,
      "z": -1,
      "name": "Soil_Hive"
    },
    {
      "x": 6,
      "y": 3,
      "z": 0,
      "name": "Soil_Hive"
    },
    {
      "x": 6,
      "y": 4,
      "z": 0,
      "name": "Soil_Hive"
    },
    {
      "x": 6,
      "y": 3,
      "z": 1,
      "name": "Soil_Needles"
    },
    {
      "x": 6,
      "y": 4,
      "z": 1,
      "name": "Soil_Needles"
    },
    {
      "x": 6,
      "y": 3,
      "z": 2,
      "name": "Soil_Hive"
    },
    {
      "x": 6,
      "y": 4,
      "z": 2,
      "name": "Soil_Hive"
    }
  ],
  "fluids": [
    {
      "x": -6,
      "y": 3,
      "z": -2,
      "name": "Empty",
      "level": 0
    },
    {
      "x": -6,
      "y": 4,
      "z": -2,
      "name": "Empty",
      "level": 0
    },
    {
      "x": -6,
      "y": 3,
      "z": -1,
      "name": "Empty",
      "level": 0
    },
    {
      "x": -6,
      "y": 4,
      "z": -1,
      "name": "Empty",
      "level": 0
    },
    {
      "x": -6,
      "y": 2,
      "z": 0,
      "name": "Empty",
      "level": 0
    },
    {
      "x": -6,
      "y": 3,
      "z": 0,
      "name": "Empty",
      "level": 0
    },
    {
      "x": -6,
      "y": 3,
      "z": 1,
      "name": "Empty",
      "level": 0
    },
    {
      "x": -6,
      "y": 4,
      "z": 1,
      "name": "Empty",
      "level": 0
    },
    {
      "x": -6,
      "y": 3,
      "z": 2,
      "name": "Empty",
      "level": 0
    },
    {
      "x": -6,
      "y": 4,
      "z": 2,
      "name": "Empty",
      "level": 0
    },
    {
      "x": -5,
      "y": 3,
      "z": -4,
      "name": "Empty",
      "level": 0
    },
    {
      "x": -5,
      "y": 4,
      "z": -4,
      "name": "Empty",
      "level": 0
    },
    {
      "x": -5,
      "y": 3,
      "z": -3,
      "name": "Empty",
      "level": 0
    },
    {
      "x": -5,
      "y": 4,
      "z": -3,
      "name": "Empty",
      "level": 0
    },
    {
      "x": -5,
      "y": 2,
      "z": -2,
      "name": "Empty",
      "level": 0
    },
    {
      "x": -5,
      "y": 4,
      "z": -2,
      "name": "Empty",
      "level": 0
    },
    {
      "x": -5,
      "y": 2,
      "z": -1,
      "name": "Empty",
      "level": 0
    },
    {
      "x": -5,
      "y": 1,
      "z": 0,
      "name": "Empty",
      "level": 0
    },
    {
      "x": -5,
      "y": 2,
      "z": 0,
      "name": "Empty",
      "level": 0
    },
    {
      "x": -5,
      "y": 3,
      "z": 0,
      "name": "Empty",
      "level": 0
    },
    {
      "x": -5,
      "y": 2,
      "z": 1,
      "name": "Empty",
      "level": 0
    },
    {
      "x": -5,
      "y": 2,
      "z": 2,
      "name": "Empty",
      "level": 0
    },
    {
      "x": -5,
      "y": 4,
      "z": 2,
      "name": "Empty",
      "level": 0
    },
    {
      "x": -5,
      "y": 5,
      "z": 2,
      "name": "Empty",
      "level": 0
    },
    {
      "x": -5,
      "y": 3,
      "z": 3,
      "name": "Empty",
      "level": 0
    },
    {
      "x": -5,
      "y": 4,
      "z": 3,
      "name": "Empty",
      "level": 0
    },
    {
      "x": -5,
      "y": 3,
      "z": 4,
      "name": "Empty",
      "level": 0
    },
    {
      "x": -5,
      "y": 4,
      "z": 4,
      "name": "Empty",
      "level": 0
    },
    {
      "x": -4,
      "y": 3,
      "z": -5,
      "name": "Empty",
      "level": 0
    },
    {
      "x": -4,
      "y": 4,
      "z": -5,
      "name": "Empty",
      "level": 0
    },
    {
      "x": -4,
      "y": 9,
      "z": -5,
      "name": "Empty",
      "level": 0
    },
    {
      "x": -4,
      "y": 2,
      "z": -4,
      "name": "Empty",
      "level": 0
    },
    {
      "x": -4,
      "y": 3,
      "z": -4,
      "name": "Empty",
      "level": 0
    },
    {
      "x": -4,
      "y": 4,
      "z": -4,
      "name": "Empty",
      "level": 0
    },
    {
      "x": -4,
      "y": 8,
      "z": -4,
      "name": "Empty",
      "level": 0
    },
    {
      "x": -4,
      "y": 9,
      "z": -4,
      "name": "Empty",
      "level": 0
    },
    {
      "x": -4,
      "y": 10,
      "z": -4,
      "name": "Empty",
      "level": 0
    },
    {
      "x": -4,
      "y": 11,
      "z": -4,
      "name": "Empty",
      "level": 0
    },
    {
      "x": -4,
      "y": 1,
      "z": -3,
      "name": "Empty",
      "level": 0
    },
    {
      "x": -4,
      "y": 2,
      "z": -3,
      "name": "Empty",
      "level": 0
    },
    {
      "x": -4,
      "y": 4,
      "z": -3,
      "name": "Empty",
      "level": 0
    },
    {
      "x": -4,
      "y": 11,
      "z": -3,
      "name": "Empty",
      "level": 0
    },
    {
      "x": -4,
      "y": 12,
      "z": -3,
      "name": "Empty",
      "level": 0
    },
    {
      "x": -4,
      "y": 13,
      "z": -3,
      "name": "Empty",
      "level": 0
    },
    {
      "x": -4,
      "y": 2,
      "z": -2,
      "name": "Empty",
      "level": 0
    },
    {
      "x": -4,
      "y": 4,
      "z": -2,
      "name": "Empty",
      "level": 0
    },
    {
      "x": -4,
      "y": 5,
      "z": -2,
      "name": "Empty",
      "level": 0
    },
    {
      "x": -4,
      "y": 7,
      "z": -2,
      "name": "Empty",
      "level": 0
    },
    {
      "x": -4,
      "y": 8,
      "z": -2,
      "name": "Empty",
      "level": 0
    },
    {
      "x": -4,
      "y": 13,
      "z": -2,
      "name": "Empty",
      "level": 0
    },
    {
      "x": -4,
      "y": 14,
      "z": -2,
      "name": "Empty",
      "level": 0
    },
    {
      "x": -4,
      "y": 0,
      "z": -1,
      "name": "Empty",
      "level": 0
    },
    {
      "x": -4,
      "y": 1,
      "z": -1,
      "name": "Empty",
      "level": 0
    },
    {
      "x": -4,
      "y": 4,
      "z": -1,
      "name": "Empty",
      "level": 0
    },
    {
      "x": -4,
      "y": 14,
      "z": -1,
      "name": "Empty",
      "level": 0
    },
    {
      "x": -4,
      "y": 15,
      "z": -1,
      "name": "Empty",
      "level": 0
    },
    {
      "x": -4,
      "y": 1,
      "z": 0,
      "name": "Empty",
      "level": 0
    },
    {
      "x": -4,
      "y": 12,
      "z": 0,
      "name": "Empty",
      "level": 0
    },
    {
      "x": -4,
      "y": 15,
      "z": 0,
      "name": "Empty",
      "level": 0
    },
    {
      "x": -4,
      "y": 16,
      "z": 0,
      "name": "Empty",
      "level": 0
    },
    {
      "x": -4,
      "y": 0,
      "z": 1,
      "name": "Empty",
      "level": 0
    },
    {
      "x": -4,
      "y": 1,
      "z": 1,
      "name": "Empty",
      "level": 0
    },
    {
      "x": -4,
      "y": 4,
      "z": 1,
      "name": "Empty",
      "level": 0
    },
    {
      "x": -4,
      "y": 14,
      "z": 1,
      "name": "Empty",
      "level": 0
    },
    {
      "x": -4,
      "y": 15,
      "z": 1,
      "name": "Empty",
      "level": 0
    },
    {
      "x": -4,
      "y": 1,
      "z": 2,
      "name": "Empty",
      "level": 0
    },
    {
      "x": -4,
      "y": 2,
      "z": 2,
      "name": "Empty",
      "level": 0
    },
    {
      "x": -4,
      "y": 4,
      "z": 2,
      "name": "Empty",
      "level": 0
    },
    {
      "x": -4,
      "y": 8,
      "z": 2,
      "name": "Empty",
      "level": 0
    },
    {
      "x": -4,
      "y": 13,
      "z": 2,
      "name": "Empty",
      "level": 0
    },
    {
      "x": -4,
      "y": 14,
      "z": 2,
      "name": "Empty",
      "level": 0
    },
    {
      "x": -4,
      "y": 2,
      "z": 3,
      "name": "Empty",
      "level": 0
    },
    {
      "x": -4,
      "y": 4,
      "z": 3,
      "name": "Empty",
      "level": 0
    },
    {
      "x": -4,
      "y": 11,
      "z": 3,
      "name": "Empty",
      "level": 0
    },
    {
      "x": -4,
      "y": 12,
      "z": 3,
      "name": "Empty",
      "level": 0
    },
    {
      "x": -4,
      "y": 13,
      "z": 3,
      "name": "Empty",
      "level": 0
    },
    {
      "x": -4,
      "y": 2,
      "z": 4,
      "name": "Empty",
      "level": 0
    },
    {
      "x": -4,
      "y": 3,
      "z": 4,
      "name": "Empty",
      "level": 0
    },
    {
      "x": -4,
      "y": 4,
      "z": 4,
      "name": "Empty",
      "level": 0
    },
    {
      "x": -4,
      "y": 9,
      "z": 4,
      "name": "Empty",
      "level": 0
    },
    {
      "x": -4,
      "y": 10,
      "z": 4,
      "name": "Empty",
      "level": 0
    },
    {
      "x": -4,
      "y": 11,
      "z": 4,
      "name": "Empty",
      "level": 0
    },
    {
      "x": -4,
      "y": 3,
      "z": 5,
      "name": "Empty",
      "level": 0
    },
    {
      "x": -4,
      "y": 4,
      "z": 5,
      "name": "Empty",
      "level": 0
    },
    {
      "x": -4,
      "y": 9,
      "z": 5,
      "name": "Empty",
      "level": 0
    },
    {
      "x": -3,
      "y": 3,
      "z": -5,
      "name": "Empty",
      "level": 0
    },
    {
      "x": -3,
      "y": 4,
      "z": -5,
      "name": "Empty",
      "level": 0
    },
    {
      "x": -3,
      "y": 6,
      "z": -5,
      "name": "Empty",
      "level": 0
    },
    {
      "x": -3,
      "y": 8,
      "z": -5,
      "name": "Empty",
      "level": 0
    },
    {
      "x": -3,
      "y": 9,
      "z": -5,
      "name": "Empty",
      "level": 0
    },
    {
      "x": -3,
      "y": 2,
      "z": -4,
      "name": "Empty",
      "level": 0
    },
    {
      "x": -3,
      "y": 4,
      "z": -4,
      "name": "Empty",
      "level": 0
    },
    {
      "x": -3,
      "y": 5,
      "z": -4,
      "name": "Empty",
      "level": 0
    },
    {
      "x": -3,
      "y": 6,
      "z": -4,
      "name": "Empty",
      "level": 0
    },
    {
      "x": -3,
      "y": 7,
      "z": -4,
      "name": "Empty",
      "level": 0
    },
    {
      "x": -3,
      "y": 8,
      "z": -4,
      "name": "Empty",
      "level": 0
    },
    {
      "x": -3,
      "y": 9,
      "z": -4,
      "name": "Empty",
      "level": 0
    },
    {
      "x": -3,
      "y": 10,
      "z": -4,
      "name": "Empty",
      "level": 0
    },
    {
      "x": -3,
      "y": 11,
      "z": -4,
      "name": "Empty",
      "level": 0
    },
    {
      "x": -3,
      "y": 2,
      "z": -3,
      "name": "Empty",
      "level": 0
    },
    {
      "x": -3,
      "y": 4,
      "z": -3,
      "name": "Empty",
      "level": 0
    },
    {
      "x": -3,
      "y": 5,
      "z": -3,
      "name": "Empty",
      "level": 0
    },
    {
      "x": -3,
      "y": 6,
      "z": -3,
      "name": "Empty",
      "level": 0
    },
    {
      "x": -3,
      "y": 7,
      "z": -3,
      "name": "Empty",
      "level": 0
    },
    {
      "x": -3,
      "y": 8,
      "z": -3,
      "name": "Empty",
      "level": 0
    },
    {
      "x": -3,
      "y": 9,
      "z": -3,
      "name": "Empty",
      "level": 0
    },
    {
      "x": -3,
      "y": 10,
      "z": -3,
      "name": "Empty",
      "level": 0
    },
    {
      "x": -3,
      "y": 11,
      "z": -3,
      "name": "Empty",
      "level": 0
    },
    {
      "x": -3,
      "y": 12,
      "z": -3,
      "name": "Empty",
      "level": 0
    },
    {
      "x": -3,
      "y": 13,
      "z": -3,
      "name": "Empty",
      "level": 0
    },
    {
      "x": -3,
      "y": 1,
      "z": -2,
      "name": "Empty",
      "level": 0
    },
    {
      "x": -3,
      "y": 4,
      "z": -2,
      "name": "Empty",
      "level": 0
    },
    {
      "x": -3,
      "y": 5,
      "z": -2,
      "name": "Empty",
      "level": 0
    },
    {
      "x": -3,
      "y": 6,
      "z": -2,
      "name": "Empty",
      "level": 0
    },
    {
      "x": -3,
      "y": 7,
      "z": -2,
      "name": "Empty",
      "level": 0
    },
    {
      "x": -3,
      "y": 8,
      "z": -2,
      "name": "Empty",
      "level": 0
    },
    {
      "x": -3,
      "y": 9,
      "z": -2,
      "name": "Empty",
      "level": 0
    },
    {
      "x": -3,
      "y": 10,
      "z": -2,
      "name": "Empty",
      "level": 0
    },
    {
      "x": -3,
      "y": 11,
      "z": -2,
      "name": "Empty",
      "level": 0
    },
    {
      "x": -3,
      "y": 12,
      "z": -2,
      "name": "Empty",
      "level": 0
    },
    {
      "x": -3,
      "y": 13,
      "z": -2,
      "name": "Empty",
      "level": 0
    },
    {
      "x": -3,
      "y": 14,
      "z": -2,
      "name": "Empty",
      "level": 0
    },
    {
      "x": -3,
      "y": 1,
      "z": -1,
      "name": "Empty",
      "level": 0
    },
    {
      "x": -3,
      "y": 4,
      "z": -1,
      "name": "Empty",
      "level": 0
    },
    {
      "x": -3,
      "y": 5,
      "z": -1,
      "name": "Empty",
      "level": 0
    },
    {
      "x": -3,
      "y": 6,
      "z": -1,
      "name": "Empty",
      "level": 0
    },
    {
      "x": -3,
      "y": 7,
      "z": -1,
      "name": "Empty",
      "level": 0
    },
    {
      "x": -3,
      "y": 8,
      "z": -1,
      "name": "Empty",
      "level": 0
    },
    {
      "x": -3,
      "y": 9,
      "z": -1,
      "name": "Empty",
      "level": 0
    },
    {
      "x": -3,
      "y": 10,
      "z": -1,
      "name": "Empty",
      "level": 0
    },
    {
      "x": -3,
      "y": 11,
      "z": -1,
      "name": "Empty",
      "level": 0
    },
    {
      "x": -3,
      "y": 12,
      "z": -1,
      "name": "Empty",
      "level": 0
    },
    {
      "x": -3,
      "y": 13,
      "z": -1,
      "name": "Empty",
      "level": 0
    },
    {
      "x": -3,
      "y": 14,
      "z": -1,
      "name": "Empty",
      "level": 0
    },
    {
      "x": -3,
      "y": 15,
      "z": -1,
      "name": "Empty",
      "level": 0
    },
    {
      "x": -3,
      "y": 1,
      "z": 0,
      "name": "Empty",
      "level": 0
    },
    {
      "x": -3,
      "y": 4,
      "z": 0,
      "name": "Empty",
      "level": 0
    },
    {
      "x": -3,
      "y": 5,
      "z": 0,
      "name": "Empty",
      "level": 0
    },
    {
      "x": -3,
      "y": 6,
      "z": 0,
      "name": "Empty",
      "level": 0
    },
    {
      "x": -3,
      "y": 7,
      "z": 0,
      "name": "Empty",
      "level": 0
    },
    {
      "x": -3,
      "y": 8,
      "z": 0,
      "name": "Empty",
      "level": 0
    },
    {
      "x": -3,
      "y": 9,
      "z": 0,
      "name": "Empty",
      "level": 0
    },
    {
      "x": -3,
      "y": 10,
      "z": 0,
      "name": "Empty",
      "level": 0
    },
    {
      "x": -3,
      "y": 11,
      "z": 0,
      "name": "Empty",
      "level": 0
    },
    {
      "x": -3,
      "y": 12,
      "z": 0,
      "name": "Empty",
      "level": 0
    },
    {
      "x": -3,
      "y": 13,
      "z": 0,
      "name": "Empty",
      "level": 0
    },
    {
      "x": -3,
      "y": 14,
      "z": 0,
      "name": "Empty",
      "level": 0
    },
    {
      "x": -3,
      "y": 15,
      "z": 0,
      "name": "Empty",
      "level": 0
    },
    {
      "x": -3,
      "y": 16,
      "z": 0,
      "name": "Empty",
      "level": 0
    },
    {
      "x": -3,
      "y": 1,
      "z": 1,
      "name": "Empty",
      "level": 0
    },
    {
      "x": -3,
      "y": 4,
      "z": 1,
      "name": "Empty",
      "level": 0
    },
    {
      "x": -3,
      "y": 5,
      "z": 1,
      "name": "Empty",
      "level": 0
    },
    {
      "x": -3,
      "y": 6,
      "z": 1,
      "name": "Empty",
      "level": 0
    },
    {
      "x": -3,
      "y": 7,
      "z": 1,
      "name": "Empty",
      "level": 0
    },
    {
      "x": -3,
      "y": 8,
      "z": 1,
      "name": "Empty",
      "level": 0
    },
    {
      "x": -3,
      "y": 9,
      "z": 1,
      "name": "Empty",
      "level": 0
    },
    {
      "x": -3,
      "y": 10,
      "z": 1,
      "name": "Empty",
      "level": 0
    },
    {
      "x": -3,
      "y": 11,
      "z": 1,
      "name": "Empty",
      "level": 0
    },
    {
      "x": -3,
      "y": 12,
      "z": 1,
      "name": "Empty",
      "level": 0
    },
    {
      "x": -3,
      "y": 13,
      "z": 1,
      "name": "Empty",
      "level": 0
    },
    {
      "x": -3,
      "y": 14,
      "z": 1,
      "name": "Empty",
      "level": 0
    },
    {
      "x": -3,
      "y": 15,
      "z": 1,
      "name": "Empty",
      "level": 0
    },
    {
      "x": -3,
      "y": 1,
      "z": 2,
      "name": "Empty",
      "level": 0
    },
    {
      "x": -3,
      "y": 4,
      "z": 2,
      "name": "Empty",
      "level": 0
    },
    {
      "x": -3,
      "y": 5,
      "z": 2,
      "name": "Empty",
      "level": 0
    },
    {
      "x": -3,
      "y": 6,
      "z": 2,
      "name": "Empty",
      "level": 0
    },
    {
      "x": -3,
      "y": 7,
      "z": 2,
      "name": "Empty",
      "level": 0
    },
    {
      "x": -3,
      "y": 8,
      "z": 2,
      "name": "Empty",
      "level": 0
    },
    {
      "x": -3,
      "y": 9,
      "z": 2,
      "name": "Empty",
      "level": 0
    },
    {
      "x": -3,
      "y": 10,
      "z": 2,
      "name": "Empty",
      "level": 0
    },
    {
      "x": -3,
      "y": 11,
      "z": 2,
      "name": "Empty",
      "level": 0
    },
    {
      "x": -3,
      "y": 12,
      "z": 2,
      "name": "Empty",
      "level": 0
    },
    {
      "x": -3,
      "y": 13,
      "z": 2,
      "name": "Empty",
      "level": 0
    },
    {
      "x": -3,
      "y": 14,
      "z": 2,
      "name": "Empty",
      "level": 0
    },
    {
      "x": -3,
      "y": 2,
      "z": 3,
      "name": "Empty",
      "level": 0
    },
    {
      "x": -3,
      "y": 4,
      "z": 3,
      "name": "Empty",
      "level": 0
    },
    {
      "x": -3,
      "y": 5,
      "z": 3,
      "name": "Empty",
      "level": 0
    },
    {
      "x": -3,
      "y": 6,
      "z": 3,
      "name": "Empty",
      "level": 0
    },
    {
      "x": -3,
      "y": 7,
      "z": 3,
      "name": "Empty",
      "level": 0
    },
    {
      "x": -3,
      "y": 8,
      "z": 3,
      "name": "Empty",
      "level": 0
    },
    {
      "x": -3,
      "y": 9,
      "z": 3,
      "name": "Empty",
      "level": 0
    },
    {
      "x": -3,
      "y": 10,
      "z": 3,
      "name": "Empty",
      "level": 0
    },
    {
      "x": -3,
      "y": 11,
      "z": 3,
      "name": "Empty",
      "level": 0
    },
    {
      "x": -3,
      "y": 12,
      "z": 3,
      "name": "Empty",
      "level": 0
    },
    {
      "x": -3,
      "y": 13,
      "z": 3,
      "name": "Empty",
      "level": 0
    },
    {
      "x": -3,
      "y": 2,
      "z": 4,
      "name": "Empty",
      "level": 0
    },
    {
      "x": -3,
      "y": 4,
      "z": 4,
      "name": "Empty",
      "level": 0
    },
    {
      "x": -3,
      "y": 5,
      "z": 4,
      "name": "Empty",
      "level": 0
    },
    {
      "x": -3,
      "y": 6,
      "z": 4,
      "name": "Empty",
      "level": 0
    },
    {
      "x": -3,
      "y": 7,
      "z": 4,
      "name": "Empty",
      "level": 0
    },
    {
      "x": -3,
      "y": 8,
      "z": 4,
      "name": "Empty",
      "level": 0
    },
    {
      "x": -3,
      "y": 9,
      "z": 4,
      "name": "Empty",
      "level": 0
    },
    {
      "x": -3,
      "y": 10,
      "z": 4,
      "name": "Empty",
      "level": 0
    },
    {
      "x": -3,
      "y": 11,
      "z": 4,
      "name": "Empty",
      "level": 0
    },
    {
      "x": -3,
      "y": 3,
      "z": 5,
      "name": "Empty",
      "level": 0
    },
    {
      "x": -3,
      "y": 4,
      "z": 5,
      "name": "Empty",
      "level": 0
    },
    {
      "x": -3,
      "y": 7,
      "z": 5,
      "name": "Empty",
      "level": 0
    },
    {
      "x": -3,
      "y": 8,
      "z": 5,
      "name": "Empty",
      "level": 0
    },
    {
      "x": -3,
      "y": 9,
      "z": 5,
      "name": "Empty",
      "level": 0
    },
    {
      "x": -2,
      "y": 3,
      "z": -6,
      "name": "Empty",
      "level": 0
    },
    {
      "x": -2,
      "y": 4,
      "z": -6,
      "name": "Empty",
      "level": 0
    },
    {
      "x": -2,
      "y": 2,
      "z": -5,
      "name": "Empty",
      "level": 0
    },
    {
      "x": -2,
      "y": 4,
      "z": -5,
      "name": "Empty",
      "level": 0
    },
    {
      "x": -2,
      "y": 9,
      "z": -5,
      "name": "Empty",
      "level": 0
    },
    {
      "x": -2,
      "y": 4,
      "z": -4,
      "name": "Empty",
      "level": 0
    },
    {
      "x": -2,
      "y": 5,
      "z": -4,
      "name": "Empty",
      "level": 0
    },
    {
      "x": -2,
      "y": 6,
      "z": -4,
      "name": "Empty",
      "level": 0
    },
    {
      "x": -2,
      "y": 7,
      "z": -4,
      "name": "Empty",
      "level": 0
    },
    {
      "x": -2,
      "y": 8,
      "z": -4,
      "name": "Empty",
      "level": 0
    },
    {
      "x": -2,
      "y": 9,
      "z": -4,
      "name": "Empty",
      "level": 0
    },
    {
      "x": -2,
      "y": 10,
      "z": -4,
      "name": "Empty",
      "level": 0
    },
    {
      "x": -2,
      "y": 11,
      "z": -4,
      "name": "Empty",
      "level": 0
    },
    {
      "x": -2,
      "y": 1,
      "z": -3,
      "name": "Empty",
      "level": 0
    },
    {
      "x": -2,
      "y": 4,
