{
  "version": 8,
  "blockIdVersion": 11,
  "anchorX": 0,
  "anchorY": 0,
  "anchorZ": 0,
  "blocks": [
    {
      "x": -2,
      "y": 0,
      "z": 0,
      "name": "Soil_Clay_Smooth_Yellow2"
    },
    {
      "x": -2,
      "y": 1,
      "z": 0,
      "name": "Soil_Clay_Smooth_Grey2"
    },
    {
      "x": -1,
      "y": 1,
      "z": -1,
      "name": "Soil_Clay_Smooth_Grey"
    },
    {
      "x": -1,
      "y": 0,
      "z": 0,
      "name": "Soil_Clay_Smooth_Grey2",
      "support": 15
    },
    {
      "x": -1,
      "y": 1,
      "z": 0,
      "name": "Soil_Clay_Smooth_Grey2"
    },
    {
      "x": -1,
      "y": 2,
      "z": 0,
      "name": "Soil_Clay_Smooth_Grey2"
    },
    {
      "x": -1,
      "y": 1,
      "z": 1,
      "name": "Soil_Clay_Smooth_Grey"
    },
    {
      "x": 0,
      "y": 1,
      "z": -1,
      "name": "Soil_Clay_Smooth_Grey2"
    },
    {
      "x": 0,
      "y": 2,
      "z": -1,
      "name": "Soil_Clay_Smooth_Grey2"
    },
    {
      "x": 0,
      "y": 1,
      "z": 0,
      "name": "Soil_Clay_Smooth_Grey2"
    },
    {
      "x": 0,
      "y": 2,
      "z": 0,
      "name": "Soil_Clay_Smooth_Yellow2"
    },
    {
      "x": 0,
      "y": 3,
      "z": 0,
      "name": "Soil_Clay_Smooth_Grey",
      "support": 15
    },
    {
      "x": 0,
      "y": 4,
      "z": 0,
      "name": "Soil_Clay_Smooth_Grey2",
      "support": 15
    },
    {
      "x": 0,
      "y": 1,
      "z": 1,
      "name": "Soil_Clay_Smooth_Grey2"
    },
    {
      "x": 0,
      "y": 2,
      "z": 1,
      "name": "Soil_Clay_Smooth_Grey2"
    },
    {
      "x": 1,
      "y": 2,
      "z": -1,
      "name": "Soil_Clay_Smooth_Grey"
    },
    {
      "x": 1,
      "y": 3,
      "z": -1,
      "name": "Soil_Clay_Smooth_Grey2"
    },
    {
      "x": 1,
      "y": 1,
      "z": 0,
      "name": "Soil_Clay_Smooth_Grey"
    },
    {
      "x": 1,
      "y": 2,
      "z": 0,
      "name": "Soil_Clay_Smooth_Yellow2"
    },
    {
      "x": 1,
      "y": 3,
      "z": 0,
      "name": "Soil_Clay_Smooth_Orange",
      "support": 15
    },
    {
      "x": 1,
      "y": 2,
      "z": 1,
      "name": "Soil_Clay_Smooth_Grey2"
    },
    {
      "x": 1,
      "y": 3,
      "z": 1,
      "name": "Soil_Clay_Smooth_Grey2"
    },
    {
      "x": 1,
      "y": 4,
      "z": 1,
      "name": "Soil_Clay_Smooth_Grey"
    },
    {
      "x": 2,
      "y": 3,
      "z": -1,
      "name": "Soil_Clay_Smooth_Grey"
    },
    {
      "x": 2,
      "y": 2,
      "z": 0,
      "name": "Soil_Clay_Smooth_Grey2"
    },
    {
      "x": 2,
      "y": 3,
      "z": 0,
      "name": "Soil_Clay_Smooth_Orange"
    },
    {
      "x": 2,
      "y": 3,
      "z": 1,
      "name": "Soil_Clay_Smooth_Grey"
    },
    {
      "x": 2,
      "y": 4,
      "z": 1,
      "name": "Soil_Clay_Smooth_Grey2"
    },
    {
      "x": 3,
      "y": 3,
      "z": 0,
      "name": "Soil_Clay_Smooth_Grey2"
    },
    {
      "x": 3,
      "y": 4,
      "z": 0,
      "name": "Soil_Clay_Smooth_Grey2"
    }
  ],
  "fluids": [
    {
      "x": -2,
      "y": 0,
      "z": 0,
      "name": "Empty",
      "level": 0
    },
    {
      "x": -2,
      "y": 1,
      "z": 0,
      "name": "Empty",
      "level": 0
    },
    {
      "x": -1,
      "y": 1,
      "z": -1,
      "name": "Empty",
      "level": 0
    },
    {
      "x": -1,
      "y": 0,
      "z": 0,
      "name": "Empty",
      "level": 0
    },
    {
      "x": -1,
      "y": 1,
      "z": 0,
      "name": "Empty",
      "level": 0
    },
    {
      "x": -1,
      "y": 2,
      "z": 0,
      "name": "Empty",
      "level": 0
    },
    {
      "x": -1,
      "y": 1,
      "z": 1,
      "name": "Empty",
      "level": 0
    },
    {
      "x": 0,
      "y": 1,
      "z": -1,
      "name": "Empty",
      "level": 0
    },
    {
      "x": 0,
      "y": 2,
      "z": -1,
      "name": "Empty",
      "level": 0
    },
    {
      "x": 0,
      "y": 1,
      "z": 0,
      "name": "Empty",
      "level": 0
    },
    {
      "x": 0,
      "y": 2,
      "z": 0,
      "name": "Empty",
      "level": 0
    },
    {
      "x": 0,
      "y": 3,
      "z": 0,
      "name": "Empty",
      "level": 0
    },
    {
      "x": 0,
      "y": 4,
      "z": 0,
      "name": "Empty",
      "level": 0
    },
    {
      "x": 0,
      "y": 1,
      "z": 1,
      "name": "Empty",
      "level": 0
    },
    {
      "x": 0,
      "y": 2,
      "z": 1,
      "name": "Empty",
      "level": 0
    },
    {
      "x": 1,
      "y": 2,
      "z": -1,
      "name": "Empty",
      "level": 0
    },
    {
      "x": 1,
      "y": 3,
      "z": -1,
      "name": "Empty",
      "level": 0
    },
    {
      "x": 1,
      "y": 1,
      "z": 0,
      "name": "Empty",
      "level": 0
    },
    {
      "x": 1,
      "y": 2,
      "z": 0,
      "name": "Empty",
      "level": 0
    },
    {
      "x": 1,
      "y": 3,
      "z": 0,
      "name": "Empty",
      "level": 0
    },
    {
      "x": 1,
      "y": 2,
      "z": 1,
      "name": "Empty",
      "level": 0
    },
    {
      "x": 1,
      "y": 3,
      "z": 1,
      "name": "Empty",
      "level": 0
    },
    {
      "x": 1,
      "y": 4,
      "z": 1,
      "name": "Empty",
      "level": 0
    },
    {
      "x": 2,
      "y": 3,
      "z": -1,
      "name": "Empty",
      "level": 0
    },
    {
      "x": 2,
      "y": 2,
      "z": 0,
      "name": "Empty",
      "level": 0
    },
    {
      "x": 2,
      "y": 3,
      "z": 0,
      "name": "Empty",
      "level": 0
    },
    {
      "x": 2,
      "y": 3,
      "z": 1,
      "name": "Empty",
      "level": 0
    },
    {
      "x": 2,
      "y": 4,
      "z": 1,
      "name": "Empty",
      "level": 0
    },
    {
      "x": 3,
      "y": 3,
      "z": 0,
      "name": "Empty",
      "level": 0
    },
    {
      "x": 3,
      "y": 4,
      "z": 0,
      "name": "Empty",
      "level": 0
    }
  ]
}
