{
  "version": 8,
  "blockIdVersion": 11,
  "anchorX": 0,
  "anchorY": 0,
  "anchorZ": 0,
  "blocks": [
    {
      "x": 2,
      "y": 3,
      "z": 3,
      "name": "Soil_Clay_Smooth_White"
    },
    {
      "x": 2,
      "y": 4,
      "z": 3,
      "name": "Soil_Clay_Smooth_White"
    },
    {
      "x": 2,
      "y": 5,
      "z": 3,
      "name": "Soil_Clay_White"
    },
    {
      "x": 2,
      "y": 2,
      "z": 4,
      "name": "Soil_Clay_Smooth_White"
    },
    {
      "x": 2,
      "y": 3,
      "z": 4,
      "name": "Soil_Clay_Smooth_White"
    },
    {
      "x": 2,
      "y": 4,
      "z": 4,
      "name": "Soil_Clay_White"
    },
    {
      "x": 2,
      "y": 5,
      "z": 4,
      "name": "Soil_Clay_Smooth_White"
    },
    {
      "x": 2,
      "y": 6,
      "z": 4,
      "name": "Soil_Clay_Smooth_White"
    },
    {
      "x": 2,
      "y": 3,
      "z": 5,
      "name": "Soil_Clay_White"
    },
    {
      "x": 2,
      "y": 4,
      "z": 5,
      "name": "Soil_Clay_Smooth_White"
    },
    {
      "x": 2,
      "y": 5,
      "z": 5,
      "name": "Soil_Clay_White"
    },
    {
      "x": 3,
      "y": 3,
      "z": 2,
      "name": "Soil_Clay_Smooth_White"
    },
    {
      "x": 3,
      "y": 4,
      "z": 2,
      "name": "Soil_Clay_White"
    },
    {
      "x": 3,
      "y": 5,
      "z": 2,
      "name": "Soil_Clay_Smooth_White"
    },
    {
      "x": 3,
      "y": 2,
      "z": 3,
      "name": "Soil_Clay_Smooth_White"
    },
    {
      "x": 3,
      "y": 5,
      "z": 3,
      "name": "Soil_Clay_Smooth_White"
    },
    {
      "x": 3,
      "y": 6,
      "z": 3,
      "name": "Soil_Clay_Smooth_White"
    },
    {
      "x": 3,
      "y": 1,
      "z": 4,
      "name": "Soil_Clay_Smooth_White"
    },
    {
      "x": 3,
      "y": 7,
      "z": 4,
      "name": "Soil_Clay_White"
    },
    {
      "x": 3,
      "y": 2,
      "z": 5,
      "name": "Soil_Clay_White"
    },
    {
      "x": 3,
      "y": 5,
      "z": 5,
      "name": "Soil_Clay_Smooth_White"
    },
    {
      "x": 3,
      "y": 6,
      "z": 5,
      "name": "Soil_Clay_Smooth_White"
    },
    {
      "x": 3,
      "y": 3,
      "z": 6,
      "name": "Soil_Clay_Smooth_White"
    },
    {
      "x": 3,
      "y": 4,
      "z": 6,
      "name": "Soil_Clay_Smooth_White"
    },
    {
      "x": 3,
      "y": 5,
      "z": 6,
      "name": "Soil_Clay_White"
    },
    {
      "x": 4,
      "y": 2,
      "z": 2,
      "name": "Soil_Clay_White"
    },
    {
      "x": 4,
      "y": 3,
      "z": 2,
      "name": "Soil_Clay_Smooth_White"
    },
    {
      "x": 4,
      "y": 4,
      "z": 2,
      "name": "Soil_Clay_Smooth_White"
    },
    {
      "x": 4,
      "y": 5,
      "z": 2,
      "name": "Soil_Clay_Smooth_White"
    },
    {
      "x": 4,
      "y": 6,
      "z": 2,
      "name": "Soil_Clay_Smooth_White"
    },
    {
      "x": 4,
      "y": 1,
      "z": 3,
      "name": "Soil_Clay_White"
    },
    {
      "x": 4,
      "y": 7,
      "z": 3,
      "name": "Soil_Clay_Smooth_White"
    },
    {
      "x": 4,
      "y": 1,
      "z": 4,
      "name": "Soil_Clay_White"
    },
    {
      "x": 4,
      "y": 7,
      "z": 4,
      "name": "Soil_Clay_Smooth_White"
    },
    {
      "x": 4,
      "y": 1,
      "z": 5,
      "name": "Soil_Clay_Smooth_White"
    },
    {
      "x": 4,
      "y": 7,
      "z": 5,
      "name": "Soil_Clay_Smooth_White"
    },
    {
      "x": 4,
      "y": 2,
      "z": 6,
      "name": "Soil_Clay_Smooth_White"
    },
    {
      "x": 4,
      "y": 3,
      "z": 6,
      "name": "Soil_Clay_Smooth_White"
    },
    {
      "x": 4,
      "y": 4,
      "z": 6,
      "name": "Soil_Clay_White"
    },
    {
      "x": 4,
      "y": 5,
      "z": 6,
      "name": "Soil_Clay_Smooth_White"
    },
    {
      "x": 4,
      "y": 6,
      "z": 6,
      "name": "Soil_Clay_White"
    },
    {
      "x": 5,
      "y": 3,
      "z": 2,
      "name": "Soil_Clay_Smooth_White"
    },
    {
      "x": 5,
      "y": 4,
      "z": 2,
      "name": "Soil_Clay_White"
    },
    {
      "x": 5,
      "y": 5,
      "z": 2,
      "name": "Soil_Clay_White"
    },
    {
      "x": 5,
      "y": 2,
      "z": 3,
      "name": "Soil_Clay_Smooth_White"
    },
    {
      "x": 5,
      "y": 5,
      "z": 3,
      "name": "Soil_Clay_Smooth_White"
    },
    {
      "x": 5,
      "y": 6,
      "z": 3,
      "name": "Soil_Clay_Smooth_White"
    },
    {
      "x": 5,
      "y": 1,
      "z": 4,
      "name": "Soil_Clay_White"
    },
    {
      "x": 5,
      "y": 7,
      "z": 4,
      "name": "Soil_Clay_White"
    },
    {
      "x": 5,
      "y": 2,
      "z": 5,
      "name": "Soil_Clay_Smooth_White"
    },
    {
      "x": 5,
      "y": 5,
      "z": 5,
      "name": "Soil_Clay_Smooth_White"
    },
    {
      "x": 5,
      "y": 6,
      "z": 5,
      "name": "Soil_Clay_Smooth_White"
    },
    {
      "x": 5,
      "y": 3,
      "z": 6,
      "name": "Soil_Clay_Smooth_White"
    },
    {
      "x": 5,
      "y": 4,
      "z": 6,
      "name": "Soil_Clay_Smooth_White"
    },
    {
      "x": 5,
      "y": 5,
      "z": 6,
      "name": "Soil_Clay_Smooth_White"
    },
    {
      "x": 6,
      "y": 3,
      "z": 3,
      "name": "Soil_Clay_White"
    },
    {
      "x": 6,
      "y": 4,
      "z": 3,
      "name": "Soil_Clay_Smooth_White"
    },
    {
      "x": 6,
      "y": 5,
      "z": 3,
      "name": "Soil_Clay_White"
    },
    {
      "x": 6,
      "y": 2,
      "z": 4,
      "name": "Soil_Clay_White"
    },
    {
      "x": 6,
      "y": 3,
      "z": 4,
      "name": "Soil_Clay_Smooth_White"
    },
    {
      "x": 6,
      "y": 4,
      "z": 4,
      "name": "Soil_Clay_Smooth_White"
    },
    {
      "x": 6,
      "y": 5,
      "z": 4,
      "name": "Soil_Clay_Smooth_White"
    },
    {
      "x": 6,
      "y": 6,
      "z": 4,
      "name": "Soil_Clay_Smooth_White"
    },
    {
      "x": 6,
      "y": 3,
      "z": 5,
      "name": "Soil_Clay_Smooth_White"
    },
    {
      "x": 6,
      "y": 4,
      "z": 5,
      "name": "Soil_Clay_White"
    },
    {
      "x": 6,
      "y": 5,
      "z": 5,
      "name": "Soil_Clay_Smooth_White"
    }
  ],
  "fluids": [
    {
      "x": 2,
      "y": 3,
      "z": 3,
      "name": "Empty",
      "level": 0
    },
    {
      "x": 2,
      "y": 4,
      "z": 3,
      "name": "Empty",
      "level": 0
    },
    {
      "x": 2,
      "y": 5,
      "z": 3,
      "name": "Empty",
      "level": 0
    },
    {
      "x": 2,
      "y": 2,
      "z": 4,
      "name": "Empty",
      "level": 0
    },
    {
      "x": 2,
      "y": 3,
      "z": 4,
      "name": "Empty",
      "level": 0
    },
    {
      "x": 2,
      "y": 4,
      "z": 4,
      "name": "Empty",
      "level": 0
    },
    {
      "x": 2,
      "y": 5,
      "z": 4,
      "name": "Empty",
      "level": 0
    },
    {
      "x": 2,
      "y": 6,
      "z": 4,
      "name": "Empty",
      "level": 0
    },
    {
      "x": 2,
      "y": 3,
      "z": 5,
      "name": "Empty",
      "level": 0
    },
    {
      "x": 2,
      "y": 4,
      "z": 5,
      "name": "Empty",
      "level": 0
    },
    {
      "x": 2,
      "y": 5,
      "z": 5,
      "name": "Empty",
      "level": 0
    },
    {
      "x": 3,
      "y": 3,
      "z": 2,
      "name": "Empty",
      "level": 0
    },
    {
      "x": 3,
      "y": 4,
      "z": 2,
      "name": "Empty",
      "level": 0
    },
    {
      "x": 3,
      "y": 5,
      "z": 2,
      "name": "Empty",
      "level": 0
    },
    {
      "x": 3,
      "y": 2,
      "z": 3,
      "name": "Empty",
      "level": 0
    },
    {
      "x": 3,
      "y": 5,
      "z": 3,
      "name": "Empty",
      "level": 0
    },
    {
      "x": 3,
      "y": 6,
      "z": 3,
      "name": "Empty",
      "level": 0
    },
    {
      "x": 3,
      "y": 1,
      "z": 4,
      "name": "Empty",
      "level": 0
    },
    {
      "x": 3,
      "y": 7,
      "z": 4,
      "name": "Empty",
      "level": 0
    },
    {
      "x": 3,
      "y": 2,
      "z": 5,
      "name": "Empty",
      "level": 0
    },
    {
      "x": 3,
      "y": 5,
      "z": 5,
      "name": "Empty",
      "level": 0
    },
    {
      "x": 3,
      "y": 6,
      "z": 5,
      "name": "Empty",
      "level": 0
    },
    {
      "x": 3,
      "y": 3,
      "z": 6,
      "name": "Empty",
      "level": 0
    },
    {
      "x": 3,
      "y": 4,
      "z": 6,
      "name": "Empty",
      "level": 0
    },
    {
      "x": 3,
      "y": 5,
      "z": 6,
      "name": "Empty",
      "level": 0
    },
    {
      "x": 4,
      "y": 2,
      "z": 2,
      "name": "Empty",
      "level": 0
    },
    {
      "x": 4,
      "y": 3,
      "z": 2,
      "name": "Empty",
      "level": 0
    },
    {
      "x": 4,
      "y": 4,
      "z": 2,
      "name": "Empty",
      "level": 0
    },
    {
      "x": 4,
      "y": 5,
      "z": 2,
      "name": "Empty",
      "level": 0
    },
    {
      "x": 4,
      "y": 6,
      "z": 2,
      "name": "Empty",
      "level": 0
    },
    {
      "x": 4,
      "y": 1,
      "z": 3,
      "name": "Empty",
      "level": 0
    },
    {
      "x": 4,
      "y": 7,
      "z": 3,
      "name": "Empty",
      "level": 0
    },
    {
      "x": 4,
      "y": 1,
      "z": 4,
      "name": "Empty",
      "level": 0
    },
    {
      "x": 4,
      "y": 7,
      "z": 4,
      "name": "Empty",
      "level": 0
    },
    {
      "x": 4,
      "y": 1,
      "z": 5,
      "name": "Empty",
      "level": 0
    },
    {
      "x": 4,
      "y": 7,
      "z": 5,
      "name": "Empty",
      "level": 0
    },
    {
      "x": 4,
      "y": 2,
      "z": 6,
      "name": "Empty",
      "level": 0
    },
    {
      "x": 4,
      "y": 3,
      "z": 6,
      "name": "Empty",
      "level": 0
    },
    {
      "x": 4,
      "y": 4,
      "z": 6,
      "name": "Empty",
      "level": 0
    },
    {
      "x": 4,
      "y": 5,
      "z": 6,
      "name": "Empty",
      "level": 0
    },
    {
      "x": 4,
      "y": 6,
      "z": 6,
      "name": "Empty",
      "level": 0
    },
    {
      "x": 5,
      "y": 3,
      "z": 2,
      "name": "Empty",
      "level": 0
    },
    {
      "x": 5,
      "y": 4,
      "z": 2,
      "name": "Empty",
      "level": 0
    },
    {
      "x": 5,
      "y": 5,
      "z": 2,
      "name": "Empty",
      "level": 0
    },
    {
      "x": 5,
      "y": 2,
      "z": 3,
      "name": "Empty",
      "level": 0
    },
    {
      "x": 5,
      "y": 5,
      "z": 3,
      "name": "Empty",
      "level": 0
    },
    {
      "x": 5,
      "y": 6,
      "z": 3,
      "name": "Empty",
      "level": 0
    },
    {
      "x": 5,
      "y": 1,
      "z": 4,
      "name": "Empty",
      "level": 0
    },
    {
      "x": 5,
      "y": 7,
      "z": 4,
      "name": "Empty",
      "level": 0
    },
    {
      "x": 5,
      "y": 2,
      "z": 5,
      "name": "Empty",
      "level": 0
    },
    {
      "x": 5,
      "y": 5,
      "z": 5,
      "name": "Empty",
      "level": 0
    },
    {
      "x": 5,
      "y": 6,
      "z": 5,
      "name": "Empty",
      "level": 0
    },
    {
      "x": 5,
      "y": 3,
      "z": 6,
      "name": "Empty",
      "level": 0
    },
    {
      "x": 5,
      "y": 4,
      "z": 6,
      "name": "Empty",
      "level": 0
    },
    {
      "x": 5,
      "y": 5,
      "z": 6,
      "name": "Empty",
      "level": 0
    },
    {
      "x": 6,
      "y": 3,
      "z": 3,
      "name": "Empty",
      "level": 0
    },
    {
      "x": 6,
      "y": 4,
      "z": 3,
      "name": "Empty",
      "level": 0
    },
    {
      "x": 6,
      "y": 5,
      "z": 3,
      "name": "Empty",
      "level": 0
    },
    {
      "x": 6,
      "y": 2,
      "z": 4,
      "name": "Empty",
      "level": 0
    },
    {
      "x": 6,
      "y": 3,
      "z": 4,
      "name": "Empty",
      "level": 0
    },
    {
      "x": 6,
      "y": 4,
      "z": 4,
      "name": "Empty",
      "level": 0
    },
    {
      "x": 6,
      "y": 5,
      "z": 4,
      "name": "Empty",
      "level": 0
    },
    {
      "x": 6,
      "y": 6,
      "z": 4,
      "name": "Empty",
      "level": 0
    },
    {
      "x": 6,
      "y": 3,
      "z": 5,
      "name": "Empty",
      "level": 0
    },
    {
      "x": 6,
      "y": 4,
      "z": 5,
      "name": "Empty",
      "level": 0
    },
    {
      "x": 6,
      "y": 5,
      "z": 5,
      "name": "Empty",
      "level": 0
    }
  ]
}
