{
  "version": 8,
  "blockIdVersion": 11,
  "anchorX": 0,
  "anchorY": 0,
  "anchorZ": 0,
  "blocks": [
    {
      "x": -16,
      "y": 12,
      "z": -3,
      "name": "Plant_Moss_Block_Green",
      "support": 15
    },
    {
      "x": -16,
      "y": 13,
      "z": -3,
      "name": "Plant_Moss_Block_Green",
      "support": 15
    },
    {
      "x": -16,
      "y": 12,
      "z": -2,
      "name": "Plant_Moss_Block_Green",
      "support": 15
    },
    {
      "x": -16,
      "y": 13,
      "z": -2,
      "name": "Plant_Moss_Block_Green",
      "support": 15
    },
    {
      "x": -16,
      "y": 12,
      "z": -1,
      "name": "Plant_Moss_Block_Green",
      "support": 15
    },
    {
      "x": -16,
      "y": 13,
      "z": -1,
      "name": "Plant_Moss_Block_Green",
      "support": 15
    },
    {
      "x": -16,
      "y": 12,
      "z": 0,
      "name": "Plant_Moss_Block_Green",
      "support": 15
    },
    {
      "x": -16,
      "y": 13,
      "z": 0,
      "name": "Plant_Moss_Block_Green",
      "support": 15
    },
    {
      "x": -16,
      "y": 12,
      "z": 1,
      "name": "Plant_Moss_Block_Green",
      "support": 15
    },
    {
      "x": -16,
      "y": 13,
      "z": 1,
      "name": "Plant_Moss_Block_Green",
      "support": 15
    },
    {
      "x": -16,
      "y": 12,
      "z": 2,
      "name": "Plant_Moss_Block_Green",
      "support": 15
    },
    {
      "x": -16,
      "y": 13,
      "z": 2,
      "name": "Plant_Moss_Block_Green",
      "support": 15
    },
    {
      "x": -16,
      "y": 13,
      "z": 3,
      "name": "Plant_Moss_Block_Green",
      "support": 15
    },
    {
      "x": -15,
      "y": 13,
      "z": -8,
      "name": "Plant_Moss_Block_Green",
      "support": 15
    },
    {
      "x": -15,
      "y": 13,
      "z": -7,
      "name": "Plant_Moss_Block_Green",
      "support": 15
    },
    {
      "x": -15,
      "y": 14,
      "z": -7,
      "name": "Plant_Moss_Block_Green",
      "support": 15
    },
    {
      "x": -15,
      "y": 10,
      "z": -6,
      "name": "Plant_Vine_Jungle",
      "support": 15,
      "rotation": 3
    },
    {
      "x": -15,
      "y": 11,
      "z": -6,
      "name": "Plant_Vine_Jungle",
      "support": 15,
      "rotation": 3
    },
    {
      "x": -15,
      "y": 13,
      "z": -6,
      "name": "Plant_Moss_Block_Green",
      "support": 15
    },
    {
      "x": -15,
      "y": 14,
      "z": -6,
      "name": "Plant_Moss_Block_Green",
      "support": 15
    },
    {
      "x": -15,
      "y": 11,
      "z": -5,
      "name": "Plant_Vine_Jungle",
      "support": 15,
      "rotation": 3
    },
    {
      "x": -15,
      "y": 12,
      "z": -5,
      "name": "Plant_Moss_Block_Green",
      "support": 15
    },
    {
      "x": -15,
      "y": 13,
      "z": -5,
      "name": "Plant_Moss_Block_Green",
      "support": 15
    },
    {
      "x": -15,
      "y": 11,
      "z": -4,
      "name": "Plant_Vine_Jungle",
      "support": 15,
      "rotation": 3
    },
    {
      "x": -15,
      "y": 12,
      "z": -4,
      "name": "Plant_Moss_Block_Green",
      "support": 15
    },
    {
      "x": -15,
      "y": 13,
      "z": -4,
      "name": "Plant_Moss_Block_Green",
      "support": 15
    },
    {
      "x": -15,
      "y": 14,
      "z": -4,
      "name": "Plant_Moss_Rug_Green",
      "support": 15
    },
    {
      "x": -15,
      "y": 11,
      "z": -3,
      "name": "Plant_Moss_Block_Green",
      "support": 15
    },
    {
      "x": -15,
      "y": 12,
      "z": -3,
      "name": "Plant_Moss_Block_Green",
      "support": 15
    },
    {
      "x": -15,
      "y": 13,
      "z": -3,
      "name": "Plant_Moss_Block_Green",
      "support": 15
    },
    {
      "x": -15,
      "y": 14,
      "z": -3,
      "name": "Plant_Moss_Block_Green",
      "support": 15
    },
    {
      "x": -15,
      "y": 10,
      "z": -2,
      "name": "Plant_Vine_Jungle",
      "support": 15,
      "rotation": 3
    },
    {
      "x": -15,
      "y": 11,
      "z": -2,
      "name": "Plant_Moss_Block_Green",
      "support": 15
    },
    {
      "x": -15,
      "y": 12,
      "z": -2,
      "name": "Plant_Moss_Block_Green",
      "support": 15
    },
    {
      "x": -15,
      "y": 13,
      "z": -2,
      "name": "Plant_Moss_Block_Green",
      "support": 15
    },
    {
      "x": -15,
      "y": 14,
      "z": -2,
      "name": "Plant_Moss_Block_Green",
      "support": 15
    },
    {
      "x": -15,
      "y": 15,
      "z": -2,
      "name": "Plant_Moss_Rug_Green",
      "support": 15
    },
    {
      "x": -15,
      "y": 10,
      "z": -1,
      "name": "Plant_Vine_Jungle",
      "support": 15,
      "rotation": 3
    },
    {
      "x": -15,
      "y": 11,
      "z": -1,
      "name": "Plant_Moss_Block_Green",
      "support": 15
    },
    {
      "x": -15,
      "y": 12,
      "z": -1,
      "name": "Plant_Moss_Block_Green",
      "support": 15
    },
    {
      "x": -15,
      "y": 13,
      "z": -1,
      "name": "Plant_Moss_Block_Green",
      "support": 15
    },
    {
      "x": -15,
      "y": 14,
      "z": -1,
      "name": "Plant_Moss_Block_Green",
      "support": 15
    },
    {
      "x": -15,
      "y": 15,
      "z": -1,
      "name": "Plant_Moss_Rug_Green",
      "support": 15
    },
    {
      "x": -15,
      "y": 9,
      "z": 0,
      "name": "Plant_Vine_Jungle",
      "support": 15,
      "rotation": 3
    },
    {
      "x": -15,
      "y": 10,
      "z": 0,
      "name": "Plant_Vine_Jungle",
      "support": 15,
      "rotation": 3
    },
    {
      "x": -15,
      "y": 11,
      "z": 0,
      "name": "Plant_Moss_Block_Green",
      "support": 15
    },
    {
      "x": -15,
      "y": 12,
      "z": 0,
      "name": "Plant_Moss_Block_Green",
      "support": 15
    },
    {
      "x": -15,
      "y": 13,
      "z": 0,
      "name": "Plant_Moss_Block_Green",
      "support": 15
    },
    {
      "x": -15,
      "y": 14,
      "z": 0,
      "name": "Rock_Stone_Mossy",
      "support": 15
    },
    {
      "x": -15,
      "y": 10,
      "z": 1,
      "name": "Plant_Vine_Jungle",
      "support": 15,
      "rotation": 3
    },
    {
      "x": -15,
      "y": 11,
      "z": 1,
      "name": "Plant_Moss_Block_Green",
      "support": 15
    },
    {
      "x": -15,
      "y": 12,
      "z": 1,
      "name": "Plant_Moss_Block_Green",
      "support": 15
    },
    {
      "x": -15,
      "y": 13,
      "z": 1,
      "name": "Soil_Clay_Lime",
      "support": 15
    },
    {
      "x": -15,
      "y": 14,
      "z": 1,
      "name": "Soil_Clay_Lime",
      "support": 15
    },
    {
      "x": -15,
      "y": 11,
      "z": 2,
      "name": "Plant_Moss_Block_Green",
      "support": 15
    },
    {
      "x": -15,
      "y": 12,
      "z": 2,
      "name": "Plant_Moss_Block_Green",
      "support": 15
    },
    {
      "x": -15,
      "y": 13,
      "z": 2,
      "name": "Soil_Clay_Lime",
      "support": 15
    },
    {
      "x": -15,
      "y": 14,
      "z": 2,
      "name": "Rock_Stone_Mossy",
      "support": 15
    },
    {
      "x": -15,
      "y": 12,
      "z": 3,
      "name": "Plant_Moss_Block_Green",
      "support": 15
    },
    {
      "x": -15,
      "y": 13,
      "z": 3,
      "name": "Plant_Moss_Block_Green",
      "support": 15
    },
    {
      "x": -15,
      "y": 14,
      "z": 3,
      "name": "Rock_Stone_Mossy",
      "support": 15
    },
    {
      "x": -15,
      "y": 12,
      "z": 4,
      "name": "Plant_Moss_Block_Green",
      "support": 15
    },
    {
      "x": -15,
      "y": 13,
      "z": 4,
      "name": "Plant_Moss_Block_Green",
      "support": 15
    },
    {
      "x": -15,
      "y": 14,
      "z": 4,
      "name": "Plant_Moss_Block_Green",
      "support": 15
    },
    {
      "x": -15,
      "y": 13,
      "z": 5,
      "name": "Plant_Moss_Block_Green",
      "support": 15
    },
    {
      "x": -15,
      "y": 13,
      "z": 6,
      "name": "Plant_Moss_Block_Green",
      "support": 15
    },
    {
      "x": -14,
      "y": 13,
      "z": -10,
      "name": "Plant_Moss_Block_Green",
      "support": 15
    },
    {
      "x": -14,
      "y": 13,
      "z": -9,
      "name": "Plant_Moss_Block_Green",
      "support": 15
    },
    {
      "x": -14,
      "y": 12,
      "z": -8,
      "name": "Plant_Moss_Block_Green",
      "support": 15
    },
    {
      "x": -14,
      "y": 13,
      "z": -8,
      "name": "Plant_Moss_Block_Green",
      "support": 15
    },
    {
      "x": -14,
      "y": 14,
      "z": -8,
      "name": "Plant_Moss_Block_Green",
      "support": 15
    },
    {
      "x": -14,
      "y": 12,
      "z": -7,
      "name": "Plant_Moss_Block_Green",
      "support": 15
    },
    {
      "x": -14,
      "y": 13,
      "z": -7,
      "name": "Plant_Moss_Block_Green",
      "support": 15
    },
    {
      "x": -14,
      "y": 14,
      "z": -7,
      "name": "Soil_Clay_Lime",
      "support": 15
    },
    {
      "x": -14,
      "y": 11,
      "z": -6,
      "name": "Plant_Moss_Block_Green",
      "support": 15
    },
    {
      "x": -14,
      "y": 12,
      "z": -6,
      "name": "Plant_Moss_Block_Green",
      "support": 15
    },
    {
      "x": -14,
      "y": 13,
      "z": -6,
      "name": "Soil_Clay_Lime",
      "support": 15
    },
    {
      "x": -14,
      "y": 14,
      "z": -6,
      "name": "Soil_Clay_Lime",
      "support": 15
    },
    {
      "x": -14,
      "y": 9,
      "z": -5,
      "name": "Plant_Vine_Jungle",
      "support": 15,
      "rotation": 3
    },
    {
      "x": -14,
      "y": 10,
      "z": -5,
      "name": "Plant_Vine_Jungle",
      "support": 15,
      "rotation": 3
    },
    {
      "x": -14,
      "y": 11,
      "z": -5,
      "name": "Plant_Moss_Block_Green",
      "support": 15
    },
    {
      "x": -14,
      "y": 12,
      "z": -5,
      "name": "Plant_Moss_Block_Green",
      "support": 15
    },
    {
      "x": -14,
      "y": 13,
      "z": -5,
      "name": "Plant_Moss_Block_Green",
      "support": 15
    },
    {
      "x": -14,
      "y": 14,
      "z": -5,
      "name": "Soil_Clay_Lime",
      "support": 15
    },
    {
      "x": -14,
      "y": 10,
      "z": -4,
      "name": "Plant_Moss_Block_Green",
      "support": 15
    },
    {
      "x": -14,
      "y": 11,
      "z": -4,
      "name": "Plant_Moss_Block_Green",
      "support": 15
    },
    {
      "x": -14,
      "y": 12,
      "z": -4,
      "name": "Plant_Moss_Block_Green",
      "support": 15
    },
    {
      "x": -14,
      "y": 13,
      "z": -4,
      "name": "Plant_Moss_Block_Green",
      "support": 15
    },
    {
      "x": -14,
      "y": 14,
      "z": -4,
      "name": "Rock_Stone_Mossy",
      "support": 15
    },
    {
      "x": -14,
      "y": 10,
      "z": -3,
      "name": "Plant_Moss_Block_Green",
      "support": 15
    },
    {
      "x": -14,
      "y": 11,
      "z": -3,
      "name": "Plant_Moss_Block_Green",
      "support": 15
    },
    {
      "x": -14,
      "y": 12,
      "z": -3,
      "name": "Plant_Moss_Block_Green",
      "support": 15
    },
    {
      "x": -14,
      "y": 13,
      "z": -3,
      "name": "Rock_Stone_Mossy",
      "support": 15
    },
    {
      "x": -14,
      "y": 14,
      "z": -3,
      "name": "Soil_Clay_Lime",
      "support": 15
    },
    {
      "x": -14,
      "y": 10,
      "z": -2,
      "name": "Plant_Moss_Block_Green",
      "support": 15
    },
    {
      "x": -14,
      "y": 11,
      "z": -2,
      "name": "Plant_Moss_Block_Green",
      "support": 15
    },
    {
      "x": -14,
      "y": 12,
      "z": -2,
      "name": "Plant_Moss_Block_Green",
      "support": 15
    },
    {
      "x": -14,
      "y": 13,
      "z": -2,
      "name": "Plant_Moss_Block_Green",
      "support": 15
    },
    {
      "x": -14,
      "y": 14,
      "z": -2,
      "name": "Soil_Clay_Lime",
      "support": 15
    },
    {
      "x": -14,
      "y": 9,
      "z": -1,
      "name": "Plant_Vine_Jungle",
      "support": 15,
      "rotation": 3
    },
    {
      "x": -14,
      "y": 10,
      "z": -1,
      "name": "Plant_Moss_Block_Green",
      "support": 15
    },
    {
      "x": -14,
      "y": 11,
      "z": -1,
      "name": "Plant_Moss_Block_Green",
      "support": 15
    },
    {
      "x": -14,
      "y": 12,
      "z": -1,
      "name": "Plant_Moss_Block_Green",
      "support": 15
    },
    {
      "x": -14,
      "y": 13,
      "z": -1,
      "name": "Plant_Moss_Block_Green",
      "support": 15
    },
    {
      "x": -14,
      "y": 14,
      "z": -1,
      "name": "Rock_Stone_Mossy",
      "support": 15
    },
    {
      "x": -14,
      "y": 9,
      "z": 0,
      "name": "Plant_Vine_Jungle",
      "support": 15,
      "rotation": 3
    },
    {
      "x": -14,
      "y": 10,
      "z": 0,
      "name": "Plant_Moss_Block_Green",
      "support": 15
    },
    {
      "x": -14,
      "y": 11,
      "z": 0,
      "name": "Plant_Moss_Block_Green",
      "support": 15
    },
    {
      "x": -14,
      "y": 12,
      "z": 0,
      "name": "Plant_Moss_Block_Green",
      "support": 15
    },
    {
      "x": -14,
      "y": 13,
      "z": 0,
      "name": "Plant_Moss_Block_Green",
      "support": 15
    },
    {
      "x": -14,
      "y": 14,
      "z": 0,
      "name": "Soil_Clay_Lime",
      "support": 15
    },
    {
      "x": -14,
      "y": 7,
      "z": 1,
      "name": "Plant_Vine_Jungle",
      "support": 15,
      "rotation": 3
    },
    {
      "x": -14,
      "y": 8,
      "z": 1,
      "name": "Plant_Vine_Jungle",
      "support": 15,
      "rotation": 3
    },
    {
      "x": -14,
      "y": 9,
      "z": 1,
      "name": "Plant_Vine_Jungle",
      "support": 15,
      "rotation": 3
    },
    {
      "x": -14,
      "y": 10,
      "z": 1,
      "name": "Plant_Moss_Block_Green",
      "support": 15
    },
    {
      "x": -14,
      "y": 11,
      "z": 1,
      "name": "Plant_Moss_Block_Green",
      "support": 15
    },
    {
      "x": -14,
      "y": 12,
      "z": 1,
      "name": "Plant_Moss_Block_Green",
      "support": 15
    },
    {
      "x": -14,
      "y": 13,
      "z": 1,
      "name": "Plant_Moss_Block_Green",
      "support": 15
    },
    {
      "x": -14,
      "y": 14,
      "z": 1,
      "name": "Soil_Clay_Lime",
      "support": 15
    },
    {
      "x": -14,
      "y": 8,
      "z": 2,
      "name": "Plant_Vine_Jungle",
      "support": 15,
      "rotation": 3
    },
    {
      "x": -14,
      "y": 9,
      "z": 2,
      "name": "Plant_Vine_Jungle",
      "support": 15,
      "rotation": 3
    },
    {
      "x": -14,
      "y": 10,
      "z": 2,
      "name": "Soil_Clay_Lime",
      "support": 15
    },
    {
      "x": -14,
      "y": 11,
      "z": 2,
      "name": "Plant_Moss_Block_Green",
      "support": 15
    },
    {
      "x": -14,
      "y": 12,
      "z": 2,
      "name": "Soil_Clay_Lime",
      "support": 15
    },
    {
      "x": -14,
      "y": 13,
      "z": 2,
      "name": "Plant_Moss_Block_Green",
      "support": 15
    },
    {
      "x": -14,
      "y": 14,
      "z": 2,
      "name": "Soil_Clay_Lime",
      "support": 15
    },
    {
      "x": -14,
      "y": 9,
      "z": 3,
      "name": "Plant_Vine_Jungle",
      "support": 15,
      "rotation": 3
    },
    {
      "x": -14,
      "y": 10,
      "z": 3,
      "name": "Plant_Moss_Block_Green",
      "support": 15
    },
    {
      "x": -14,
      "y": 11,
      "z": 3,
      "name": "Plant_Moss_Block_Green",
      "support": 15
    },
    {
      "x": -14,
      "y": 12,
      "z": 3,
      "name": "Plant_Moss_Block_Green",
      "support": 15
    },
    {
      "x": -14,
      "y": 13,
      "z": 3,
      "name": "Plant_Moss_Block_Green",
      "support": 15
    },
    {
      "x": -14,
      "y": 14,
      "z": 3,
      "name": "Soil_Clay_Lime",
      "support": 15
    },
    {
      "x": -14,
      "y": 11,
      "z": 4,
      "name": "Plant_Moss_Block_Green",
      "support": 15
    },
    {
      "x": -14,
      "y": 12,
      "z": 4,
      "name": "Plant_Moss_Block_Green",
      "support": 15
    },
    {
      "x": -14,
      "y": 13,
      "z": 4,
      "name": "Rock_Stone_Mossy",
      "support": 15
    },
    {
      "x": -14,
      "y": 14,
      "z": 4,
      "name": "Soil_Clay_Lime",
      "support": 15
    },
    {
      "x": -14,
      "y": 11,
      "z": 5,
      "name": "Plant_Moss_Block_Green",
      "support": 15
    },
    {
      "x": -14,
      "y": 12,
      "z": 5,
      "name": "Plant_Moss_Block_Green",
      "support": 15
    },
    {
      "x": -14,
      "y": 13,
      "z": 5,
      "name": "Plant_Moss_Block_Green",
      "support": 15
    },
    {
      "x": -14,
      "y": 14,
      "z": 5,
      "name": "Soil_Clay_Lime",
      "support": 15
    },
    {
      "x": -14,
      "y": 10,
      "z": 6,
      "name": "Plant_Vine_Jungle",
      "support": 15
    },
    {
      "x": -14,
      "y": 11,
      "z": 6,
      "name": "Plant_Vine_Jungle",
      "support": 15
    },
    {
      "x": -14,
      "y": 12,
      "z": 6,
      "name": "Plant_Moss_Block_Green",
      "support": 15
    },
    {
      "x": -14,
      "y": 13,
      "z": 6,
      "name": "Plant_Moss_Block_Green",
      "support": 15
    },
    {
      "x": -14,
      "y": 14,
      "z": 6,
      "name": "Plant_Moss_Block_Green",
      "support": 15
    },
    {
      "x": -14,
      "y": 15,
      "z": 6,
      "name": "Plant_Moss_Rug_Green",
      "support": 15
    },
    {
      "x": -14,
      "y": 12,
      "z": 7,
      "name": "Plant_Moss_Block_Green",
      "support": 15
    },
    {
      "x": -14,
      "y": 13,
      "z": 7,
      "name": "Plant_Moss_Block_Green",
      "support": 15
    },
    {
      "x": -14,
      "y": 12,
      "z": 8,
      "name": "Plant_Vine_Jungle",
      "support": 15
    },
    {
      "x": -13,
      "y": 12,
      "z": -11,
      "name": "Plant_Moss_Block_Green",
      "support": 15
    },
    {
      "x": -13,
      "y": 13,
      "z": -11,
      "name": "Plant_Moss_Block_Green",
      "support": 15
    },
    {
      "x": -13,
      "y": 13,
      "z": -10,
      "name": "Plant_Moss_Block_Green",
      "support": 15
    },
    {
      "x": -13,
      "y": 12,
      "z": -9,
      "name": "Plant_Moss_Block_Green",
      "support": 15
    },
    {
      "x": -13,
      "y": 13,
      "z": -9,
      "name": "Plant_Moss_Block_Green",
      "support": 15
    },
    {
      "x": -13,
      "y": 14,
      "z": -9,
      "name": "Soil_Clay_Lime",
      "support": 15
    },
    {
      "x": -13,
      "y": 11,
      "z": -8,
      "name": "Plant_Moss_Block_Green",
      "support": 15
    },
    {
      "x": -13,
      "y": 12,
      "z": -8,
      "name": "Plant_Moss_Block_Green",
      "support": 15
    },
    {
      "x": -13,
      "y": 13,
      "z": -8,
      "name": "Soil_Clay_Lime",
      "support": 15
    },
    {
      "x": -13,
      "y": 14,
      "z": -8,
      "name": "Soil_Clay_Lime",
      "support": 15
    },
    {
      "x": -13,
      "y": 9,
      "z": -7,
      "name": "Plant_Moss_Block_Green",
      "support": 15
    },
    {
      "x": -13,
      "y": 10,
      "z": -7,
      "name": "Plant_Moss_Block_Green",
      "support": 15
    },
    {
      "x": -13,
      "y": 11,
      "z": -7,
      "name": "Plant_Moss_Block_Green",
      "support": 15
    },
    {
      "x": -13,
      "y": 12,
      "z": -7,
      "name": "Plant_Moss_Block_Green",
      "support": 15
    },
    {
      "x": -13,
      "y": 13,
      "z": -7,
      "name": "Plant_Moss_Block_Green",
      "support": 15
    },
    {
      "x": -13,
      "y": 14,
      "z": -7,
      "name": "Rock_Stone_Mossy",
      "support": 15
    },
    {
      "x": -13,
      "y": 15,
      "z": -7,
      "name": "Rock_Stone",
      "support": 15
    },
    {
      "x": -13,
      "y": 10,
      "z": -6,
      "name": "Soil_Clay_Lime",
      "support": 15
    },
    {
      "x": -13,
      "y": 11,
      "z": -6,
      "name": "Plant_Moss_Block_Green",
      "support": 15
    },
    {
      "x": -13,
      "y": 12,
      "z": -6,
      "name": "Plant_Moss_Block_Green",
      "support": 15
    },
    {
      "x": -13,
      "y": 13,
      "z": -6,
      "name": "Plant_Moss_Block_Green",
      "support": 15
    },
    {
      "x": -13,
      "y": 14,
      "z": -6,
      "name": "Soil_Clay_Lime",
      "support": 15
    },
    {
      "x": -13,
      "y": 15,
      "z": -6,
      "name": "Plant_Moss_Block_Green",
      "support": 15
    },
    {
      "x": -13,
      "y": 16,
      "z": -6,
      "name": "Plant_Moss_Rug_Green",
      "support": 15
    },
    {
      "x": -13,
      "y": 9,
      "z": -5,
      "name": "Soil_Clay_Lime",
      "support": 15
    },
    {
      "x": -13,
      "y": 10,
      "z": -5,
      "name": "Plant_Moss_Block_Green",
      "support": 15
    },
    {
      "x": -13,
      "y": 11,
      "z": -5,
      "name": "Plant_Moss_Block_Green",
      "support": 15
    },
    {
      "x": -13,
      "y": 12,
      "z": -5,
      "name": "Plant_Moss_Block_Green",
      "support": 15
    },
    {
      "x": -13,
      "y": 13,
      "z": -5,
      "name": "Plant_Moss_Block_Green",
      "support": 15
    },
    {
      "x": -13,
      "y": 14,
      "z": -5,
      "name": "Rock_Stone_Mossy",
      "support": 15
    },
    {
      "x": -13,
      "y": 15,
      "z": -5,
      "name": "Plant_Moss_Block_Green",
      "support": 15
    },
    {
      "x": -13,
      "y": 16,
      "z": -5,
      "name": "Plant_Moss_Rug_Green",
      "support": 15
    },
    {
      "x": -13,
      "y": 9,
      "z": -4,
      "name": "Soil_Clay_Lime",
      "support": 15
    },
    {
      "x": -13,
      "y": 10,
      "z": -4,
      "name": "Plant_Moss_Block_Green",
      "support": 15
    },
    {
      "x": -13,
      "y": 11,
      "z": -4,
      "name": "Plant_Moss_Block_Green",
      "support": 15
    },
    {
      "x": -13,
      "y": 12,
      "z": -4,
      "name": "Plant_Moss_Block_Green",
      "support": 15
    },
    {
      "x": -13,
      "y": 13,
      "z": -4,
      "name": "Plant_Moss_Block_Green",
      "support": 15
    },
    {
      "x": -13,
      "y": 14,
      "z": -4,
      "name": "Plant_Moss_Block_Green",
      "support": 15
    },
    {
      "x": -13,
      "y": 15,
      "z": -4,
      "name": "Plant_Moss_Block_Green",
      "support": 15
    },
    {
      "x": -13,
      "y": 16,
      "z": -4,
      "name": "Plant_Moss_Rug_Green",
      "support": 15
    },
    {
      "x": -13,
      "y": 9,
      "z": -3,
      "name": "Plant_Moss_Block_Green",
      "support": 15
    },
    {
      "x": -13,
      "y": 10,
      "z": -3,
      "name": "Plant_Moss_Block_Green",
      "support": 15
    },
    {
      "x": -13,
      "y": 11,
      "z": -3,
      "name": "Plant_Moss_Block_Green",
      "support": 15
    },
    {
      "x": -13,
      "y": 12,
      "z": -3,
      "name": "Plant_Moss_Block_Green",
      "support": 15
    },
    {
      "x": -13,
      "y": 13,
      "z": -3,
      "name": "Plant_Moss_Block_Green",
      "support": 15
    },
    {
      "x": -13,
      "y": 14,
      "z": -3,
      "name": "Plant_Moss_Block_Green",
      "support": 15
    },
    {
      "x": -13,
      "y": 15,
      "z": -3,
      "name": "Plant_Moss_Block_Green",
      "support": 15
    },
    {
      "x": -13,
      "y": 9,
      "z": -2,
      "name": "Soil_Clay_Lime",
      "support": 15
    },
    {
      "x": -13,
      "y": 10,
      "z": -2,
      "name": "Plant_Moss_Block_Green",
      "support": 15
    },
    {
      "x": -13,
      "y": 11,
      "z": -2,
      "name": "Plant_Moss_Block_Green",
      "support": 15
    },
    {
      "x": -13,
      "y": 12,
      "z": -2,
      "name": "Plant_Moss_Block_Green",
      "support": 15
    },
    {
      "x": -13,
      "y": 13,
      "z": -2,
      "name": "Plant_Moss_Block_Green",
      "support": 15
    },
    {
      "x": -13,
      "y": 14,
      "z": -2,
      "name": "Rock_Stone_Mossy",
      "support": 15
    },
    {
      "x": -13,
      "y": 15,
      "z": -2,
      "name": "Rock_Stone",
      "support": 15
    },
    {
      "x": -13,
      "y": 9,
      "z": -1,
      "name": "Plant_Moss_Block_Green",
      "support": 15
    },
    {
      "x": -13,
      "y": 10,
      "z": -1,
      "name": "Plant_Moss_Block_Green",
      "support": 15
    },
    {
      "x": -13,
      "y": 11,
      "z": -1,
      "name": "Plant_Moss_Block_Green",
      "support": 15
    },
    {
      "x": -13,
      "y": 12,
      "z": -1,
      "name": "Plant_Moss_Block_Green",
      "support": 15
    },
    {
      "x": -13,
      "y": 13,
      "z": -1,
      "name": "Plant_Moss_Block_Green",
      "support": 15
    },
    {
      "x": -13,
      "y": 14,
      "z": -1,
      "name": "Soil_Clay_Lime",
      "support": 15
    },
    {
      "x": -13,
      "y": 9,
      "z": 0,
      "name": "Plant_Moss_Block_Green",
      "support": 15
    },
    {
      "x": -13,
      "y": 10,
      "z": 0,
      "name": "Plant_Moss_Block_Green",
      "support": 15
    },
    {
      "x": -13,
      "y": 11,
      "z": 0,
      "name": "Plant_Moss_Block_Green",
      "support": 15
    },
    {
      "x": -13,
      "y": 12,
      "z": 0,
      "name": "Plant_Moss_Block_Green",
      "support": 15
    },
    {
      "x": -13,
      "y": 13,
      "z": 0,
      "name": "Plant_Moss_Block_Green",
      "support": 15
    },
    {
      "x": -13,
      "y": 14,
      "z": 0,
      "name": "Soil_Clay_Lime",
      "support": 15
    },
    {
      "x": -13,
      "y": 9,
      "z": 1,
      "name": "Soil_Clay_Lime",
      "support": 15
    },
    {
      "x": -13,
      "y": 10,
      "z": 1,
      "name": "Plant_Moss_Block_Green",
      "support": 15
    },
    {
      "x": -13,
      "y": 11,
      "z": 1,
      "name": "Plant_Moss_Block_Green",
      "support": 15
    },
    {
      "x": -13,
      "y": 12,
      "z": 1,
      "name": "Plant_Moss_Block_Green",
      "support": 15
    },
    {
      "x": -13,
      "y": 13,
      "z": 1,
      "name": "Plant_Moss_Block_Green",
      "support": 15
    },
    {
      "x": -13,
      "y": 14,
      "z": 1,
      "name": "Soil_Clay_Lime",
      "support": 15
    },
    {
      "x": -13,
      "y": 9,
      "z": 2,
      "name": "Soil_Clay_Lime",
      "support": 15
    },
    {
      "x": -13,
      "y": 10,
      "z": 2,
      "name": "Plant_Moss_Block_Green",
      "support": 15
    },
    {
      "x": -13,
      "y": 11,
      "z": 2,
      "name": "Plant_Moss_Block_Green",
      "support": 15
    },
    {
      "x": -13,
      "y": 12,
      "z": 2,
      "name": "Plant_Moss_Block_Green",
      "support": 15
    },
    {
      "x": -13,
      "y": 13,
      "z": 2,
      "name": "Plant_Moss_Block_Green",
      "support": 15
    },
    {
      "x": -13,
      "y": 14,
      "z": 2,
      "name": "Rock_Stone",
      "support": 15
    },
    {
      "x": -13,
      "y": 9,
      "z": 3,
      "name": "Soil_Clay_Lime",
      "support": 15
    },
    {
      "x": -13,
      "y": 10,
      "z": 3,
      "name": "Plant_Moss_Block_Green",
      "support": 15
    },
    {
      "x": -13,
      "y": 11,
      "z": 3,
      "name": "Plant_Moss_Block_Green",
      "support": 15
    },
    {
      "x": -13,
      "y": 12,
      "z": 3,
      "name": "Plant_Moss_Block_Green",
      "support": 15
    },
    {
      "x": -13,
      "y": 13,
      "z": 3,
      "name": "Plant_Moss_Block_Green",
      "support": 15
    },
    {
      "x": -13,
      "y": 14,
      "z": 3,
      "name": "Rock_Stone_Mossy",
      "support": 15
    },
    {
      "x": -13,
      "y": 10,
      "z": 4,
      "name": "Plant_Moss_Block_Green",
      "support": 15
    },
    {
      "x": -13,
      "y": 11,
      "z": 4,
      "name": "Plant_Moss_Block_Green",
      "support": 15
    },
    {
      "x": -13,
      "y": 12,
      "z": 4,
      "name": "Plant_Moss_Block_Green",
      "support": 15
    },
    {
      "x": -13,
      "y": 13,
      "z": 4,
      "name": "Plant_Moss_Block_Green",
      "support": 15
    },
    {
      "x": -13,
      "y": 14,
      "z": 4,
      "name": "Soil_Clay_Lime",
      "support": 15
    },
    {
      "x": -13,
      "y": 10,
      "z": 5,
      "name": "Plant_Moss_Block_Green",
      "support": 15
    },
    {
      "x": -13,
      "y": 11,
      "z": 5,
      "name": "Plant_Moss_Block_Green",
      "support": 15
    },
    {
      "x": -13,
      "y": 12,
      "z": 5,
      "name": "Plant_Moss_Block_Green",
      "support": 15
    },
    {
      "x": -13,
      "y": 13,
      "z": 5,
      "name": "Plant_Moss_Block_Green",
      "support": 15
    },
    {
      "x": -13,
      "y": 14,
      "z": 5,
      "name": "Soil_Clay_Lime",
      "support": 15
    },
    {
      "x": -13,
      "y": 10,
      "z": 6,
      "name": "Plant_Moss_Block_Green",
      "support": 15
    },
    {
      "x": -13,
      "y": 11,
      "z": 6,
      "name": "Plant_Moss_Block_Green",
      "support": 15
    },
    {
      "x": -13,
      "y": 12,
      "z": 6,
      "name": "Plant_Moss_Block_Green",
      "support": 15
    },
    {
      "x": -13,
      "y": 13,
      "z": 6,
      "name": "Plant_Moss_Block_Green",
      "support": 15
    },
    {
      "x": -13,
      "y": 14,
      "z": 6,
      "name": "Soil_Clay_Lime",
      "support": 15
    },
    {
      "x": -13,
      "y": 9,
      "z": 7,
      "name": "Plant_Vine_Jungle",
      "support": 15
    },
    {
      "x": -13,
      "y": 10,
      "z": 7,
      "name": "Plant_Vine_Jungle",
      "support": 15
    },
    {
      "x": -13,
      "y": 11,
      "z": 7,
      "name": "Plant_Moss_Block_Green",
      "support": 15
    },
    {
      "x": -13,
      "y": 12,
      "z": 7,
      "name": "Plant_Moss_Block_Green",
      "support": 15
    },
    {
      "x": -13,
      "y": 13,
      "z": 7,
      "name": "Plant_Moss_Block_Green",
      "support": 15
    },
    {
      "x": -13,
      "y": 14,
      "z": 7,
      "name": "Plant_Moss_Block_Green",
      "support": 15
    },
    {
      "x": -13,
      "y": 15,
      "z": 7,
      "name": "Plant_Moss_Rug_Green",
      "support": 15
    },
    {
      "x": -13,
      "y": 11,
      "z": 8,
      "name": "Plant_Vine_Jungle",
      "support": 15
    },
    {
      "x": -13,
      "y": 12,
      "z": 8,
      "name": "Plant_Moss_Block_Green",
      "support": 15
    },
    {
      "x": -13,
      "y": 13,
      "z": 8,
      "name": "Plant_Moss_Block_Green",
      "support": 15
    },
    {
      "x": -12,
      "y": 12,
      "z": -12,
      "name": "Plant_Moss_Block_Green",
      "support": 15
    },
    {
      "x": -12,
      "y": 13,
      "z": -12,
      "name": "Plant_Moss_Block_Green",
      "support": 15
    },
    {
      "x": -12,
      "y": 11,
      "z": -11,
      "name": "Plant_Vine_Jungle",
      "support": 15,
      "rotation": 3
    },
    {
      "x": -12,
      "y": 12,
      "z": -11,
      "name": "Plant_Moss_Block_Green",
      "support": 15
    },
    {
      "x": -12,
      "y": 13,
      "z": -11,
      "name": "Plant_Moss_Block_Green",
      "support": 15
    },
    {
      "x": -12,
      "y": 14,
      "z": -11,
      "name": "Plant_Moss_Block_Green",
      "support": 15
    },
    {
      "x": -12,
      "y": 8,
      "z": -10,
      "name": "Plant_Vine_Jungle",
      "support": 15,
      "rotation": 3
    },
    {
      "x": -12,
      "y": 9,
      "z": -10,
      "name": "Plant_Vine_Jungle",
      "support": 15,
      "rotation": 3
    },
    {
      "x": -12,
      "y": 10,
      "z": -10,
      "name": "Plant_Vine_Jungle",
      "support": 15,
      "rotation": 3
    },
    {
      "x": -12,
      "y": 11,
      "z": -10,
      "name": "Plant_Vine_Jungle",
      "support": 15,
      "rotation": 3
    },
    {
      "x": -12,
      "y": 12,
      "z": -10,
      "name": "Plant_Moss_Block_Green",
      "support": 15
    },
    {
      "x": -12,
      "y": 13,
      "z": -10,
      "name": "Plant_Moss_Block_Green",
      "support": 15
    },
    {
      "x": -12,
      "y": 14,
      "z": -10,
      "name": "Soil_Clay_Lime",
      "support": 15
    },
    {
      "x": -12,
      "y": 10,
      "z": -9,
      "name": "Plant_Vine_Jungle",
      "support": 15,
      "rotation": 3
    },
    {
      "x": -12,
      "y": 11,
      "z": -9,
      "name": "Plant_Moss_Block_Green",
      "support": 15
    },
    {
      "x": -12,
      "y": 12,
      "z": -9,
      "name": "Plant_Moss_Block_Green",
      "support": 15
    },
    {
      "x": -12,
      "y": 13,
      "z": -9,
      "name": "Soil_Clay_Lime",
      "support": 15
    },
    {
      "x": -12,
      "y": 14,
      "z": -9,
      "name": "Soil_Clay_Lime",
      "support": 15
    },
    {
      "x": -12,
      "y": 10,
      "z": -8,
      "name": "Plant_Moss_Block_Green",
      "support": 15
    },
    {
      "x": -12,
      "y": 11,
      "z": -8,
      "name": "Plant_Moss_Block_Green",
      "support": 15
    },
    {
      "x": -12,
      "y": 12,
      "z": -8,
      "name": "Rock_Stone_Mossy",
      "support": 15
    },
    {
      "x": -12,
      "y": 13,
      "z": -8,
      "name": "Plant_Moss_Block_Green",
      "support": 15
    },
    {
      "x": -12,
      "y": 14,
      "z": -8,
      "name": "Soil_Clay_Lime",
      "support": 15
    },
    {
      "x": -12,
      "y": 9,
      "z": -7,
      "name": "Plant_Moss_Block_Green",
      "support": 15
    },
    {
      "x": -12,
      "y": 10,
      "z": -7,
      "name": "Soil_Clay_Lime",
      "support": 15
    },
    {
      "x": -12,
      "y": 11,
      "z": -7,
      "name": "Plant_Moss_Block_Green",
      "support": 15
    },
    {
      "x": -12,
      "y": 12,
      "z": -7,
      "name": "Plant_Moss_Block_Green",
      "support": 15
    },
    {
      "x": -12,
      "y": 13,
      "z": -7,
      "name": "Plant_Moss_Block_Green",
      "support": 15
    },
    {
      "x": -12,
      "y": 14,
      "z": -7,
      "name": "Soil_Clay_Lime",
      "support": 15
    },
    {
      "x": -12,
      "y": 15,
      "z": -7,
      "name": "Rock_Stone",
      "support": 15
    },
    {
      "x": -12,
      "y": 9,
      "z": -6,
      "name": "Plant_Moss_Block_Green",
      "support": 15
    },
    {
      "x": -12,
      "y": 10,
      "z": -6,
      "name": "Plant_Moss_Block_Green",
      "support": 15
    },
    {
      "x": -12,
      "y": 11,
      "z": -6,
      "name": "Plant_Moss_Block_Green",
      "support": 15
    },
    {
      "x": -12,
      "y": 12,
      "z": -6,
      "name": "Plant_Moss_Block_Green",
      "support": 15
    },
    {
      "x": -12,
      "y": 13,
      "z": -6,
      "name": "Plant_Moss_Block_Green",
      "support": 15
    },
    {
      "x": -12,
      "y": 14,
      "z": -6,
      "name": "Soil_Clay_Lime",
      "support": 15
    },
    {
      "x": -12,
      "y": 15,
      "z": -6,
      "name": "Rock_Stone",
      "support": 15
    },
    {
      "x": -12,
      "y": 16,
      "z": -6,
      "name": "Rock_Stone",
      "support": 15
    },
    {
      "x": -12,
      "y": 8,
      "z": -5,
      "name": "Soil_Clay_Lime",
      "support": 15
    },
    {
      "x": -12,
      "y": 9,
      "z": -5,
      "name": "Plant_Moss_Block_Green",
      "support": 15
    },
    {
      "x": -12,
      "y": 10,
      "z": -5,
      "name": "Plant_Moss_Block_Green",
      "support": 15
    },
    {
      "x": -12,
      "y": 11,
      "z": -5,
      "name": "Plant_Moss_Block_Green",
      "support": 15
    },
    {
      "x": -12,
      "y": 12,
      "z": -5,
      "name": "Plant_Moss_Block_Green",
      "support": 15
    },
    {
      "x": -12,
      "y": 13,
      "z": -5,
      "name": "Plant_Moss_Block_Green",
      "support": 15
    },
    {
      "x": -12,
      "y": 14,
      "z": -5,
      "name": "Rock_Stone_Mossy",
      "support": 15
    },
    {
      "x": -12,
      "y": 15,
      "z": -5,
      "name": "Rock_Stone",
      "support": 15
    },
    {
      "x": -12,
      "y": 16,
      "z": -5,
      "name": "Rock_Stone",
      "support": 15
    },
    {
      "x": -12,
      "y": 8,
      "z": -4,
      "name": "Soil_Clay_Lime",
      "support": 15
    },
    {
      "x": -12,
      "y": 9,
      "z": -4,
      "name": "Soil_Clay_Lime",
      "support": 15
    },
    {
      "x": -12,
      "y": 10,
      "z": -4,
      "name": "Plant_Moss_Block_Green",
      "support": 15
    },
    {
      "x": -12,
      "y": 11,
      "z": -4,
      "name": "Plant_Moss_Block_Green",
      "support": 15
    },
    {
      "x": -12,
      "y": 12,
      "z": -4,
      "name": "Plant_Moss_Block_Green",
      "support": 15
    },
    {
      "x": -12,
      "y": 13,
      "z": -4,
      "name": "Plant_Moss_Block_Green",
      "support": 15
    },
    {
      "x": -12,
      "y": 14,
      "z": -4,
      "name": "Rock_Stone_Mossy",
      "support": 15
    },
    {
      "x": -12,
      "y": 15,
      "z": -4,
      "name": "Rock_Stone",
      "support": 15
    },
    {
      "x": -12,
      "y": 16,
      "z": -4,
      "name": "Plant_Moss_Block_Green",
      "support": 15
    },
    {
      "x": -12,
      "y": 17,
      "z": -4,
      "name": "Plant_Moss_Rug_Green",
      "support": 15
    },
    {
      "x": -12,
      "y": 8,
      "z": -3,
      "name": "Soil_Clay_Lime",
      "support": 15
    },
    {
      "x": -12,
      "y": 9,
      "z": -3,
      "name": "Soil_Clay_Lime",
      "support": 15
    },
    {
      "x": -12,
      "y": 10,
      "z": -3,
      "name": "Soil_Clay_Lime",
      "support": 15
    },
    {
      "x": -12,
      "y": 11,
      "z": -3,
      "name": "Plant_Moss_Block_Green",
      "support": 15
    },
    {
      "x": -12,
      "y": 12,
      "z": -3,
      "name": "Plant_Moss_Block_Green",
      "support": 15
    },
    {
      "x": -12,
      "y": 13,
      "z": -3,
      "name": "Plant_Moss_Block_Green",
      "support": 15
    },
    {
      "x": -12,
      "y": 14,
      "z": -3,
      "name": "Soil_Clay_Lime",
      "support": 15
    },
    {
      "x": -12,
      "y": 15,
      "z": -3,
      "name": "Rock_Stone",
      "support": 15
    },
    {
      "x": -12,
      "y": 16,
      "z": -3,
      "name": "Rock_Stone",
      "support": 15
    },
    {
      "x": -12,
      "y": 8,
      "z": -2,
      "name": "Soil_Clay_Lime",
      "support": 15
    },
    {
      "x": -12,
      "y": 9,
      "z": -2,
      "name": "Plant_Moss_Block_Green",
      "support": 15
    },
    {
      "x": -12,
      "y": 10,
      "z": -2,
      "name": "Plant_Moss_Block_Green",
      "support": 15
    },
    {
      "x": -12,
      "y": 11,
      "z": -2,
      "name": "Plant_Moss_Block_Green",
      "support": 15
    },
    {
      "x": -12,
      "y": 12,
      "z": -2,
      "name": "Plant_Moss_Block_Green",
      "support": 15
    },
    {
      "x": -12,
      "y": 13,
      "z": -2,
      "name": "Plant_Moss_Block_Green",
      "support": 15
    },
    {
      "x": -12,
      "y": 14,
      "z": -2,
      "name": "Soil_Clay_Lime",
      "support": 15
    },
    {
      "x": -12,
      "y": 15,
      "z": -2,
      "name": "Plant_Moss_Block_Green",
      "support": 15
    },
    {
      "x": -12,
      "y": 8,
      "z": -1,
      "name": "Soil_Clay_Lime",
      "support": 15
    },
    {
      "x": -12,
      "y": 9,
      "z": -1,
      "name": "Soil_Clay_Lime",
      "support": 15
    },
    {
      "x": -12,
      "y": 10,
      "z": -1,
      "name": "Soil_Clay_Lime",
      "support": 15
    },
    {
      "x": -12,
      "y": 11,
      "z": -1,
      "name": "Plant_Moss_Block_Green",
      "support": 15
    },
    {
      "x": -12,
      "y": 12,
      "z": -1,
      "name": "Plant_Moss_Block_Green",
      "support": 15
    },
    {
      "x": -12,
      "y": 13,
      "z": -1,
      "name": "Plant_Moss_Block_Green",
      "support": 15
    },
    {
      "x": -12,
      "y": 14,
      "z": -1,
      "name": "Soil_Clay_Lime",
      "support": 15
    },
    {
      "x": -12,
      "y": 8,
      "z": 0,
      "name": "Soil_Clay_Lime",
      "support": 15
    },
    {
      "x": -12,
      "y": 9,
      "z": 0,
      "name": "Plant_Moss_Block_Green",
      "support": 15
    },
    {
      "x": -12,
      "y": 10,
      "z": 0,
      "name": "Plant_Moss_Block_Green",
      "support": 15
    },
    {
      "x": -12,
      "y": 11,
      "z": 0,
      "name": "Plant_Moss_Block_Green",
      "support": 15
    },
    {
      "x": -12,
      "y": 12,
      "z": 0,
      "name": "Plant_Moss_Block_Green",
      "support": 15
    },
    {
      "x": -12,
      "y": 13,
      "z": 0,
      "name": "Plant_Moss_Block_Green",
      "support": 15
    },
    {
      "x": -12,
      "y": 14,
      "z": 0,
      "name": "Soil_Clay_Lime",
      "support": 15
    },
    {
      "x": -12,
      "y": 15,
      "z": 0,
      "name": "Rubble_Marble_Medium",
      "support": 15
    },
    {
      "x": -12,
      "y": 8,
      "z": 1,
      "name": "Plant_Moss_Block_Green",
      "support": 15
    },
    {
      "x": -12,
      "y": 9,
      "z": 1,
      "name": "Soil_Clay_Lime",
      "support": 15
    },
    {
      "x": -12,
      "y": 10,
      "z": 1,
      "name": "Soil_Clay_Lime",
      "support": 15
    },
    {
      "x": -12,
      "y": 11,
      "z": 1,
      "name": "Plant_Moss_Block_Green",
      "support": 15
    },
    {
      "x": -12,
      "y": 12,
      "z": 1,
      "name": "Plant_Moss_Block_Green",
      "support": 15
    },
    {
      "x": -12,
      "y": 13,
      "z": 1,
      "name": "Plant_Moss_Block_Green",
      "support": 15
    },
    {
      "x": -12,
      "y": 14,
      "z": 1,
      "name": "Soil_Clay_Lime",
      "support": 15
    },
    {
      "x": -12,
      "y": 15,
      "z": 1,
      "name": "Rubble_Stone",
      "support": 15
    },
    {
      "x": -12,
      "y": 8,
      "z": 2,
      "name": "Soil_Clay_Lime",
      "support": 15
    },
    {
      "x": -12,
      "y": 9,
      "z": 2,
      "name": "Plant_Moss_Block_Green",
      "support": 15
    },
    {
      "x": -12,
      "y": 10,
      "z": 2,
      "name": "Plant_Moss_Block_Green",
      "support": 15
    },
    {
      "x": -12,
      "y": 11,
      "z": 2,
      "name": "Plant_Moss_Block_Green",
      "support": 15
    },
    {
      "x": -12,
      "y": 12,
      "z": 2,
      "name": "Plant_Moss_Block_Green",
      "support": 15
    },
    {
      "x": -12,
      "y": 13,
      "z": 2,
      "name": "Plant_Moss_Block_Green",
      "support": 15
    },
    {
      "x": -12,
      "y": 14,
      "z": 2,
      "name": "Soil_Clay_Lime",
      "support": 15
    },
    {
      "x": -12,
      "y": 8,
      "z": 3,
      "name": "Plant_Moss_Block_Green",
      "support": 15
    },
    {
      "x": -12,
      "y": 9,
      "z": 3,
      "name": "Plant_Moss_Block_Green",
      "support": 15
    },
    {
      "x": -12,
      "y": 10,
      "z": 3,
      "name": "Plant_Moss_Block_Green",
      "support": 15
    },
    {
      "x": -12,
      "y": 11,
      "z": 3,
      "name": "Plant_Moss_Block_Green",
      "support": 15
    },
    {
      "x": -12,
      "y": 12,
      "z": 3,
      "name": "Plant_Moss_Block_Green",
      "support": 15
    },
    {
      "x": -12,
      "y": 13,
      "z": 3,
      "name": "Plant_Moss_Block_Green",
      "support": 15
    },
    {
      "x": -12,
      "y": 14,
      "z": 3,
      "name": "Soil_Clay_Lime",
      "support": 15
    },
    {
      "x": -12,
      "y": 8,
      "z": 4,
      "name": "Soil_Clay_Lime",
      "support": 15
    },
    {
      "x": -12,
      "y": 9,
      "z": 4,
      "name": "Plant_Moss_Block_Green",
      "support": 15
    },
    {
      "x": -12,
      "y": 10,
      "z": 4,
      "name": "Plant_Moss_Block_Green",
      "support": 15
    },
    {
      "x": -12,
      "y": 11,
      "z": 4,
      "name": "Plant_Moss_Block_Green",
      "support": 15
    },
    {
      "x": -12,
      "y": 12,
      "z": 4,
      "name": "Plant_Moss_Block_Green",
      "support": 15
    },
    {
      "x": -12,
      "y": 13,
      "z": 4,
      "name": "Plant_Moss_Block_Green",
      "support": 15
    },
    {
      "x": -12,
      "y": 14,
      "z": 4,
      "name": "Rock_Stone_Mossy",
      "support": 15
    },
    {
      "x": -12,
      "y": 15,
      "z": 4,
      "name": "Rock_Stone",
      "support": 15
    },
    {
      "x": -12,
      "y": 9,
      "z": 5,
      "name": "Soil_Clay_Lime",
      "support": 15
    },
    {
      "x": -12,
      "y": 10,
      "z": 5,
      "name": "Plant_Moss_Block_Green",
      "support": 15
    },
    {
      "x": -12,
      "y": 11,
      "z": 5,
      "name": "Plant_Moss_Block_Green",
      "support": 15
    },
    {
      "x": -12,
      "y": 12,
      "z": 5,
      "name": "Plant_Moss_Block_Green",
      "support": 15
    },
    {
      "x": -12,
      "y": 13,
      "z": 5,
      "name": "Plant_Moss_Block_Green",
      "support": 15
    },
    {
      "x": -12,
      "y": 14,
      "z": 5,
      "name": "Soil_Clay_Lime",
      "support": 15
    },
    {
      "x": -12,
      "y": 15,
      "z": 5,
      "name": "Rock_Stone",
      "support": 15
    },
    {
      "x": -12,
      "y": 9,
      "z": 6,
      "name": "Plant_Moss_Block_Green",
      "support": 15
    },
    {
      "x": -12,
      "y": 10,
      "z": 6,
      "name": "Soil_Clay_Lime",
      "support": 15
    },
    {
      "x": -12,
      "y": 11,
      "z": 6,
      "name": "Plant_Moss_Block_Green",
      "support": 15
    },
    {
      "x": -12,
      "y": 12,
      "z": 6,
      "name": "Plant_Moss_Block_Green",
      "support": 15
    },
    {
      "x": -12,
      "y": 13,
      "z": 6,
      "name": "Plant_Moss_Block_Green",
      "support": 15
    },
    {
      "x": -12,
      "y": 14,
      "z": 6,
      "name": "Soil_Clay_Lime",
      "support": 15
    },
    {
      "x": -12,
      "y": 15,
      "z": 6,
      "name": "Rock_Stone",
      "support": 15
    },
    {
      "x": -12,
      "y": 16,
      "z": 6,
      "name": "Rubble_Stone",
      "support": 15
    },
    {
      "x": -12,
      "y": 10,
      "z": 7,
      "name": "Plant_Moss_Block_Green",
      "support": 15
    },
    {
      "x": -12,
      "y": 11,
      "z": 7,
      "name": "Plant_Moss_Block_Green",
      "support": 15
    },
    {
      "x": -12,
      "y": 12,
      "z": 7,
      "name": "Plant_Moss_Block_Green",
      "support": 15
    },
    {
      "x": -12,
      "y": 13,
      "z": 7,
      "name": "Soil_Clay_Lime",
      "support": 15
    },
    {
      "x": -12,
      "y": 14,
      "z": 7,
      "name": "Soil_Clay_Lime",
      "support": 15
    },
    {
      "x": -12,
      "y": 11,
      "z": 8,
      "name": "Plant_Moss_Block_Green",
      "support": 15
    },
    {
      "x": -12,
      "y": 12,
      "z": 8,
      "name": "Plant_Moss_Block_Green",
      "support": 15
    },
    {
      "x": -12,
      "y": 13,
      "z": 8,
      "name": "Soil_Clay_Lime",
      "support": 15
    },
    {
      "x": -12,
      "y": 14,
      "z": 8,
      "name": "Soil_Clay_Lime",
      "support": 15
    },
    {
      "x": -12,
      "y": 11,
      "z": 9,
      "name": "Plant_Moss_Block_Green",
      "support": 15
    },
    {
      "x": -12,
      "y": 12,
      "z": 9,
      "name": "Plant_Moss_Block_Green",
      "support": 15
    },
    {
      "x": -12,
      "y": 13,
      "z": 9,
      "name": "Plant_Moss_Block_Green",
      "support": 15
    },
    {
      "x": -12,
      "y": 12,
      "z": 10,
      "name": "Plant_Moss_Block_Green",
      "support": 15
    },
    {
      "x": -11,
      "y": 12,
      "z": -14,
      "name": "Plant_Moss_Block_Green",
      "support": 15
    },
    {
      "x": -11,
      "y": 12,
      "z": -13,
      "name": "Plant_Moss_Block_Green",
      "support": 15
    },
    {
      "x": -11,
      "y": 13,
      "z": -13,
      "name": "Plant_Moss_Block_Green",
      "support": 15
    },
    {
      "x": -11,
      "y": 13,
      "z": -12,
      "name": "Plant_Moss_Block_Green",
      "support": 15
    },
    {
      "x": -11,
      "y": 11,
      "z": -11,
      "name": "Plant_Moss_Block_Green",
      "support": 15
    },
    {
      "x": -11,
      "y": 12,
      "z": -11,
      "name": "Plant_Moss_Block_Green",
      "support": 15
    },
    {
      "x": -11,
      "y": 13,
      "z": -11,
      "name": "Plant_Moss_Block_Green",
      "support": 15
    },
    {
      "x": -11,
      "y": 14,
      "z": -11,
      "name": "Rock_Stone_Mossy",
      "support": 15
    },
    {
      "x": -11,
      "y": 10,
      "z": -10,
      "name": "Plant_Moss_Block_Green",
      "support": 15
    },
    {
      "x": -11,
      "y": 11,
      "z": -10,
      "name": "Plant_Moss_Block_Green",
      "support": 15
    },
    {
      "x": -11,
      "y": 12,
      "z": -10,
      "name": "Plant_Moss_Block_Green",
      "support": 15
    },
    {
      "x": -11,
      "y": 13,
      "z": -10,
      "name": "Plant_Moss_Block_Green",
      "support": 15
    },
    {
      "x": -11,
      "y": 14,
      "z": -10,
      "name": "Soil_Clay_Lime",
      "support": 15
    },
    {
      "x": -11,
      "y": 9,
      "z": -9,
      "name": "Plant_Moss_Block_Green",
      "support": 15
    },
    {
      "x": -11,
      "y": 10,
      "z": -9,
      "name": "Soil_Clay_Lime",
      "support": 15
    },
    {
      "x": -11,
      "y": 11,
      "z": -9,
      "name": "Plant_Moss_Block_Green",
      "support": 15
    },
    {
      "x": -11,
      "y": 12,
      "z": -9,
      "name": "Soil_Clay_Lime",
      "support": 15
    },
    {
      "x": -11,
      "y": 13,
      "z": -9,
      "name": "Plant_Moss_Block_Green",
      "support": 15
    },
    {
      "x": -11,
      "y": 14,
      "z": -9,
      "name": "Soil_Clay_Lime",
      "support": 15
    },
    {
      "x": -11,
      "y": 9,
      "z": -8,
      "name": "Soil_Clay_Lime",
      "support": 15
    },
    {
      "x": -11,
      "y": 10,
      "z": -8,
      "name": "Soil_Clay_Lime",
      "support": 15
    },
    {
      "x": -11,
      "y": 11,
      "z": -8,
      "name": "Plant_Moss_Block_Green",
      "support": 15
    },
    {
      "x": -11,
      "y": 12,
      "z": -8,
      "name": "Plant_Moss_Block_Green",
      "support": 15
    },
    {
      "x": -11,
      "y": 13,
      "z": -8,
      "name": "Plant_Moss_Block_Green",
      "support": 15
    },
    {
      "x": -11,
      "y": 14,
      "z": -8,
      "name": "Soil_Clay_Lime",
      "support": 15
    },
    {
      "x": -11,
      "y": 8,
      "z": -7,
      "name": "Soil_Clay_Lime",
      "support": 15
    },
    {
      "x": -11,
      "y": 9,
      "z": -7,
      "name": "Soil_Clay_Lime",
      "support": 15
    },
    {
      "x": -11,
      "y": 10,
      "z": -7,
      "name": "Plant_Moss_Block_Green",
      "support": 15
    },
    {
      "x": -11,
      "y": 11,
      "z": -7,
      "name": "Plant_Moss_Block_Green",
      "support": 15
    },
    {
      "x": -11,
      "y": 12,
      "z": -7,
      "name": "Plant_Moss_Block_Green",
      "support": 15
    },
    {
      "x": -11,
      "y": 13,
      "z": -7,
      "name": "Plant_Moss_Block_Green",
      "support": 15
    },
    {
      "x": -11,
      "y": 14,
      "z": -7,
      "name": "Soil_Clay_Lime",
      "support": 15
    },
    {
      "x": -11,
      "y": 15,
      "z": -7,
      "name": "Rock_Stone",
      "support": 15
    },
    {
      "x": -11,
      "y": 16,
      "z": -7,
      "name": "Plant_Moss_Block_Green",
      "support": 15
    },
    {
      "x": -11,
      "y": 7,
      "z": -6,
      "name": "Rock_Stone_Cobble",
      "support": 15
    },
    {
      "x": -11,
      "y": 8,
      "z": -6,
      "name": "Soil_Clay_Lime",
      "support": 15
    },
    {
      "x": -11,
      "y": 9,
      "z": -6,
      "name": "Soil_Clay_Lime",
      "support": 15
    },
    {
      "x": -11,
      "y": 10,
      "z": -6,
      "name": "Plant_Moss_Block_Green",
      "support": 15
    },
    {
      "x": -11,
      "y": 11,
      "z": -6,
      "name": "Plant_Moss_Block_Green",
      "support": 15
    },
    {
      "x": -11,
      "y": 12,
      "z": -6,
      "name": "Plant_Moss_Block_Green",
      "support": 15
    },
    {
      "x": -11,
      "y": 13,
      "z": -6,
      "name": "Plant_Moss_Block_Green",
      "support": 15
    },
    {
      "x": -11,
      "y": 14,
      "z": -6,
      "name": "Rock_Stone_Mossy",
      "support": 15
    },
    {
      "x": -11,
      "y": 15,
      "z": -6,
      "name": "Rock_Stone",
      "support": 15
    },
    {
      "x": -11,
      "y": 16,
      "z": -6,
      "name": "Plant_Moss_Block_Green",
      "support": 15
    },
    {
      "x": -11,
      "y": 17,
      "z": -6,
      "name": "Plant_Moss_Rug_Green",
      "support": 15
    },
    {
      "x": -11,
      "y": 7,
      "z": -5,
      "name": "Soil_Clay_Lime",
      "support": 15
    },
    {
      "x": -11,
      "y": 8,
      "z": -5,
      "name": "Soil_Clay_Lime",
      "support": 15
    },
    {
      "x": -11,
      "y": 9,
      "z": -5,
      "name": "Soil_Clay_Lime",
      "support": 15
    },
    {
      "x": -11,
      "y": 10,
      "z": -5,
      "name": "Soil_Clay_Lime",
      "support": 15
    },
    {
      "x": -11,
      "y": 11,
      "z": -5,
      "name": "Plant_Moss_Block_Green",
      "support": 15
    },
    {
      "x": -11,
      "y": 12,
      "z": -5,
      "name": "Plant_Moss_Block_Green",
      "support": 15
    },
    {
      "x": -11,
      "y": 13,
      "z": -5,
      "name": "Plant_Moss_Block_Green",
      "support": 15
    },
    {
      "x": -11,
      "y": 14,
      "z": -5,
      "name": "Soil_Clay_Lime",
      "support": 15
    },
    {
      "x": -11,
      "y": 15,
      "z": -5,
      "name": "Rock_Stone",
      "support": 15
    },
    {
      "x": -11,
      "y": 16,
      "z": -5,
      "name": "Plant_Moss_Block_Green",
      "support": 15
    },
    {
      "x": -11,
      "y": 17,
      "z": -5,
      "name": "Plant_Moss_Rug_Green",
      "support": 15
    },
    {
      "x": -11,
      "y": 7,
      "z": -4,
      "name": "Soil_Clay_Lime",
      "support": 15
    },
    {
      "x": -11,
      "y": 8,
      "z": -4,
      "name": "Soil_Clay_Lime",
      "support": 15
    },
    {
      "x": -11,
      "y": 9,
      "z": -4,
      "name": "Soil_Clay_Lime",
      "support": 15
    },
    {
      "x": -11,
      "y": 10,
      "z": -4,
      "name": "Plant_Moss_Block_Green",
      "support": 15
    },
    {
      "x": -11,
      "y": 11,
      "z": -4,
      "name": "Plant_Moss_Block_Green",
      "support": 15
    },
    {
      "x": -11,
      "y": 12,
      "z": -4,
      "name": "Plant_Moss_Block_Green",
      "support": 15
    },
    {
      "x": -11,
      "y": 13,
      "z": -4,
      "name": "Plant_Moss_Block_Green",
      "support": 15
    },
    {
      "x": -11,
      "y": 14,
      "z": -4,
      "name": "Soil_Clay_Lime",
      "support": 15
    },
    {
      "x": -11,
      "y": 15,
      "z": -4,
      "name": "Plant_Moss_Block_Green",
      "support": 15
    },
    {
      "x": -11,
      "y": 16,
      "z": -4,
      "name": "Plant_Moss_Rug_Green",
      "support": 15
    },
    {
      "x": -11,
      "y": 7,
      "z": -3,
      "name": "Rock_Stone_Cobble",
      "support": 15
    },
    {
      "x": -11,
      "y": 8,
      "z": -3,
      "name": "Soil_Clay_Lime",
      "support": 15
    },
    {
      "x": -11,
      "y": 9,
      "z": -3,
      "name": "Plant_Moss_Block_Green",
      "support": 15
    },
    {
      "x": -11,
      "y": 10,
      "z": -3,
      "name": "Plant_Moss_Block_Green",
      "support": 15
    },
    {
      "x": -11,
      "y": 11,
      "z": -3,
      "name": "Plant_Moss_Block_Green",
      "support": 15
    },
    {
      "x": -11,
      "y": 12,
      "z": -3,
      "name": "Plant_Moss_Block_Green",
      "support": 15
    },
    {
      "x": -11,
      "y": 13,
      "z": -3,
      "name": "Plant_Moss_Block_Green",
      "support": 15
    },
    {
      "x": -11,
      "y": 14,
      "z": -3,
      "name": "Rock_Stone_Mossy",
      "support": 15
    },
    {
      "x": -11,
      "y": 15,
      "z": -3,
      "name": "Rock_Stone",
      "support": 15
    },
    {
      "x": -11,
      "y": 7,
      "z": -2,
      "name": "Soil_Clay_Lime",
      "support": 15
    },
    {
      "x": -11,
      "y": 8,
      "z": -2,
      "name": "Soil_Clay_Lime",
      "support": 15
    },
    {
      "x": -11,
      "y": 9,
      "z": -2,
      "name": "Plant_Moss_Block_Green",
      "support": 15
    },
    {
      "x": -11,
      "y": 10,
      "z": -2,
      "name": "Plant_Moss_Block_Green",
      "support": 15
    },
    {
      "x": -11,
      "y": 11,
      "z": -2,
      "name": "Plant_Moss_Block_Green",
      "support": 15
    },
    {
      "x": -11,
      "y": 12,
      "z": -2,
      "name": "Plant_Moss_Block_Green",
      "support": 15
    },
    {
      "x": -11,
      "y": 13,
      "z": -2,
      "name": "Plant_Moss_Block_Green",
      "support": 15
    },
    {
      "x": -11,
      "y": 14,
      "z": -2,
      "name": "Soil_Clay_Lime",
      "support": 15
    },
    {
      "x": -11,
      "y": 15,
      "z": -2,
      "name": "Plant_Moss_Block_Green",
      "support": 15
    },
    {
      "x": -11,
      "y": 16,
      "z": -2,
      "name": "Plant_Moss_Rug_Green",
      "support": 15
    },
    {
      "x": -11,
      "y": 7,
      "z": -1,
      "name": "Soil_Clay_Lime",
      "support": 15
    },
    {
      "x": -11,
      "y": 8,
      "z": -1,
      "name": "Soil_Clay_Lime",
      "support": 15
    },
    {
      "x": -11,
      "y": 9,
      "z": -1,
      "name": "Soil_Clay_Lime",
      "support": 15
    },
    {
      "x": -11,
      "y": 10,
      "z": -1,
      "name": "Plant_Moss_Block_Green",
      "support": 15
    },
    {
      "x": -11,
      "y": 11,
      "z": -1,
      "name": "Plant_Moss_Block_Green",
      "support": 15
    },
    {
      "x": -11,
      "y": 12,
      "z": -1,
      "name": "Plant_Moss_Block_Green",
      "support": 15
    },
    {
      "x": -11,
      "y": 13,
      "z": -1,
      "name": "Plant_Moss_Block_Green",
      "support": 15
    },
    {
      "x": -11,
      "y": 14,
      "z": -1,
      "name": "Rock_Stone_Mossy",
      "support": 15
    },
    {
      "x": -11,
      "y": 7,
      "z": 0,
      "name": "Soil_Clay_Lime",
      "support": 15
    },
    {
      "x": -11,
      "y": 8,
      "z": 0,
      "name": "Soil_Clay_Lime",
      "support": 15
    },
    {
      "x": -11,
      "y": 9,
      "z": 0,
      "name": "Plant_Moss_Block_Green",
      "support": 15
    },
    {
      "x": -11,
      "y": 10,
      "z": 0,
      "name": "Plant_Moss_Block_Green",
      "support": 15
    },
    {
      "x": -11,
      "y": 11,
      "z": 0,
      "name": "Plant_Moss_Block_Green",
      "support": 15
    },
    {
      "x": -11,
      "y": 12,
      "z": 0,
      "name": "Plant_Moss_Block_Green",
      "support": 15
    },
    {
      "x": -11,
      "y": 13,
      "z": 0,
      "name": "Plant_Moss_Block_Green",
      "support": 15
    },
    {
      "x": -11,
      "y": 14,
      "z": 0,
      "name": "Rock_Stone_Mossy",
      "support": 15
    },
    {
      "x": -11,
      "y": 15,
      "z": 0,
      "name": "Rock_Marble_Brick",
      "support": 15
    },
    {
      "x": -11,
      "y": 7,
      "z": 1,
      "name": "Soil_Clay_Lime",
      "support": 15
    },
    {
      "x": -11,
      "y": 8,
      "z": 1,
      "name": "Soil_Clay_Lime",
      "support": 15
    },
    {
      "x": -11,
      "y": 9,
      "z": 1,
      "name": "Soil_Clay_Lime",
      "support": 15
    },
    {
      "x": -11,
      "y": 10,
      "z": 1,
      "name": "Plant_Moss_Block_Green",
      "support": 15
    },
    {
      "x": -11,
      "y": 11,
      "z": 1,
      "name": "Plant_Moss_Block_Green",
      "support": 15
    },
    {
      "x": -11,
      "y": 12,
      "z": 1,
      "name": "Plant_Moss_Block_Green",
      "support": 15
    },
    {
      "x": -11,
      "y": 13,
      "z": 1,
      "name": "Plant_Moss_Block_Green",
      "support": 15
    },
    {
      "x": -11,
      "y": 14,
      "z": 1,
      "name": "Soil_Clay_Lime",
      "support": 15
    },
    {
      "x": -11,
      "y": 15,
      "z": 1,
      "name": "Rock_Marble_Brick",
      "support": 15
    },
    {
      "x": -11,
      "y": 7,
      "z": 2,
      "name": "Soil_Clay_Lime",
      "support": 15
    },
    {
      "x": -11,
      "y": 8,
      "z": 2,
      "name": "Plant_Moss_Block_Green",
      "support": 15
    },
    {
      "x": -11,
      "y": 9,
      "z": 2,
      "name": "Plant_Moss_Block_Green",
      "support": 15
    },
    {
      "x": -11,
      "y": 10,
      "z": 2,
      "name": "Plant_Moss_Block_Green",
      "support": 15
    },
    {
      "x": -11,
      "y": 11,
      "z": 2,
      "name": "Plant_Moss_Block_Green",
      "support": 15
    },
    {
      "x": -11,
      "y": 12,
      "z": 2,
      "name": "Plant_Moss_Block_Green",
      "support": 15
    },
    {
      "x": -11,
      "y": 13,
      "z": 2,
      "name": "Plant_Moss_Block_Green",
      "support": 15
    },
    {
      "x": -11,
      "y": 14,
      "z": 2,
      "name": "Rock_Stone_Mossy",
      "support": 15
    },
    {
      "x": -11,
      "y": 7,
      "z": 3,
      "name": "Soil_Clay_Lime",
      "support": 15
    },
    {
      "x": -11,
      "y": 8,
      "z": 3,
      "name": "Soil_Clay_Lime",
      "support": 15
    },
    {
      "x": -11,
      "y": 9,
      "z": 3,
      "name": "Soil_Clay_Lime",
      "support": 15
    },
    {
      "x": -11,
      "y": 10,
      "z": 3,
      "name": "Plant_Moss_Block_Green",
      "support": 15
    },
    {
      "x": -11,
      "y": 11,
      "z": 3,
      "name": "Plant_Moss_Block_Green",
      "support": 15
    },
    {
      "x": -11,
      "y": 12,
      "z": 3,
      "name": "Plant_Moss_Block_Green",
      "support": 15
    },
    {
      "x": -11,
      "y": 13,
      "z": 3,
      "name": "Plant_Moss_Block_Green",
      "support": 15
    },
    {
      "x": -11,
      "y": 14,
      "z": 3,
      "name": "Soil_Clay_Lime",
      "support": 15
    },
    {
      "x": -11,
      "y": 7,
      "z": 4,
      "name": "Soil_Clay_Lime",
      "support": 15
    },
    {
      "x": -11,
      "y": 8,
      "z": 4,
      "name": "Plant_Moss_Block_Green",
      "support": 15
    },
    {
      "x": -11,
      "y": 9,
      "z": 4,
      "name": "Soil_Clay_Lime",
      "support": 15
    },
    {
      "x": -11,
      "y": 10,
      "z": 4,
      "name": "Plant_Moss_Block_Green",
      "support": 15
    },
    {
      "x": -11,
      "y": 11,
      "z": 4,
      "name": "Plant_Moss_Block_Green",
      "support": 15
    },
    {
      "x": -11,
      "y": 12,
      "z": 4,
      "name": "Plant_Moss_Block_Green",
      "support": 15
    },
    {
      "x": -11,
      "y": 13,
      "z": 4,
      "name": "Plant_Moss_Block_Green",
      "support": 15
    },
    {
      "x": -11,
      "y": 14,
      "z": 4,
      "name": "Soil_Clay_Lime",
      "support": 15
    },
    {
      "x": -11,
      "y": 15,
      "z": 4,
      "name": "Plant_Moss_Block_Green",
      "support": 15
    },
    {
      "x": -11,
      "y": 16,
      "z": 4,
      "name": "Plant_Moss_Rug_Green",
      "support": 15
    },
    {
      "x": -11,
      "y": 8,
      "z": 5,
      "name": "Soil_Clay_Lime",
      "support": 15
    },
    {
      "x": -11,
      "y": 9,
      "z": 5,
      "name": "Soil_Clay_Lime",
      "support": 15
    },
    {
      "x": -11,
      "y": 10,
      "z": 5,
      "name": "Plant_Moss_Block_Green",
      "support": 15
    },
    {
      "x": -11,
      "y": 11,
      "z": 5,
      "name": "Plant_Moss_Block_Green",
      "support": 15
    },
    {
      "x": -11,
      "y": 12,
      "z": 5,
      "name": "Plant_Moss_Block_Green",
      "support": 15
    },
    {
      "x": -11,
      "y": 13,
      "z": 5,
      "name": "Plant_Moss_Block_Green",
      "support": 15
    },
    {
      "x": -11,
      "y": 14,
      "z": 5,
      "name": "Soil_Clay_Lime",
      "support": 15
    },
    {
      "x": -11,
      "y": 15,
      "z": 5,
      "name": "Rock_Stone",
      "support": 15
    },
    {
      "x": -11,
      "y": 8,
      "z": 6,
      "name": "Soil_Clay_Lime",
      "support": 15
    },
    {
      "x": -11,
      "y": 9,
      "z": 6,
      "name": "Plant_Moss_Block_Green",
      "support": 15
    },
    {
      "x": -11,
      "y": 10,
      "z": 6,
      "name": "Plant_Moss_Block_Green",
      "support": 15
    },
    {
      "x": -11,
      "y": 11,
      "z": 6,
      "name": "Plant_Moss_Block_Green",
      "support": 15
    },
    {
      "x": -11,
      "y": 12,
      "z": 6,
      "name": "Plant_Moss_Block_Green",
      "support": 15
    },
    {
      "x": -11,
      "y": 13,
      "z": 6,
      "name": "Plant_Moss_Block_Green",
      "support": 15
    },
    {
      "x": -11,
      "y": 14,
      "z": 6,
      "name": "Rock_Stone",
      "support": 15
    },
    {
      "x": -11,
      "y": 15,
      "z": 6,
      "name": "Plant_Moss_Block_Green",
      "support": 15
    },
    {
      "x": -11,
      "y": 16,
      "z": 6,
      "name": "Plant_Moss_Block_Green",
      "support": 15
    },
    {
      "x": -11,
      "y": 17,
      "z": 6,
      "name": "Plant_Moss_Rug_Green",
      "support": 15
    },
    {
      "x": -11,
      "y": 8,
      "z": 7,
      "name": "Plant_Vine_Jungle",
      "support": 15,
      "rotation": 3
    },
    {
      "x": -11,
      "y": 9,
      "z": 7,
      "name": "Plant_Moss_Block_Green",
      "support": 15
    },
    {
      "x": -11,
      "y": 10,
      "z": 7,
      "name": "Plant_Moss_Block_Green",
      "support": 15
    },
    {
      "x": -11,
      "y": 11,
      "z": 7,
      "name": "Plant_Moss_Block_Green",
      "support": 15
    },
    {
      "x": -11,
      "y": 12,
      "z": 7,
      "name": "Plant_Moss_Block_Green",
      "support": 15
    },
    {
      "x": -11,
      "y": 13,
      "z": 7,
      "name": "Plant_Moss_Block_Green",
      "support": 15
    },
    {
      "x": -11,
      "y": 14,
      "z": 7,
      "name": "Soil_Clay_Lime",
      "support": 15
    },
    {
      "x": -11,
      "y": 15,
      "z": 7,
      "name": "Rock_Stone",
      "support": 15
    },
    {
      "x": -11,
      "y": 16,
      "z": 7,
      "name": "Rock_Stone",
      "support": 15
    },
    {
      "x": -11,
      "y": 17,
      "z": 7,
      "name": "Rubble_Stone",
      "support": 15
    },
    {
      "x": -11,
      "y": 9,
      "z": 8,
      "name": "Plant_Moss_Block_Green",
      "support": 15
    },
    {
      "x": -11,
      "y": 10,
      "z": 8,
      "name": "Plant_Moss_Block_Green",
      "support": 15
    },
    {
      "x": -11,
      "y": 11,
      "z": 8,
      "name": "Plant_Moss_Block_Green",
      "support": 15
    },
    {
      "x": -11,
      "y": 12,
      "z": 8,
      "name": "Plant_Moss_Block_Green",
      "support": 15
    },
    {
      "x": -11,
      "y": 13,
      "z": 8,
      "name": "Soil_Clay_Lime",
      "support": 15
    },
    {
      "x": -11,
      "y": 14,
      "z": 8,
      "name": "Rock_Stone_Mossy",
      "support": 15
    },
    {
      "x": -11,
      "y": 15,
      "z": 8,
      "name": "Plant_Moss_Block_Green",
      "support": 15
    },
    {
      "x": -11,
      "y": 7,
      "z": 9,
      "name": "Plant_Vine_Jungle",
      "support": 15,
      "rotation": 3
    },
    {
      "x": -11,
      "y": 8,
      "z": 9,
      "name": "Plant_Vine_Jungle",
      "support": 15,
      "rotation": 3
    },
    {
      "x": -11,
      "y": 9,
      "z": 9,
      "name": "Plant_Vine_Jungle",
      "support": 15,
      "rotation": 3
    },
    {
      "x": -11,
      "y": 10,
      "z": 9,
      "name": "Plant_Moss_Block_Green",
      "support": 15
    },
    {
      "x": -11,
      "y": 11,
      "z": 9,
      "name": "Plant_Moss_Block_Green",
      "support": 15
    },
    {
      "x": -11,
      "y": 12,
      "z": 9,
      "name": "Plant_Moss_Block_Green",
      "support": 15
    },
    {
      "x": -11,
      "y": 13,
      "z": 9,
      "name": "Rock_Stone_Mossy",
      "support": 15
    },
    {
      "x": -11,
      "y": 14,
      "z": 9,
      "name": "Rock_Stone_Mossy",
      "support": 15
    },
    {
      "x": -11,
      "y": 11,
      "z": 10,
      "name": "Plant_Moss_Block_Green",
      "support": 15
    },
    {
      "x": -11,
      "y": 12,
      "z": 10,
      "name": "Plant_Moss_Block_Green",
      "support": 15
    },
    {
      "x": -11,
      "y": 13,
      "z": 10,
      "name": "Plant_Moss_Block_Green",
      "support": 15
    },
    {
      "x": -11,
      "y": 14,
      "z": 10,
      "name": "Soil_Clay_Lime",
      "support": 15
    },
    {
      "x": -11,
      "y": 12,
      "z": 11,
      "name": "Plant_Moss_Block_Green",
      "support": 15
    },
    {
      "x": -11,
      "y": 13,
      "z": 11,
      "name": "Plant_Moss_Block_Green",
      "support": 15
    },
    {
      "x": -11,
      "y": 14,
      "z": 11,
      "name": "Plant_Moss_Rug_Green",
      "support": 15
    },
    {
      "x": -10,
      "y": 12,
      "z": -15,
      "name": "Plant_Moss_Block_Green",
      "support": 15
    },
    {
      "x": -10,
      "y": 13,
      "z": -15,
      "name": "Plant_Moss_Block_Green",
      "support": 15
    },
    {
      "x": -10,
      "y": 11,
      "z": -14,
      "name": "Plant_Moss_Block_Green",
      "support": 15
    },
    {
      "x": -10,
      "y": 12,
      "z": -14,
      "name": "Plant_Moss_Block_Green",
      "support": 15
    },
    {
      "x": -10,
      "y": 13,
      "z": -14,
      "name": "Plant_Moss_Block_Green",
      "support": 15
    },
    {
      "x": -10,
      "y": 14,
      "z": -14,
      "name": "Plant_Moss_Block_Green",
      "support": 15
    },
    {
      "x": -10,
      "y": 11,
      "z": -13,
      "name": "Plant_Moss_Block_Green",
      "support": 15
    },
    {
      "x": -10,
      "y": 12,
      "z": -13,
      "name": "Plant_Moss_Block_Green",
      "support": 15
    },
    {
      "x": -10,
      "y": 14,
      "z": -13,
      "name": "Plant_Moss_Block_Green",
      "support": 15
    },
    {
      "x": -10,
      "y": 11,
      "z": -12,
      "name": "Plant_Moss_Block_Green",
      "support": 15
    },
    {
      "x": -10,
      "y": 12,
      "z": -12,
      "name": "Plant_Moss_Block_Green",
      "support": 15
    },
    {
      "x": -10,
      "y": 13,
      "z": -12,
      "name": "Plant_Moss_Block_Green",
      "support": 15
    },
    {
      "x": -10,
      "y": 14,
      "z": -12,
      "name": "Plant_Moss_Block_Green",
      "support": 15
    },
    {
      "x": -10,
      "y": 10,
      "z": -11,
      "name": "Soil_Clay_Lime",
      "support": 15
    },
    {
      "x": -10,
      "y": 11,
      "z": -11,
      "name": "Plant_Moss_Block_Green",
      "support": 15
    },
    {
      "x": -10,
      "y": 12,
      "z": -11,
      "name": "Plant_Moss_Block_Green",
      "support": 15
    },
    {
      "x": -10,
      "y": 13,
      "z": -11,
      "name": "Soil_Clay_Lime",
      "support": 15
    },
    {
      "x": -10,
      "y": 14,
      "z": -11,
      "name": "Soil_Clay_Lime",
      "support": 15
    },
    {
      "x": -10,
      "y": 9,
      "z": -10,
      "name": "Plant_Moss_Block_Green",
      "support": 15
    },
    {
      "x": -10,
      "y": 10,
      "z": -10,
      "name": "Plant_Moss_Block_Green",
      "support": 15
    },
    {
      "x": -10,
      "y": 11,
      "z": -10,
      "name": "Plant_Moss_Block_Green",
      "support": 15
    },
    {
      "x": -10,
      "y": 12,
      "z": -10,
      "name": "Plant_Moss_Block_Green",
      "support": 15
    },
    {
      "x": -10,
      "y": 13,
      "z": -10,
      "name": "Plant_Moss_Block_Green",
      "support": 15
    },
    {
      "x": -10,
      "y": 14,
      "z": -10,
      "name": "Soil_Clay_Lime",
      "support": 15
    },
    {
      "x": -10,
      "y": 15,
      "z": -10,
      "name": "Rock_Marble_Brick_Pillar_Base",
      "support": 15
    },
    {
      "x": -10,
      "y": 16,
      "z": -10,
      "name": "Rock_Marble_Brick_Pillar_Middle",
      "support": 15
    },
    {
      "x": -10,
      "y": 17,
      "z": -10,
      "name": "Rubble_Marble",
      "support": 15
    },
    {
      "x": -10,
      "y": 9,
      "z": -9,
      "name": "Plant_Moss_Block_Green",
      "support": 15
    },
    {
      "x": -10,
      "y": 10,
      "z": -9,
      "name": "Plant_Moss_Block_Green",
      "support": 15
    },
    {
      "x": -10,
      "y": 11,
      "z": -9,
      "name": "Plant_Moss_Block_Green",
      "support": 15
    },
    {
      "x": -10,
      "y": 12,
      "z": -9,
      "name": "Plant_Moss_Block_Green",
      "support": 15
    },
    {
      "x": -10,
      "y": 13,
      "z": -9,
      "name": "Plant_Moss_Block_Green",
      "support": 15
    },
    {
      "x": -10,
      "y": 14,
      "z": -9,
      "name": "Soil_Clay_Lime",
      "support": 15
    },
    {
      "x": -10,
      "y": 15,
      "z": -9,
      "name": "Rock_Marble_Brick_Pillar_Base",
      "support": 15
    },
    {
      "x": -10,
      "y": 16,
      "z": -9,
      "name": "Rock_Marble_Brick_Pillar_Middle",
      "support": 15
    },
    {
      "x": -10,
      "y": 17,
      "z": -9,
      "name": "Rock_Marble_Stalactite_Small",
      "support": 15
    },
    {
      "x": -10,
      "y": 8,
      "z": -8,
      "name": "Soil_Clay_Lime",
      "support": 15
    },
    {
      "x": -10,
      "y": 9,
      "z": -8,
      "name": "Soil_Clay_Lime",
      "support": 15
    },
    {
      "x": -10,
      "y": 10,
      "z": -8,
      "name": "Plant_Moss_Block_Green",
      "support": 15
    },
    {
      "x": -10,
      "y": 11,
      "z": -8,
      "name": "Plant_Moss_Block_Green",
      "support": 15
    },
    {
      "x": -10,
      "y": 12,
      "z": -8,
      "name": "Plant_Moss_Block_Green",
      "support": 15
    },
    {
      "x": -10,
      "y": 13,
      "z": -8,
      "name": "Plant_Moss_Block_Green",
      "support": 15
    },
    {
      "x": -10,
      "y": 14,
      "z": -8,
      "name": "Rock_Stone_Mossy",
      "support": 15
    },
    {
      "x": -10,
      "y": 7,
      "z": -7,
      "name": "Soil_Clay_Lime",
      "support": 15
    },
    {
      "x": -10,
      "y": 8,
      "z": -7,
      "name": "Soil_Clay_Lime",
      "support": 15
    },
    {
      "x": -10,
      "y": 9,
      "z": -7,
      "name": "Plant_Moss_Block_Green",
      "support": 15
    },
    {
      "x": -10,
      "y": 10,
      "z": -7,
      "name": "Plant_Moss_Block_Green",
      "support": 15
    },
    {
      "x": -10,
      "y": 11,
      "z": -7,
      "name": "Plant_Moss_Block_Green",
      "support": 15
    },
    {
      "x": -10,
      "y": 12,
      "z": -7,
      "name": "Plant_Moss_Block_Green",
      "support": 15
    },
    {
      "x": -10,
      "y": 13,
      "z": -7,
      "name": "Plant_Moss_Block_Green",
      "support": 15
    },
    {
      "x": -10,
      "y": 14,
      "z": -7,
      "name": "Soil_Clay_Lime",
      "support": 15
    },
    {
      "x": -10,
      "y": 15,
      "z": -7,
      "name": "Plant_Moss_Block_Green",
      "support": 15
    },
    {
      "x": -10,
      "y": 16,
      "z": -7,
      "name": "Plant_Moss_Rug_Green",
      "support": 15
    },
    {
      "x": -10,
      "y": 7,
      "z": -6,
      "name": "Rock_Stone_Cobble",
      "support": 15
    },
    {
      "x": -10,
      "y": 8,
      "z": -6,
      "name": "Soil_Clay_Lime",
      "support": 15
    },
    {
      "x": -10,
      "y": 9,
      "z": -6,
      "name": "Plant_Moss_Block_Green",
      "support": 15
    },
    {
      "x": -10,
      "y": 10,
      "z": -6,
      "name": "Plant_Moss_Block_Green",
      "support": 15
    },
    {
      "x": -10,
      "y": 11,
      "z": -6,
      "name": "Plant_Moss_Block_Green",
      "support": 15
    },
    {
      "x": -10,
      "y": 12,
      "z": -6,
      "name": "Plant_Moss_Block_Green",
      "support": 15
    },
    {
      "x": -10,
      "y": 13,
      "z": -6,
      "name": "Plant_Moss_Block_Green",
      "support": 15
    },
    {
      "x": -10,
      "y": 14,
      "z": -6,
      "name": "Rock_Stone_Mossy",
      "support": 15
    },
    {
      "x": -10,
      "y": 15,
      "z": -6,
      "name": "Plant_Moss_Block_Green",
      "support": 15
    },
    {
      "x": -10,
      "y": 16,
      "z": -6,
      "name": "Plant_Moss_Rug_Green",
      "support": 15
    },
    {
      "x": -10,
      "y": 7,
      "z": -5,
      "name": "Soil_Clay_Lime",
      "support": 15
    },
    {
      "x": -10,
      "y": 8,
      "z": -5,
      "name": "Soil_Clay_Lime",
      "support": 15
    },
    {
      "x": -10,
      "y": 9,
      "z": -5,
      "name": "Soil_Clay_Lime",
      "support": 15
    },
    {
      "x": -10,
      "y": 10,
      "z": -5,
      "name": "Plant_Moss_Block_Green",
      "support": 15
    },
    {
      "x": -10,
      "y": 11,
      "z": -5,
      "name": "Plant_Moss_Block_Green",
      "support": 15
    },
    {
      "x": -10,
      "y": 12,
      "z": -5,
      "name": "Plant_Moss_Block_Green",
      "support": 15
    },
    {
      "x": -10,
      "y": 13,
      "z": -5,
      "name": "Plant_Moss_Block_Green",
      "support": 15
    },
    {
      "x": -10,
      "y": 14,
      "z": -5,
      "name": "Soil_Clay_Lime",
      "support": 15
    },
    {
      "x": -10,
      "y": 7,
      "z": -4,
      "name": "Soil_Clay_Lime",
      "support": 15
    },
    {
      "x": -10,
      "y": 8,
      "z": -4,
      "name": "Soil_Clay_Lime",
      "support": 15
    },
    {
      "x": -10,
      "y": 9,
      "z": -4,
      "name": "Plant_Moss_Block_Green",
      "support": 15
    },
    {
      "x": -10,
      "y": 10,
      "z": -4,
      "name": "Soil_Clay_Lime",
      "support": 15
    },
    {
      "x": -10,
      "y": 11,
      "z": -4,
      "name": "Plant_Moss_Block_Green",
      "support": 15
    },
    {
      "x": -10,
      "y": 12,
      "z": -4,
      "name": "Plant_Moss_Block_Green",
      "support": 15
    },
    {
      "x": -10,
      "y": 13,
      "z": -4,
      "name": "Plant_Moss_Block_Green",
      "support": 15
    },
    {
      "x": -10,
      "y": 14,
      "z": -4,
      "name": "Soil_Clay_Lime",
      "support": 15
    },
    {
      "x": -10,
      "y": 15,
      "z": -4,
      "name": "Rock_Stone",
      "support": 15
    },
    {
      "x": -10,
      "y": 7,
      "z": -3,
      "name": "Soil_Clay_Lime",
      "support": 15
    },
    {
      "x": -10,
      "y": 8,
      "z": -3,
      "name": "Soil_Clay_Lime",
      "support": 15
    },
    {
      "x": -10,
      "y": 9,
      "z": -3,
      "name": "Soil_Clay_Lime",
      "support": 15
    },
    {
      "x": -10,
      "y": 10,
      "z": -3,
      "name": "Plant_Moss_Block_Green",
      "support": 15
    },
    {
      "x": -10,
      "y": 11,
      "z": -3,
      "name": "Plant_Moss_Block_Green",
      "support": 15
    },
    {
      "x": -10,
      "y": 12,
      "z": -3,
      "name": "Plant_Moss_Block_Green",
      "support": 15
    },
    {
      "x": -10,
      "y": 13,
      "z": -3,
      "name": "Plant_Moss_Block_Green",
      "support": 15
    },
    {
      "x": -10,
      "y": 14,
      "z": -3,
      "name": "Rock_Stone_Mossy",
      "support": 15
    },
    {
      "x": -10,
      "y": 7,
      "z": -2,
      "name": "Soil_Clay_Lime",
      "support": 15
    },
    {
      "x": -10,
      "y": 8,
      "z": -2,
      "name": "Soil_Clay_Lime",
      "support": 15
    },
    {
      "x": -10,
      "y": 9,
      "z": -2,
      "name": "Plant_Moss_Block_Green",
      "support": 15
    },
    {
      "x": -10,
      "y": 10,
      "z": -2,
      "name": "Plant_Moss_Block_Green",
      "support": 15
    },
    {
      "x": -10,
      "y": 11,
      "z": -2,
      "name": "Plant_Moss_Block_Green",
      "support": 15
    },
    {
      "x": -10,
      "y": 12,
      "z": -2,
      "name": "Plant_Moss_Block_Green",
      "support": 15
    },
    {
      "x": -10,
      "y": 13,
      "z": -2,
      "name": "Plant_Moss_Block_Green",
      "support": 15
    },
    {
      "x": -10,
      "y": 14,
      "z": -2,
      "name": "Soil_Clay_Lime",
      "support": 15
    },
    {
      "x": -10,
      "y": 6,
      "z": -1,
      "name": "Soil_Clay_Lime",
      "support": 15
    },
    {
      "x": -10,
      "y": 7,
      "z": -1,
      "name": "Soil_Clay_Lime",
      "support": 15
    },
    {
      "x": -10,
      "y": 8,
      "z": -1,
      "name": "Soil_Clay_Lime",
      "support": 15
    },
    {
      "x": -10,
      "y": 9,
      "z": -1,
      "name": "Plant_Moss_Block_Green",
      "support": 15
    },
    {
      "x": -10,
      "y": 10,
      "z": -1,
      "name": "Plant_Moss_Block_Green",
      "support": 15
    },
    {
      "x": -10,
      "y": 11,
      "z": -1,
      "name": "Plant_Moss_Block_Green",
      "support": 15
    },
    {
      "x": -10,
      "y": 12,
      "z": -1,
      "name": "Plant_Moss_Block_Green",
      "support": 15
    },
    {
      "x": -10,
      "y": 13,
      "z": -1,
      "name": "Plant_Moss_Block_Green",
      "support": 15
    },
    {
      "x": -10,
      "y": 14,
      "z": -1,
      "name": "Rock_Stone_Mossy",
      "support": 15
    },
    {
      "x": -10,
      "y": 6,
      "z": 0,
      "name": "Rock_Stone_Cobble",
      "support": 15
    },
    {
      "x": -10,
      "y": 7,
      "z": 0,
      "name": "Rock_Stone_Cobble",
      "support": 15
    },
    {
      "x": -10,
      "y": 8,
      "z": 0,
      "name": "Soil_Clay_Lime",
      "support": 15
    },
    {
      "x": -10,
      "y": 9,
      "z": 0,
      "name": "Soil_Clay_Lime",
      "support": 15
    },
    {
      "x": -10,
      "y": 10,
      "z": 0,
      "name": "Plant_Moss_Block_Green",
      "support": 15
    },
    {
      "x": -10,
      "y": 11,
      "z": 0,
      "name": "Plant_Moss_Block_Green",
      "support": 15
    },
    {
      "x": -10,
      "y": 12,
      "z": 0,
      "name": "Plant_Moss_Block_Green",
      "support": 15
    },
    {
      "x": -10,
      "y": 13,
      "z": 0,
      "name": "Plant_Moss_Block_Green",
      "support": 15
    },
    {
      "x": -10,
      "y": 14,
      "z": 0,
      "name": "Soil_Clay_Lime",
      "support": 15
    },
    {
      "x": -10,
      "y": 6,
      "z": 1,
      "name": "Rock_Stone_Cobble",
      "support": 15
    },
    {
      "x": -10,
      "y": 7,
      "z": 1,
      "name": "Rock_Stone_Cobble",
      "support": 15
    },
    {
      "x": -10,
      "y": 8,
      "z": 1,
      "name": "Soil_Clay_Lime",
      "support": 15
    },
    {
      "x": -10,
      "y": 9,
      "z": 1,
      "name": "Soil_Clay_Lime",
      "support": 15
    },
    {
      "x": -10,
      "y": 10,
      "z": 1,
      "name": "Soil_Clay_Lime",
      "support": 15
    },
    {
      "x": -10,
      "y": 11,
      "z": 1,
      "name": "Plant_Moss_Block_Green",
      "support": 15
    },
    {
      "x": -10,
      "y": 12,
      "z": 1,
      "name": "Plant_Moss_Block_Green",
      "support": 15
    },
    {
      "x": -10,
      "y": 13,
      "z": 1,
      "name": "Plant_Moss_Block_Green",
      "support": 15
    },
    {
      "x": -10,
      "y": 14,
      "z": 1,
      "name": "Soil_Clay_Lime",
      "support": 15
    },
    {
      "x": -10,
      "y": 6,
      "z": 2,
      "name": "Rock_Stone_Cobble",
      "support": 15
    },
    {
      "x": -10,
      "y": 7,
      "z": 2,
      "name": "Soil_Clay_Lime",
      "support": 15
    },
    {
      "x": -10,
      "y": 8,
      "z": 2,
      "name": "Soil_Clay_Lime",
      "support": 15
    },
    {
      "x": -10,
      "y": 9,
      "z": 2,
      "name": "Soil_Clay_Lime",
      "support": 15
    },
    {
      "x": -10,
      "y": 10,
      "z": 2,
      "name": "Plant_Moss_Block_Green",
      "support": 15
    },
    {
      "x": -10,
      "y": 11,
      "z": 2,
      "name": "Plant_Moss_Block_Green",
      "support": 15
    },
    {
      "x": -10,
      "y": 12,
      "z": 2,
      "name": "Plant_Moss_Block_Green",
      "support": 15
    },
    {
      "x": -10,
      "y": 13,
      "z": 2,
      "name": "Plant_Moss_Block_Green",
      "support": 15
    },
    {
      "x": -10,
      "y": 14,
      "z": 2,
      "name": "Rock_Stone_Mossy",
      "support": 15
    },
    {
      "x": -10,
      "y": 7,
      "z": 3,
      "name": "Rock_Stone_Cobble",
      "support": 15
    },
    {
      "x": -10,
      "y": 8,
      "z": 3,
      "name": "Soil_Clay_Lime",
      "support": 15
    },
    {
      "x": -10,
      "y": 9,
      "z": 3,
      "name": "Soil_Clay_Lime",
      "support": 15
    },
    {
      "x": -10,
      "y": 10,
      "z": 3,
      "name": "Soil_Clay_Lime",
      "support": 15
    },
    {
      "x": -10,
      "y": 11,
      "z": 3,
      "name": "Plant_Moss_Block_Green",
      "support": 15
    },
    {
      "x": -10,
      "y": 12,
      "z": 3,
      "name": "Plant_Moss_Block_Green",
      "support": 15
    },
    {
      "x": -10,
      "y": 13,
      "z": 3,
      "name": "Plant_Moss_Block_Green",
      "support": 15
    },
    {
      "x": -10,
      "y": 14,
      "z": 3,
      "name": "Soil_Clay_Lime",
      "support": 15
    },
    {
      "x": -10,
      "y": 7,
      "z": 4,
      "name": "Soil_Clay_Lime",
      "support": 15
    },
    {
      "x": -10,
      "y": 8,
      "z": 4,
      "name": "Soil_Clay_Lime",
      "support": 15
    },
    {
      "x": -10,
      "y": 9,
      "z": 4,
      "name": "Soil_Clay_Lime",
      "support": 15
    },
    {
      "x": -10,
      "y": 10,
      "z": 4,
      "name": "Plant_Moss_Block_Green",
      "support": 15
    },
    {
      "x": -10,
      "y": 11,
      "z": 4,
      "name": "Plant_Moss_Block_Green",
      "support": 15
    },
    {
      "x": -10,
      "y": 12,
      "z": 4,
      "name": "Plant_Moss_Block_Green",
      "support": 15
    },
    {
      "x": -10,
      "y": 13,
      "z": 4,
      "name": "Plant_Moss_Block_Green",
      "support": 15
    },
    {
      "x": -10,
      "y": 14,
      "z": 4,
      "name": "Soil_Clay_Lime",
      "support": 15
    },
    {
      "x": -10,
      "y": 7,
      "z": 5,
      "name": "Soil_Clay_Lime",
      "support": 15
    },
    {
      "x": -10,
      "y": 8,
      "z": 5,
      "name": "Soil_Clay_Lime",
      "support": 15
    },
    {
      "x": -10,
      "y": 9,
      "z": 5,
      "name": "Plant_Moss_Block_Green",
      "support": 15
    },
    {
      "x": -10,
      "y": 10,
      "z": 5,
      "name": "Plant_Moss_Block_Green",
      "support": 15
    },
    {
      "x": -10,
      "y": 11,
      "z": 5,
      "name": "Plant_Moss_Block_Green",
      "support": 15
    },
    {
      "x": -10,
      "y": 12,
      "z": 5,
      "name": "Plant_Moss_Block_Green",
      "support": 15
    },
    {
      "x": -10,
      "y": 13,
      "z": 5,
      "name": "Plant_Moss_Block_Green",
      "support": 15
    },
    {
      "x": -10,
      "y": 14,
      "z": 5,
      "name": "Rock_Stone_Mossy",
      "support": 15
    },
    {
      "x": -10,
      "y": 15,
      "z": 5,
      "name": "Rock_Stone",
      "support": 15
    },
    {
      "x": -10,
      "y": 16,
      "z": 5,
      "name": "Plant_Moss_Block_Green",
      "support": 15
    },
    {
      "x": -10,
      "y": 7,
      "z": 6,
      "name": "Rock_Stone_Cobble",
      "support": 15
    },
    {
      "x": -10,
      "y": 8,
      "z": 6,
      "name": "Soil_Clay_Lime",
      "support": 15
    },
    {
      "x": -10,
      "y": 9,
      "z": 6,
      "name": "Soil_Clay_Lime",
      "support": 15
    },
    {
      "x": -10,
      "y": 10,
      "z": 6,
      "name": "Plant_Moss_Block_Green",
      "support": 15
    },
    {
      "x": -10,
      "y": 11,
      "z": 6,
      "name": "Plant_Moss_Block_Green",
      "support": 15
    },
    {
      "x": -10,
      "y": 12,
      "z": 6,
      "name": "Plant_Moss_Block_Green",
      "support": 15
    },
    {
      "x": -10,
      "y": 13,
      "z": 6,
      "name": "Plant_Moss_Block_Green",
      "support": 15
    },
    {
      "x": -10,
      "y": 14,
      "z": 6,
      "name": "Soil_Clay_Lime",
      "support": 15
    },
    {
      "x": -10,
      "y": 15,
      "z": 6,
      "name": "Rock_Stone",
      "support": 15
    },
    {
      "x": -10,
      "y": 16,
      "z": 6,
      "name": "Plant_Moss_Block_Green",
      "support": 15
    },
    {
      "x": -10,
      "y": 17,
      "z": 6,
      "name": "Plant_Moss_Rug_Green",
      "support": 15
    },
    {
      "x": -10,
      "y": 8,
      "z": 7,
      "name": "Plant_Moss_Block_Green",
      "support": 15
    },
    {
      "x": -10,
      "y": 9,
      "z": 7,
      "name": "Plant_Moss_Block_Green",
      "support": 15
    },
    {
      "x": -10,
      "y": 10,
      "z": 7,
      "name": "Plant_Moss_Block_Green",
      "support": 15
    },
    {
      "x": -10,
      "y": 11,
      "z": 7,
      "name": "Plant_Moss_Block_Green",
      "support": 15
    },
    {
      "x": -10,
      "y": 12,
      "z": 7,
      "name": "Plant_Moss_Block_Green",
      "support": 15
    },
    {
      "x": -10,
      "y": 13,
      "z": 7,
      "name": "Plant_Moss_Block_Green",
      "support": 15
    },
    {
      "x": -10,
      "y": 14,
      "z": 7,
      "name": "Soil_Clay_Lime",
      "support": 15
    },
    {
      "x": -10,
      "y": 15,
      "z": 7,
      "name": "Plant_Moss_Block_Green",
      "support": 15
    },
    {
      "x": -10,
      "y": 16,
      "z": 7,
      "name": "Plant_Moss_Block_Green",
      "support": 15
    },
    {
      "x": -10,
      "y": 9,
      "z": 8,
      "name": "Plant_Moss_Block_Green",
      "support": 15
    },
    {
      "x": -10,
      "y": 10,
      "z": 8,
      "name": "Plant_Moss_Block_Green",
      "support": 15
    },
    {
      "x": -10,
      "y": 11,
      "z": 8,
      "name": "Plant_Moss_Block_Green",
      "support": 15
    },
    {
      "x": -10,
      "y": 12,
      "z": 8,
      "name": "Plant_Moss_Block_Green",
      "support": 15
    },
    {
      "x": -10,
      "y": 13,
      "z": 8,
      "name": "Plant_Moss_Block_Green",
      "support": 15
    },
    {
      "x": -10,
      "y": 14,
      "z": 8,
      "name": "Soil_Clay_Lime",
      "support": 15
    },
    {
      "x": -10,
      "y": 15,
      "z": 8,
      "name": "Rock_Stone",
      "support": 15
    },
    {
      "x": -10,
      "y": 16,
      "z": 8,
      "name": "Plant_Moss_Block_Green",
      "support": 15
    },
    {
      "x": -10,
      "y": 17,
      "z": 8,
      "name": "Plant_Moss_Rug_Green",
      "support": 15
    },
    {
      "x": -10,
      "y": 9,
      "z": 9,
      "name": "Plant_Moss_Block_Green",
      "support": 15
    },
    {
      "x": -10,
      "y": 10,
      "z": 9,
      "name": "Plant_Moss_Block_Green",
      "support": 15
    },
    {
      "x": -10,
      "y": 11,
      "z": 9,
      "name": "Plant_Moss_Block_Green",
      "support": 15
    },
    {
      "x": -10,
      "y": 12,
      "z": 9,
      "name": "Plant_Moss_Block_Green",
      "support": 15
    },
    {
      "x": -10,
      "y": 13,
      "z": 9,
      "name": "Plant_Moss_Block_Green",
      "support": 15
    },
    {
      "x": -10,
      "y": 14,
      "z": 9,
      "name": "Rock_Stone_Mossy",
      "support": 15
    },
    {
      "x": -10,
      "y": 10,
      "z": 10,
      "name": "Soil_Clay_Lime",
      "support": 15
    },
    {
      "x": -10,
      "y": 11,
      "z": 10,
      "name": "Plant_Moss_Block_Green",
      "support": 15
    },
    {
      "x": -10,
      "y": 12,
      "z": 10,
      "name": "Plant_Moss_Block_Green",
      "support": 15
    },
    {
      "x": -10,
      "y": 13,
      "z": 10,
      "name": "Soil_Clay_Lime",
      "support": 15
    },
    {
      "x": -10,
      "y": 14,
      "z": 10,
      "name": "Rock_Stone_Mossy",
      "support": 15
    },
    {
      "x": -10,
      "y": 10,
      "z": 11,
      "name": "Soil_Clay_Lime",
      "support": 15
    },
    {
      "x": -10,
      "y": 11,
      "z": 11,
      "name": "Plant_Moss_Block_Green",
      "support": 15
    },
    {
      "x": -10,
      "y": 12,
      "z": 11,
      "name": "Plant_Moss_Block_Green",
      "support": 15
    },
    {
      "x": -10,
      "y": 13,
      "z": 11,
      "name": "Plant_Moss_Block_Green",
      "support": 15
    },
    {
      "x": -10,
      "y": 14,
      "z": 11,
      "name": "Plant_Moss_Rug_Green",
      "support": 15
    },
    {
      "x": -10,
      "y": 13,
      "z": 12,
      "name": "Plant_Moss_Block_Green",
      "support": 15
    },
    {
      "x": -9,
      "y": 11,
      "z": -16,
      "name": "Plant_Moss_Block_Green",
      "support": 15
    },
    {
      "x": -9,
      "y": 12,
      "z": -16,
      "name": "Plant_Moss_Block_Green",
      "support": 15
    },
    {
      "x": -9,
      "y": 13,
      "z": -16,
      "name": "Plant_Moss_Rug_Green",
      "support": 15
    },
    {
      "x": -9,
      "y": 12,
      "z": -15,
      "name": "Plant_Moss_Block_Green",
      "support": 15
    },
    {
      "x": -9,
      "y": 13,
      "z": -15,
      "name": "Plant_Moss_Block_Green",
      "support": 15
    },
    {
      "x": -9,
      "y": 12,
      "z": -14,
      "name": "Plant_Moss_Block_Green",
      "support": 15
    },
    {
      "x": -9,
      "y": 13,
      "z": -14,
      "name": "Plant_Moss_Block_Green",
      "support": 15
    },
    {
      "x": -9,
      "y": 14,
      "z": -14,
      "name": "Plant_Moss_Block_Green",
      "support": 15
    },
    {
      "x": -9,
      "y": 15,
      "z": -14,
      "name": "Plant_Moss_Rug_Green",
      "support": 15
    },
    {
      "x": -9,
      "y": 12,
      "z": -13,
      "name": "Plant_Moss_Block_Green",
      "support": 15
    },
    {
      "x": -9,
      "y": 13,
      "z": -13,
      "name": "Plant_Moss_Block_Green",
      "support": 15
    },
    {
      "x": -9,
      "y": 14,
      "z": -13,
      "name": "Plant_Moss_Block_Green",
      "support": 15
    },
    {
      "x": -9,
      "y": 15,
      "z": -13,
      "name": "Plant_Moss_Rug_Green",
      "support": 15
    },
    {
      "x": -9,
      "y": 10,
      "z": -12,
      "name": "Soil_Clay_Lime",
      "support": 15
    },
    {
      "x": -9,
      "y": 11,
      "z": -12,
      "name": "Plant_Moss_Block_Green",
      "support": 15
    },
    {
      "x": -9,
      "y": 12,
      "z": -12,
      "name": "Plant_Moss_Block_Green",
      "support": 15
    },
    {
      "x": -9,
      "y": 13,
      "z": -12,
      "name": "Plant_Moss_Block_Green",
      "support": 15
    },
    {
      "x": -9,
      "y": 14,
      "z": -12,
      "name": "Soil_Clay_Lime",
      "support": 15
    },
    {
      "x": -9,
      "y": 9,
      "z": -11,
      "name": "Soil_Clay_Lime",
      "support": 15
    },
    {
      "x": -9,
      "y": 10,
      "z": -11,
      "name": "Plant_Moss_Block_Green",
      "support": 15
    },
    {
      "x": -9,
      "y": 11,
      "z": -11,
      "name": "Plant_Moss_Block_Green",
      "support": 15
    },
    {
      "x": -9,
      "y": 12,
      "z": -11,
      "name": "Plant_Moss_Block_Green",
      "support": 15
    },
    {
      "x": -9,
      "y": 13,
      "z": -11,
      "name": "Plant_Moss_Block_Green",
      "support": 15
    },
    {
      "x": -9,
      "y": 14,
      "z": -11,
      "name": "Soil_Clay_Lime",
      "support": 15
    },
    {
      "x": -9,
      "y": 8,
      "z": -10,
      "name": "Soil_Clay_Lime",
      "support": 15
    },
    {
      "x": -9,
      "y": 9,
      "z": -10,
      "name": "Soil_Clay_Lime",
      "support": 15
    },
    {
      "x": -9,
      "y": 10,
      "z": -10,
      "name": "Soil_Clay_Lime",
      "support": 15
    },
    {
      "x": -9,
      "y": 11,
      "z": -10,
      "name": "Plant_Moss_Block_Green",
      "support": 15
    },
    {
      "x": -9,
      "y": 12,
      "z": -10,
      "name": "Plant_Moss_Block_Green",
      "support": 15
    },
    {
      "x": -9,
      "y": 13,
      "z": -10,
      "name": "Plant_Moss_Block_Green",
      "support": 15
    },
    {
      "x": -9,
      "y": 14,
      "z": -10,
      "name": "Rock_Stone_Mossy",
      "support": 15
    },
    {
      "x": -9,
      "y": 15,
      "z": -10,
      "name": "Rock_Marble_Brick_Pillar_Base",
      "support": 15
    },
    {
      "x": -9,
      "y": 16,
      "z": -10,
      "name": "Rock_Marble_Brick_Pillar_Middle",
      "support": 15
    },
    {
      "x": -9,
      "y": 17,
      "z": -10,
      "name": "Rubble_Marble_Medium",
      "support": 15
    },
    {
      "x": -9,
      "y": 8,
      "z": -9,
      "name": "Soil_Clay_Lime",
      "support": 15
    },
    {
      "x": -9,
      "y": 9,
      "z": -9,
      "name": "Soil_Clay_Lime",
      "support": 15
    },
    {
      "x": -9,
      "y": 10,
      "z": -9,
      "name": "Soil_Clay_Lime",
      "support": 15
    },
    {
      "x": -9,
      "y": 11,
      "z": -9,
      "name": "Soil_Clay_Lime",
      "support": 15
    },
    {
      "x": -9,
      "y": 12,
      "z": -9,
      "name": "Plant_Moss_Block_Green",
      "support": 15
    },
    {
      "x": -9,
      "y": 13,
      "z": -9,
      "name": "Plant_Moss_Block_Green",
      "support": 15
    },
    {
      "x": -9,
      "y": 14,
      "z": -9,
      "name": "Rock_Stone_Mossy",
      "support": 15
    },
    {
      "x": -9,
      "y": 15,
      "z": -9,
      "name": "Rock_Marble_Brick_Pillar_Base",
      "support": 15
    },
    {
      "x": -9,
      "y": 16,
      "z": -9,
      "name": "Rock_Marble_Brick_Pillar_Middle",
      "support": 15
    },
    {
      "x": -9,
      "y": 17,
      "z": -9,
      "name": "Rock_Marble_Brick_Pillar_Middle",
      "support": 15
    },
    {
      "x": -9,
      "y": 7,
      "z": -8,
      "name": "Soil_Clay_Lime",
      "support": 15
    },
    {
      "x": -9,
      "y": 8,
      "z": -8,
      "name": "Rock_Stone_Cobble",
      "support": 15
    },
    {
      "x": -9,
      "y": 9,
      "z": -8,
      "name": "Soil_Clay_Lime",
      "support": 15
    },
    {
      "x": -9,
      "y": 10,
      "z": -8,
      "name": "Plant_Moss_Block_Green",
      "support": 15
    },
    {
      "x": -9,
      "y": 11,
      "z": -8,
      "name": "Plant_Moss_Block_Green",
      "support": 15
    },
    {
      "x": -9,
      "y": 12,
      "z": -8,
      "name": "Plant_Moss_Block_Green",
      "support": 15
    },
    {
      "x": -9,
      "y": 13,
      "z": -8,
      "name": "Plant_Moss_Block_Green",
      "support": 15
    },
    {
      "x": -9,
      "y": 14,
      "z": -8,
      "name": "Rock_Stone_Mossy",
      "support": 15
    },
    {
      "x": -9,
      "y": 7,
      "z": -7,
      "name": "Rock_Stone_Cobble",
      "support": 15
    },
    {
      "x": -9,
      "y": 8,
      "z": -7,
      "name": "Soil_Clay_Lime",
      "support": 15
    },
    {
      "x": -9,
      "y": 9,
      "z": -7,
      "name": "Soil_Clay_Lime",
      "support": 15
    },
    {
      "x": -9,
      "y": 10,
      "z": -7,
      "name": "Plant_Moss_Block_Green",
      "support": 15
    },
    {
      "x": -9,
      "y": 11,
      "z": -7,
      "name": "Soil_Clay_Lime",
      "support": 15
    },
    {
      "x": -9,
      "y": 12,
      "z": -7,
      "name": "Plant_Moss_Block_Green",
      "support": 15
    },
    {
      "x": -9,
      "y": 13,
      "z": -7,
      "name": "Plant_Moss_Block_Green",
      "support": 15
    },
    {
      "x": -9,
      "y": 14,
      "z": -7,
      "name": "Rock_Stone_Mossy",
      "support": 15
    },
    {
      "x": -9,
      "y": 7,
      "z": -6,
      "name": "Rock_Stone_Cobble",
      "support": 15
    },
    {
      "x": -9,
      "y": 8,
      "z": -6,
      "name": "Soil_Clay_Lime",
      "support": 15
    },
    {
