{
  "version": 8,
  "blockIdVersion": 11,
  "anchorX": 0,
  "anchorY": 0,
  "anchorZ": 0,
  "blocks": [
    {
      "x": -6,
      "y": 6,
      "z": -2,
      "name": "Rock_Lime_Brick_Smooth_Half",
      "rotation": 7
    },
    {
      "x": -6,
      "y": 7,
      "z": -2,
      "name": "Rock_Lime_Brick_Smooth_Half",
      "rotation": 7
    },
    {
      "x": -6,
      "y": 6,
      "z": -1,
      "name": "Rock_Lime_Brick_Smooth_Half",
      "rotation": 7
    },
    {
      "x": -6,
      "y": 7,
      "z": -1,
      "name": "Rock_Lime_Brick_Smooth_Half",
      "rotation": 7
    },
    {
      "x": -6,
      "y": 8,
      "z": -1,
      "name": "Rock_Lime_Brick_Smooth_Half",
      "rotation": 7
    },
    {
      "x": -6,
      "y": 6,
      "z": 0,
      "name": "Rock_Lime_Brick_Smooth_Half",
      "rotation": 7
    },
    {
      "x": -6,
      "y": 7,
      "z": 0,
      "name": "Rock_Lime_Brick_Smooth_Half",
      "rotation": 7
    },
    {
      "x": -6,
      "y": 8,
      "z": 0,
      "name": "Rock_Lime_Brick_Smooth_Half",
      "rotation": 7
    },
    {
      "x": -6,
      "y": 6,
      "z": 1,
      "name": "Rock_Lime_Brick_Smooth_Half",
      "rotation": 7
    },
    {
      "x": -6,
      "y": 7,
      "z": 1,
      "name": "Rock_Lime_Brick_Smooth_Half",
      "rotation": 7
    },
    {
      "x": -6,
      "y": 8,
      "z": 1,
      "name": "Rock_Lime_Brick_Smooth_Half",
      "rotation": 7
    },
    {
      "x": -6,
      "y": 6,
      "z": 2,
      "name": "Rock_Lime_Brick_Smooth_Half",
      "rotation": 7
    },
    {
      "x": -6,
      "y": 7,
      "z": 2,
      "name": "Rock_Lime_Brick_Smooth_Half",
      "rotation": 7
    },
    {
      "x": -6,
      "y": 8,
      "z": 2,
      "name": "Rock_Lime_Brick_Smooth_Half",
      "rotation": 7
    },
    {
      "x": -6,
      "y": 6,
      "z": 3,
      "name": "Rock_Lime_Brick_Smooth_Half",
      "rotation": 7
    },
    {
      "x": -6,
      "y": 7,
      "z": 3,
      "name": "Rock_Lime_Brick_Smooth_Half",
      "rotation": 7
    },
    {
      "x": -5,
      "y": 2,
      "z": -6,
      "name": "Rock_Lime_Brick_Smooth_Half",
      "rotation": 7
    },
    {
      "x": -5,
      "y": 3,
      "z": -6,
      "name": "Rock_Lime_Brick_Smooth_Half",
      "rotation": 7
    },
    {
      "x": -5,
      "y": 4,
      "z": -6,
      "name": "Rock_Lime_Brick_Smooth_Half",
      "rotation": 7
    },
    {
      "x": -5,
      "y": 5,
      "z": -6,
      "name": "Rock_Lime_Brick_Smooth_Half",
      "rotation": 7
    },
    {
      "x": -5,
      "y": 6,
      "z": -6,
      "name": "Rock_Lime_Brick_Smooth_Half",
      "rotation": 7
    },
    {
      "x": -5,
      "y": 1,
      "z": -5,
      "name": "Deco_Bone_Ribs_Long",
      "rotation": 1
    },
    {
      "x": -5,
      "y": 2,
      "z": -5,
      "name": "Deco_Bone_Full",
      "rotation": 1
    },
    {
      "x": -5,
      "y": 3,
      "z": -5,
      "name": "Deco_Bone_Full",
      "rotation": 1
    },
    {
      "x": -5,
      "y": 4,
      "z": -5,
      "name": "Deco_Bone_Full",
      "rotation": 1
    },
    {
      "x": -5,
      "y": 5,
      "z": -5,
      "name": "Deco_Bone_Full",
      "rotation": 1
    },
    {
      "x": -5,
      "y": 6,
      "z": -5,
      "name": "Deco_Bone_Full",
      "rotation": 1
    },
    {
      "x": -5,
      "y": 7,
      "z": -5,
      "name": "Deco_Bone_Full",
      "rotation": 1
    },
    {
      "x": -5,
      "y": 2,
      "z": -4,
      "name": "Deco_Bone_Full",
      "rotation": 1
    },
    {
      "x": -5,
      "y": 3,
      "z": -4,
      "name": "Deco_Bone_Full",
      "rotation": 1
    },
    {
      "x": -5,
      "y": 4,
      "z": -4,
      "name": "Deco_Bone_Full",
      "rotation": 1
    },
    {
      "x": -5,
      "y": 5,
      "z": -4,
      "name": "Deco_Bone_Full",
      "rotation": 1
    },
    {
      "x": -5,
      "y": 6,
      "z": -4,
      "name": "Deco_Bone_Full",
      "rotation": 1
    },
    {
      "x": -5,
      "y": 7,
      "z": -4,
      "name": "Deco_Bone_Full",
      "rotation": 1
    },
    {
      "x": -5,
      "y": 8,
      "z": -4,
      "name": "Deco_Bone_Full",
      "rotation": 1
    },
    {
      "x": -5,
      "y": 1,
      "z": -3,
      "name": "Deco_Bone_Full",
      "rotation": 1
    },
    {
      "x": -5,
      "y": 2,
      "z": -3,
      "name": "Deco_Bone_Full",
      "rotation": 1
    },
    {
      "x": -5,
      "y": 3,
      "z": -3,
      "name": "Deco_Bone_Full",
      "rotation": 1
    },
    {
      "x": -5,
      "y": 4,
      "z": -3,
      "name": "Deco_Bone_Full",
      "rotation": 1
    },
    {
      "x": -5,
      "y": 5,
      "z": -3,
      "name": "Deco_Bone_Full",
      "rotation": 1
    },
    {
      "x": -5,
      "y": 6,
      "z": -3,
      "name": "Deco_Bone_Full",
      "rotation": 1
    },
    {
      "x": -5,
      "y": 7,
      "z": -3,
      "name": "Deco_Bone_Full",
      "rotation": 1
    },
    {
      "x": -5,
      "y": 8,
      "z": -3,
      "name": "Deco_Bone_Full",
      "rotation": 1
    },
    {
      "x": -5,
      "y": 1,
      "z": -2,
      "name": "Deco_Bone_Full",
      "rotation": 1
    },
    {
      "x": -5,
      "y": 2,
      "z": -2,
      "name": "Deco_Bone_Full",
      "rotation": 1
    },
    {
      "x": -5,
      "y": 3,
      "z": -2,
      "name": "Deco_Bone_Full",
      "rotation": 1
    },
    {
      "x": -5,
      "y": 4,
      "z": -2,
      "name": "Deco_Bone_Full",
      "rotation": 1
    },
    {
      "x": -5,
      "y": 5,
      "z": -2,
      "name": "Deco_Bone_Full",
      "rotation": 1
    },
    {
      "x": -5,
      "y": 6,
      "z": -2,
      "name": "Deco_Bone_Full",
      "rotation": 1
    },
    {
      "x": -5,
      "y": 7,
      "z": -2,
      "name": "Deco_Bone_Full",
      "rotation": 1
    },
    {
      "x": -5,
      "y": 8,
      "z": -2,
      "name": "Deco_Bone_Full",
      "rotation": 1
    },
    {
      "x": -5,
      "y": 9,
      "z": -2,
      "name": "Deco_Bone_Full",
      "rotation": 1
    },
    {
      "x": -5,
      "y": 5,
      "z": -1,
      "name": "Deco_Bone_Full",
      "rotation": 1
    },
    {
      "x": -5,
      "y": 6,
      "z": -1,
      "name": "Deco_Bone_Full",
      "rotation": 1
    },
    {
      "x": -5,
      "y": 7,
      "z": -1,
      "name": "Deco_Bone_Full",
      "rotation": 1
    },
    {
      "x": -5,
      "y": 8,
      "z": -1,
      "name": "Deco_Bone_Full",
      "rotation": 1
    },
    {
      "x": -5,
      "y": 9,
      "z": -1,
      "name": "Deco_Bone_Full",
      "rotation": 1
    },
    {
      "x": -5,
      "y": 5,
      "z": 0,
      "name": "Deco_Bone_Full",
      "rotation": 1
    },
    {
      "x": -5,
      "y": 6,
      "z": 0,
      "name": "Deco_Bone_Full",
      "rotation": 1
    },
    {
      "x": -5,
      "y": 7,
      "z": 0,
      "name": "Deco_Bone_Full",
      "rotation": 1
    },
    {
      "x": -5,
      "y": 8,
      "z": 0,
      "name": "Deco_Bone_Full",
      "rotation": 1
    },
    {
      "x": -5,
      "y": 9,
      "z": 0,
      "name": "Deco_Bone_Full",
      "rotation": 1
    },
    {
      "x": -5,
      "y": 5,
      "z": 1,
      "name": "Deco_Bone_Full",
      "rotation": 1
    },
    {
      "x": -5,
      "y": 6,
      "z": 1,
      "name": "Deco_Bone_Full",
      "rotation": 1
    },
    {
      "x": -5,
      "y": 7,
      "z": 1,
      "name": "Deco_Bone_Full",
      "rotation": 1
    },
    {
      "x": -5,
      "y": 8,
      "z": 1,
      "name": "Deco_Bone_Full",
      "rotation": 1
    },
    {
      "x": -5,
      "y": 9,
      "z": 1,
      "name": "Deco_Bone_Full",
      "rotation": 1
    },
    {
      "x": -5,
      "y": 5,
      "z": 2,
      "name": "Deco_Bone_Full",
      "rotation": 1
    },
    {
      "x": -5,
      "y": 6,
      "z": 2,
      "name": "Deco_Bone_Full",
      "rotation": 1
    },
    {
      "x": -5,
      "y": 7,
      "z": 2,
      "name": "Deco_Bone_Full",
      "rotation": 1
    },
    {
      "x": -5,
      "y": 8,
      "z": 2,
      "name": "Deco_Bone_Full",
      "rotation": 1
    },
    {
      "x": -5,
      "y": 9,
      "z": 2,
      "name": "Deco_Bone_Full",
      "rotation": 1
    },
    {
      "x": -5,
      "y": 5,
      "z": 3,
      "name": "Deco_Bone_Full",
      "rotation": 1
    },
    {
      "x": -5,
      "y": 6,
      "z": 3,
      "name": "Deco_Bone_Full",
      "rotation": 1
    },
    {
      "x": -5,
      "y": 7,
      "z": 3,
      "name": "Deco_Bone_Full",
      "rotation": 1
    },
    {
      "x": -5,
      "y": 8,
      "z": 3,
      "name": "Deco_Bone_Full",
      "rotation": 1
    },
    {
      "x": -5,
      "y": 9,
      "z": 3,
      "name": "Deco_Bone_Full",
      "rotation": 1
    },
    {
      "x": -5,
      "y": 5,
      "z": 4,
      "name": "Deco_Bone_Full",
      "rotation": 1
    },
    {
      "x": -5,
      "y": 6,
      "z": 4,
      "name": "Deco_Bone_Full",
      "rotation": 1
    },
    {
      "x": -5,
      "y": 7,
      "z": 4,
      "name": "Deco_Bone_Full",
      "rotation": 1
    },
    {
      "x": -5,
      "y": 8,
      "z": 4,
      "name": "Deco_Bone_Full",
      "rotation": 1
    },
    {
      "x": -4,
      "y": 5,
      "z": -8,
      "name": "Rock_Lime_Brick_Smooth_Half",
      "rotation": 7
    },
    {
      "x": -4,
      "y": 6,
      "z": -8,
      "name": "Rock_Lime_Brick_Smooth_Half",
      "rotation": 7
    },
    {
      "x": -4,
      "y": 1,
      "z": -7,
      "name": "Deco_Bone_Ribs_Long",
      "rotation": 1
    },
    {
      "x": -4,
      "y": 2,
      "z": -7,
      "name": "Deco_Bone_Full",
      "rotation": 1
    },
    {
      "x": -4,
      "y": 3,
      "z": -7,
      "name": "Deco_Bone_Full",
      "rotation": 1
    },
    {
      "x": -4,
      "y": 4,
      "z": -7,
      "name": "Deco_Bone_Full",
      "rotation": 1
    },
    {
      "x": -4,
      "y": 5,
      "z": -7,
      "name": "Deco_Bone_Full",
      "rotation": 1
    },
    {
      "x": -4,
      "y": 6,
      "z": -7,
      "name": "Deco_Bone_Full",
      "rotation": 1
    },
    {
      "x": -4,
      "y": 7,
      "z": -7,
      "name": "Deco_Bone_Full",
      "rotation": 1
    },
    {
      "x": -4,
      "y": 8,
      "z": -7,
      "name": "Deco_Bone_Full",
      "rotation": 1
    },
    {
      "x": -4,
      "y": 1,
      "z": -6,
      "name": "Deco_Bone_Ribs_Long",
      "rotation": 1
    },
    {
      "x": -4,
      "y": 2,
      "z": -6,
      "name": "Deco_Bone_Full",
      "rotation": 1
    },
    {
      "x": -4,
      "y": 3,
      "z": -6,
      "name": "Deco_Bone_Full",
      "rotation": 1
    },
    {
      "x": -4,
      "y": 4,
      "z": -6,
      "name": "Deco_Bone_Full",
      "rotation": 1
    },
    {
      "x": -4,
      "y": 5,
      "z": -6,
      "name": "Deco_Bone_Full",
      "rotation": 1
    },
    {
      "x": -4,
      "y": 6,
      "z": -6,
      "name": "Deco_Bone_Full",
      "rotation": 1
    },
    {
      "x": -4,
      "y": 7,
      "z": -6,
      "name": "Deco_Bone_Full",
      "rotation": 1
    },
    {
      "x": -4,
      "y": 8,
      "z": -6,
      "name": "Deco_Bone_Full",
      "rotation": 1
    },
    {
      "x": -4,
      "y": 4,
      "z": -5,
      "name": "Deco_Bone_Full",
      "rotation": 1
    },
    {
      "x": -4,
      "y": 8,
      "z": -5,
      "name": "Deco_Bone_Full",
      "rotation": 1
    },
    {
      "x": -4,
      "y": 9,
      "z": -5,
      "name": "Deco_Bone_Full",
      "rotation": 1
    },
    {
      "x": -4,
      "y": 4,
      "z": -4,
      "name": "Soil_Clay_Smooth_Black"
    },
    {
      "x": -4,
      "y": 9,
      "z": -4,
      "name": "Deco_Bone_Full",
      "rotation": 1
    },
    {
      "x": -4,
      "y": 4,
      "z": -3,
      "name": "Soil_Clay_Smooth_Black"
    },
    {
      "x": -4,
      "y": 9,
      "z": -3,
      "name": "Deco_Bone_Full",
      "rotation": 1
    },
    {
      "x": -4,
      "y": 4,
      "z": -2,
      "name": "Soil_Clay_Smooth_Black"
    },
    {
      "x": -4,
      "y": 9,
      "z": -2,
      "name": "Deco_Bone_Full",
      "rotation": 1
    },
    {
      "x": -4,
      "y": 10,
      "z": -2,
      "name": "Rock_Lime_Brick_Smooth_Half",
      "rotation": 1
    },
    {
      "x": -4,
      "y": 9,
      "z": -1,
      "name": "Deco_Bone_Full",
      "rotation": 1
    },
    {
      "x": -4,
      "y": 10,
      "z": -1,
      "name": "Deco_Bone_Full",
      "rotation": 1
    },
    {
      "x": -4,
      "y": 9,
      "z": 0,
      "name": "Deco_Bone_Full",
      "rotation": 1
    },
    {
      "x": -4,
      "y": 10,
      "z": 0,
      "name": "Deco_Bone_Full",
      "rotation": 1
    },
    {
      "x": -4,
      "y": 9,
      "z": 1,
      "name": "Deco_Bone_Full",
      "rotation": 1
    },
    {
      "x": -4,
      "y": 10,
      "z": 1,
      "name": "Deco_Bone_Full",
      "rotation": 1
    },
    {
      "x": -4,
      "y": 9,
      "z": 2,
      "name": "Deco_Bone_Full",
      "rotation": 1
    },
    {
      "x": -4,
      "y": 10,
      "z": 2,
      "name": "Deco_Bone_Full",
      "rotation": 1
    },
    {
      "x": -4,
      "y": 4,
      "z": 3,
      "name": "Deco_Bone_Full",
      "rotation": 1
    },
    {
      "x": -4,
      "y": 9,
      "z": 3,
      "name": "Deco_Bone_Full",
      "rotation": 1
    },
    {
      "x": -4,
      "y": 10,
      "z": 3,
      "name": "Rock_Lime_Brick_Smooth_Half",
      "rotation": 1
    },
    {
      "x": -4,
      "y": 4,
      "z": 4,
      "name": "Deco_Bone_Full",
      "rotation": 1
    },
    {
      "x": -4,
      "y": 5,
      "z": 4,
      "name": "Deco_Bone_Full",
      "rotation": 1
    },
    {
      "x": -4,
      "y": 6,
      "z": 4,
      "name": "Deco_Bone_Full",
      "rotation": 1
    },
    {
      "x": -4,
      "y": 7,
      "z": 4,
      "name": "Deco_Bone_Full",
      "rotation": 1
    },
    {
      "x": -4,
      "y": 8,
      "z": 4,
      "name": "Deco_Bone_Full",
      "rotation": 1
    },
    {
      "x": -4,
      "y": 9,
      "z": 4,
      "name": "Deco_Bone_Full",
      "rotation": 1
    },
    {
      "x": -4,
      "y": 5,
      "z": 5,
      "name": "Deco_Bone_Full",
      "rotation": 1
    },
    {
      "x": -4,
      "y": 6,
      "z": 5,
      "name": "Deco_Bone_Full",
      "rotation": 1
    },
    {
      "x": -4,
      "y": 7,
      "z": 5,
      "name": "Deco_Bone_Full",
      "rotation": 1
    },
    {
      "x": -4,
      "y": 8,
      "z": 5,
      "name": "Deco_Bone_Full",
      "rotation": 1
    },
    {
      "x": -4,
      "y": 9,
      "z": 5,
      "name": "Deco_Bone_Full",
      "rotation": 1
    },
    {
      "x": -4,
      "y": 7,
      "z": 6,
      "name": "Deco_Bone_Full",
      "rotation": 1
    },
    {
      "x": -4,
      "y": 8,
      "z": 6,
      "name": "Deco_Bone_Full",
      "rotation": 1
    },
    {
      "x": -3,
      "y": 1,
      "z": -8,
      "name": "Deco_Bone_Ribs_Long",
      "rotation": 1
    },
    {
      "x": -3,
      "y": 2,
      "z": -8,
      "name": "Rock_Lime_Stairs",
      "rotation": 2
    },
    {
      "x": -3,
      "y": 3,
      "z": -8,
      "name": "Rock_Lime_Brick_Smooth_Half",
      "rotation": 6
    },
    {
      "x": -3,
      "y": 4,
      "z": -8,
      "name": "Deco_Bone_Full",
      "rotation": 1
    },
    {
      "x": -3,
      "y": 5,
      "z": -8,
      "name": "Deco_Bone_Full",
      "rotation": 1
    },
    {
      "x": -3,
      "y": 7,
      "z": -8,
      "name": "Rock_Lime_Stairs",
      "rotation": 11
    },
    {
      "x": -3,
      "y": 8,
      "z": -8,
      "name": "Deco_Bone_Full",
      "rotation": 1
    },
    {
      "x": -3,
      "y": 4,
      "z": -7,
      "name": "Deco_Bone_Full",
      "rotation": 1
    },
    {
      "x": -3,
      "y": 6,
      "z": -7,
      "name": "Build_Lightsource_Red",
      "rotation": 4
    },
    {
      "x": -3,
      "y": 7,
      "z": -7,
      "name": "Build_Lightsource_Red",
      "rotation": 4
    },
    {
      "x": -3,
      "y": 8,
      "z": -7,
      "name": "Deco_Bone_Full",
      "rotation": 1
    },
    {
      "x": -3,
      "y": 4,
      "z": -6,
      "name": "Soil_Clay_Smooth_Black"
    },
    {
      "x": -3,
      "y": 9,
      "z": -6,
      "name": "Deco_Bone_Full",
      "rotation": 1
    },
    {
      "x": -3,
      "y": 4,
      "z": -5,
      "name": "Soil_Clay_Smooth_Black"
    },
    {
      "x": -3,
      "y": 9,
      "z": -5,
      "name": "Deco_Bone_Full",
      "rotation": 1
    },
    {
      "x": -3,
      "y": 10,
      "z": -5,
      "name": "Rock_Lime_Brick_Smooth_Half",
      "rotation": 1
    },
    {
      "x": -3,
      "y": 4,
      "z": -4,
      "name": "Soil_Clay_Smooth_Black"
    },
    {
      "x": -3,
      "y": 10,
      "z": -4,
      "name": "Deco_Bone_Full",
      "rotation": 1
    },
    {
      "x": -3,
      "y": 4,
      "z": -3,
      "name": "Soil_Clay_Smooth_Black"
    },
    {
      "x": -3,
      "y": 10,
      "z": -3,
      "name": "Deco_Bone_Full",
      "rotation": 1
    },
    {
      "x": -3,
      "y": 4,
      "z": -2,
      "name": "Soil_Clay_Smooth_Black"
    },
    {
      "x": -3,
      "y": 10,
      "z": -2,
      "name": "Deco_Bone_Full",
      "rotation": 1
    },
    {
      "x": -3,
      "y": 1,
      "z": -1,
      "name": "Soil_Clay_Smooth_Black"
    },
    {
      "x": -3,
      "y": 2,
      "z": -1,
      "name": "Soil_Clay_Smooth_Black"
    },
    {
      "x": -3,
      "y": 3,
      "z": -1,
      "name": "Soil_Clay_Smooth_Black"
    },
    {
      "x": -3,
      "y": 10,
      "z": -1,
      "name": "Deco_Bone_Full",
      "rotation": 1
    },
    {
      "x": -3,
      "y": 11,
      "z": -1,
      "name": "Rock_Lime_Brick_Smooth_Half",
      "rotation": 1
    },
    {
      "x": -3,
      "y": 10,
      "z": 0,
      "name": "Deco_Bone_Full",
      "rotation": 1
    },
    {
      "x": -3,
      "y": 11,
      "z": 0,
      "name": "Rock_Lime_Brick_Smooth_Half",
      "rotation": 1
    },
    {
      "x": -3,
      "y": 10,
      "z": 1,
      "name": "Deco_Bone_Full",
      "rotation": 1
    },
    {
      "x": -3,
      "y": 11,
      "z": 1,
      "name": "Rock_Lime_Brick_Smooth_Half",
      "rotation": 1
    },
    {
      "x": -3,
      "y": 10,
      "z": 2,
      "name": "Deco_Bone_Full",
      "rotation": 1
    },
    {
      "x": -3,
      "y": 11,
      "z": 2,
      "name": "Rock_Lime_Brick_Smooth_Half",
      "rotation": 1
    },
    {
      "x": -3,
      "y": 4,
      "z": 3,
      "name": "Deco_Bone_Full",
      "rotation": 1
    },
    {
      "x": -3,
      "y": 10,
      "z": 3,
      "name": "Deco_Bone_Full",
      "rotation": 1
    },
    {
      "x": -3,
      "y": 4,
      "z": 4,
      "name": "Deco_Bone_Full",
      "rotation": 1
    },
    {
      "x": -3,
      "y": 10,
      "z": 4,
      "name": "Deco_Bone_Full",
      "rotation": 1
    },
    {
      "x": -3,
      "y": 4,
      "z": 5,
      "name": "Deco_Bone_Full",
      "rotation": 1
    },
    {
      "x": -3,
      "y": 5,
      "z": 5,
      "name": "Deco_Bone_Full",
      "rotation": 1
    },
    {
      "x": -3,
      "y": 10,
      "z": 5,
      "name": "Deco_Bone_Full",
      "rotation": 1
    },
    {
      "x": -3,
      "y": 6,
      "z": 6,
      "name": "Deco_Bone_Full",
      "rotation": 1
    },
    {
      "x": -3,
      "y": 9,
      "z": 6,
      "name": "Deco_Bone_Full",
      "rotation": 1
    },
    {
      "x": -3,
      "y": 7,
      "z": 7,
      "name": "Deco_Bone_Full",
      "rotation": 1
    },
    {
      "x": -3,
      "y": 8,
      "z": 7,
      "name": "Deco_Bone_Full",
      "rotation": 1
    },
    {
      "x": -2,
      "y": 2,
      "z": -9,
      "name": "Rock_Lime_Brick_Smooth_Half",
      "rotation": 6
    },
    {
      "x": -2,
      "y": 1,
      "z": -8,
      "name": "Deco_Bone_Ribs_Long",
      "rotation": 1
    },
    {
      "x": -2,
      "y": 2,
      "z": -8,
      "name": "Deco_Bone_Full",
      "rotation": 1
    },
    {
      "x": -2,
      "y": 3,
      "z": -8,
      "name": "Deco_Bone_Full",
      "rotation": 1
    },
    {
      "x": -2,
      "y": 4,
      "z": -8,
      "name": "Deco_Bone_Full",
      "rotation": 1
    },
    {
      "x": -2,
      "y": 5,
      "z": -8,
      "name": "Deco_Bone_Full",
      "rotation": 1
    },
    {
      "x": -2,
      "y": 7,
      "z": -8,
      "name": "Rock_Lime_Stairs",
      "rotation": 9
    },
    {
      "x": -2,
      "y": 8,
      "z": -8,
      "name": "Deco_Bone_Full",
      "rotation": 1
    },
    {
      "x": -2,
      "y": 4,
      "z": -7,
      "name": "Soil_Clay_Smooth_Black"
    },
    {
      "x": -2,
      "y": 6,
      "z": -7,
      "name": "Build_Lightsource_Red",
      "rotation": 4
    },
    {
      "x": -2,
      "y": 7,
      "z": -7,
      "name": "Build_Lightsource_Red",
      "rotation": 4
    },
    {
      "x": -2,
      "y": 9,
      "z": -7,
      "name": "Deco_Bone_Full",
      "rotation": 1
    },
    {
      "x": -2,
      "y": 4,
      "z": -6,
      "name": "Soil_Clay_Smooth_Black"
    },
    {
      "x": -2,
      "y": 9,
      "z": -6,
      "name": "Deco_Bone_Full",
      "rotation": 1
    },
    {
      "x": -2,
      "y": 10,
      "z": -6,
      "name": "Rock_Lime_Brick_Smooth_Half",
      "rotation": 1
    },
    {
      "x": -2,
      "y": 4,
      "z": -5,
      "name": "Soil_Clay_Smooth_Black"
    },
    {
      "x": -2,
      "y": 10,
      "z": -5,
      "name": "Deco_Bone_Full",
      "rotation": 1
    },
    {
      "x": -2,
      "y": 4,
      "z": -4,
      "name": "Soil_Clay_Smooth_Black"
    },
    {
      "x": -2,
      "y": 10,
      "z": -4,
      "name": "Deco_Bone_Full",
      "rotation": 1
    },
    {
      "x": -2,
      "y": 11,
      "z": -4,
      "name": "Rock_Lime_Brick_Smooth_Half",
      "rotation": 1
    },
    {
      "x": -2,
      "y": 4,
      "z": -3,
      "name": "Soil_Clay_Smooth_Black"
    },
    {
      "x": -2,
      "y": 11,
      "z": -3,
      "name": "Deco_Bone_Full",
      "rotation": 1
    },
    {
      "x": -2,
      "y": 4,
      "z": -2,
      "name": "Soil_Clay_Smooth_Black"
    },
    {
      "x": -2,
      "y": 11,
      "z": -2,
      "name": "Deco_Bone_Full",
      "rotation": 1
    },
    {
      "x": -2,
      "y": 1,
      "z": -1,
      "name": "Soil_Clay_Smooth_Black"
    },
    {
      "x": -2,
      "y": 2,
      "z": -1,
      "name": "Soil_Clay_Smooth_Black"
    },
    {
      "x": -2,
      "y": 3,
      "z": -1,
      "name": "Soil_Clay_Smooth_Black"
    },
    {
      "x": -2,
      "y": 11,
      "z": -1,
      "name": "Deco_Bone_Full",
      "rotation": 1
    },
    {
      "x": -2,
      "y": 11,
      "z": 0,
      "name": "Deco_Bone_Full",
      "rotation": 1
    },
    {
      "x": -2,
      "y": 11,
      "z": 1,
      "name": "Deco_Bone_Full",
      "rotation": 1
    },
    {
      "x": -2,
      "y": 11,
      "z": 2,
      "name": "Deco_Bone_Full",
      "rotation": 1
    },
    {
      "x": -2,
      "y": 4,
      "z": 3,
      "name": "Deco_Bone_Full",
      "rotation": 1
    },
    {
      "x": -2,
      "y": 11,
      "z": 3,
      "name": "Deco_Bone_Full",
      "rotation": 1
    },
    {
      "x": -2,
      "y": 4,
      "z": 4,
      "name": "Deco_Bone_Full",
      "rotation": 1
    },
    {
      "x": -2,
      "y": 11,
      "z": 4,
      "name": "Deco_Bone_Full",
      "rotation": 1
    },
    {
      "x": -2,
      "y": 4,
      "z": 5,
      "name": "Deco_Bone_Full",
      "rotation": 1
    },
    {
      "x": -2,
      "y": 5,
      "z": 5,
      "name": "Deco_Bone_Full",
      "rotation": 1
    },
    {
      "x": -2,
      "y": 10,
      "z": 5,
      "name": "Deco_Bone_Full",
      "rotation": 1
    },
    {
      "x": -2,
      "y": 11,
      "z": 5,
      "name": "Rock_Lime_Brick_Smooth_Half",
      "rotation": 1
    },
    {
      "x": -2,
      "y": 5,
      "z": 6,
      "name": "Deco_Bone_Full",
      "rotation": 1
    },
    {
      "x": -2,
      "y": 6,
      "z": 6,
      "name": "Deco_Bone_Full",
      "rotation": 1
    },
    {
      "x": -2,
      "y": 10,
      "z": 6,
      "name": "Deco_Bone_Full",
      "rotation": 1
    },
    {
      "x": -2,
      "y": 7,
      "z": 7,
      "name": "Deco_Bone_Full",
      "rotation": 1
    },
    {
      "x": -2,
      "y": 8,
      "z": 7,
      "name": "Deco_Bone_Full",
      "rotation": 1
    },
    {
      "x": -2,
      "y": 9,
      "z": 7,
      "name": "Deco_Bone_Full",
      "rotation": 1
    },
    {
      "x": -1,
      "y": 2,
      "z": -9,
      "name": "Rock_Lime_Brick_Smooth_Half",
      "rotation": 6
    },
    {
      "x": -1,
      "y": 1,
      "z": -8,
      "name": "Deco_Bone_Ribs_Long",
      "rotation": 1
    },
    {
      "x": -1,
      "y": 2,
      "z": -8,
      "name": "Deco_Bone_Full",
      "rotation": 1
    },
    {
      "x": -1,
      "y": 3,
      "z": -8,
      "name": "Deco_Bone_Full",
      "rotation": 1
    },
    {
      "x": -1,
      "y": 4,
      "z": -8,
      "name": "Rock_Lime_Brick_Smooth_Half",
      "rotation": 5
    },
    {
      "x": -1,
      "y": 5,
      "z": -8,
      "name": "Deco_Bone_Full",
      "rotation": 1
    },
    {
      "x": -1,
      "y": 6,
      "z": -8,
      "name": "Deco_Bone_Full",
      "rotation": 1
    },
    {
      "x": -1,
      "y": 7,
      "z": -8,
      "name": "Deco_Bone_Full",
      "rotation": 1
    },
    {
      "x": -1,
      "y": 8,
      "z": -8,
      "name": "Deco_Bone_Full",
      "rotation": 1
    },
    {
      "x": -1,
      "y": 4,
      "z": -7,
      "name": "Soil_Clay_Smooth_Black"
    },
    {
      "x": -1,
      "y": 9,
      "z": -7,
      "name": "Deco_Bone_Full",
      "rotation": 1
    },
    {
      "x": -1,
      "y": 4,
      "z": -6,
      "name": "Soil_Clay_Smooth_Black"
    },
    {
      "x": -1,
      "y": 10,
      "z": -6,
      "name": "Deco_Bone_Full",
      "rotation": 1
    },
    {
      "x": -1,
      "y": 4,
      "z": -5,
      "name": "Soil_Clay_Smooth_Black"
    },
    {
      "x": -1,
      "y": 10,
      "z": -5,
      "name": "Deco_Bone_Full",
      "rotation": 1
    },
    {
      "x": -1,
      "y": 4,
      "z": -4,
      "name": "Soil_Clay_Smooth_Black"
    },
    {
      "x": -1,
      "y": 11,
      "z": -4,
      "name": "Deco_Bone_Full",
      "rotation": 1
    },
    {
      "x": -1,
      "y": 4,
      "z": -3,
      "name": "Soil_Clay_Smooth_Black"
    },
    {
      "x": -1,
      "y": 11,
      "z": -3,
      "name": "Deco_Bone_Full",
      "rotation": 1
    },
    {
      "x": -1,
      "y": 4,
      "z": -2,
      "name": "Soil_Clay_Smooth_Black"
    },
    {
      "x": -1,
      "y": 11,
      "z": -2,
      "name": "Deco_Bone_Full",
      "rotation": 1
    },
    {
      "x": -1,
      "y": 1,
      "z": -1,
      "name": "Soil_Clay_Smooth_Black"
    },
    {
      "x": -1,
      "y": 2,
      "z": -1,
      "name": "Soil_Clay_Smooth_Black"
    },
    {
      "x": -1,
      "y": 3,
      "z": -1,
      "name": "Soil_Clay_Smooth_Black"
    },
    {
      "x": -1,
      "y": 11,
      "z": -1,
      "name": "Deco_Bone_Full",
      "rotation": 1
    },
    {
      "x": -1,
      "y": 11,
      "z": 0,
      "name": "Deco_Bone_Full",
      "rotation": 1
    },
    {
      "x": -1,
      "y": 11,
      "z": 1,
      "name": "Deco_Bone_Full",
      "rotation": 1
    },
    {
      "x": -1,
      "y": 11,
      "z": 2,
      "name": "Deco_Bone_Full",
      "rotation": 1
    },
    {
      "x": -1,
      "y": 4,
      "z": 3,
      "name": "Deco_Bone_Full",
      "rotation": 1
    },
    {
      "x": -1,
      "y": 11,
      "z": 3,
      "name": "Deco_Bone_Full",
      "rotation": 1
    },
    {
      "x": -1,
      "y": 4,
      "z": 4,
      "name": "Deco_Bone_Full",
      "rotation": 1
    },
    {
      "x": -1,
      "y": 11,
      "z": 4,
      "name": "Deco_Bone_Full",
      "rotation": 1
    },
    {
      "x": -1,
      "y": 4,
      "z": 5,
      "name": "Deco_Bone_Full",
      "rotation": 1
    },
    {
      "x": -1,
      "y": 5,
      "z": 5,
      "name": "Deco_Bone_Full",
      "rotation": 1
    },
    {
      "x": -1,
      "y": 11,
      "z": 5,
      "name": "Deco_Bone_Full",
      "rotation": 1
    },
    {
      "x": -1,
      "y": 5,
      "z": 6,
      "name": "Deco_Bone_Full",
      "rotation": 1
    },
    {
      "x": -1,
      "y": 6,
      "z": 6,
      "name": "Deco_Bone_Full",
      "rotation": 1
    },
    {
      "x": -1,
      "y": 10,
      "z": 6,
      "name": "Deco_Bone_Full",
      "rotation": 1
    },
    {
      "x": -1,
      "y": 6,
      "z": 7,
      "name": "Deco_Bone_Full",
      "rotation": 1
    },
    {
      "x": -1,
      "y": 7,
      "z": 7,
      "name": "Deco_Bone_Full",
      "rotation": 1
    },
    {
      "x": -1,
      "y": 8,
      "z": 7,
      "name": "Deco_Bone_Full",
      "rotation": 1
    },
    {
      "x": -1,
      "y": 9,
      "z": 7,
      "name": "Deco_Bone_Full",
      "rotation": 1
    },
    {
      "x": 0,
      "y": 2,
      "z": -9,
      "name": "Rock_Lime_Brick_Smooth_Half",
      "rotation": 6
    },
    {
      "x": 0,
      "y": 6,
      "z": -9,
      "name": "Rock_Lime_Brick_Smooth_Half",
      "rotation": 6
    },
    {
      "x": 0,
      "y": 7,
      "z": -9,
      "name": "Rock_Lime_Brick_Smooth_Half",
      "rotation": 6
    },
    {
      "x": 0,
      "y": 1,
      "z": -8,
      "name": "Deco_Bone_Ribs_Long",
      "rotation": 1
    },
    {
      "x": 0,
      "y": 2,
      "z": -8,
      "name": "Deco_Bone_Full",
      "rotation": 1
    },
    {
      "x": 0,
      "y": 3,
      "z": -8,
      "name": "Deco_Bone_Full",
      "rotation": 1
    },
    {
      "x": 0,
      "y": 6,
      "z": -8,
      "name": "Deco_Bone_Full",
      "rotation": 1
    },
    {
      "x": 0,
      "y": 7,
      "z": -8,
      "name": "Deco_Bone_Full",
      "rotation": 1
    },
    {
      "x": 0,
      "y": 8,
      "z": -8,
      "name": "Deco_Bone_Full",
      "rotation": 1
    },
    {
      "x": 0,
      "y": 4,
      "z": -7,
      "name": "Soil_Clay_Smooth_Black"
    },
    {
      "x": 0,
      "y": 5,
      "z": -7,
      "name": "Soil_Clay_Smooth_Black"
    },
    {
      "x": 0,
      "y": 9,
      "z": -7,
      "name": "Deco_Bone_Full",
      "rotation": 1
    },
    {
      "x": 0,
      "y": 4,
      "z": -6,
      "name": "Soil_Clay_Smooth_Black"
    },
    {
      "x": 0,
      "y": 10,
      "z": -6,
      "name": "Deco_Bone_Full",
      "rotation": 1
    },
    {
      "x": 0,
      "y": 4,
      "z": -5,
      "name": "Soil_Clay_Smooth_Black"
    },
    {
      "x": 0,
      "y": 10,
      "z": -5,
      "name": "Deco_Bone_Full",
      "rotation": 1
    },
    {
      "x": 0,
      "y": 4,
      "z": -4,
      "name": "Soil_Clay_Smooth_Black"
    },
    {
      "x": 0,
      "y": 11,
      "z": -4,
      "name": "Deco_Bone_Full",
      "rotation": 1
    },
    {
      "x": 0,
      "y": 4,
      "z": -3,
      "name": "Soil_Clay_Smooth_Black"
    },
    {
      "x": 0,
      "y": 11,
      "z": -3,
      "name": "Deco_Bone_Full",
      "rotation": 1
    },
    {
      "x": 0,
      "y": 4,
      "z": -2,
      "name": "Soil_Clay_Smooth_Black"
    },
    {
      "x": 0,
      "y": 11,
      "z": -2,
      "name": "Deco_Bone_Full",
      "rotation": 1
    },
    {
      "x": 0,
      "y": 1,
      "z": -1,
      "name": "Soil_Clay_Smooth_Black"
    },
    {
      "x": 0,
      "y": 2,
      "z": -1,
      "name": "Soil_Clay_Smooth_Black"
    },
    {
      "x": 0,
      "y": 3,
      "z": -1,
      "name": "Soil_Clay_Smooth_Black"
    },
    {
      "x": 0,
      "y": 11,
      "z": -1,
      "name": "Deco_Bone_Full",
      "rotation": 1
    },
    {
      "x": 0,
      "y": 11,
      "z": 0,
      "name": "Deco_Bone_Full",
      "rotation": 1
    },
    {
      "x": 0,
      "y": 11,
      "z": 1,
      "name": "Deco_Bone_Full",
      "rotation": 1
    },
    {
      "x": 0,
      "y": 11,
      "z": 2,
      "name": "Deco_Bone_Full",
      "rotation": 1
    },
    {
      "x": 0,
      "y": 4,
      "z": 3,
      "name": "Deco_Bone_Full",
      "rotation": 1
    },
    {
      "x": 0,
      "y": 11,
      "z": 3,
      "name": "Deco_Bone_Full",
      "rotation": 1
    },
    {
      "x": 0,
      "y": 4,
      "z": 4,
      "name": "Deco_Bone_Full",
      "rotation": 1
    },
    {
      "x": 0,
      "y": 11,
      "z": 4,
      "name": "Deco_Bone_Full",
      "rotation": 1
    },
    {
      "x": 0,
      "y": 4,
      "z": 5,
      "name": "Deco_Bone_Full",
      "rotation": 1
    },
    {
      "x": 0,
      "y": 5,
      "z": 5,
      "name": "Deco_Bone_Full",
      "rotation": 1
    },
    {
      "x": 0,
      "y": 11,
      "z": 5,
      "name": "Deco_Bone_Full",
      "rotation": 1
    },
    {
      "x": 0,
      "y": 5,
      "z": 6,
      "name": "Deco_Bone_Full",
      "rotation": 1
    },
    {
      "x": 0,
      "y": 6,
      "z": 6,
      "name": "Deco_Bone_Full",
      "rotation": 1
    },
    {
      "x": 0,
      "y": 10,
      "z": 6,
      "name": "Deco_Bone_Full",
      "rotation": 1
    },
    {
      "x": 0,
      "y": 6,
      "z": 7,
      "name": "Deco_Bone_Full",
      "rotation": 1
    },
    {
      "x": 0,
      "y": 7,
      "z": 7,
      "name": "Deco_Bone_Full",
      "rotation": 1
    },
    {
      "x": 0,
      "y": 8,
      "z": 7,
      "name": "Deco_Bone_Full",
      "rotation": 1
    },
    {
      "x": 0,
      "y": 9,
      "z": 7,
      "name": "Deco_Bone_Full",
      "rotation": 1
    },
    {
      "x": 1,
      "y": 2,
      "z": -9,
      "name": "Rock_Lime_Brick_Smooth_Half",
      "rotation": 6
    },
    {
      "x": 1,
      "y": 1,
      "z": -8,
      "name": "Deco_Bone_Ribs_Long",
      "rotation": 1
    },
    {
      "x": 1,
      "y": 2,
      "z": -8,
      "name": "Deco_Bone_Full",
      "rotation": 1
    },
    {
      "x": 1,
      "y": 3,
      "z": -8,
      "name": "Deco_Bone_Full",
      "rotation": 1
    },
    {
      "x": 1,
      "y": 4,
      "z": -8,
      "name": "Rock_Lime_Brick_Smooth_Half",
      "rotation": 7
    },
    {
      "x": 1,
      "y": 5,
      "z": -8,
      "name": "Deco_Bone_Full",
      "rotation": 1
    },
    {
      "x": 1,
      "y": 6,
      "z": -8,
      "name": "Deco_Bone_Full",
      "rotation": 1
    },
    {
      "x": 1,
      "y": 7,
      "z": -8,
      "name": "Deco_Bone_Full",
      "rotation": 1
    },
    {
      "x": 1,
      "y": 8,
      "z": -8,
      "name": "Deco_Bone_Full",
      "rotation": 1
    },
    {
      "x": 1,
      "y": 4,
      "z": -7,
      "name": "Soil_Clay_Smooth_Black"
    },
    {
      "x": 1,
      "y": 9,
      "z": -7,
      "name": "Deco_Bone_Full",
      "rotation": 1
    },
    {
      "x": 1,
      "y": 4,
      "z": -6,
      "name": "Soil_Clay_Smooth_Black"
    },
    {
      "x": 1,
      "y": 10,
      "z": -6,
      "name": "Deco_Bone_Full",
      "rotation": 1
    },
    {
      "x": 1,
      "y": 4,
      "z": -5,
      "name": "Soil_Clay_Smooth_Black"
    },
    {
      "x": 1,
      "y": 10,
      "z": -5,
      "name": "Deco_Bone_Full",
      "rotation": 1
    },
    {
      "x": 1,
      "y": 4,
      "z": -4,
      "name": "Soil_Clay_Smooth_Black"
    },
    {
      "x": 1,
      "y": 11,
      "z": -4,
      "name": "Deco_Bone_Full",
      "rotation": 1
    },
    {
      "x": 1,
      "y": 4,
      "z": -3,
      "name": "Soil_Clay_Smooth_Black"
    },
    {
      "x": 1,
      "y": 11,
      "z": -3,
      "name": "Deco_Bone_Full",
      "rotation": 1
    },
    {
      "x": 1,
      "y": 4,
      "z": -2,
      "name": "Soil_Clay_Smooth_Black"
    },
    {
      "x": 1,
      "y": 11,
      "z": -2,
      "name": "Deco_Bone_Full",
      "rotation": 1
    },
    {
      "x": 1,
      "y": 1,
      "z": -1,
      "name": "Soil_Clay_Smooth_Black"
    },
    {
      "x": 1,
      "y": 2,
      "z": -1,
      "name": "Soil_Clay_Smooth_Black"
    },
    {
      "x": 1,
      "y": 3,
      "z": -1,
      "name": "Soil_Clay_Smooth_Black"
    },
    {
      "x": 1,
      "y": 11,
      "z": -1,
      "name": "Deco_Bone_Full",
      "rotation": 1
    },
    {
      "x": 1,
      "y": 11,
      "z": 0,
      "name": "Deco_Bone_Full",
      "rotation": 1
    },
    {
      "x": 1,
      "y": 11,
      "z": 1,
      "name": "Deco_Bone_Full",
      "rotation": 1
    },
    {
      "x": 1,
      "y": 11,
      "z": 2,
      "name": "Deco_Bone_Full",
      "rotation": 1
    },
    {
      "x": 1,
      "y": 4,
      "z": 3,
      "name": "Deco_Bone_Full",
      "rotation": 1
    },
    {
      "x": 1,
      "y": 11,
      "z": 3,
      "name": "Deco_Bone_Full",
      "rotation": 1
    },
    {
      "x": 1,
      "y": 4,
      "z": 4,
      "name": "Deco_Bone_Full",
      "rotation": 1
    },
    {
      "x": 1,
      "y": 11,
      "z": 4,
      "name": "Deco_Bone_Full",
      "rotation": 1
    },
    {
      "x": 1,
      "y": 4,
      "z": 5,
      "name": "Deco_Bone_Full",
      "rotation": 1
    },
    {
      "x": 1,
      "y": 5,
      "z": 5,
      "name": "Deco_Bone_Full",
      "rotation": 1
    },
    {
      "x": 1,
      "y": 11,
      "z": 5,
      "name": "Deco_Bone_Full",
      "rotation": 1
    },
    {
      "x": 1,
      "y": 5,
      "z": 6,
      "name": "Deco_Bone_Full",
      "rotation": 1
    },
    {
      "x": 1,
      "y": 6,
      "z": 6,
      "name": "Deco_Bone_Full",
      "rotation": 1
    },
    {
      "x": 1,
      "y": 10,
      "z": 6,
      "name": "Deco_Bone_Full",
      "rotation": 1
    },
    {
      "x": 1,
      "y": 6,
      "z": 7,
      "name": "Deco_Bone_Full",
      "rotation": 1
    },
    {
      "x": 1,
      "y": 7,
      "z": 7,
      "name": "Deco_Bone_Full",
      "rotation": 1
    },
    {
      "x": 1,
      "y": 8,
      "z": 7,
      "name": "Deco_Bone_Full",
      "rotation": 1
    },
    {
      "x": 1,
      "y": 9,
      "z": 7,
      "name": "Deco_Bone_Full",
      "rotation": 1
    },
    {
      "x": 2,
      "y": 2,
      "z": -9,
      "name": "Rock_Lime_Brick_Smooth_Half",
      "rotation": 6
    },
    {
      "x": 2,
      "y": 1,
      "z": -8,
      "name": "Deco_Bone_Ribs_Long",
      "rotation": 1
    },
    {
      "x": 2,
      "y": 2,
      "z": -8,
      "name": "Deco_Bone_Full",
      "rotation": 1
    },
    {
      "x": 2,
      "y": 3,
      "z": -8,
      "name": "Deco_Bone_Full",
      "rotation": 1
    },
    {
      "x": 2,
      "y": 4,
      "z": -8,
      "name": "Deco_Bone_Full",
      "rotation": 1
    },
    {
      "x": 2,
      "y": 5,
      "z": -8,
      "name": "Deco_Bone_Full",
      "rotation": 1
    },
    {
      "x": 2,
      "y": 7,
      "z": -8,
      "name": "Rock_Lime_Stairs",
      "rotation": 11
    },
    {
      "x": 2,
      "y": 8,
      "z": -8,
      "name": "Deco_Bone_Full",
      "rotation": 1
    },
    {
      "x": 2,
      "y": 4,
      "z": -7,
      "name": "Soil_Clay_Smooth_Black"
    },
    {
      "x": 2,
      "y": 6,
      "z": -7,
      "name": "Build_Lightsource_Red",
      "rotation": 4
    },
    {
      "x": 2,
      "y": 7,
      "z": -7,
      "name": "Build_Lightsource_Red",
      "rotation": 4
    },
    {
      "x": 2,
      "y": 9,
      "z": -7,
      "name": "Deco_Bone_Full",
      "rotation": 1
    },
    {
      "x": 2,
      "y": 4,
      "z": -6,
      "name": "Soil_Clay_Smooth_Black"
    },
    {
      "x": 2,
      "y": 9,
      "z": -6,
      "name": "Deco_Bone_Full",
      "rotation": 1
    },
    {
      "x": 2,
      "y": 10,
      "z": -6,
      "name": "Rock_Lime_Brick_Smooth_Half",
      "rotation": 1
    },
    {
      "x": 2,
      "y": 4,
      "z": -5,
      "name": "Soil_Clay_Smooth_Black"
    },
    {
      "x": 2,
      "y": 10,
      "z": -5,
      "name": "Deco_Bone_Full",
      "rotation": 1
    },
    {
      "x": 2,
      "y": 4,
      "z": -4,
      "name": "Soil_Clay_Smooth_Black"
    },
    {
      "x": 2,
      "y": 10,
      "z": -4,
      "name": "Deco_Bone_Full",
      "rotation": 1
    },
    {
      "x": 2,
      "y": 11,
      "z": -4,
      "name": "Rock_Lime_Brick_Smooth_Half",
      "rotation": 1
    },
    {
      "x": 2,
      "y": 4,
      "z": -3,
      "name": "Soil_Clay_Smooth_Black"
    },
    {
      "x": 2,
      "y": 11,
      "z": -3,
      "name": "Deco_Bone_Full",
      "rotation": 1
    },
    {
      "x": 2,
      "y": 4,
      "z": -2,
      "name": "Soil_Clay_Smooth_Black"
    },
    {
      "x": 2,
      "y": 11,
      "z": -2,
      "name": "Deco_Bone_Full",
      "rotation": 1
    },
    {
      "x": 2,
      "y": 1,
      "z": -1,
      "name": "Soil_Clay_Smooth_Black"
    },
    {
      "x": 2,
      "y": 2,
      "z": -1,
      "name": "Soil_Clay_Smooth_Black"
    },
    {
      "x": 2,
      "y": 3,
      "z": -1,
      "name": "Soil_Clay_Smooth_Black"
    },
    {
      "x": 2,
      "y": 11,
      "z": -1,
      "name": "Deco_Bone_Full",
      "rotation": 1
    },
    {
      "x": 2,
      "y": 11,
      "z": 0,
      "name": "Deco_Bone_Full",
      "rotation": 1
    },
    {
      "x": 2,
      "y": 11,
      "z": 1,
      "name": "Deco_Bone_Full",
      "rotation": 1
    },
    {
      "x": 2,
      "y": 11,
      "z": 2,
      "name": "Deco_Bone_Full",
      "rotation": 1
    },
    {
      "x": 2,
      "y": 4,
      "z": 3,
      "name": "Deco_Bone_Full",
      "rotation": 1
    },
    {
      "x": 2,
      "y": 11,
      "z": 3,
      "name": "Deco_Bone_Full",
      "rotation": 1
    },
    {
      "x": 2,
      "y": 4,
      "z": 4,
      "name": "Deco_Bone_Full",
      "rotation": 1
    },
    {
      "x": 2,
      "y": 11,
      "z": 4,
      "name": "Deco_Bone_Full",
      "rotation": 1
    },
    {
      "x": 2,
      "y": 4,
      "z": 5,
      "name": "Deco_Bone_Full",
      "rotation": 1
    },
    {
      "x": 2,
      "y": 5,
      "z": 5,
      "name": "Deco_Bone_Full",
      "rotation": 1
    },
    {
      "x": 2,
      "y": 10,
      "z": 5,
      "name": "Deco_Bone_Full",
      "rotation": 1
    },
    {
      "x": 2,
      "y": 11,
      "z": 5,
      "name": "Rock_Lime_Brick_Smooth_Half",
      "rotation": 1
    },
    {
      "x": 2,
      "y": 5,
      "z": 6,
      "name": "Deco_Bone_Full",
      "rotation": 1
    },
    {
      "x": 2,
      "y": 6,
      "z": 6,
      "name": "Deco_Bone_Full",
      "rotation": 1
    },
    {
      "x": 2,
      "y": 10,
      "z": 6,
      "name": "Deco_Bone_Full",
      "rotation": 1
    },
    {
      "x": 2,
      "y": 7,
      "z": 7,
      "name": "Deco_Bone_Full",
      "rotation": 1
    },
    {
      "x": 2,
      "y": 8,
      "z": 7,
      "name": "Deco_Bone_Full",
      "rotation": 1
    },
    {
      "x": 2,
      "y": 9,
      "z": 7,
      "name": "Deco_Bone_Full",
      "rotation": 1
    },
    {
      "x": 3,
      "y": 1,
      "z": -8,
      "name": "Deco_Bone_Ribs_Long",
      "rotation": 1
    },
    {
      "x": 3,
      "y": 2,
      "z": -8,
      "name": "Rock_Lime_Stairs",
      "rotation": 2
    },
    {
      "x": 3,
      "y": 3,
      "z": -8,
      "name": "Rock_Lime_Brick_Smooth_Half",
      "rotation": 6
    },
    {
      "x": 3,
      "y": 4,
      "z": -8,
      "name": "Deco_Bone_Full",
      "rotation": 1
    },
    {
      "x": 3,
      "y": 5,
      "z": -8,
      "name": "Deco_Bone_Full",
      "rotation": 1
    },
    {
      "x": 3,
      "y": 7,
      "z": -8,
      "name": "Rock_Lime_Stairs",
      "rotation": 9
    },
    {
      "x": 3,
      "y": 8,
      "z": -8,
      "name": "Deco_Bone_Full",
      "rotation": 1
    },
    {
      "x": 3,
      "y": 4,
      "z": -7,
      "name": "Soil_Clay_Smooth_Black"
    },
    {
      "x": 3,
      "y": 6,
      "z": -7,
      "name": "Build_Lightsource_Red",
      "rotation": 4
    },
    {
      "x": 3,
      "y": 7,
      "z": -7,
      "name": "Build_Lightsource_Red",
      "rotation": 4
    },
    {
      "x": 3,
      "y": 8,
      "z": -7,
      "name": "Deco_Bone_Full",
      "rotation": 1
    },
    {
      "x": 3,
      "y": 4,
      "z": -6,
      "name": "Soil_Clay_Smooth_Black"
    },
    {
      "x": 3,
      "y": 9,
      "z": -6,
      "name": "Deco_Bone_Full",
      "rotation": 1
    },
    {
      "x": 3,
      "y": 4,
      "z": -5,
      "name": "Soil_Clay_Smooth_Black"
    },
    {
      "x": 3,
      "y": 9,
      "z": -5,
      "name": "Deco_Bone_Full",
      "rotation": 1
    },
    {
      "x": 3,
      "y": 10,
      "z": -5,
      "name": "Rock_Lime_Brick_Smooth_Half",
      "rotation": 1
    },
    {
      "x": 3,
      "y": 4,
      "z": -4,
      "name": "Soil_Clay_Smooth_Black"
    },
    {
      "x": 3,
      "y": 10,
      "z": -4,
      "name": "Deco_Bone_Full",
      "rotation": 1
    },
    {
      "x": 3,
      "y": 4,
      "z": -3,
      "name": "Soil_Clay_Smooth_Black"
    },
    {
      "x": 3,
      "y": 10,
      "z": -3,
      "name": "Deco_Bone_Full",
      "rotation": 1
    },
    {
      "x": 3,
      "y": 4,
      "z": -2,
      "name": "Soil_Clay_Smooth_Black"
    },
    {
      "x": 3,
      "y": 10,
      "z": -2,
      "name": "Deco_Bone_Full",
      "rotation": 1
    },
    {
      "x": 3,
      "y": 1,
      "z": -1,
      "name": "Soil_Clay_Smooth_Black"
    },
    {
      "x": 3,
      "y": 2,
      "z": -1,
      "name": "Soil_Clay_Smooth_Black"
    },
    {
      "x": 3,
      "y": 3,
      "z": -1,
      "name": "Soil_Clay_Smooth_Black"
    },
    {
      "x": 3,
      "y": 10,
      "z": -1,
      "name": "Deco_Bone_Full",
      "rotation": 1
    },
    {
      "x": 3,
      "y": 11,
      "z": -1,
      "name": "Rock_Lime_Brick_Smooth_Half",
      "rotation": 1
    },
    {
      "x": 3,
      "y": 10,
      "z": 0,
      "name": "Deco_Bone_Full",
      "rotation": 1
    },
    {
      "x": 3,
      "y": 11,
      "z": 0,
      "name": "Rock_Lime_Brick_Smooth_Half",
      "rotation": 1
    },
    {
      "x": 3,
      "y": 10,
      "z": 1,
      "name": "Deco_Bone_Full",
      "rotation": 1
    },
    {
      "x": 3,
      "y": 11,
      "z": 1,
      "name": "Rock_Lime_Brick_Smooth_Half",
      "rotation": 1
    },
    {
      "x": 3,
      "y": 10,
      "z": 2,
      "name": "Deco_Bone_Full",
      "rotation": 1
    },
    {
      "x": 3,
      "y": 11,
      "z": 2,
      "name": "Rock_Lime_Brick_Smooth_Half",
      "rotation": 1
    },
    {
      "x": 3,
      "y": 4,
      "z": 3,
      "name": "Deco_Bone_Full",
      "rotation": 1
    },
    {
      "x": 3,
      "y": 10,
      "z": 3,
      "name": "Deco_Bone_Full",
      "rotation": 1
    },
    {
      "x": 3,
      "y": 4,
      "z": 4,
      "name": "Deco_Bone_Full",
      "rotation": 1
    },
    {
      "x": 3,
      "y": 10,
      "z": 4,
      "name": "Deco_Bone_Full",
      "rotation": 1
    },
    {
      "x": 3,
      "y": 4,
      "z": 5,
      "name": "Deco_Bone_Full",
      "rotation": 1
    },
    {
      "x": 3,
      "y": 5,
      "z": 5,
      "name": "Deco_Bone_Full",
      "rotation": 1
    },
    {
      "x": 3,
      "y": 6,
      "z": 5,
      "name": "Deco_Bone_Full",
      "rotation": 1
    },
    {
      "x": 3,
      "y": 10,
      "z": 5,
      "name": "Deco_Bone_Full",
      "rotation": 1
    },
    {
      "x": 3,
      "y": 6,
      "z": 6,
      "name": "Deco_Bone_Full",
      "rotation": 1
    },
    {
      "x": 3,
      "y": 7,
      "z": 6,
      "name": "Deco_Bone_Full",
      "rotation": 1
    },
    {
      "x": 3,
      "y": 8,
      "z": 6,
      "name": "Deco_Bone_Full",
      "rotation": 1
    },
    {
      "x": 3,
      "y": 9,
      "z": 6,
      "name": "Deco_Bone_Full",
      "rotation": 1
    },
    {
      "x": 3,
      "y": 7,
      "z": 7,
      "name": "Deco_Bone_Full",
      "rotation": 1
    },
    {
      "x": 3,
      "y": 8,
      "z": 7,
      "name": "Deco_Bone_Full",
      "rotation": 1
    },
    {
      "x": 4,
      "y": 5,
      "z": -8,
      "name": "Rock_Lime_Brick_Smooth_Half",
      "rotation": 5
    },
    {
      "x": 4,
      "y": 6,
      "z": -8,
      "name": "Rock_Lime_Brick_Smooth_Half",
      "rotation": 5
    },
    {
      "x": 4,
      "y": 1,
      "z": -7,
      "name": "Deco_Bone_Ribs_Long",
      "rotation": 1
    },
    {
      "x": 4,
      "y": 2,
      "z": -7,
      "name": "Deco_Bone_Full",
      "rotation": 1
    },
    {
      "x": 4,
      "y": 3,
      "z": -7,
      "name": "Deco_Bone_Full",
      "rotation": 1
    },
    {
      "x": 4,
      "y": 4,
      "z": -7,
      "name": "Deco_Bone_Full",
      "rotation": 1
    },
    {
      "x": 4,
      "y": 5,
      "z": -7,
      "name": "Deco_Bone_Full",
      "rotation": 1
    },
    {
      "x": 4,
      "y": 6,
      "z": -7,
      "name": "Deco_Bone_Full",
      "rotation": 1
    },
    {
      "x": 4,
      "y": 7,
      "z": -7,
      "name": "Deco_Bone_Full",
      "rotation": 1
    },
    {
      "x": 4,
      "y": 8,
      "z": -7,
      "name": "Deco_Bone_Full",
      "rotation": 1
    },
    {
      "x": 4,
      "y": 1,
      "z": -6,
      "name": "Deco_Bone_Ribs_Long",
      "rotation": 1
    },
    {
      "x": 4,
      "y": 2,
      "z": -6,
      "name": "Deco_Bone_Full",
      "rotation": 1
    },
    {
      "x": 4,
      "y": 3,
      "z": -6,
      "name": "Deco_Bone_Full",
      "rotation": 1
    },
    {
      "x": 4,
      "y": 4,
      "z": -6,
      "name": "Deco_Bone_Full",
      "rotation": 1
    },
    {
      "x": 4,
      "y": 5,
      "z": -6,
      "name": "Deco_Bone_Full",
      "rotation": 1
    },
    {
      "x": 4,
      "y": 6,
      "z": -6,
      "name": "Deco_Bone_Full",
      "rotation": 1
    },
    {
      "x": 4,
      "y": 7,
      "z": -6,
      "name": "Deco_Bone_Full",
      "rotation": 1
    },
    {
      "x": 4,
      "y": 8,
      "z": -6,
      "name": "Deco_Bone_Full",
      "rotation": 1
    },
    {
      "x": 4,
      "y": 4,
      "z": -5,
      "name": "Soil_Clay_Smooth_Black"
    },
    {
      "x": 4,
      "y": 8,
      "z": -5,
      "name": "Deco_Bone_Full",
      "rotation": 1
    },
    {
      "x": 4,
      "y": 9,
      "z": -5,
      "name": "Deco_Bone_Full",
      "rotation": 1
    },
    {
      "x": 4,
      "y": 4,
      "z": -4,
      "name": "Soil_Clay_Smooth_Black"
    },
    {
      "x": 4,
      "y": 9,
      "z": -4,
      "name": "Deco_Bone_Full",
      "rotation": 1
    },
    {
      "x": 4,
      "y": 4,
      "z": -3,
      "name": "Soil_Clay_Smooth_Black"
    },
    {
      "x": 4,
      "y": 9,
      "z": -3,
      "name": "Deco_Bone_Full",
      "rotation": 1
    },
    {
      "x": 4,
      "y": 4,
      "z": -2,
      "name": "Soil_Clay_Smooth_Black"
    },
    {
      "x": 4,
      "y": 9,
      "z": -2,
      "name": "Deco_Bone_Full",
      "rotation": 1
    },
    {
      "x": 4,
      "y": 10,
      "z": -2,
      "name": "Rock_Lime_Brick_Smooth_Half",
      "rotation": 1
    },
    {
      "x": 4,
      "y": 9,
      "z": -1,
      "name": "Deco_Bone_Full",
      "rotation": 1
    },
    {
      "x": 4,
      "y": 10,
      "z": -1,
      "name": "Deco_Bone_Full",
      "rotation": 1
    },
    {
      "x": 4,
      "y": 9,
      "z": 0,
      "name": "Deco_Bone_Full",
      "rotation": 1
    },
    {
      "x": 4,
      "y": 10,
      "z": 0,
      "name": "Deco_Bone_Full",
      "rotation": 1
    },
    {
      "x": 4,
      "y": 9,
      "z": 1,
      "name": "Deco_Bone_Full",
      "rotation": 1
    },
    {
      "x": 4,
      "y": 10,
      "z": 1,
      "name": "Deco_Bone_Full",
      "rotation": 1
    },
    {
      "x": 4,
      "y": 9,
      "z": 2,
      "name": "Deco_Bone_Full",
      "rotation": 1
    },
    {
      "x": 4,
      "y": 10,
      "z": 2,
      "name": "Deco_Bone_Full",
      "rotation": 1
    },
    {
      "x": 4,
      "y": 4,
      "z": 3,
      "name": "Deco_Bone_Full",
      "rotation": 1
    },
    {
      "x": 4,
      "y": 9,
      "z": 3,
      "name": "Deco_Bone_Full",
      "rotation": 1
    },
    {
      "x": 4,
      "y": 10,
      "z": 3,
      "name": "Rock_Lime_Brick_Smooth_Half",
      "rotation": 1
    },
    {
      "x": 4,
      "y": 4,
      "z": 4,
      "name": "Deco_Bone_Full",
      "rotation": 1
    },
    {
      "x": 4,
      "y": 5,
      "z": 4,
      "name": "Deco_Bone_Full",
      "rotation": 1
    },
    {
      "x": 4,
      "y": 6,
      "z": 4,
      "name": "Deco_Bone_Full",
      "rotation": 1
    },
    {
      "x": 4,
      "y": 7,
      "z": 4,
      "name": "Deco_Bone_Full",
      "rotation": 1
    },
    {
      "x": 4,
      "y": 8,
      "z": 4,
      "name": "Deco_Bone_Full",
      "rotation": 1
    },
    {
      "x": 4,
      "y": 9,
      "z": 4,
      "name": "Deco_Bone_Full",
      "rotation": 1
    },
    {
      "x": 4,
      "y": 5,
      "z": 5,
      "name": "Deco_Bone_Full",
      "rotation": 1
    },
    {
      "x": 4,
      "y": 6,
      "z": 5,
      "name": "Deco_Bone_Full",
      "rotation": 1
    },
    {
      "x": 4,
      "y": 7,
      "z": 5,
      "name": "Deco_Bone_Full",
      "rotation": 1
    },
    {
      "x": 4,
      "y": 8,
      "z": 5,
      "name": "Deco_Bone_Full",
      "rotation": 1
    },
    {
      "x": 4,
      "y": 9,
      "z": 5,
      "name": "Deco_Bone_Full",
      "rotation": 1
    },
    {
      "x": 4,
      "y": 7,
      "z": 6,
      "name": "Deco_Bone_Full",
      "rotation": 1
    },
    {
      "x": 4,
      "y": 8,
      "z": 6,
      "name": "Deco_Bone_Full",
      "rotation": 1
    },
    {
      "x": 5,
      "y": 2,
      "z": -6,
      "name": "Rock_Lime_Brick_Smooth_Half",
      "rotation": 5
    },
    {
      "x": 5,
      "y": 3,
      "z": -6,
      "name": "Rock_Lime_Brick_Smooth_Half",
      "rotation": 5
    },
    {
      "x": 5,
      "y": 4,
      "z": -6,
      "name": "Rock_Lime_Brick_Smooth_Half",
      "rotation": 5
    },
    {
      "x": 5,
      "y": 5,
      "z": -6,
      "name": "Rock_Lime_Brick_Smooth_Half",
      "rotation": 5
    },
    {
      "x": 5,
      "y": 6,
      "z": -6,
      "name": "Rock_Lime_Brick_Smooth_Half",
      "rotation": 5
    },
    {
      "x": 5,
      "y": 1,
      "z": -5,
      "name": "Deco_Bone_Ribs_Long",
      "rotation": 1
    },
    {
      "x": 5,
      "y": 2,
      "z": -5,
      "name": "Deco_Bone_Full",
      "rotation": 1
    },
    {
      "x": 5,
      "y": 3,
      "z": -5,
      "name": "Deco_Bone_Full",
      "rotation": 1
    },
    {
      "x": 5,
      "y": 4,
      "z": -5,
      "name": "Deco_Bone_Full",
      "rotation": 1
    },
    {
      "x": 5,
      "y": 5,
      "z": -5,
      "name": "Deco_Bone_Full",
      "rotation": 1
    },
    {
      "x": 5,
      "y": 6,
      "z": -5,
      "name": "Deco_Bone_Full",
      "rotation": 1
    },
    {
      "x": 5,
      "y": 7,
      "z": -5,
      "name": "Deco_Bone_Full",
      "rotation": 1
    },
    {
      "x": 5,
      "y": 2,
      "z": -4,
      "name": "Deco_Bone_Full",
      "rotation": 1
    },
    {
      "x": 5,
      "y": 3,
      "z": -4,
      "name": "Deco_Bone_Full",
      "rotation": 1
    },
    {
      "x": 5,
      "y": 4,
      "z": -4,
      "name": "Deco_Bone_Full",
      "rotation": 1
    },
    {
      "x": 5,
      "y": 5,
      "z": -4,
      "name": "Deco_Bone_Full",
      "rotation": 1
    },
    {
      "x": 5,
      "y": 6,
      "z": -4,
      "name": "Deco_Bone_Full",
      "rotation": 1
    },
    {
      "x": 5,
      "y": 7,
      "z": -4,
      "name": "Deco_Bone_Full",
      "rotation": 1
    },
    {
      "x": 5,
      "y": 8,
      "z": -4,
      "name": "Deco_Bone_Full",
      "rotation": 1
    },
    {
      "x": 5,
      "y": 1,
      "z": -3,
      "name": "Deco_Bone_Full",
      "rotation": 1
    },
    {
      "x": 5,
      "y": 2,
      "z": -3,
      "name": "Deco_Bone_Full",
      "rotation": 1
    },
    {
      "x": 5,
      "y": 3,
      "z": -3,
      "name": "Deco_Bone_Full",
      "rotation": 1
    },
    {
      "x": 5,
      "y": 4,
      "z": -3,
      "name": "Deco_Bone_Full",
      "rotation": 1
    },
    {
      "x": 5,
      "y": 5,
      "z": -3,
      "name": "Deco_Bone_Full",
      "rotation": 1
    },
    {
      "x": 5,
      "y": 6,
      "z": -3,
      "name": "Deco_Bone_Full",
      "rotation": 1
    },
    {
      "x": 5,
      "y": 7,
      "z": -3,
      "name": "Deco_Bone_Full",
      "rotation": 1
    },
    {
      "x": 5,
      "y": 8,
      "z": -3,
      "name": "Deco_Bone_Full",
      "rotation": 1
    },
    {
      "x": 5,
      "y": 1,
      "z": -2,
      "name": "Deco_Bone_Full",
      "rotation": 1
    },
    {
      "x": 5,
      "y": 2,
      "z": -2,
      "name": "Deco_Bone_Full",
      "rotation": 1
    },
    {
      "x": 5,
      "y": 3,
      "z": -2,
      "name": "Deco_Bone_Full",
      "rotation": 1
    },
    {
      "x": 5,
      "y": 4,
      "z": -2,
      "name": "Deco_Bone_Full",
      "rotation": 1
    },
    {
      "x": 5,
      "y": 5,
      "z": -2,
      "name": "Deco_Bone_Full",
      "rotation": 1
    },
    {
      "x": 5,
      "y": 6,
      "z": -2,
      "name": "Deco_Bone_Full",
      "rotation": 1
    },
    {
      "x": 5,
      "y": 7,
      "z": -2,
      "name": "Deco_Bone_Full",
      "rotation": 1
    },
    {
      "x": 5,
      "y": 8,
      "z": -2,
      "name": "Deco_Bone_Full",
      "rotation": 1
    },
    {
      "x": 5,
      "y": 9,
      "z": -2,
      "name": "Deco_Bone_Full",
      "rotation": 1
    },
    {
      "x": 5,
      "y": 5,
      "z": -1,
      "name": "Deco_Bone_Full",
      "rotation": 1
    },
    {
      "x": 5,
      "y": 6,
      "z": -1,
      "name": "Deco_Bone_Full",
      "rotation": 1
    },
    {
      "x": 5,
      "y": 7,
      "z": -1,
      "name": "Deco_Bone_Full",
      "rotation": 1
    },
    {
      "x": 5,
      "y": 8,
      "z": -1,
      "name": "Deco_Bone_Full",
      "rotation": 1
    },
    {
      "x": 5,
      "y": 9,
      "z": -1,
      "name": "Deco_Bone_Full",
      "rotation": 1
    },
    {
      "x": 5,
      "y": 5,
      "z": 0,
      "name": "Deco_Bone_Full",
      "rotation": 1
    },
    {
      "x": 5,
      "y": 6,
      "z": 0,
      "name": "Deco_Bone_Full",
      "rotation": 1
    },
    {
      "x": 5,
      "y": 7,
      "z": 0,
      "name": "Deco_Bone_Full",
      "rotation": 1
    },
    {
      "x": 5,
      "y": 8,
      "z": 0,
      "name": "Deco_Bone_Full",
      "rotation": 1
    },
    {
      "x": 5,
      "y": 9,
      "z": 0,
      "name": "Deco_Bone_Full",
      "rotation": 1
    },
    {
      "x": 5,
      "y": 5,
      "z": 1,
      "name": "Deco_Bone_Full",
      "rotation": 1
    },
    {
      "x": 5,
      "y": 6,
      "z": 1,
      "name": "Deco_Bone_Full",
      "rotation": 1
    },
    {
      "x": 5,
      "y": 7,
      "z": 1,
      "name": "Deco_Bone_Full",
      "rotation": 1
    },
    {
      "x": 5,
      "y": 8,
      "z": 1,
      "name": "Deco_Bone_Full",
      "rotation": 1
    },
    {
      "x": 5,
      "y": 9,
      "z": 1,
      "name": "Deco_Bone_Full",
      "rotation": 1
    },
    {
      "x": 5,
      "y": 5,
      "z": 2,
      "name": "Deco_Bone_Full",
      "rotation": 1
    },
    {
      "x": 5,
      "y": 6,
      "z": 2,
      "name": "Deco_Bone_Full",
      "rotation": 1
    },
    {
      "x": 5,
      "y": 7,
      "z": 2,
      "name": "Deco_Bone_Full",
      "rotation": 1
    },
    {
      "x": 5,
      "y": 8,
      "z": 2,
      "name": "Deco_Bone_Full",
      "rotation": 1
    },
    {
      "x": 5,
      "y": 9,
      "z": 2,
      "name": "Deco_Bone_Full",
      "rotation": 1
    },
    {
      "x": 5,
      "y": 5,
      "z": 3,
      "name": "Deco_Bone_Full",
      "rotation": 1
    },
    {
      "x": 5,
      "y": 6,
      "z": 3,
      "name": "Deco_Bone_Full",
      "rotation": 1
    },
    {
      "x": 5,
      "y": 7,
      "z": 3,
      "name": "Deco_Bone_Full",
      "rotation": 1
    },
    {
      "x": 5,
      "y": 8,
      "z": 3,
      "name": "Deco_Bone_Full",
      "rotation": 1
    },
    {
      "x": 5,
      "y": 9,
      "z": 3,
      "name": "Deco_Bone_Full",
      "rotation": 1
    },
    {
      "x": 5,
      "y": 5,
      "z": 4,
      "name": "Deco_Bone_Full",
      "rotation": 1
    },
    {
      "x": 5,
      "y": 6,
      "z": 4,
      "name": "Deco_Bone_Full",
      "rotation": 1
    },
    {
      "x": 5,
      "y": 7,
      "z": 4,
      "name": "Deco_Bone_Full",
      "rotation": 1
    },
    {
      "x": 5,
      "y": 8,
      "z": 4,
      "name": "Deco_Bone_Full",
      "rotation": 1
    },
    {
      "x": 6,
      "y": 6,
      "z": -2,
      "name": "Rock_Lime_Brick_Smooth_Half",
      "rotation": 5
    },
    {
      "x": 6,
      "y": 7,
      "z": -2,
      "name": "Rock_Lime_Brick_Smooth_Half",
      "rotation": 5
    },
    {
      "x": 6,
      "y": 6,
      "z": -1,
      "name": "Rock_Lime_Brick_Smooth_Half",
      "rotation": 5
    },
    {
      "x": 6,
      "y": 7,
      "z": -1,
      "name": "Rock_Lime_Brick_Smooth_Half",
      "rotation": 5
    },
    {
      "x": 6,
      "y": 8,
      "z": -1,
      "name": "Rock_Lime_Brick_Smooth_Half",
      "rotation": 5
    },
    {
      "x": 6,
      "y": 6,
      "z": 0,
      "name": "Rock_Lime_Brick_Smooth_Half",
      "rotation": 5
    },
    {
      "x": 6,
      "y": 7,
      "z": 0,
      "name": "Rock_Lime_Brick_Smooth_Half",
      "rotation": 5
    },
    {
      "x": 6,
      "y": 8,
      "z": 0,
      "name": "Rock_Lime_Brick_Smooth_Half",
      "rotation": 5
    },
    {
      "x": 6,
      "y": 6,
      "z": 1,
      "name": "Rock_Lime_Brick_Smooth_Half",
      "rotation": 5
    },
    {
      "x": 6,
      "y": 7,
      "z": 1,
      "name": "Rock_Lime_Brick_Smooth_Half",
      "rotation": 5
    },
    {
      "x": 6,
      "y": 8,
      "z": 1,
      "name": "Rock_Lime_Brick_Smooth_Half",
      "rotation": 5
    },
    {
      "x": 6,
      "y": 6,
      "z": 2,
      "name": "Rock_Lime_Brick_Smooth_Half",
      "rotation": 5
    },
    {
      "x": 6,
      "y": 7,
      "z": 2,
      "name": "Rock_Lime_Brick_Smooth_Half",
      "rotation": 5
    },
    {
      "x": 6,
      "y": 8,
      "z": 2,
      "name": "Rock_Lime_Brick_Smooth_Half",
      "rotation": 5
    },
    {
      "x": 6,
      "y": 6,
      "z": 3,
      "name": "Rock_Lime_Brick_Smooth_Half",
      "rotation": 5
    },
    {
      "x": 6,
      "y": 7,
      "z": 3,
      "name": "Rock_Lime_Brick_Smooth_Half",
      "rotation": 5
    }
  ],
  "fluids": [
    {
      "x": -6,
      "y": 6,
      "z": -2,
      "name": "Empty",
      "level": 0
    },
    {
      "x": -6,
      "y": 7,
      "z": -2,
      "name": "Empty",
      "level": 0
    },
    {
      "x": -6,
      "y": 6,
      "z": -1,
      "name": "Empty",
      "level": 0
    },
    {
      "x": -6,
      "y": 7,
      "z": -1,
      "name": "Empty",
      "level": 0
    },
    {
      "x": -6,
      "y": 8,
      "z": -1,
      "name": "Empty",
      "level": 0
    },
    {
      "x": -6,
      "y": 6,
      "z": 0,
      "name": "Empty",
      "level": 0
    },
    {
      "x": -6,
      "y": 7,
      "z": 0,
      "name": "Empty",
      "level": 0
    },
    {
      "x": -6,
      "y": 8,
      "z": 0,
      "name": "Empty",
      "level": 0
    },
    {
      "x": -6,
      "y": 6,
      "z": 1,
      "name": "Empty",
      "level": 0
    },
    {
      "x": -6,
      "y": 7,
      "z": 1,
      "name": "Empty",
      "level": 0
    },
    {
      "x": -6,
      "y": 8,
      "z": 1,
      "name": "Empty",
      "level": 0
    },
    {
      "x": -6,
      "y": 6,
      "z": 2,
      "name": "Empty",
      "level": 0
    },
    {
      "x": -6,
      "y": 7,
      "z": 2,
      "name": "Empty",
      "level": 0
    },
    {
      "x": -6,
      "y": 8,
      "z": 2,
      "name": "Empty",
      "level": 0
    },
    {
      "x": -6,
      "y": 6,
      "z": 3,
      "name": "Empty",
      "level": 0
    },
    {
      "x": -6,
      "y": 7,
      "z": 3,
      "name": "Empty",
      "level": 0
    },
    {
      "x": -5,
      "y": 2,
      "z": -6,
      "name": "Empty",
      "level": 0
    },
    {
      "x": -5,
      "y": 3,
      "z": -6,
      "name": "Empty",
      "level": 0
    },
    {
      "x": -5,
      "y": 4,
      "z": -6,
      "name": "Empty",
      "level": 0
    },
    {
      "x": -5,
      "y": 5,
      "z": -6,
      "name": "Empty",
      "level": 0
    },
    {
      "x": -5,
      "y": 6,
      "z": -6,
      "name": "Empty",
      "level": 0
    },
    {
      "x": -5,
      "y": 1,
      "z": -5,
      "name": "Empty",
      "level": 0
    },
    {
      "x": -5,
      "y": 2,
      "z": -5,
      "name": "Empty",
      "level": 0
    },
    {
      "x": -5,
      "y": 3,
      "z": -5,
      "name": "Empty",
      "level": 0
    },
    {
      "x": -5,
      "y": 4,
      "z": -5,
      "name": "Empty",
      "level": 0
    },
    {
      "x": -5,
      "y": 5,
      "z": -5,
      "name": "Empty",
      "level": 0
    },
    {
      "x": -5,
      "y": 6,
      "z": -5,
      "name": "Empty",
      "level": 0
    },
    {
      "x": -5,
      "y": 7,
      "z": -5,
      "name": "Empty",
      "level": 0
    },
    {
      "x": -5,
      "y": 2,
      "z": -4,
      "name": "Empty",
      "level": 0
    },
    {
      "x": -5,
      "y": 3,
      "z": -4,
      "name": "Empty",
      "level": 0
    },
    {
      "x": -5,
      "y": 4,
      "z": -4,
      "name": "Empty",
      "level": 0
    },
    {
      "x": -5,
      "y": 5,
      "z": -4,
      "name": "Empty",
      "level": 0
    },
    {
      "x": -5,
      "y": 6,
      "z": -4,
      "name": "Empty",
      "level": 0
    },
    {
      "x": -5,
      "y": 7,
      "z": -4,
      "name": "Empty",
      "level": 0
    },
    {
      "x": -5,
      "y": 8,
      "z": -4,
      "name": "Empty",
      "level": 0
    },
    {
      "x": -5,
      "y": 1,
      "z": -3,
      "name": "Empty",
      "level": 0
    },
    {
      "x": -5,
      "y": 2,
      "z": -3,
      "name": "Empty",
      "level": 0
    },
    {
      "x": -5,
      "y": 3,
      "z": -3,
      "name": "Empty",
      "level": 0
    },
    {
      "x": -5,
      "y": 4,
      "z": -3,
      "name": "Empty",
      "level": 0
    },
    {
      "x": -5,
      "y": 5,
      "z": -3,
      "name": "Empty",
      "level": 0
    },
    {
      "x": -5,
      "y": 6,
      "z": -3,
      "name": "Empty",
      "level": 0
    },
    {
      "x": -5,
      "y": 7,
      "z": -3,
      "name": "Empty",
      "level": 0
    },
    {
      "x": -5,
      "y": 8,
      "z": -3,
      "name": "Empty",
      "level": 0
    },
    {
      "x": -5,
      "y": 1,
      "z": -2,
      "name": "Empty",
      "level": 0
    },
    {
      "x": -5,
      "y": 2,
      "z": -2,
      "name": "Empty",
      "level": 0
    },
    {
      "x": -5,
      "y": 3,
      "z": -2,
      "name": "Empty",
      "level": 0
    },
    {
      "x": -5,
      "y": 4,
      "z": -2,
      "name": "Empty",
      "level": 0
    },
    {
      "x": -5,
      "y": 5,
      "z": -2,
      "name": "Empty",
      "level": 0
    },
    {
      "x": -5,
      "y": 6,
      "z": -2,
      "name": "Empty",
      "level": 0
    },
    {
      "x": -5,
      "y": 7,
      "z": -2,
      "name": "Empty",
      "level": 0
    },
    {
      "x": -5,
      "y": 8,
      "z": -2,
      "name": "Empty",
      "level": 0
    },
    {
      "x": -5,
      "y": 9,
      "z": -2,
      "name": "Empty",
      "level": 0
    },
    {
      "x": -5,
      "y": 5,
      "z": -1,
      "name": "Empty",
      "level": 0
    },
    {
      "x": -5,
      "y": 6,
      "z": -1,
      "name": "Empty",
      "level": 0
    },
    {
      "x": -5,
      "y": 7,
      "z": -1,
      "name": "Empty",
      "level": 0
    },
    {
      "x": -5,
      "y": 8,
      "z": -1,
      "name": "Empty",
      "level": 0
    },
    {
      "x": -5,
      "y": 9,
      "z": -1,
      "name": "Empty",
      "level": 0
    },
    {
      "x": -5,
      "y": 5,
      "z": 0,
      "name": "Empty",
      "level": 0
    },
    {
      "x": -5,
      "y": 6,
      "z": 0,
      "name": "Empty",
      "level": 0
    },
    {
      "x": -5,
      "y": 7,
      "z": 0,
      "name": "Empty",
      "level": 0
    },
    {
      "x": -5,
      "y": 8,
      "z": 0,
      "name": "Empty",
      "level": 0
    },
    {
      "x": -5,
      "y": 9,
      "z": 0,
      "name": "Empty",
      "level": 0
    },
    {
      "x": -5,
      "y": 5,
      "z": 1,
      "name": "Empty",
      "level": 0
    },
    {
      "x": -5,
      "y": 6,
      "z": 1,
      "name": "Empty",
      "level": 0
    },
    {
      "x": -5,
      "y": 7,
      "z": 1,
      "name": "Empty",
      "level": 0
    },
    {
      "x": -5,
      "y": 8,
      "z": 1,
      "name": "Empty",
      "level": 0
    },
    {
      "x": -5,
      "y": 9,
      "z": 1,
      "name": "Empty",
      "level": 0
    },
    {
      "x": -5,
      "y": 5,
      "z": 2,
      "name": "Empty",
      "level": 0
    },
    {
      "x": -5,
      "y": 6,
      "z": 2,
      "name": "Empty",
      "level": 0
    },
    {
      "x": -5,
      "y": 7,
      "z": 2,
      "name": "Empty",
      "level": 0
    },
    {
      "x": -5,
      "y": 8,
      "z": 2,
      "name": "Empty",
      "level": 0
    },
    {
      "x": -5,
      "y": 9,
      "z": 2,
      "name": "Empty",
      "level": 0
    },
    {
      "x": -5,
      "y": 5,
      "z": 3,
      "name": "Empty",
      "level": 0
    },
    {
      "x": -5,
      "y": 6,
      "z": 3,
      "name": "Empty",
      "level": 0
    },
    {
      "x": -5,
      "y": 7,
      "z": 3,
      "name": "Empty",
      "level": 0
    },
    {
      "x": -5,
      "y": 8,
      "z": 3,
      "name": "Empty",
      "level": 0
    },
    {
      "x": -5,
      "y": 9,
      "z": 3,
      "name": "Empty",
      "level": 0
    },
    {
      "x": -5,
      "y": 5,
      "z": 4,
      "name": "Empty",
      "level": 0
    },
    {
      "x": -5,
      "y": 6,
      "z": 4,
      "name": "Empty",
      "level": 0
    },
    {
      "x": -5,
      "y": 7,
      "z": 4,
      "name": "Empty",
      "level": 0
    },
    {
      "x": -5,
      "y": 8,
      "z": 4,
      "name": "Empty",
      "level": 0
    },
    {
      "x": -4,
      "y": 5,
      "z": -8,
      "name": "Empty",
      "level": 0
    },
    {
      "x": -4,
      "y": 6,
      "z": -8,
      "name": "Empty",
      "level": 0
    },
    {
      "x": -4,
      "y": 1,
      "z": -7,
      "name": "Empty",
      "level": 0
    },
    {
      "x": -4,
      "y": 2,
      "z": -7,
      "name": "Empty",
      "level": 0
    },
    {
      "x": -4,
      "y": 3,
      "z": -7,
      "name": "Empty",
      "level": 0
    },
    {
      "x": -4,
      "y": 4,
      "z": -7,
      "name": "Empty",
      "level": 0
    },
    {
      "x": -4,
      "y": 5,
      "z": -7,
      "name": "Empty",
      "level": 0
    },
    {
      "x": -4,
      "y": 6,
      "z": -7,
      "name": "Empty",
      "level": 0
    },
    {
      "x": -4,
      "y": 7,
      "z": -7,
      "name": "Empty",
      "level": 0
    },
    {
      "x": -4,
      "y": 8,
      "z": -7,
      "name": "Empty",
      "level": 0
    },
    {
      "x": -4,
      "y": 1,
      "z": -6,
      "name": "Empty",
      "level": 0
    },
    {
      "x": -4,
      "y": 2,
      "z": -6,
      "name": "Empty",
      "level": 0
    },
    {
      "x": -4,
      "y": 3,
      "z": -6,
      "name": "Empty",
      "level": 0
    },
    {
      "x": -4,
      "y": 4,
      "z": -6,
      "name": "Empty",
      "level": 0
    },
    {
      "x": -4,
      "y": 5,
      "z": -6,
      "name": "Empty",
      "level": 0
    },
    {
      "x": -4,
      "y": 6,
      "z": -6,
      "name": "Empty",
      "level": 0
    },
    {
      "x": -4,
      "y": 7,
      "z": -6,
      "name": "Empty",
      "level": 0
    },
    {
      "x": -4,
      "y": 8,
      "z": -6,
      "name": "Empty",
      "level": 0
    },
    {
      "x": -4,
      "y": 4,
      "z": -5,
      "name": "Empty",
      "level": 0
    },
    {
      "x": -4,
      "y": 8,
      "z": -5,
      "name": "Empty",
      "level": 0
    },
    {
      "x": -4,
      "y": 9,
      "z": -5,
      "name": "Empty",
      "level": 0
    },
    {
      "x": -4,
      "y": 4,
      "z": -4,
      "name": "Empty",
      "level": 0
    },
    {
      "x": -4,
      "y": 9,
      "z": -4,
      "name": "Empty",
      "level": 0
    },
    {
      "x": -4,
      "y": 4,
      "z": -3,
      "name": "Empty",
      "level": 0
    },
    {
      "x": -4,
      "y": 9,
      "z": -3,
      "name": "Empty",
      "level": 0
    },
    {
      "x": -4,
      "y": 4,
      "z": -2,
      "name": "Empty",
      "level": 0
    },
    {
      "x": -4,
      "y": 9,
      "z": -2,
      "name": "Empty",
      "level": 0
    },
    {
      "x": -4,
      "y": 10,
      "z": -2,
      "name": "Empty",
      "level": 0
    },
    {
      "x": -4,
      "y": 9,
      "z": -1,
      "name": "Empty",
      "level": 0
    },
    {
      "x": -4,
      "y": 10,
      "z": -1,
      "name": "Empty",
      "level": 0
    },
    {
      "x": -4,
      "y": 9,
      "z": 0,
      "name": "Empty",
      "level": 0
    },
    {
      "x": -4,
      "y": 10,
      "z": 0,
      "name": "Empty",
      "level": 0
    },
    {
      "x": -4,
      "y": 9,
      "z": 1,
      "name": "Empty",
      "level": 0
    },
    {
      "x": -4,
      "y": 10,
      "z": 1,
      "name": "Empty",
      "level": 0
    },
    {
      "x": -4,
      "y": 9,
      "z": 2,
      "name": "Empty",
      "level": 0
    },
    {
      "x": -4,
      "y": 10,
      "z": 2,
      "name": "Empty",
      "level": 0
    },
    {
      "x": -4,
      "y": 4,
      "z": 3,
      "name": "Empty",
      "level": 0
    },
    {
      "x": -4,
      "y": 9,
      "z": 3,
      "name": "Empty",
      "level": 0
    },
    {
      "x": -4,
      "y": 10,
      "z": 3,
      "name": "Empty",
      "level": 0
    },
    {
      "x": -4,
      "y": 4,
      "z": 4,
      "name": "Empty",
      "level": 0
    },
    {
      "x": -4,
      "y": 5,
      "z": 4,
      "name": "Empty",
      "level": 0
    },
    {
      "x": -4,
      "y": 6,
      "z": 4,
      "name": "Empty",
      "level": 0
    },
    {
      "x": -4,
      "y": 7,
      "z": 4,
      "name": "Empty",
      "level": 0
    },
    {
      "x": -4,
      "y": 8,
      "z": 4,
      "name": "Empty",
      "level": 0
    },
    {
      "x": -4,
      "y": 9,
      "z": 4,
      "name": "Empty",
      "level": 0
    },
    {
      "x": -4,
      "y": 5,
      "z": 5,
      "name": "Empty",
      "level": 0
    },
    {
      "x": -4,
      "y": 6,
      "z": 5,
      "name": "Empty",
      "level": 0
    },
    {
      "x": -4,
      "y": 7,
      "z": 5,
      "name": "Empty",
      "level": 0
    },
    {
      "x": -4,
      "y": 8,
      "z": 5,
      "name": "Empty",
      "level": 0
    },
    {
      "x": -4,
      "y": 9,
      "z": 5,
      "name": "Empty",
      "level": 0
    },
    {
      "x": -4,
      "y": 7,
      "z": 6,
      "name": "Empty",
      "level": 0
    },
    {
      "x": -4,
      "y": 8,
      "z": 6,
      "name": "Empty",
      "level": 0
    },
    {
      "x": -3,
      "y": 1,
      "z": -8,
      "name": "Empty",
      "level": 0
    },
    {
      "x": -3,
      "y": 2,
      "z": -8,
      "name": "Empty",
      "level": 0
    },
    {
      "x": -3,
      "y": 3,
      "z": -8,
      "name": "Empty",
      "level": 0
    },
    {
      "x": -3,
      "y": 4,
      "z": -8,
      "name": "Empty",
      "level": 0
    },
    {
      "x": -3,
      "y": 5,
      "z": -8,
      "name": "Empty",
      "level": 0
    },
    {
      "x": -3,
      "y": 7,
      "z": -8,
      "name": "Empty",
      "level": 0
    },
    {
      "x": -3,
      "y": 8,
      "z": -8,
      "name": "Empty",
      "level": 0
    },
    {
      "x": -3,
      "y": 4,
      "z": -7,
      "name": "Empty",
      "level": 0
    },
    {
      "x": -3,
      "y": 6,
      "z": -7,
      "name": "Empty",
      "level": 0
    },
    {
      "x": -3,
      "y": 7,
      "z": -7,
      "name": "Empty",
      "level": 0
    },
    {
      "x": -3,
      "y": 8,
      "z": -7,
      "name": "Empty",
      "level": 0
    },
    {
      "x": -3,
      "y": 4,
      "z": -6,
      "name": "Empty",
      "level": 0
    },
    {
      "x": -3,
      "y": 9,
      "z": -6,
      "name": "Empty",
      "level": 0
    },
    {
      "x": -3,
      "y": 4,
      "z": -5,
      "name": "Empty",
      "level": 0
    },
    {
      "x": -3,
      "y": 9,
      "z": -5,
      "name": "Empty",
      "level": 0
    },
    {
      "x": -3,
      "y": 10,
      "z": -5,
      "name": "Empty",
      "level": 0
    },
    {
      "x": -3,
      "y": 4,
      "z": -4,
      "name": "Empty",
      "level": 0
    },
    {
      "x": -3,
      "y": 10,
      "z": -4,
      "name": "Empty",
      "level": 0
    },
    {
      "x": -3,
      "y": 4,
      "z": -3,
      "name": "Empty",
      "level": 0
    },
    {
      "x": -3,
      "y": 10,
      "z": -3,
      "name": "Empty",
      "level": 0
    },
    {
      "x": -3,
      "y": 4,
      "z": -2,
      "name": "Empty",
      "level": 0
    },
    {
      "x": -3,
      "y": 10,
      "z": -2,
      "name": "Empty",
      "level": 0
    },
    {
      "x": -3,
      "y": 1,
      "z": -1,
      "name": "Empty",
      "level": 0
    },
    {
      "x": -3,
      "y": 2,
      "z": -1,
      "name": "Empty",
      "level": 0
    },
    {
      "x": -3,
      "y": 3,
      "z": -1,
      "name": "Empty",
      "level": 0
    },
    {
      "x": -3,
      "y": 10,
      "z": -1,
      "name": "Empty",
      "level": 0
    },
    {
      "x": -3,
      "y": 11,
      "z": -1,
      "name": "Empty",
      "level": 0
    },
    {
      "x": -3,
      "y": 10,
      "z": 0,
      "name": "Empty",
      "level": 0
    },
    {
      "x": -3,
      "y": 11,
      "z": 0,
      "name": "Empty",
      "level": 0
    },
    {
      "x": -3,
      "y": 10,
      "z": 1,
      "name": "Empty",
      "level": 0
    },
    {
      "x": -3,
      "y": 11,
      "z": 1,
      "name": "Empty",
      "level": 0
    },
    {
      "x": -3,
      "y": 10,
      "z": 2,
      "name": "Empty",
      "level": 0
    },
    {
      "x": -3,
      "y": 11,
      "z": 2,
      "name": "Empty",
      "level": 0
    },
    {
      "x": -3,
      "y": 4,
      "z": 3,
      "name": "Empty",
      "level": 0
    },
    {
      "x": -3,
      "y": 10,
      "z": 3,
      "name": "Empty",
      "level": 0
    },
    {
      "x": -3,
      "y": 4,
      "z": 4,
      "name": "Empty",
      "level": 0
    },
    {
      "x": -3,
      "y": 10,
      "z": 4,
      "name": "Empty",
      "level": 0
    },
    {
      "x": -3,
      "y": 4,
      "z": 5,
      "name": "Empty",
      "level": 0
    },
    {
      "x": -3,
      "y": 5,
      "z": 5,
      "name": "Empty",
      "level": 0
    },
    {
      "x": -3,
      "y": 10,
      "z": 5,
      "name": "Empty",
      "level": 0
    },
    {
      "x": -3,
      "y": 6,
      "z": 6,
      "name": "Empty",
      "level": 0
    },
    {
      "x": -3,
      "y": 9,
      "z": 6,
      "name": "Empty",
      "level": 0
    },
    {
      "x": -3,
      "y": 7,
      "z": 7,
      "name": "Empty",
      "level": 0
    },
    {
      "x": -3,
      "y": 8,
      "z": 7,
      "name": "Empty",
      "level": 0
    },
    {
      "x": -2,
      "y": 2,
      "z": -9,
      "name": "Empty",
      "level": 0
    },
    {
      "x": -2,
      "y": 1,
      "z": -8,
      "name": "Empty",
      "level": 0
    },
    {
      "x": -2,
      "y": 2,
      "z": -8,
      "name": "Empty",
      "level": 0
    },
    {
      "x": -2,
      "y": 3,
      "z": -8,
      "name": "Empty",
      "level": 0
    },
    {
      "x": -2,
      "y": 4,
      "z": -8,
      "name": "Empty",
      "level": 0
    },
    {
      "x": -2,
      "y": 5,
      "z": -8,
      "name": "Empty",
      "level": 0
    },
    {
      "x": -2,
      "y": 7,
      "z": -8,
      "name": "Empty",
      "level": 0
    },
    {
      "x": -2,
      "y": 8,
      "z": -8,
      "name": "Empty",
      "level": 0
    },
    {
      "x": -2,
      "y": 4,
      "z": -7,
      "name": "Empty",
      "level": 0
    },
    {
      "x": -2,
      "y": 6,
      "z": -7,
      "name": "Empty",
      "level": 0
    },
    {
      "x": -2,
      "y": 7,
      "z": -7,
      "name": "Empty",
      "level": 0
    },
    {
      "x": -2,
      "y": 9,
      "z": -7,
      "name": "Empty",
      "level": 0
    },
    {
      "x": -2,
      "y": 4,
      "z": -6,
      "name": "Empty",
      "level": 0
    },
    {
      "x": -2,
      "y": 9,
      "z": -6,
      "name": "Empty",
      "level": 0
    },
    {
      "x": -2,
      "y": 10,
      "z": -6,
      "name": "Empty",
      "level": 0
    },
    {
      "x": -2,
      "y": 4,
      "z": -5,
      "name": "Empty",
      "level": 0
    },
    {
      "x": -2,
      "y": 10,
      "z": -5,
      "name": "Empty",
      "level": 0
    },
    {
      "x": -2,
      "y": 4,
      "z": -4,
      "name": "Empty",
      "level": 0
    },
    {
      "x": -2,
      "y": 10,
      "z": -4,
      "name": "Empty",
      "level": 0
    },
    {
      "x": -2,
      "y": 11,
      "z": -4,
      "name": "Empty",
      "level": 0
    },
    {
      "x": -2,
      "y": 4,
      "z": -3,
      "name": "Empty",
      "level": 0
    },
    {
      "x": -2,
      "y": 11,
      "z": -3,
      "name": "Empty",
      "level": 0
    },
    {
      "x": -2,
      "y": 4,
      "z": -2,
      "name": "Empty",
      "level": 0
    },
    {
      "x": -2,
      "y": 11,
      "z": -2,
      "name": "Empty",
      "level": 0
    },
    {
      "x": -2,
      "y": 1,
      "z": -1,
      "name": "Empty",
      "level": 0
    },
    {
      "x": -2,
      "y": 2,
      "z": -1,
      "name": "Empty",
      "level": 0
    },
    {
      "x": -2,
      "y": 3,
      "z": -1,
      "name": "Empty",
      "level": 0
    },
    {
      "x": -2,
      "y": 11,
      "z": -1,
      "name": "Empty",
      "level": 0
    },
    {
      "x": -2,
      "y": 11,
      "z": 0,
      "name": "Empty",
      "level": 0
    },
    {
      "x": -2,
      "y": 11,
      "z": 1,
      "name": "Empty",
      "level": 0
    },
    {
      "x": -2,
      "y": 11,
      "z": 2,
      "name": "Empty",
      "level": 0
    },
    {
      "x": -2,
      "y": 4,
      "z": 3,
      "name": "Empty",
      "level": 0
    },
    {
      "x": -2,
      "y": 11,
      "z": 3,
      "name": "Empty",
      "level": 0
    },
    {
      "x": -2,
      "y": 4,
      "z": 4,
      "name": "Empty",
      "level": 0
    },
    {
      "x": -2,
      "y": 11,
      "z": 4,
      "name": "Empty",
      "level": 0
    },
    {
      "x": -2,
      "y": 4,
      "z": 5,
      "name": "Empty",
      "level": 0
    },
    {
      "x": -2,
      "y": 5,
      "z": 5,
      "name": "Empty",
      "level": 0
    },
    {
      "x": -2,
      "y": 10,
      "z": 5,
      "name": "Empty",
      "level": 0
    },
    {
      "x": -2,
      "y": 11,
      "z": 5,
      "name": "Empty",
      "level": 0
    },
    {
      "x": -2,
      "y": 5,
      "z": 6,
      "name": "Empty",
      "level": 0
    },
    {
      "x": -2,
      "y": 6,
      "z": 6,
      "name": "Empty",
      "level": 0
    },
    {
      "x": -2,
      "y": 10,
      "z": 6,
      "name": "Empty",
      "level": 0
    },
    {
      "x": -2,
      "y": 7,
      "z": 7,
      "name": "Empty",
      "level": 0
    },
    {
      "x": -2,
      "y": 8,
      "z": 7,
      "name": "Empty",
      "level": 0
    },
    {
      "x": -2,
      "y": 9,
      "z": 7,
      "name": "Empty",
      "level": 0
    },
    {
      "x": -1,
      "y": 2,
      "z": -9,
      "name": "Empty",
      "level": 0
    },
    {
      "x": -1,
      "y": 1,
      "z": -8,
      "name": "Empty",
      "level": 0
    },
    {
      "x": -1,
      "y": 2,
      "z": -8,
      "name": "Empty",
      "level": 0
    },
    {
      "x": -1,
      "y": 3,
      "z": -8,
      "name": "Empty",
      "level": 0
    },
    {
      "x": -1,
      "y": 4,
      "z": -8,
      "name": "Empty",
      "level": 0
    },
    {
      "x": -1,
      "y": 5,
      "z": -8,
      "name": "Empty",
      "level": 0
    },
    {
      "x": -1,
      "y": 6,
      "z": -8,
      "name": "Empty",
      "level": 0
    },
    {
      "x": -1,
      "y": 7,
      "z": -8,
      "name": "Empty",
      "level": 0
    },
    {
      "x": -1,
      "y": 8,
      "z": -8,
      "name": "Empty",
      "level": 0
    },
    {
      "x": -1,
      "y": 4,
      "z": -7,
      "name": "Empty",
      "level": 0
    },
    {
      "x": -1,
      "y": 9,
      "z": -7,
      "name": "Empty",
      "level": 0
    },
    {
      "x": -1,
      "y": 4,
      "z": -6,
      "name": "Empty",
      "level": 0
    },
    {
      "x": -1,
      "y": 10,
      "z": -6,
      "name": "Empty",
      "level": 0
    },
    {
      "x": -1,
      "y": 4,
      "z": -5,
      "name": "Empty",
      "level": 0
    },
    {
      "x": -1,
      "y": 10,
      "z": -5,
      "name": "Empty",
      "level": 0
    },
    {
      "x": -1,
      "y": 4,
      "z": -4,
      "name": "Empty",
      "level": 0
    },
    {
      "x": -1,
      "y": 11,
      "z": -4,
      "name": "Empty",
      "level": 0
    },
    {
      "x": -1,
      "y": 4,
      "z": -3,
      "name": "Empty",
      "level": 0
    },
    {
      "x": -1,
      "y": 11,
      "z": -3,
      "name": "Empty",
      "level": 0
    },
    {
      "x": -1,
      "y": 4,
      "z": -2,
      "name": "Empty",
      "level": 0
    },
    {
      "x": -1,
      "y": 11,
      "z": -2,
      "name": "Empty",
      "level": 0
    },
    {
      "x": -1,
      "y": 1,
      "z": -1,
      "name": "Empty",
      "level": 0
    },
    {
      "x": -1,
      "y": 2,
      "z": -1,
      "name": "Empty",
      "level": 0
    },
    {
      "x": -1,
      "y": 3,
      "z": -1,
      "name": "Empty",
      "level": 0
    },
    {
      "x": -1,
      "y": 11,
      "z": -1,
      "name": "Empty",
      "level": 0
    },
    {
      "x": -1,
      "y": 11,
      "z": 0,
      "name": "Empty",
      "level": 0
    },
    {
      "x": -1,
      "y": 11,
      "z": 1,
      "name": "Empty",
      "level": 0
    },
    {
      "x": -1,
      "y": 11,
      "z": 2,
      "name": "Empty",
      "level": 0
    },
    {
      "x": -1,
      "y": 4,
      "z": 3,
      "name": "Empty",
      "level": 0
    },
    {
      "x": -1,
      "y": 11,
      "z": 3,
      "name": "Empty",
      "level": 0
    },
    {
      "x": -1,
      "y": 4,
      "z": 4,
      "name": "Empty",
      "level": 0
    },
    {
      "x": -1,
      "y": 11,
      "z": 4,
      "name": "Empty",
      "level": 0
    },
    {
      "x": -1,
      "y": 4,
      "z": 5,
      "name": "Empty",
      "level": 0
    },
    {
      "x": -1,
      "y": 5,
      "z": 5,
      "name": "Empty",
      "level": 0
    },
    {
      "x": -1,
      "y": 11,
      "z": 5,
      "name": "Empty",
      "level": 0
    },
    {
      "x": -1,
      "y": 5,
      "z": 6,
      "name": "Empty",
      "level": 0
    },
    {
      "x": -1,
      "y": 6,
      "z": 6,
      "name": "Empty",
      "level": 0
    },
    {
      "x": -1,
      "y": 10,
      "z": 6,
      "name": "Empty",
      "level": 0
    },
    {
      "x": -1,
      "y": 6,
      "z": 7,
      "name": "Empty",
      "level": 0
    },
    {
      "x": -1,
      "y": 7,
      "z": 7,
      "name": "Empty",
      "level": 0
    },
    {
      "x": -1,
      "y": 8,
      "z": 7,
      "name": "Empty",
      "level": 0
    },
    {
      "x": -1,
      "y": 9,
      "z": 7,
      "name": "Empty",
      "level": 0
    },
    {
      "x": 0,
      "y": 2,
      "z": -9,
      "name": "Empty",
      "level": 0
    },
    {
      "x": 0,
      "y": 6,
      "z": -9,
      "name": "Empty",
      "level": 0
    },
    {
      "x": 0,
      "y": 7,
      "z": -9,
      "name": "Empty",
      "level": 0
    },
    {
      "x": 0,
      "y": 1,
      "z": -8,
      "name": "Empty",
      "level": 0
    },
    {
      "x": 0,
      "y": 2,
      "z": -8,
      "name": "Empty",
      "level": 0
    },
    {
      "x": 0,
      "y": 3,
      "z": -8,
      "name": "Empty",
      "level": 0
    },
    {
      "x": 0,
      "y": 6,
      "z": -8,
      "name": "Empty",
      "level": 0
    },
    {
      "x": 0,
      "y": 7,
      "z": -8,
      "name": "Empty",
      "level": 0
    },
    {
      "x": 0,
      "y": 8,
      "z": -8,
      "name": "Empty",
      "level": 0
    },
    {
      "x": 0,
      "y": 4,
      "z": -7,
      "name": "Empty",
      "level": 0
    },
    {
      "x": 0,
      "y": 5,
      "z": -7,
      "name": "Empty",
      "level": 0
    },
    {
      "x": 0,
      "y": 9,
      "z": -7,
      "name": "Empty",
      "level": 0
    },
    {
      "x": 0,
      "y": 4,
      "z": -6,
      "name": "Empty",
      "level": 0
    },
    {
      "x": 0,
      "y": 10,
      "z": -6,
      "name": "Empty",
      "level": 0
    },
    {
      "x": 0,
      "y": 4,
      "z": -5,
      "name": "Empty",
      "level": 0
    },
    {
      "x": 0,
      "y": 10,
      "z": -5,
      "name": "Empty",
      "level": 0
    },
    {
      "x": 0,
      "y": 4,
      "z": -4,
      "name": "Empty",
      "level": 0
    },
    {
      "x": 0,
      "y": 11,
      "z": -4,
      "name": "Empty",
      "level": 0
    },
    {
      "x": 0,
      "y": 4,
      "z": -3,
      "name": "Empty",
      "level": 0
    },
    {
      "x": 0,
      "y": 11,
      "z": -3,
      "name": "Empty",
      "level": 0
    },
    {
      "x": 0,
      "y": 4,
      "z": -2,
      "name": "Empty",
      "level": 0
    },
    {
      "x": 0,
      "y": 11,
      "z": -2,
      "name": "Empty",
      "level": 0
    },
    {
      "x": 0,
      "y": 1,
      "z": -1,
      "name": "Empty",
      "level": 0
    },
    {
      "x": 0,
      "y": 2,
      "z": -1,
      "name": "Empty",
      "level": 0
    },
    {
      "x": 0,
      "y": 3,
      "z": -1,
      "name": "Empty",
      "level": 0
    },
    {
      "x": 0,
      "y": 11,
      "z": -1,
      "name": "Empty",
      "level": 0
    },
    {
      "x": 0,
      "y": 11,
      "z": 0,
      "name": "Empty",
      "level": 0
    },
    {
      "x": 0,
      "y": 11,
      "z": 1,
      "name": "Empty",
      "level": 0
    },
    {
      "x": 0,
      "y": 11,
      "z": 2,
      "name": "Empty",
      "level": 0
    },
    {
      "x": 0,
      "y": 4,
      "z": 3,
      "name": "Empty",
      "level": 0
    },
    {
      "x": 0,
      "y": 11,
      "z": 3,
      "name": "Empty",
      "level": 0
    },
    {
      "x": 0,
      "y": 4,
      "z": 4,
      "name": "Empty",
      "level": 0
    },
    {
      "x": 0,
      "y": 11,
      "z": 4,
      "name": "Empty",
      "level": 0
    },
    {
      "x": 0,
      "y": 4,
      "z": 5,
      "name": "Empty",
      "level": 0
    },
    {
      "x": 0,
      "y": 5,
      "z": 5,
      "name": "Empty",
      "level": 0
    },
    {
      "x": 0,
      "y": 11,
      "z": 5,
      "name": "Empty",
      "level": 0
    },
    {
      "x": 0,
      "y": 5,
      "z": 6,
      "name": "Empty",
      "level": 0
    },
    {
      "x": 0,
      "y": 6,
      "z": 6,
      "name": "Empty",
      "level": 0
    },
    {
      "x": 0,
      "y": 10,
      "z": 6,
      "name": "Empty",
      "level": 0
    },
    {
      "x": 0,
      "y": 6,
      "z": 7,
      "name": "Empty",
      "level": 0
    },
    {
      "x": 0,
      "y": 7,
      "z": 7,
      "name": "Empty",
      "level": 0
    },
    {
      "x": 0,
      "y": 8,
      "z": 7,
      "name": "Empty",
      "level": 0
    },
    {
      "x": 0,
      "y": 9,
      "z": 7,
      "name": "Empty",
      "level": 0
    },
    {
      "x": 1,
      "y": 2,
      "z": -9,
      "name": "Empty",
      "level": 0
    },
    {
      "x": 1,
      "y": 1,
      "z": -8,
      "name": "Empty",
      "level": 0
    },
    {
      "x": 1,
      "y": 2,
      "z": -8,
      "name": "Empty",
      "level": 0
    },
    {
      "x": 1,
      "y": 3,
      "z": -8,
      "name": "Empty",
      "level": 0
    },
    {
      "x": 1,
      "y": 4,
      "z": -8,
      "name": "Empty",
      "level": 0
    },
    {
      "x": 1,
      "y": 5,
      "z": -8,
      "name": "Empty",
      "level": 0
    },
    {
      "x": 1,
      "y": 6,
      "z": -8,
      "name": "Empty",
      "level": 0
    },
    {
      "x": 1,
      "y": 7,
      "z": -8,
      "name": "Empty",
      "level": 0
    },
    {
      "x": 1,
      "y": 8,
      "z": -8,
      "name": "Empty",
      "level": 0
    },
    {
      "x": 1,
      "y": 4,
      "z": -7,
      "name": "Empty",
      "level": 0
    },
    {
      "x": 1,
      "y": 9,
      "z": -7,
      "name": "Empty",
      "level": 0
    },
    {
      "x": 1,
      "y": 4,
      "z": -6,
      "name": "Empty",
      "level": 0
    },
    {
      "x": 1,
      "y": 10,
      "z": -6,
      "name": "Empty",
      "level": 0
    },
    {
      "x": 1,
      "y": 4,
      "z": -5,
      "name": "Empty",
      "level": 0
    },
    {
      "x": 1,
      "y": 10,
      "z": -5,
      "name": "Empty",
      "level": 0
    },
    {
      "x": 1,
      "y": 4,
      "z": -4,
      "name": "Empty",
      "level": 0
    },
    {
      "x": 1,
      "y": 11,
      "z": -4,
      "name": "Empty",
      "level": 0
    },
    {
      "x": 1,
      "y": 4,
      "z": -3,
      "name": "Empty",
      "level": 0
    },
    {
      "x": 1,
      "y": 11,
      "z": -3,
      "name": "Empty",
      "level": 0
    },
    {
      "x": 1,
      "y": 4,
      "z": -2,
      "name": "Empty",
      "level": 0
    },
    {
      "x": 1,
      "y": 11,
      "z": -2,
      "name": "Empty",
      "level": 0
    },
    {
      "x": 1,
      "y": 1,
      "z": -1,
      "name": "Empty",
      "level": 0
    },
    {
      "x": 1,
      "y": 2,
      "z": -1,
      "name": "Empty",
      "level": 0
    },
    {
      "x": 1,
      "y": 3,
      "z": -1,
      "name": "Empty",
      "level": 0
    },
    {
      "x": 1,
      "y": 11,
      "z": -1,
      "name": "Empty",
      "level": 0
    },
    {
      "x": 1,
      "y": 11,
      "z": 0,
      "name": "Empty",
      "level": 0
    },
    {
      "x": 1,
      "y": 11,
      "z": 1,
      "name": "Empty",
      "level": 0
    },
    {
      "x": 1,
      "y": 11,
      "z": 2,
      "name": "Empty",
      "level": 0
    },
    {
      "x": 1,
      "y": 4,
      "z": 3,
      "name": "Empty",
      "level": 0
    },
    {
      "x": 1,
      "y": 11,
      "z": 3,
      "name": "Empty",
      "level": 0
    },
    {
      "x": 1,
      "y": 4,
      "z": 4,
      "name": "Empty",
      "level": 0
    },
    {
      "x": 1,
      "y": 11,
      "z": 4,
      "name": "Empty",
      "level": 0
    },
    {
      "x": 1,
      "y": 4,
      "z": 5,
      "name": "Empty",
      "level": 0
    },
    {
      "x": 1,
      "y": 5,
      "z": 5,
      "name": "Empty",
      "level": 0
    },
    {
      "x": 1,
      "y": 11,
      "z": 5,
      "name": "Empty",
      "level": 0
    },
    {
      "x": 1,
      "y": 5,
      "z": 6,
      "name": "Empty",
      "level": 0
    },
    {
      "x": 1,
      "y": 6,
      "z": 6,
      "name": "Empty",
      "level": 0
    },
    {
      "x": 1,
      "y": 10,
      "z": 6,
      "name": "Empty",
      "level": 0
    },
    {
      "x": 1,
      "y": 6,
      "z": 7,
      "name": "Empty",
      "level": 0
    },
    {
      "x": 1,
      "y": 7,
      "z": 7,
      "name": "Empty",
      "level": 0
    },
    {
      "x": 1,
      "y": 8,
      "z": 7,
      "name": "Empty",
      "level": 0
    },
    {
      "x": 1,
      "y": 9,
      "z": 7,
      "name": "Empty",
      "level": 0
    },
    {
      "x": 2,
      "y": 2,
      "z": -9,
      "name": "Empty",
      "level": 0
    },
    {
      "x": 2,
      "y": 1,
      "z": -8,
      "name": "Empty",
      "level": 0
    },
    {
      "x": 2,
      "y": 2,
      "z": -8,
      "name": "Empty",
      "level": 0
    },
    {
      "x": 2,
      "y": 3,
      "z": -8,
      "name": "Empty",
      "level": 0
    },
    {
      "x": 2,
      "y": 4,
      "z": -8,
      "name": "Empty",
      "level": 0
    },
    {
      "x": 2,
      "y": 5,
      "z": -8,
      "name": "Empty",
      "level": 0
    },
    {
      "x": 2,
      "y": 7,
      "z": -8,
      "name": "Empty",
      "level": 0
    },
    {
      "x": 2,
      "y": 8,
      "z": -8,
      "name": "Empty",
      "level": 0
    },
    {
      "x": 2,
      "y": 4,
      "z": -7,
      "name": "Empty",
      "level": 0
    },
    {
      "x": 2,
      "y": 6,
      "z": -7,
      "name": "Empty",
      "level": 0
    },
    {
      "x": 2,
      "y": 7,
      "z": -7,
      "name": "Empty",
      "level": 0
    },
    {
      "x": 2,
      "y": 9,
      "z": -7,
      "name": "Empty",
      "level": 0
    },
    {
      "x": 2,
      "y": 4,
      "z": -6,
      "name": "Empty",
      "level": 0
    },
    {
      "x": 2,
      "y": 9,
      "z": -6,
      "name": "Empty",
      "level": 0
    },
    {
      "x": 2,
      "y": 10,
      "z": -6,
      "name": "Empty",
      "level": 0
    },
    {
      "x": 2,
      "y": 4,
      "z": -5,
      "name": "Empty",
      "level": 0
    },
    {
      "x": 2,
      "y": 10,
      "z": -5,
      "name": "Empty",
      "level": 0
    },
    {
      "x": 2,
      "y": 4,
      "z": -4,
      "name": "Empty",
      "level": 0
    },
    {
      "x": 2,
      "y": 10,
      "z": -4,
      "name": "Empty",
      "level": 0
    },
    {
      "x": 2,
      "y": 11,
      "z": -4,
      "name": "Empty",
      "level": 0
    },
    {
      "x": 2,
      "y": 4,
      "z": -3,
      "name": "Empty",
      "level": 0
    },
    {
      "x": 2,
      "y": 11,
      "z": -3,
      "name": "Empty",
      "level": 0
    },
    {
      "x": 2,
      "y": 4,
      "z": -2,
      "name": "Empty",
      "level": 0
    },
    {
      "x": 2,
      "y": 11,
      "z": -2,
      "name": "Empty",
      "level": 0
    },
    {
      "x": 2,
      "y": 1,
      "z": -1,
      "name": "Empty",
      "level": 0
    },
    {
      "x": 2,
      "y": 2,
      "z": -1,
      "name": "Empty",
      "level": 0
    },
    {
      "x": 2,
      "y": 3,
      "z": -1,
      "name": "Empty",
      "level": 0
    },
    {
      "x": 2,
      "y": 11,
      "z": -1,
      "name": "Empty",
      "level": 0
    },
    {
      "x": 2,
      "y": 11,
      "z": 0,
      "name": "Empty",
      "level": 0
    },
    {
      "x": 2,
      "y": 11,
      "z": 1,
      "name": "Empty",
      "level": 0
    },
    {
      "x": 2,
      "y": 11,
      "z": 2,
      "name": "Empty",
      "level": 0
    },
    {
      "x": 2,
      "y": 4,
      "z": 3,
      "name": "Empty",
      "level": 0
    },
    {
      "x": 2,
      "y": 11,
      "z": 3,
      "name": "Empty",
      "level": 0
    },
    {
      "x": 2,
      "y": 4,
      "z": 4,
      "name": "Empty",
      "level": 0
    },
    {
      "x": 2,
      "y": 11,
      "z": 4,
      "name": "Empty",
      "level": 0
    },
    {
      "x": 2,
      "y": 4,
      "z": 5,
      "name": "Empty",
      "level": 0
    },
    {
      "x": 2,
      "y": 5,
      "z": 5,
      "name": "Empty",
      "level": 0
    },
    {
      "x": 2,
      "y": 10,
      "z": 5,
      "name": "Empty",
      "level": 0
    },
    {
      "x": 2,
      "y": 11,
      "z": 5,
      "name": "Empty",
      "level": 0
    },
    {
      "x": 2,
      "y": 5,
      "z": 6,
      "name": "Empty",
